Workbook

Sheet Sheet1
A1: ID | B1: Description | C1: Level | D1: Color | E1: Exp | F1: NextLevelExp | G1: NextLevelID | H1: NodeTemplateID1 | I1: NodeTemplateID2 | J1: ExchangeCount | K1: GroupID | L1: ExChangeAvaible | M1: JobLimitedShow | N1: BroadcastStringID | O1: Icon0
A2: Both | B2: Client | C2: Both | D2: Both | E2: Both | F2: Both | G2: Both | H2: Both | I2: Both | J2: Both | K2: Both | L2: Both | M2: Both | N2: Both | O2: Client
A3: 0 | B3: Null | C3: 0 | D3: 0 | E3: 0 | F3: 0 | G3: 0 | H3: 0 | I3: 0 | J3: 0 | K3: 0 | L3: 0 | M3: -1 | N3: 0
A4: 101 | B4: 热血 | C4: 1 | D4: 1 | E4: 30 | F4: 120 | G4: =IF(C4=10,A4,A4+1) -> 102 | H4: 0 | I4: 0 | J4: 0 | K4: 1 | L4: 0 | M4: -1 | N4: 0 | O4: MMOUI_HeavenFx_Lib/1
A5: 102 | B5: 热血 | C5: 2 | D5: 1 | E5: 30 | F5: 240 | G5: =IF(C5=10,A5,A5+1) -> 103 | H5: 0 | I5: 0 | J5: 0 | K5: 1 | L5: 0 | M5: -1 | N5: 0 | O5: MMOUI_HeavenFx_Lib/1
A6: 103 | B6: 热血 | C6: 3 | D6: 1 | E6: 30 | F6: =F5*2 -> 480 | G6: =IF(C6=10,A6,A6+1) -> 104 | H6: 0 | I6: 0 | J6: 0 | K6: 1 | L6: 0 | M6: -1 | N6: 0 | O6: MMOUI_HeavenFx_Lib/1
A7: 104 | B7: 热血 | C7: 4 | D7: 1 | E7: 30 | F7: =F6*2 -> 960 | G7: =IF(C7=10,A7,A7+1) -> 105 | H7: 0 | I7: 0 | J7: 0 | K7: 1 | L7: 0 | M7: -1 | N7: 0 | O7: MMOUI_HeavenFx_Lib/1
A8: 105 | B8: 热血 | C8: 5 | D8: 1 | E8: 30 | F8: =F7*2 -> 1920 | G8: =IF(C8=10,A8,A8+1) -> 106 | H8: 0 | I8: 0 | J8: 0 | K8: 1 | L8: 0 | M8: -1 | N8: 0 | O8: MMOUI_HeavenFx_Lib/1
A9: 106 | B9: 热血 | C9: 6 | D9: 1 | E9: 30 | F9: =F8*2 -> 3840 | G9: =IF(C9=10,A9,A9+1) -> 107 | H9: 0 | I9: 0 | J9: 0 | K9: 1 | L9: 0 | M9: -1 | N9: 0 | O9: MMOUI_HeavenFx_Lib/1
A10: 107 | B10: 热血 | C10: 7 | D10: 1 | E10: 30 | F10: =F9*2 -> 7680 | G10: =IF(C10=10,A10,A10+1) -> 108 | H10: 0 | I10: 0 | J10: 0 | K10: 1 | L10: 0 | M10: -1 | N10: 0 | O10: MMOUI_HeavenFx_Lib/1
A11: 108 | B11: 热血 | C11: 8 | D11: 1 | E11: 30 | F11: =F10*2 -> 15360 | G11: =IF(C11=10,A11,A11+1) -> 109 | H11: 0 | I11: 0 | J11: 0 | K11: 1 | L11: 0 | M11: -1 | N11: 0 | O11: MMOUI_HeavenFx_Lib/1
A12: 109 | B12: 热血 | C12: 9 | D12: 1 | E12: 30 | F12: =F11*2 -> 30720 | G12: =IF(C12=10,A12,A12+1) -> 110 | H12: 0 | I12: 0 | J12: 0 | K12: 1 | L12: 0 | M12: -1 | N12: 0 | O12: MMOUI_HeavenFx_Lib/1
A13: 110 | B13: 热血 | C13: 10 | D13: 1 | E13: 30 | F13: =F12*2 -> 61440 | G13: =IF(C13=10,A13,A13+1) -> 110 | H13: 0 | I13: 0 | J13: 0 | K13: 1 | L13: 0 | M13: -1 | N13: 0 | O13: MMOUI_HeavenFx_Lib/1
A14: 111 | B14: 岩御 | C14: 1 | D14: 1 | E14: 30 | F14: 120 | G14: =IF(C14=10,A14,A14+1) -> 112 | H14: 0 | I14: 0 | J14: 0 | K14: 2 | L14: 0 | M14: -1 | N14: 0 | O14: MMOUI_HeavenFx_Lib/2
A15: 112 | B15: 岩御 | C15: 2 | D15: 1 | E15: 30 | F15: 240 | G15: =IF(C15=10,A15,A15+1) -> 113 | H15: 0 | I15: 0 | J15: 0 | K15: 2 | L15: 0 | M15: -1 | N15: 0 | O15: MMOUI_HeavenFx_Lib/2
A16: 113 | B16: 岩御 | C16: 3 | D16: 1 | E16: 30 | F16: =F15*2 -> 480 | G16: =IF(C16=10,A16,A16+1) -> 114 | H16: 0 | I16: 0 | J16: 0 | K16: 2 | L16: 0 | M16: -1 | N16: 0 | O16: MMOUI_HeavenFx_Lib/2
A17: 114 | B17: 岩御 | C17: 4 | D17: 1 | E17: 30 | F17: =F16*2 -> 960 | G17: =IF(C17=10,A17,A17+1) -> 115 | H17: 0 | I17: 0 | J17: 0 | K17: 2 | L17: 0 | M17: -1 | N17: 0 | O17: MMOUI_HeavenFx_Lib/2
A18: 115 | B18: 岩御 | C18: 5 | D18: 1 | E18: 30 | F18: =F17*2 -> 1920 | G18: =IF(C18=10,A18,A18+1) -> 116 | H18: 0 | I18: 0 | J18: 0 | K18: 2 | L18: 0 | M18: -1 | N18: 0 | O18: MMOUI_HeavenFx_Lib/2
A19: 116 | B19: 岩御 | C19: 6 | D19: 1 | E19: 30 | F19: =F18*2 -> 3840 | G19: =IF(C19=10,A19,A19+1) -> 117 | H19: 0 | I19: 0 | J19: 0 | K19: 2 | L19: 0 | M19: -1 | N19: 0 | O19: MMOUI_HeavenFx_Lib/2
A20: 117 | B20: 岩御 | C20: 7 | D20: 1 | E20: 30 | F20: =F19*2 -> 7680 | G20: =IF(C20=10,A20,A20+1) -> 118 | H20: 0 | I20: 0 | J20: 0 | K20: 2 | L20: 0 | M20: -1 | N20: 0 | O20: MMOUI_HeavenFx_Lib/2
A21: 118 | B21: 岩御 | C21: 8 | D21: 1 | E21: 30 | F21: =F20*2 -> 15360 | G21: =IF(C21=10,A21,A21+1) -> 119 | H21: 0 | I21: 0 | J21: 0 | K21: 2 | L21: 0 | M21: -1 | N21: 0 | O21: MMOUI_HeavenFx_Lib/2
A22: 119 | B22: 岩御 | C22: 9 | D22: 1 | E22: 30 | F22: =F21*2 -> 30720 | G22: =IF(C22=10,A22,A22+1) -> 120 | H22: 0 | I22: 0 | J22: 0 | K22: 2 | L22: 0 | M22: -1 | N22: 0 | O22: MMOUI_HeavenFx_Lib/2
A23: 120 | B23: 岩御 | C23: 10 | D23: 1 | E23: 30 | F23: =F22*2 -> 61440 | G23: =IF(C23=10,A23,A23+1) -> 120 | H23: 0 | I23: 0 | J23: 0 | K23: 2 | L23: 0 | M23: -1 | N23: 0 | O23: MMOUI_HeavenFx_Lib/2
A24: 121 | B24: 斩铁 | C24: 1 | D24: 1 | E24: 30 | F24: 120 | G24: =IF(C24=10,A24,A24+1) -> 122 | H24: 0 | I24: 0 | J24: 0 | K24: 3 | L24: 0 | M24: -1 | N24: 0 | O24: MMOUI_HeavenFx_Lib/3
A25: 122 | B25: 斩铁 | C25: 2 | D25: 1 | E25: 30 | F25: 240 | G25: =IF(C25=10,A25,A25+1) -> 123 | H25: 0 | I25: 0 | J25: 0 | K25: 3 | L25: 0 | M25: -1 | N25: 0 | O25: MMOUI_HeavenFx_Lib/3
A26: 123 | B26: 斩铁 | C26: 3 | D26: 1 | E26: 30 | F26: =F25*2 -> 480 | G26: =IF(C26=10,A26,A26+1) -> 124 | H26: 0 | I26: 0 | J26: 0 | K26: 3 | L26: 0 | M26: -1 | N26: 0 | O26: MMOUI_HeavenFx_Lib/3
A27: 124 | B27: 斩铁 | C27: 4 | D27: 1 | E27: 30 | F27: =F26*2 -> 960 | G27: =IF(C27=10,A27,A27+1) -> 125 | H27: 0 | I27: 0 | J27: 0 | K27: 3 | L27: 0 | M27: -1 | N27: 0 | O27: MMOUI_HeavenFx_Lib/3
A28: 125 | B28: 斩铁 | C28: 5 | D28: 1 | E28: 30 | F28: =F27*2 -> 1920 | G28: =IF(C28=10,A28,A28+1) -> 126 | H28: 0 | I28: 0 | J28: 0 | K28: 3 | L28: 0 | M28: -1 | N28: 0 | O28: MMOUI_HeavenFx_Lib/3
A29: 126 | B29: 斩铁 | C29: 6 | D29: 1 | E29: 30 | F29: =F28*2 -> 3840 | G29: =IF(C29=10,A29,A29+1) -> 127 | H29: 0 | I29: 0 | J29: 0 | K29: 3 | L29: 0 | M29: -1 | N29: 0 | O29: MMOUI_HeavenFx_Lib/3
A30: 127 | B30: 斩铁 | C30: 7 | D30: 1 | E30: 30 | F30: =F29*2 -> 7680 | G30: =IF(C30=10,A30,A30+1) -> 128 | H30: 0 | I30: 0 | J30: 0 | K30: 3 | L30: 0 | M30: -1 | N30: 0 | O30: MMOUI_HeavenFx_Lib/3
A31: 128 | B31: 斩铁 | C31: 8 | D31: 1 | E31: 30 | F31: =F30*2 -> 15360 | G31: =IF(C31=10,A31,A31+1) -> 129 | H31: 0 | I31: 0 | J31: 0 | K31: 3 | L31: 0 | M31: -1 | N31: 0 | O31: MMOUI_HeavenFx_Lib/3
A32: 129 | B32: 斩铁 | C32: 9 | D32: 1 | E32: 30 | F32: =F31*2 -> 30720 | G32: =IF(C32=10,A32,A32+1) -> 130 | H32: 0 | I32: 0 | J32: 0 | K32: 3 | L32: 0 | M32: -1 | N32: 0 | O32: MMOUI_HeavenFx_Lib/3
A33: 130 | B33: 斩铁 | C33: 10 | D33: 1 | E33: 30 | F33: =F32*2 -> 61440 | G33: =IF(C33=10,A33,A33+1) -> 130 | H33: 0 | I33: 0 | J33: 0 | K33: 3 | L33: 0 | M33: -1 | N33: 0 | O33: MMOUI_HeavenFx_Lib/3
A34: 181 | B34: 必中 | C34: 1 | D34: 1 | E34: 30 | F34: 120 | G34: =IF(C34=10,A34,A34+1) -> 182 | H34: 0 | I34: 0 | J34: 0 | K34: 9 | L34: 0 | M34: -1 | N34: 0 | O34: MMOUI_HeavenFx_Lib/9
A35: 182 | B35: 必中 | C35: 2 | D35: 1 | E35: 30 | F35: 240 | G35: =IF(C35=10,A35,A35+1) -> 183 | H35: 0 | I35: 0 | J35: 0 | K35: 9 | L35: 0 | M35: -1 | N35: 0 | O35: MMOUI_HeavenFx_Lib/9
A36: 183 | B36: 必中 | C36: 3 | D36: 1 | E36: 30 | F36: =F35*2 -> 480 | G36: =IF(C36=10,A36,A36+1) -> 184 | H36: 0 | I36: 0 | J36: 0 | K36: 9 | L36: 0 | M36: -1 | N36: 0 | O36: MMOUI_HeavenFx_Lib/9
A37: 184 | B37: 必中 | C37: 4 | D37: 1 | E37: 30 | F37: =F36*2 -> 960 | G37: =IF(C37=10,A37,A37+1) -> 185 | H37: 0 | I37: 0 | J37: 0 | K37: 9 | L37: 0 | M37: -1 | N37: 0 | O37: MMOUI_HeavenFx_Lib/9
A38: 185 | B38: 必中 | C38: 5 | D38: 1 | E38: 30 | F38: =F37*2 -> 1920 | G38: =IF(C38=10,A38,A38+1) -> 186 | H38: 0 | I38: 0 | J38: 0 | K38: 9 | L38: 0 | M38: -1 | N38: 0 | O38: MMOUI_HeavenFx_Lib/9
A39: 186 | B39: 必中 | C39: 6 | D39: 1 | E39: 30 | F39: =F38*2 -> 3840 | G39: =IF(C39=10,A39,A39+1) -> 187 | H39: 0 | I39: 0 | J39: 0 | K39: 9 | L39: 0 | M39: -1 | N39: 0 | O39: MMOUI_HeavenFx_Lib/9
A40: 187 | B40: 必中 | C40: 7 | D40: 1 | E40: 30 | F40: =F39*2 -> 7680 | G40: =IF(C40=10,A40,A40+1) -> 188 | H40: 0 | I40: 0 | J40: 0 | K40: 9 | L40: 0 | M40: -1 | N40: 0 | O40: MMOUI_HeavenFx_Lib/9
...

Sheet ICON索引
A1: 技能名称 | B1: ICON
A2: 精通格档 | B2: MMOUI_HeavenFx_Lib/1
A3: 盾牌大师 | B3: MMOUI_HeavenFx_Lib/2
A4: 无懈防御 | B4: MMOUI_HeavenFx_Lib/3
A5: 精通双手 | B5: MMOUI_HeavenFx_Lib/4
A6: 怒火中烧 | B6: MMOUI_HeavenFx_Lib/5
A7: 战斗意志 | B7: MMOUI_HeavenFx_Lib/6
A8: 战场暴君 | B8: MMOUI_HeavenFx_Lib/7
A9: 奋战不息 | B9: MMOUI_HeavenFx_Lib/8
A10: 烈焰斗气 | B10: MMOUI_HeavenFx_Lib/9
A11: 忍死术 | B11: MMOUI_HeavenFx_Lib/10
A12: 残影乱闪 | B12: MMOUI_HeavenFx_Lib/11
... A41: 时间之流 | B41: MMOUI_HeavenFx_Lib/40

Sheet 备注
A1: ID | B1: 名称 | C1: 等级 | D1: 品质 0白色 | E1: Exp 经验 | F1: NextLevelExp 下级经验 | G1: NextLevelID 对应下个ID | H1: NodeTemplateID1 | I1: NodeTemplateID2 | J1: ExchangeCount 万法之气对应量 | K1: 万法之气是否兑换 | L1: 职业分类兑换 -1不限0战士1法师2刺客3弓手 | M1: Icon0 | N1: Icon1
A2: 0 | B2: Null | C2: 0 | D2: 0 | E2: 0 | G2: 0 | J2: 0 | M2: 中心 | N2: 外围
