Workbook

Sheet Sheet1
A1: DropGroupID | B1: Enabled | C1: ModChanceByLevel | D1: RandomDur | E1: DropLimitType | F1: CheckDropLimit | G1: Item | H1: Weight | I1: CountMin | J1: CountMax | K1: desc
A2: Both | B2: Both | C2: Server | D2: Server | E2: Server | F2: Server | G2: Both | H2: Both | I2: Both | J2: Both | K2: Client
A3: 0 | B3: 0 | C3: 1 | D3: 1 | E3: 0 | F3: 1 | G3: 0 | H3: 0 | I3: 0 | J3: 0 | K3: 0
A4: 301 | B4: 1 | C4: 1 | D4: 0 | E4: 0 | F4: 1 | G4: 301 | H4: 1 | I4: 1 | J4: 1 | K4: 金创药(小量)
A5: 302 | B5: 1 | C5: 1 | D5: 0 | E5: 0 | F5: 1 | G5: 302 | H5: 1 | I5: 1 | J5: 1 | K5: 金创药(中量)
A6: 303 | B6: 1 | C6: 1 | D6: 0 | E6: 0 | F6: 1 | G6: 303 | H6: 1 | I6: 1 | J6: 1 | K6: 强效金创药
A7: 304 | B7: 1 | C7: 1 | D7: 0 | E7: 0 | F7: 1 | G7: 304 | H7: 1 | I7: 1 | J7: 1 | K7: 超强金创药（占位）
A8: 305 | B8: 1 | C8: 1 | D8: 0 | E8: 0 | F8: 1 | G8: 305 | H8: 1 | I8: 1 | J8: 1 | K8: 金创药（占位）
A9: 311 | B9: 1 | C9: 1 | D9: 0 | E9: 0 | F9: 1 | G9: 311 | H9: 1 | I9: 1 | J9: 1 | K9: 小金创药(绑定)
A10: 312 | B10: 1 | C10: 1 | D10: 0 | E10: 0 | F10: 1 | G10: 312 | H10: 1 | I10: 1 | J10: 1 | K10: 中金创药(绑定)
A11: 321 | B11: 1 | C11: 1 | D11: 0 | E11: 0 | F11: 1 | G11: 321 | H11: 1 | I11: 1 | J11: 1 | K11: 魔法药(小量)
A12: 322 | B12: 1 | C12: 1 | D12: 0 | E12: 0 | F12: 1 | G12: 322 | H12: 1 | I12: 1 | J12: 1 | K12: 魔法药(中量)
A13: 323 | B13: 1 | C13: 1 | D13: 0 | E13: 0 | F13: 1 | G13: 323 | H13: 1 | I13: 1 | J13: 1 | K13: 强效魔法药
A14: 324 | B14: 1 | C14: 1 | D14: 0 | E14: 0 | F14: 1 | G14: 324 | H14: 1 | I14: 1 | J14: 1 | K14: 超强魔法药(占位）
A15: 331 | B15: 1 | C15: 1 | D15: 0 | E15: 0 | F15: 1 | G15: 331 | H15: 1 | I15: 1 | J15: 1 | K15: 新手药水(绑定)
... A360: 110001 | B360: 1 | C360: 1 | D360: 0 | E360: 0 | F360: 1 | G360: 111004 | H360: 1 | I360: 1 | J360: 1 | K360: 草药
A361: 111001 | B361: 1 | C361: 1 | D361: 0 | E361: 0 | F361: 1 | G361: 111001 | H361: 1 | I361: =ROUND(RIGHT(A361,3)*80%,0) -> 1 | J361: =ROUND(RIGHT(A361,3)*120%,0) -> 1 | K361: 装备碎片1
A362: 111002 | B362: 1 | C362: 1 | D362: 0 | E362: 0 | F362: 1 | G362: 111001 | H362: 1 | I362: =ROUND(RIGHT(A362,3)*80%,0) -> 2 | J362: =ROUND(RIGHT(A362,3)*120%,0) -> 2 | K362: 装备碎片2
A363: 111003 | B363: 1 | C363: 1 | D363: 0 | E363: 0 | F363: 1 | G363: 111001 | H363: 1 | I363: =ROUND(RIGHT(A363,3)*80%,0) -> 2 | J363: =ROUND(RIGHT(A363,3)*120%,0) -> 4 | K363: 装备碎片3
A364: 111004 | B364: 1 | C364: 1 | D364: 0 | E364: 0 | F364: 1 | G364: 111001 | H364: 1 | I364: =ROUND(RIGHT(A364,3)*80%,0) -> 3 | J364: =ROUND(RIGHT(A364,3)*120%,0) -> 5 | K364: 装备碎片4
A365: 111005 | B365: 1 | C365: 1 | D365: 0 | E365: 0 | F365: 1 | G365: 111001 | H365: 1 | I365: =ROUND(RIGHT(A365,3)*80%,0) -> 4 | J365: =ROUND(RIGHT(A365,3)*120%,0) -> 6 | K365: 装备碎片5
A366: 111006 | B366: 1 | C366: 1 | D366: 0 | E366: 0 | F366: 1 | G366: 111001 | H366: 1 | I366: =ROUND(RIGHT(A366,3)*80%,0) -> 5 | J366: =ROUND(RIGHT(A366,3)*120%,0) -> 7 | K366: 装备碎片6
A367: 111007 | B367: 1 | C367: 1 | D367: 0 | E367: 0 | F367: 1 | G367: 111001 | H367: 1 | I367: =ROUND(RIGHT(A367,3)*80%,0) -> 6 | J367: =ROUND(RIGHT(A367,3)*120%,0) -> 8 | K367: 装备碎片7
A368: 111008 | B368: 1 | C368: 1 | D368: 0 | E368: 0 | F368: 1 | G368: 111001 | H368: 1 | I368: =ROUND(RIGHT(A368,3)*80%,0) -> 6 | J368: =ROUND(RIGHT(A368,3)*120%,0) -> 10 | K368: 装备碎片8
A369: 111009 | B369: 1 | C369: 1 | D369: 0 | E369: 0 | F369: 1 | G369: 111001 | H369: 1 | I369: =ROUND(RIGHT(A369,3)*80%,0) -> 7 | J369: =ROUND(RIGHT(A369,3)*120%,0) -> 11 | K369: 装备碎片9
A370: 111010 | B370: 1 | C370: 1 | D370: 0 | E370: 0 | F370: 1 | G370: 111001 | H370: 1 | I370: =ROUND(RIGHT(A370,3)*80%,0) -> 8 | J370: =ROUND(RIGHT(A370,3)*120%,0) -> 12 | K370: 装备碎片10
A371: 111011 | B371: 1 | C371: 1 | D371: 0 | E371: 0 | F371: 1 | G371: 111001 | H371: 1 | I371: =ROUND(RIGHT(A371,3)*80%,0) -> 9 | J371: =ROUND(RIGHT(A371,3)*120%,0) -> 13 | K371: 装备碎片11
A372: 111012 | B372: 1 | C372: 1 | D372: 0 | E372: 0 | F372: 1 | G372: 111001 | H372: 1 | I372: =ROUND(RIGHT(A372,3)*80%,0) -> 10 | J372: =ROUND(RIGHT(A372,3)*120%,0) -> 14 | K372: 装备碎片12
... A1859: 112500 | B1859: 1 | C1859: 1 | D1859: 0 | E1859: 0 | F1859: 1 | G1859: 111003 | H1859: 1 | I1859: =ROUND(RIGHT(A1859,3)*80%,0) -> 400 | J1859: =ROUND(RIGHT(A1859,3)*120%,0) -> 600 | K1859: 技能书碎片500
A1860: 114000 | B1860: 1 | C1860: 1 | D1860: 0 | E1860: 0 | F1860: 1 | G1860: 114003 | H1860: 6818 | I1860: 1 | J1860: 1 | K1860: 挖矿1
A1861: 114000 | B1861: 1 | C1861: 1 | D1861: 0 | E1861: 0 | F1861: 1 | G1861: 114004 | H1861: 6851 | I1861: 1 | J1861: 1 | K1861: 挖矿2
A1862: 114000 | B1862: 1 | C1862: 1 | D1862: 0 | E1862: 0 | F1862: 1 | G1862: 114005 | H1862: 6883 | I1862: 1 | J1862: 1 | K1862: 挖矿3
A1863: 114000 | B1863: 1 | C1863: 1 | D1863: 0 | E1863: 0 | F1863: 1 | G1863: 114006 | H1863: 6916 | I1863: 1 | J1863: 1 | K1863: 挖矿4
A1864: 114000 | B1864: 1 | C1864: 1 | D1864: 0 | E1864: 0 | F1864: 1 | G1864: 114007 | H1864: 6948 | I1864: 1 | J1864: 1 | K1864: 挖矿5
A1865: 114000 | B1865: 1 | C1865: 1 | D1865: 0 | E1865: 0 | F1865: 1 | G1865: 114008 | H1865: 6981 | I1865: 1 | J1865: 1 | K1865: 挖矿6
A1866: 114000 | B1866: 1 | C1866: 1 | D1866: 0 | E1866: 0 | F1866: 1 | G1866: 114009 | H1866: 7013 | I1866: 1 | J1866: 1 | K1866: 挖矿7
A1867: 114000 | B1867: 1 | C1867: 1 | D1867: 0 | E1867: 0 | F1867: 1 | G1867: 114010 | H1867: 7045 | I1867: 1 | J1867: 1 | K1867: 挖矿8
A1868: 114000 | B1868: 1 | C1868: 1 | D1868: 0 | E1868: 0 | F1868: 1 | G1868: 114011 | H1868: 7078 | I1868: 1 | J1868: 1 | K1868: 挖矿9
A1869: 114000 | B1869: 1 | C1869: 1 | D1869: 0 | E1869: 0 | F1869: 1 | G1869: 114012 | H1869: 7110 | I1869: 1 | J1869: 1 | K1869: 挖矿10
A1870: 114000 | B1870: 1 | C1870: 1 | D1870: 0 | E1870: 0 | F1870: 1 | G1870: 114013 | H1870: 7143 | I1870: 1 | J1870: 1 | K1870: 挖矿11
...

Sheet define
A1: 字段 | B1: 描述 | C1: 说明
A2: DropGroupID | B2: id
A3: Enabled | B3: 是否有效 | C3: 设置为1
A4: ModChanceByLevel | B4: 等级衰减标志 | C4: 1会衰减，0不会衰减
A5: Item | B5: 道具id
A6: Weight | B6: 权重
A7: CountMin | B7: 最小数量
A8: CountMax | B8: 最大数量
A9: desc | B9: 描述信息 | C9: 不会导入txt

Sheet doodad和绑金
A1: 5001 | B1: 1 | C1: 0 | D1: 90068 | E1: 1 | F1: 1 | G1: 1 | H1: doodad | I1: 海族的武器
A2: 5002 | B2: 1 | C2: 0 | D2: 90088 | E2: 1 | F2: 1 | G2: 1 | I2: 疗伤草药
A3: 5003 | B3: 1 | C3: 0 | D3: 90090 | E3: 1 | F3: 1 | G3: 1 | I3: 货物
A4: 5004 | B4: 1 | C4: 0 | D4: 90091 | E4: 1 | F4: 1 | G4: 1 | I4: 疗毒草药
A5: 5005 | B5: 1 | C5: 0 | D5: 90096 | E5: 1 | F5: 1 | G5: 1 | I5: 元素精魄
A6: 5006 | B6: 1 | C6: 0 | D6: 90076 | E6: 1 | F6: 1 | G6: 1 | I6: 散落的货物
A7: 5007 | B7: 1 | C7: 0 | D7: 90094 | E7: 1 | F7: 1 | G7: 1 | I7: 黑暗晶体
A8: 5008 | B8: 1 | C8: 0 | D8: 90098 | E8: 1 | F8: 1 | G8: 1 | I8: 前线药剂箱
A9: 5009 | B9: 1 | C9: 0 | D9: 90099 | E9: 1 | F9: 1 | G9: 1 | I9: 腐烂的蚌肉
A10: 5010 | B10: 1 | C10: 0 | D10: 90106 | E10: 1 | F10: 1 | G10: 1 | I10: 香甜的蟹肉
A11: 5011 | B11: 1 | C11: 0 | D11: 90108 | E11: 1 | F11: 1 | G11: 1 | I11: 幻魔晶石
A12: 5012 | B12: 1 | C12: 0 | D12: 90104 | E12: 1 | F12: 1 | G12: 1 | I12: 库奇的地图
A13: 5013 | B13: 1 | C13: 0 | D13: 90109 | E13: 1 | F13: 1 | G13: 1 | I13: 发光的鳞片
... A37: 5037 | B37: 1 | C37: 0 | D37: 90152 | E37: 1 | F37: 1 | G37: 1 | I37: 木材
A38: 5038 | B38: 1 | C38: 0 | D38: 90153 | E38: 1 | F38: 1 | G38: 1
A39: 5039 | B39: 1 | C39: 0 | D39: 90154 | E39: 1 | F39: 1 | G39: 1
A40: 5040 | B40: 1 | C40: 0 | D40: 90155 | E40: 1 | F40: 1 | G40: 1
A41: 5041 | B41: 1 | C41: 0 | D41: 90156 | E41: 1 | F41: 1 | G41: 1
A42: 5042 | B42: 1 | C42: 0 | D42: 90157 | E42: 1 | F42: 1 | G42: 1
A43: 5043 | B43: 1 | C43: 0 | D43: 90158 | E43: 1 | F43: 1 | G43: 1
A44: 5044 | B44: 1 | C44: 0 | D44: 90164 | E44: 1 | F44: 1 | G44: 1 | I44: 奇怪的矿石
A45: 5045 | B45: 1 | C45: 0 | D45: 90174 | E45: 1 | F45: 1 | G45: 1 | I45: 菱铁矿
A46: 5046 | B46: 1 | C46: 0 | D46: 90167 | E46: 1 | F46: 1 | G46: 1 | I46: 瘟疫的蔓延
A47: 5047 | B47: 1 | C47: 0 | D47: 90176 | E47: 1 | F47: 1 | G47: 1 | I47: 玲月
A48: 5048 | B48: 1 | C48: 0 | D48: 90177 | E48: 1 | F48: 1 | G48: 1 | I48: 阿九
A49: 5049 | B49: 1 | C49: 0 | D49: 90178 | E49: 1 | F49: 1 | G49: 1 | I49: 南苍公
A50: 5050 | B50: 1 | C50: 0 | D50: 90179 | E50: 1 | F50: 1 | G50: 1 | I50: 铁牛的护身符（上）
A51: 5051 | B51: 1 | C51: 0 | D51: 90180 | E51: 1 | F51: 1 | G51: 1 | I51: 铁牛的护身符（中）
A52: 5052 | B52: 1 | C52: 0 | D52: 90181 | E52: 1 | F52: 1 | G52: 1 | I52: 铁牛的护身符（下）
A53: 5053 | B53: 1 | C53: 0 | D53: 90182 | E53: 1 | F53: 1 | G53: 1 | I53: 朴克手记
A54: 5054 | B54: 1 | C54: 0 | D54: 90183 | E54: 1 | F54: 1 | G54: 1 | I54: 藏匿的宝贝
A55: 5055 | B55: 1 | C55: 0 | D55: 90184 | E55: 1 | F55: 1 | G55: 1 | I55: 海边的贝壳
... A62: 5062 | B62: 1 | C62: 0 | D62: 90191 | E62: 1 | F62: 1 | G62: 1 | I62: 传奇七星草
A63: 6001 | B63: 1 | C63: 0 | D63: 90065 | E63: 1 | F63: 1 | G63: 1 | H63: quest，monstor | I63: 蟹螯
A64: 6002 | B64: 1 | C64: 0 | D64: 90066 | E64: 1 | F64: 1 | G64: 1 | I64: 地图碎片
A65: 6003 | B65: 1 | C65: 0 | D65: 90082 | E65: 1 | F65: 1 | G65: 1 | I65: 僵尸的腿骨粉末
A66: 6004 | B66: 1 | C66: 0 | D66: 90080 | E66: 1 | F66: 1 | G66: 1 | I66: 土灵核心
A67: 6005 | B67: 1 | C67: 0 | D67: 90081 | E67: 1 | F67: 1 | G67: 1 | I67: 食人蜥蜴的鳞片
A68: 6006 | B68: 1 | C68: 0 | D68: 90079 | E68: 1 | F68: 1 | G68: 1 | I68: 魔犬之血
A69: 6007 | B69: 1 | C69: 0 | D69: 90067 | E69: 1 | F69: 1 | G69: 1 | I69: 海蜥蜴人的鳞片
...

Sheet Sheet2
C6: 115003 | D6: 0 | H6: 115003 | M6: =SUM(H6:K6) -> 115003
I7: 115003 | M7: =SUM(H7:K7) -> 115003
E8: 0 | J8: 115003 | M8: =SUM(H8:K8) -> 115003
K9: 115003 | M9: =SUM(H9:K9) -> 115003
C10: 115004 | D10: 0 | H10: 115004 | M10: =SUM(H10:K10) -> 115004
I11: 115004 | M11: =SUM(H11:K11) -> 115004
E12: 0 | J12: 115004 | M12: =SUM(H12:K12) -> 115004
K13: 115004 | M13: =SUM(H13:K13) -> 115004
C14: 115005 | D14: 0 | H14: 115005 | M14: =SUM(H14:K14) -> 115005
I15: 115005 | M15: =SUM(H15:K15) -> 115005
E16: 0 | J16: 115005 | M16: =SUM(H16:K16) -> 115005
K17: 115005 | M17: =SUM(H17:K17) -> 115005
C18: 115006 | D18: 0 | H18: 115006 | M18: =SUM(H18:K18) -> 115006
I19: 115006 | M19: =SUM(H19:K19) -> 115006
E20: 0 | J20: 115006 | M20: =SUM(H20:K20) -> 115006
K21: 115006 | M21: =SUM(H21:K21) -> 115006
C22: 115007 | D22: 0 | H22: 115007 | M22: =SUM(H22:K22) -> 115007
I23: 115007 | M23: =SUM(H23:K23) -> 115007
E24: 0 | J24: 115007 | M24: =SUM(H24:K24) -> 115007
K25: 115007 | M25: =SUM(H25:K25) -> 115007
C26: 115008 | D26: 0 | H26: 115008 | M26: =SUM(H26:K26) -> 115008
I27: 115008 | M27: =SUM(H27:K27) -> 115008
E28: 0 | J28: 115008 | M28: =SUM(H28:K28) -> 115008
K29: 115008 | M29: =SUM(H29:K29) -> 115008
C30: 115009 | D30: 0 | H30: 115009 | M30: =SUM(H30:K30) -> 115009
I31: 115009 | M31: =SUM(H31:K31) -> 115009
E32: 0 | J32: 115009 | M32: =SUM(H32:K32) -> 115009
K33: 115009 | M33: =SUM(H33:K33) -> 115009
C34: 115010 | D34: 0 | H34: 115010 | M34: =SUM(H34:K34) -> 115010
I35: 115010 | M35: =SUM(H35:K35) -> 115010
E36: 0 | J36: 115010 | M36: =SUM(H36:K36) -> 115010
K37: 115010 | M37: =SUM(H37:K37) -> 115010
C38: 115011 | D38: 0 | H38: 115011 | M38: =SUM(H38:K38) -> 115011
I39: 115011 | M39: =SUM(H39:K39) -> 115011
E40: 0 | J40: 115011 | M40: =SUM(H40:K40) -> 115011
K41: 115011 | M41: =SUM(H41:K41) -> 115011
C42: 115012 | D42: 0 | H42: 115012 | M42: =SUM(H42:K42) -> 115012
I43: 115012 | M43: =SUM(H43:K43) -> 115012
E44: 0 | J44: 115012 | M44: =SUM(H44:K44) -> 115012
K45: 115012 | M45: =SUM(H45:K45) -> 115012
...

Sheet Sheet3
C10: 117003 | D10: 0 | G10: 117003 | U10: =SUM(G10:T10) -> 117003 | V10: =U10+1000 -> 118003
H11: 117003 | U11: =SUM(G11:T11) -> 117003 | V11: =U11+1000 -> 118003
I12: 117003 | U12: =SUM(G12:T12) -> 117003 | V12: =U12+1000 -> 118003
E13: 0 | J13: 117003 | U13: =SUM(G13:T13) -> 117003 | V13: =U13+1000 -> 118003
K14: 117003 | U14: =SUM(G14:T14) -> 117003 | V14: =U14+1000 -> 118003
L15: 117003 | U15: =SUM(G15:T15) -> 117003 | V15: =U15+1000 -> 118003
M16: 117003 | U16: =SUM(G16:T16) -> 117003 | V16: =U16+1000 -> 118003
D17: 0 | N17: 117003 | U17: =SUM(G17:T17) -> 117003 | V17: =U17+1000 -> 118003
D18: 0 | O18: 117003 | U18: =SUM(G18:T18) -> 117003 | V18: =U18+1000 -> 118003
D19: 0 | P19: 117003 | U19: =SUM(G19:T19) -> 117003 | V19: =U19+1000 -> 118003
Q20: 117003 | U20: =SUM(G20:T20) -> 117003 | V20: =U20+1000 -> 118003
E21: 0 | R21: 117003 | U21: =SUM(G21:T21) -> 117003 | V21: =U21+1000 -> 118003
S22: 117003 | U22: =SUM(G22:T22) -> 117003 | V22: =U22+1000 -> 118003
T23: 117003 | U23: =SUM(G23:T23) -> 117003 | V23: =U23+1000 -> 118003
C24: 117004 | D24: 0 | G24: 117004 | U24: =SUM(G24:T24) -> 117004 | V24: =U24+1000 -> 118004
H25: 117004 | U25: =SUM(G25:T25) -> 117004 | V25: =U25+1000 -> 118004
I26: 117004 | U26: =SUM(G26:T26) -> 117004 | V26: =U26+1000 -> 118004
E27: 0 | J27: 117004 | U27: =SUM(G27:T27) -> 117004 | V27: =U27+1000 -> 118004
K28: 117004 | U28: =SUM(G28:T28) -> 117004 | V28: =U28+1000 -> 118004
L29: 117004 | U29: =SUM(G29:T29) -> 117004 | V29: =U29+1000 -> 118004
M30: 117004 | U30: =SUM(G30:T30) -> 117004 | V30: =U30+1000 -> 118004
D31: 0 | N31: 117004 | U31: =SUM(G31:T31) -> 117004 | V31: =U31+1000 -> 118004
D32: 0 | O32: 117004 | U32: =SUM(G32:T32) -> 117004 | V32: =U32+1000 -> 118004
D33: 0 | P33: 117004 | U33: =SUM(G33:T33) -> 117004 | V33: =U33+1000 -> 118004
Q34: 117004 | U34: =SUM(G34:T34) -> 117004 | V34: =U34+1000 -> 118004
E35: 0 | R35: 117004 | U35: =SUM(G35:T35) -> 117004 | V35: =U35+1000 -> 118004
S36: 117004 | U36: =SUM(G36:T36) -> 117004 | V36: =U36+1000 -> 118004
T37: 117004 | U37: =SUM(G37:T37) -> 117004 | V37: =U37+1000 -> 118004
C38: 117005 | D38: 0 | G38: 117005 | U38: =SUM(G38:T38) -> 117005 | V38: =U38+1000 -> 118005
H39: 117005 | U39: =SUM(G39:T39) -> 117005 | V39: =U39+1000 -> 118005
I40: 117005 | U40: =SUM(G40:T40) -> 117005 | V40: =U40+1000 -> 118005
E41: 0 | J41: 117005 | U41: =SUM(G41:T41) -> 117005 | V41: =U41+1000 -> 118005
K42: 117005 | U42: =SUM(G42:T42) -> 117005 | V42: =U42+1000 -> 118005
L43: 117005 | U43: =SUM(G43:T43) -> 117005 | V43: =U43+1000 -> 118005
M44: 117005 | U44: =SUM(G44:T44) -> 117005 | V44: =U44+1000 -> 118005
D45: 0 | N45: 117005 | U45: =SUM(G45:T45) -> 117005 | V45: =U45+1000 -> 118005
D46: 0 | O46: 117005 | U46: =SUM(G46:T46) -> 117005 | V46: =U46+1000 -> 118005
D47: 0 | P47: 117005 | U47: =SUM(G47:T47) -> 117005 | V47: =U47+1000 -> 118005
Q48: 117005 | U48: =SUM(G48:T48) -> 117005 | V48: =U48+1000 -> 118005
E49: 0 | R49: 117005 | U49: =SUM(G49:T49) -> 117005 | V49: =U49+1000 -> 118005
...

Sheet 洗矿索引
A1: 矿石种类 | B1: 道具ID | C1: 矿产率 | D1: 矿渣数量 | E1: 1级灵石概率 | F1: 2级灵石概率 | G1: 铭文石概率 | H1: 矿渣概率
A2: 铜3 | B2: 115003 | C2: 0.036363636 | D2: 1 | E2: 0 | F2: 0 | G2: 0.0004 | H2: 0.9996
A3: 铜4 | B3: 115004 | C3: 0.036536797 | D3: 1 | E3: 0 | F3: 0 | G3: 0.00048 | H3: 0.99952
A4: 铜5 | B4: 115005 | C4: 0.036709957 | D4: 1 | E4: 0 | F4: 0 | G4: 0.00056 | H4: 0.99944
A5: 铜6 | B5: 115006 | C5: 0.036883117 | D5: 1 | E5: 0 | F5: 0 | G5: 0.00064 | H5: 0.99936
A6: 铜7 | B6: 115007 | C6: 0.037056277 | D6: 1 | E6: 0 | F6: 0 | G6: 0.00072 | H6: 0.99928
A7: 铜8 | B7: 115008 | C7: 0.037229437 | D7: 1 | E7: 0 | F7: 0 | G7: 0.0008 | H7: 0.9992
A8: 铜9 | B8: 115009 | C8: 0.037402597 | D8: 1 | E8: 0 | F8: 0 | G8: 0.00088 | H8: 0.99912
A9: 铜10 | B9: 115010 | C9: 0.037575758 | D9: 1 | E9: 0 | F9: 0 | G9: 0.00096 | H9: 0.99904
A10: 铜11 | B10: 115011 | C10: 0.037748918 | D10: 1 | E10: 0 | F10: 0 | G10: 0.00104 | H10: 0.99896
A11: 铜12 | B11: 115012 | C11: 0.037922078 | D11: 1 | E11: 0 | F11: 0 | G11: 0.00112 | H11: 0.99888
A12: 铜13 | B12: 115013 | C12: 0.038095238 | D12: 1 | E12: 0 | F12: 0 | G12: 0.0012 | H12: 0.9988
A13: 铜14 | B13: 115014 | C13: 0.038095238 | D13: 1 | E13: 0 | F13: 0 | G13: 0.00128 | H13: 0.99872
... A97: 金26 | B97: 118026 | C97: 5.4112554e-06 | D97: 6 | E97: 0.0014 | F97: 0 | G97: 0.0672 | H97: 0.9314
