Workbook

Sheet Sheet2
A1: npcname | B1: npcmap | C1: NpcTemplateID | D1: DropChance1 | E1: DropGroupID1 | F1: GroupName1 | G1: GroupPrice1 | H1: DropChance2 | I1: DropGroupID2 | J1: GroupName2 | K1: GroupPrice2 | L1: DropChance3 | M1: DropGroupID3 | N1: GroupName3 | O1: GroupPrice3 | P1: DropChance4 | Q1: DropGroupID4 | R1: GroupName4 | S1: GroupPrice4 | T1: DropChance5 | U1: DropGroupID5 | V1: GroupName5 | W1: GroupPrice5 | X1: DropChance6 | Y1: DropGroupID6 | Z1: GroupName6 | AA1: GroupPrice6 | AB1: DropChance7 | AC1: DropGroupID7 | AD1: GroupName7 | AE1: GroupPrice7 | AF1: DropChance8 | AG1: DropGroupID8 | AH1: GroupName8 | AI1: GroupPrice8 | AJ1: DropChance9 | AK1: DropGroupID9 | AL1: GroupName9 | AM1: GroupPrice9 | AN1: DropChance10 | AO1: DropGroupID10 | AP1: GroupName10 | AQ1: GroupPrice10 | AR1: DropChance11 | AS1: DropGroupID11 | AT1: GroupName11 | AU1: GroupPrice11 | AV1: DropChance12 | AW1: DropGroupID12 | AX1: GroupName12 | AY1: GroupPrice12 | AZ1: DropChance13 | BA1: DropGroupID13 | BB1: GroupName13 | BC1: GroupPrice13 | BD1: DropChance14 | BE1: DropGroupID14 | BF1: GroupName14 | BG1: GroupPrice14 | BH1: DropChance15 | BI1: DropGroupID15 | BJ1: GroupName15 | BK1: GroupPrice15 | BL1: DropChance16 | BM1: DropGroupID16 | BN1: GroupName16 | BO1: GroupPrice16 | BP1: DropChance17 | BQ1: DropGroupID17 | BR1: GroupName17 | BS1: GroupPrice17 | BT1: DropChance18 | BU1: DropGroupID18 | BV1: GroupName18 | BW1: GroupPrice18 | BX1: DropChance19 | BY1: DropGroupID19 | BZ1: GroupName19 | CA1: GroupPrice19 | CB1: DropChance20 | CC1: DropGroupID20 | CD1: GroupName20 | CE1: GroupPrice20 | CF1: DropChance21 | CG1: DropGroupID21 | CH1: GroupName21 | CI1: GroupPrice21 | CJ1: DropChance22 | CK1: DropGroupID22 | CL1: GroupName22 | CM1: GroupPrice22 | CN1: DropChance23 | CO1: DropGroupID23 | CP1: GroupName23 | CQ1: GroupPrice23 | CR1: DropChance24 | CS1: DropGroupID24 | CT1: GroupName24 | CU1: GroupPrice24 | CV1: DropChance25 | CW1: DropGroupID25 | CX1: GroupName25 | CY1: GroupPrice25 | CZ1: DropChance26 | DA1: DropGroupID26 | DB1: GroupName26 | DC1: GroupPrice26 | DD1: DropChance27 | DE1: DropGroupID27 | DF1: GroupName27 | DG1: GroupPrice27 | DH1: DropChance28 | DI1: DropGroupID28 | DJ1: GroupName28 | DK1: GroupPrice28 | DL1: DropChance29 | DM1: DropGroupID29 | DN1: GroupName29 | DO1: GroupPrice29 | DP1: DropChance30 | DQ1: DropGroupID30 | DR1: GroupName30 | DS1: GroupPrice30 | DT1: DropChance31 | DU1: DropGroupID31 | DV1: GroupName31 | DW1: GroupPrice31 | DX1: DropChance32 | DY1: DropGroupID32 | DZ1: GroupName32 | EA1: GroupPrice32 | EB1: DropChance33 | EC1: DropGroupID33 | ED1: GroupName33 | EE1: GroupPrice33 | EF1: DropChance34 | EG1: DropGroupID34 | EH1: GroupName34 | EI1: GroupPrice34 | EJ1: DropChance35 | EK1: DropGroupID35 | EL1: GroupName35 | EM1: GroupPrice35 | EN1: DropChance36 | EO1: DropGroupID36 | EP1: GroupName36 | EQ1: GroupPrice36 | ER1: DropChance37 | ES1: DropGroupID37 | ET1: GroupName37 | EU1: GroupPrice37 | EV1: DropChance38 | EW1: DropGroupID38 | EX1: GroupName38 | EY1: GroupPrice38 | EZ1: DropChance39 | FA1: DropGroupID39 | FB1: GroupName39 | FC1: GroupPrice39 | FD1: DropChance40 | FE1: DropGroupID40 | FF1: GroupName40 | FG1: GroupPrice40 | FH1: DropChance41 | FI1: DropGroupID41 | FJ1: GroupName41 | FK1: GroupPrice41 | FL1: DropChance42 | FM1: DropGroupID42 | FN1: GroupName42 | FO1: GroupPrice42 | FP1: DropChance43 | FQ1: DropGroupID43 | FR1: GroupName43 | FS1: GroupPrice43 | FT1: DropChance44 | FU1: DropGroupID44 | FV1: GroupName44 | FW1: GroupPrice44 | FX1: DropChance45 | FY1: DropGroupID45 | FZ1: GroupName45 | GA1: GroupPrice45 | GB1: DropChance46 | GC1: DropGroupID46 | GD1: GroupName46 | GE1: GroupPrice46 | GF1: DropChance47 | GG1: DropGroupID47 | GH1: GroupName47 | GI1: GroupPrice47 | GJ1: DropChance48 | GK1: DropGroupID48 | GL1: GroupName48 | GM1: GroupPrice48 | GN1: DropChance49 | GO1: DropGroupID49 | GP1: GroupName49 | GQ1: GroupPrice49 | GR1: DropChance50 | GS1: DropGroupID50 | GT1: GroupName50 | GU1: GroupPrice50 | GV1: DropChance51 | GW1: DropGroupID51 | GX1: GroupName51 | GY1: GroupPrice51 | GZ1: DropChance52 | HA1: DropGroupID52 | HB1: GroupName52 | HC1: GroupPrice52 | HD1: DropChance53 | HE1: DropGroupID53 | HF1: GroupName53 | HG1: GroupPrice53 | HH1: DropChance54 | HI1: DropGroupID54 | HJ1: GroupName54 | HK1: GroupPrice54 | HL1: DropChance55 | HM1: DropGroupID55 | HN1: GroupName55 | HO1: GroupPrice55 | HP1: DropChance56 | HQ1: DropGroupID56 | HR1: GroupName56 | HS1: GroupPrice56 | HT1: DropChance57 | HU1: DropGroupID57 | HV1: GroupName57 | HW1: GroupPrice57 | HX1: DropChance58 | HY1: DropGroupID58 | HZ1: GroupName58 | IA1: GroupPrice58 | IB1: DropChance59 | IC1: DropGroupID59 | ID1: GroupName59 | IE1: GroupPrice59 | IF1: DropChance60 | IG1: DropGroupID60 | IH1: GroupName60 | II1: GroupPrice60 | IJ1: DropChance61 | IK1: DropGroupID61 | IL1: GroupName61 | IM1: GroupPrice61 | IN1: DropChance62 | IO1: DropGroupID62 | IP1: GroupName62 | IQ1: GroupPrice62 | IR1: DropChance63 | IS1: DropGroupID63 | IT1: GroupName63 | IU1: GroupPrice63 | IV1: DropChance64 | IW1: DropGroupID64 | IX1: GroupName64 | IY1: GroupPrice64 | IZ1: DropChance65 | JA1: DropGroupID65 | JB1: GroupName65 | JC1: GroupPrice65 | JD1: DropChance66 | JE1: DropGroupID66 | JF1: GroupName66 | JG1: GroupPrice66 | JH1: DropChance67 | JI1: DropGroupID67 | JJ1: GroupName67 | JK1: GroupPrice67 | JL1: DropChance68 | JM1: DropGroupID68 | JN1: GroupName68 | JO1: GroupPrice68 | JP1: DropChance69 | JQ1: DropGroupID69 | JR1: GroupName69 | JS1: GroupPrice69 | JT1: DropChance70 | JU1: DropGroupID70 | JV1: GroupName70 | JW1: GroupPrice70 | JX1: DropChance71 | JY1: DropGroupID71 | JZ1: GroupName71 | KA1: GroupPrice71 | KB1: DropChance72 | KC1: DropGroupID72 | KD1: GroupName72 | KE1: GroupPrice72 | KF1: DropChance73 | KG1: DropGroupID73 | KH1: GroupName73 | KI1: GroupPrice73 | KJ1: DropChance74 | KK1: DropGroupID74 | KL1: GroupName74 | KM1: GroupPrice74 | KN1: DropChance75 | KO1: DropGroupID75 | KP1: GroupName75 | KQ1: GroupPrice75 | KR1: DropChance76 | KS1: DropGroupID76 | KT1: GroupName76 | KU1: GroupPrice76 | KV1: DropChance77 | KW1: DropGroupID77 | KX1: GroupName77 | KY1: GroupPrice77 | KZ1: DropChance78 | LA1: DropGroupID78 | LB1: GroupName78 | LC1: GroupPrice78 | LD1: DropChance79 | LE1: DropGroupID79 | LF1: GroupName79 | LG1: GroupPrice79 | LH1: DropChance80 | LI1: DropGroupID80 | LJ1: GroupName80 | LK1: GroupPrice80 | LL1: DropChance81 | LM1: DropGroupID81 | LN1: GroupName81 | LO1: GroupPrice81 | LP1: DropChance82 | LQ1: DropGroupID82 | LR1: GroupName82 | LS1: GroupPrice82 | LT1: DropChance83 | LU1: DropGroupID83 | LV1: GroupName83 | LW1: GroupPrice83 | LX1: DropChance84 | LY1: DropGroupID84 | LZ1: GroupName84 | MA1: GroupPrice84 | MB1: DropChance85 | MC1: DropGroupID85 | MD1: GroupName85 | ME1: GroupPrice85 | MF1: DropChance86 | MG1: DropGroupID86 | MH1: GroupName86 | MI1: GroupPrice86 | MJ1: DropChance87 | MK1: DropGroupID87 | ML1: GroupName87 | MM1: GroupPrice87 | MN1: DropChance88 | MO1: DropGroupID88 | MP1: GroupName88 | MQ1: GroupPrice88 | MR1: DropChance89 | MS1: DropGroupID89 | MT1: GroupName89 | MU1: GroupPrice89 | MV1: DropChance90 | MW1: DropGroupID90 | MX1: GroupName90 | MY1: GroupPrice90 | MZ1: DropChance91 | NA1: DropGroupID91 | NB1: GroupName91 | NC1: GroupPrice91 | ND1: DropChance92 | NE1: DropGroupID92 | NF1: GroupName92 | NG1: GroupPrice92 | NH1: DropChance93 | NI1: DropGroupID93 | NJ1: GroupName93 | NK1: GroupPrice93 | NL1: DropChance94 | NM1: DropGroupID94 | NN1: GroupName94 | NO1: GroupPrice94 | NP1: DropChance95 | NQ1: DropGroupID95 | NR1: GroupName95 | NS1: GroupPrice95 | NT1: DropChance96 | NU1: DropGroupID96 | NV1: GroupName96 | NW1: GroupPrice96 | NX1: DropChance97 | NY1: DropGroupID97 | NZ1: GroupName97 | OA1: GroupPrice97 | OB1: DropChance98 | OC1: DropGroupID98 | OD1: GroupName98 | OE1: GroupPrice98 | OF1: DropChance99 | OG1: DropGroupID99 | OH1: GroupName99 | OI1: GroupPrice99 | OJ1: DropChance100 | OK1: DropGroupID100 | OL1: GroupName100 | OM1: GroupPrice100 | ON1: DropChance101 | OO1: DropGroupID101 | OP1: GroupName101 | OQ1: GroupPrice101 | OR1: DropChance102 | OS1: DropGroupID102 | OT1: GroupName102 | OU1: GroupPrice102 | OV1: DropChance103 | OW1: DropGroupID103 | OX1: GroupName103 | OY1: GroupPrice103 | OZ1: DropChance104 | PA1: DropGroupID104 | PB1: GroupName104 | PC1: GroupPrice104 | PD1: DropChance105 | PE1: DropGroupID105 | PF1: GroupName105 | PG1: GroupPrice105 | PH1: DropChance106 | PI1: DropGroupID106 | PJ1: GroupName106 | PK1: GroupPrice106 | PL1: DropChance107 | PM1: DropGroupID107 | PN1: GroupName107 | PO1: GroupPrice107 | PP1: DropChance108 | PQ1: DropGroupID108 | PR1: GroupName108 | PS1: GroupPrice108 | PT1: DropChance109 | PU1: DropGroupID109 | PV1: GroupName109 | PW1: GroupPrice109 | PX1: DropChance110 | PY1: DropGroupID110 | PZ1: GroupName110 | QA1: GroupPrice110 | QB1: DropChance111 | QC1: DropGroupID111 | QD1: GroupName111 | QE1: GroupPrice111 | QF1: DropChance112 | QG1: DropGroupID112 | QH1: GroupName112 | QI1: GroupPrice112 | QJ1: DropChance113 | QK1: DropGroupID113 | QL1: GroupName113 | QM1: GroupPrice113 | QN1: DropChance114 | QO1: DropGroupID114 | QP1: GroupName114 | QQ1: GroupPrice114 | QR1: DropChance115 | QS1: DropGroupID115 | QT1: GroupName115 | QU1: GroupPrice115 | QV1: DropChance116 | QW1: DropGroupID116 | QX1: GroupName116 | QY1: GroupPrice116 | QZ1: DropChance117 | RA1: DropGroupID117 | RB1: GroupName117 | RC1: GroupPrice117 | RD1: DropChance118 | RE1: DropGroupID118 | RF1: GroupName118 | RG1: GroupPrice118 | RH1: DropChance119 | RI1: DropGroupID119 | RJ1: GroupName119 | RK1: GroupPrice119 | RL1: DropChance120 | RM1: DropGroupID120 | RN1: GroupName120 | RO1: GroupPrice120 | RP1: DropChance121 | RQ1: DropGroupID121 | RR1: GroupName121 | RS1: GroupPrice121 | RT1: DropChance122 | RU1: DropGroupID122 | RV1: GroupName122 | RW1: GroupPrice122 | RX1: DropChance123 | RY1: DropGroupID123 | RZ1: GroupName123 | SA1: GroupPrice123 | SB1: DropChance124 | SC1: DropGroupID124 | SD1: GroupName124 | SE1: GroupPrice124 | SF1: DropChance125 | SG1: DropGroupID125 | SH1: GroupName125 | SI1: GroupPrice125 | SJ1: DropChance126 | SK1: DropGroupID126 | SL1: GroupName126 | SM1: GroupPrice126 | SN1: DropChance127 | SO1: DropGroupID127 | SP1: GroupName127 | SQ1: GroupPrice127 | SR1: DropChance128 | SS1: DropGroupID128 | ST1: GroupName128 | SU1: GroupPrice128 | SV1: ExpectedMoney
A2: client | B2: client | C2: N/A | D2: N/A | E2: N/A | F2: N/A | G2: N/A | H2: N/A | I2: N/A | J2: N/A | K2: N/A | L2: N/A | M2: N/A | N2: N/A | O2: N/A | P2: N/A | Q2: N/A | R2: N/A | S2: N/A | T2: N/A | U2: N/A | V2: N/A | W2: N/A | X2: N/A | Y2: N/A | Z2: N/A | AA2: N/A | AB2: N/A | AC2: N/A | AD2: N/A | AE2: N/A | AF2: N/A | AG2: N/A | AH2: N/A | AI2: N/A | AJ2: N/A | AK2: N/A | AL2: N/A | AM2: N/A | AN2: N/A | AO2: N/A | AP2: N/A | AQ2: N/A | AR2: N/A | AS2: N/A | AT2: N/A | AU2: N/A | AV2: N/A | AW2: N/A | AX2: N/A | AY2: N/A | AZ2: N/A | BA2: N/A | BB2: N/A | BC2: N/A | BD2: N/A | BE2: N/A | BF2: N/A | BG2: N/A | BH2: N/A | BI2: N/A | BJ2: N/A | BK2: N/A | BL2: N/A | BM2: N/A | BN2: N/A | BO2: N/A | BP2: N/A | BQ2: N/A | BR2: N/A | BS2: N/A | BT2: N/A | BU2: N/A | BV2: N/A | BW2: N/A | BX2: N/A | BY2: N/A | BZ2: N/A | CA2: N/A | CB2: N/A | CC2: N/A | CD2: N/A | CE2: N/A | CF2: N/A | CG2: N/A | CH2: N/A | CI2: N/A | CJ2: N/A | CK2: N/A | CL2: N/A | CM2: N/A | CN2: N/A | CO2: N/A | CP2: N/A | CQ2: N/A | CR2: N/A | CS2: N/A | CT2: N/A | CU2: N/A | CV2: N/A | CW2: N/A | CX2: N/A | CY2: N/A | CZ2: N/A | DA2: N/A | DB2: N/A | DC2: N/A | DD2: N/A | DE2: N/A | DF2: N/A | DG2: N/A | DH2: N/A | DI2: N/A | DJ2: N/A | DK2: N/A | DL2: N/A | DM2: N/A | DN2: N/A | DO2: N/A | DP2: N/A | DQ2: N/A | DR2: N/A | DS2: N/A | DT2: N/A | DU2: N/A | DV2: N/A | DW2: N/A | DX2: N/A | DY2: N/A | DZ2: N/A | EA2: N/A | EB2: N/A | EC2: N/A | ED2: N/A | EE2: N/A | EF2: N/A | EG2: N/A | EH2: N/A | EI2: N/A | EJ2: N/A | EK2: N/A | EL2: N/A | EM2: N/A | EN2: N/A | EO2: N/A | EP2: N/A | EQ2: N/A | ER2: N/A | ES2: N/A | ET2: N/A | EU2: N/A | EV2: N/A | EW2: N/A | EX2: N/A | EY2: N/A | EZ2: N/A | FA2: N/A | FB2: N/A | FC2: N/A | FD2: N/A | FE2: N/A | FF2: N/A | FG2: N/A | FH2: N/A | FI2: N/A | FJ2: N/A | FK2: N/A | FL2: N/A | FM2: N/A | FN2: N/A | FO2: N/A | FP2: N/A | FQ2: N/A | FR2: N/A | FS2: N/A | FT2: N/A | FU2: N/A | FV2: N/A | FW2: N/A | FX2: N/A | FY2: N/A | FZ2: N/A | GA2: N/A | GB2: N/A | GC2: N/A | GD2: N/A | GE2: N/A | GF2: N/A | GG2: N/A | GH2: N/A | GI2: N/A | GJ2: N/A | GK2: N/A | GL2: N/A | GM2: N/A | GN2: N/A | GO2: N/A | GP2: N/A | GQ2: N/A | GR2: N/A | GS2: N/A | GT2: N/A | GU2: N/A | GV2: N/A | GW2: N/A | GX2: N/A | GY2: N/A | GZ2: N/A | HA2: N/A | HB2: N/A | HC2: N/A | HD2: N/A | HE2: N/A | HF2: N/A | HG2: N/A | HH2: N/A | HI2: N/A | HJ2: N/A | HK2: N/A | HL2: N/A | HM2: N/A | HN2: N/A | HO2: N/A | HP2: N/A | HQ2: N/A | HR2: N/A | HS2: N/A | HT2: N/A | HU2: N/A | HV2: N/A | HW2: N/A | HX2: N/A | HY2: N/A | HZ2: N/A | IA2: N/A | IB2: N/A | IC2: N/A | ID2: N/A | IE2: N/A | IF2: N/A | IG2: N/A | IH2: N/A | II2: N/A | IJ2: N/A | IK2: N/A | IL2: N/A | IM2: N/A | IN2: N/A | IO2: N/A | IP2: N/A | IQ2: N/A | IR2: N/A | IS2: N/A | IT2: N/A | IU2: N/A | IV2: N/A | IW2: N/A | IX2: N/A | IY2: N/A | IZ2: N/A | JA2: N/A | JB2: N/A | JC2: N/A | JD2: N/A | JE2: N/A | JF2: N/A | JG2: N/A | JH2: N/A | JI2: N/A | JJ2: N/A | JK2: N/A | JL2: N/A | JM2: N/A | JN2: N/A | JO2: N/A | JP2: N/A | JQ2: N/A | JR2: N/A | JS2: N/A | JT2: N/A | JU2: N/A | JV2: N/A | JW2: N/A | JX2: N/A | JY2: N/A | JZ2: N/A | KA2: N/A | KB2: N/A | KC2: N/A | KD2: N/A | KE2: N/A | KF2: N/A | KG2: N/A | KH2: N/A | KI2: N/A | KJ2: N/A | KK2: N/A | KL2: N/A | KM2: N/A | KN2: N/A | KO2: N/A | KP2: N/A | KQ2: N/A | KR2: N/A | KS2: N/A | KT2: N/A | KU2: N/A | KV2: N/A | KW2: N/A | KX2: N/A | KY2: N/A | KZ2: N/A | LA2: N/A | LB2: N/A | LC2: N/A | LD2: N/A | LE2: N/A | LF2: N/A | LG2: N/A | LH2: N/A | LI2: N/A | LJ2: N/A | LK2: N/A | LL2: N/A | LM2: N/A | LN2: N/A | LO2: N/A | LP2: N/A | LQ2: N/A | LR2: N/A | LS2: N/A | LT2: N/A | LU2: N/A | LV2: N/A | LW2: N/A | LX2: N/A | LY2: N/A | LZ2: N/A | MA2: N/A | MB2: N/A | MC2: N/A | MD2: N/A | ME2: N/A | MF2: N/A | MG2: N/A | MH2: N/A | MI2: N/A | MJ2: N/A | MK2: N/A | ML2: N/A | MM2: N/A | MN2: N/A | MO2: N/A | MP2: N/A | MQ2: N/A | MR2: N/A | MS2: N/A | MT2: N/A | MU2: N/A | MV2: N/A | MW2: N/A | MX2: N/A | MY2: N/A | MZ2: N/A | NA2: N/A | NB2: N/A | NC2: N/A | ND2: N/A | NE2: N/A | NF2: N/A | NG2: N/A | NH2: N/A | NI2: N/A | NJ2: N/A | NK2: N/A | NL2: N/A | NM2: N/A | NN2: N/A | NO2: N/A | NP2: N/A | NQ2: N/A | NR2: N/A | NS2: N/A | NT2: N/A | NU2: N/A | NV2: N/A | NW2: N/A | NX2: N/A | NY2: N/A | NZ2: N/A | OA2: N/A | OB2: N/A | OC2: N/A | OD2: N/A | OE2: N/A | OF2: N/A | OG2: N/A | OH2: N/A | OI2: N/A | OJ2: N/A | OK2: N/A | OL2: N/A | OM2: N/A | ON2: N/A | OO2: N/A | OP2: N/A | OQ2: N/A | OR2: N/A | OS2: N/A | OT2: N/A | OU2: N/A | OV2: N/A | OW2: N/A | OX2: N/A | OY2: N/A | OZ2: N/A | PA2: N/A | PB2: N/A | PC2: N/A | PD2: N/A | PE2: N/A | PF2: N/A | PG2: N/A | PH2: N/A | PI2: N/A | PJ2: N/A | PK2: N/A | PL2: N/A | PM2: N/A | PN2: N/A | PO2: N/A | PP2: N/A | PQ2: N/A | PR2: N/A | PS2: N/A | PT2: N/A | PU2: N/A | PV2: N/A | PW2: N/A | PX2: N/A | PY2: N/A | PZ2: N/A | QA2: N/A | QB2: N/A | QC2: N/A | QD2: N/A | QE2: N/A | QF2: N/A | QG2: N/A | QH2: N/A | QI2: N/A | QJ2: N/A | QK2: N/A | QL2: N/A | QM2: N/A | QN2: N/A | QO2: N/A | QP2: N/A | QQ2: N/A | QR2: N/A | QS2: N/A | QT2: N/A | QU2: N/A | QV2: N/A | QW2: N/A | QX2: N/A | QY2: N/A | QZ2: N/A | RA2: N/A | RB2: N/A | RC2: N/A | RD2: N/A | RE2: N/A | RF2: N/A | RG2: N/A | RH2: N/A | RI2: N/A | RJ2: N/A | RK2: N/A | RL2: N/A | RM2: N/A | RN2: N/A | RO2: N/A | RP2: N/A | RQ2: N/A | RR2: N/A | RS2: N/A | RT2: N/A | RU2: N/A | RV2: N/A | RW2: N/A | RX2: N/A | RY2: N/A | RZ2: N/A | SA2: N/A | SB2: N/A | SC2: N/A | SD2: N/A | SE2: N/A | SF2: N/A | SG2: N/A | SH2: N/A | SI2: N/A | SJ2: N/A | SK2: N/A | SL2: N/A | SM2: N/A | SN2: N/A | SO2: N/A | SP2: N/A | SQ2: N/A | SR2: N/A | SS2: N/A | ST2: N/A | SU2: N/A | SV2: N/A
A3: 0 | B3: 0 | C3: 0 | D3: 0 | E3: 0 | F3: 0 | G3: 0 | H3: 0 | I3: 0 | J3: 0 | K3: 0 | L3: 0 | M3: 0 | N3: 0 | O3: 0 | P3: 0 | Q3: 0 | R3: 0 | S3: 0 | T3: 0 | U3: 0 | V3: 0 | W3: 0 | X3: 0 | Y3: 0 | Z3: 0 | AA3: 0 | AB3: 0 | AC3: 0 | AD3: 0 | AE3: 0 | AF3: 0 | AG3: 0 | AH3: 0 | AI3: 0 | AJ3: 0 | AK3: 0 | AL3: 0 | AM3: 0 | AN3: 0 | AO3: 0 | AP3: 0 | AQ3: 0 | AR3: 0 | AS3: 0 | AT3: 0 | AU3: 0 | AV3: 0 | AW3: 0 | AX3: 0 | AY3: 0 | AZ3: 0 | BA3: 0 | BB3: 0 | BC3: 0 | BD3: 0 | BE3: 0 | BF3: 0 | BG3: 0 | BH3: 0 | BI3: 0 | BJ3: 0 | BK3: 0 | BL3: 0 | BM3: 0 | BN3: 0 | BO3: 0 | BP3: 0 | BQ3: 0 | BR3: 0 | BS3: 0 | BT3: 0 | BU3: 0 | BV3: 0 | BW3: 0 | BX3: 0 | BY3: 0 | BZ3: 0 | CA3: 0 | CB3: 0 | CC3: 0 | CD3: 0 | CE3: 0 | CF3: 0 | CG3: 0 | CH3: 0 | CI3: 0 | CJ3: 0 | CK3: 0 | CL3: 0 | CM3: 0 | CN3: 0 | CO3: 0 | CP3: 0 | CQ3: 0 | CR3: 0 | CS3: 0 | CT3: 0 | CU3: 0 | CV3: 0 | CW3: 0 | CX3: 0 | CY3: 0 | CZ3: 0 | DA3: 0 | DB3: 0 | DC3: 0 | DD3: 0 | DE3: 0 | DF3: 0 | DG3: 0 | DH3: 0 | DI3: 0 | DJ3: 0 | DK3: 0 | DL3: 0 | DM3: 0 | DN3: 0 | DO3: 0 | DP3: 0 | DQ3: 0 | DR3: 0 | DS3: 0 | DT3: 0 | DU3: 0 | DV3: 0 | DW3: 0 | DX3: 0 | DY3: 0 | DZ3: 0 | EA3: 0 | EB3: 0 | EC3: 0 | ED3: 0 | EE3: 0 | EF3: 0 | EG3: 0 | EH3: 0 | EI3: 0 | EJ3: 0 | EK3: 0 | EL3: 0 | EM3: 0 | EN3: 0 | EO3: 0 | EP3: 0 | EQ3: 0 | ER3: 0 | ES3: 0 | ET3: 0 | EU3: 0 | EV3: 0 | EW3: 0 | EX3: 0 | EY3: 0 | EZ3: 0 | FA3: 0 | FB3: 0 | FC3: 0 | FD3: 0 | FE3: 0 | FF3: 0 | FG3: 0 | FH3: 0 | FI3: 0 | FJ3: 0 | FK3: 0 | FL3: 0 | FM3: 0 | FN3: 0 | FO3: 0 | FP3: 0 | FQ3: 0 | FR3: 0 | FS3: 0 | FT3: 0 | FU3: 0 | FV3: 0 | FW3: 0 | FX3: 0 | FY3: 0 | FZ3: 0 | GA3: 0 | GB3: 0 | GC3: 0 | GD3: 0 | GE3: 0 | GF3: 0 | GG3: 0 | GH3: 0 | GI3: 0 | GJ3: 0 | GK3: 0 | GL3: 0 | GM3: 0 | GN3: 0 | GO3: 0 | GP3: 0 | GQ3: 0 | GR3: 0 | GS3: 0 | GT3: 0 | GU3: 0 | GV3: 0 | GW3: 0 | GX3: 0 | GY3: 0 | GZ3: 0 | HA3: 0 | HB3: 0 | HC3: 0 | HD3: 0 | HE3: 0 | HF3: 0 | HG3: 0 | HH3: 0 | HI3: 0 | HJ3: 0 | HK3: 0 | HL3: 0 | HM3: 0 | HN3: 0 | HO3: 0 | HP3: 0 | HQ3: 0 | HR3: 0 | HS3: 0 | HT3: 0 | HU3: 0 | HV3: 0 | HW3: 0 | HX3: 0 | HY3: 0 | HZ3: 0 | IA3: 0 | IB3: 0 | IC3: 0 | ID3: 0 | IE3: 0 | IF3: 0 | IG3: 0 | IH3: 0 | II3: 0 | IJ3: 0 | IK3: 0 | IL3: 0 | IM3: 0 | IN3: 0 | IO3: 0 | IP3: 0 | IQ3: 0 | IR3: 0 | IS3: 0 | IT3: 0 | IU3: 0 | IV3: 0 | IW3: 0 | IX3: 0 | IY3: 0 | IZ3: 0 | JA3: 0 | JB3: 0 | JC3: 0 | JD3: 0 | JE3: 0 | JF3: 0 | JG3: 0 | JH3: 0 | JI3: 0 | JJ3: 0 | JK3: 0 | JL3: 0 | JM3: 0 | JN3: 0 | JO3: 0 | JP3: 0 | JQ3: 0 | JR3: 0 | JS3: 0 | JT3: 0 | JU3: 0 | JV3: 0 | JW3: 0 | JX3: 0 | JY3: 0 | JZ3: 0 | KA3: 0 | KB3: 0 | KC3: 0 | KD3: 0 | KE3: 0 | KF3: 0 | KG3: 0 | KH3: 0 | KI3: 0 | KJ3: 0 | KK3: 0 | KL3: 0 | KM3: 0 | KN3: 0 | KO3: 0 | KP3: 0 | KQ3: 0 | KR3: 0 | KS3: 0 | KT3: 0 | KU3: 0 | KV3: 0 | KW3: 0 | KX3: 0 | KY3: 0 | KZ3: 0 | LA3: 0 | LB3: 0 | LC3: 0 | LD3: 0 | LE3: 0 | LF3: 0 | LG3: 0 | LH3: 0 | LI3: 0 | LJ3: 0 | LK3: 0 | LL3: 0 | LM3: 0 | LN3: 0 | LO3: 0 | LP3: 0 | LQ3: 0 | LR3: 0 | LS3: 0 | LT3: 0 | LU3: 0 | LV3: 0 | LW3: 0 | LX3: 0 | LY3: 0 | LZ3: 0 | MA3: 0 | MB3: 0 | MC3: 0 | MD3: 0 | ME3: 0 | MF3: 0 | MG3: 0 | MH3: 0 | MI3: 0 | MJ3: 0 | MK3: 0 | ML3: 0 | MM3: 0 | MN3: 0 | MO3: 0 | MP3: 0 | MQ3: 0 | MR3: 0 | MS3: 0 | MT3: 0 | MU3: 0 | MV3: 0 | MW3: 0 | MX3: 0 | MY3: 0 | MZ3: 0 | NA3: 0 | NB3: 0 | NC3: 0 | ND3: 0 | NE3: 0 | NF3: 0 | NG3: 0 | NH3: 0 | NI3: 0 | NJ3: 0 | NK3: 0 | NL3: 0 | NM3: 0 | NN3: 0 | NO3: 0 | NP3: 0 | NQ3: 0 | NR3: 0 | NS3: 0 | NT3: 0 | NU3: 0 | NV3: 0 | NW3: 0 | NX3: 0 | NY3: 0 | NZ3: 0 | OA3: 0 | OB3: 0 | OC3: 0 | OD3: 0 | OE3: 0 | OF3: 0 | OG3: 0 | OH3: 0 | OI3: 0 | OJ3: 0 | OK3: 0 | OL3: 0 | OM3: 0 | ON3: 0 | OO3: 0 | OP3: 0 | OQ3: 0 | OR3: 0 | OS3: 0 | OT3: 0 | OU3: 0 | OV3: 0 | OW3: 0 | OX3: 0 | OY3: 0 | OZ3: 0 | PA3: 0 | PB3: 0 | PC3: 0 | PD3: 0 | PE3: 0 | PF3: 0 | PG3: 0 | PH3: 0 | PI3: 0 | PJ3: 0 | PK3: 0 | PL3: 0 | PM3: 0 | PN3: 0 | PO3: 0 | PP3: 0 | PQ3: 0 | PR3: 0 | PS3: 0 | PT3: 0 | PU3: 0 | PV3: 0 | PW3: 0 | PX3: 0 | PY3: 0 | PZ3: 0 | QA3: 0 | QB3: 0 | QC3: 0 | QD3: 0 | QE3: 0 | QF3: 0 | QG3: 0 | QH3: 0 | QI3: 0 | QJ3: 0 | QK3: 0 | QL3: 0 | QM3: 0 | QN3: 0 | QO3: 0 | QP3: 0 | QQ3: 0 | QR3: 0 | QS3: 0 | QT3: 0 | QU3: 0 | QV3: 0 | QW3: 0 | QX3: 0 | QY3: 0 | QZ3: 0 | RA3: 0 | RB3: 0 | RC3: 0 | RD3: 0 | RE3: 0 | RF3: 0 | RG3: 0 | RH3: 0 | RI3: 0 | RJ3: 0 | RK3: 0 | RL3: 0 | RM3: 0 | RN3: 0 | RO3: 0 | RP3: 0 | RQ3: 0 | RR3: 0 | RS3: 0 | RT3: 0 | RU3: 0 | RV3: 0 | RW3: 0 | RX3: 0 | RY3: 0 | RZ3: 0 | SA3: 0 | SB3: 0 | SC3: 0 | SD3: 0 | SE3: 0 | SF3: 0 | SG3: 0 | SH3: 0 | SI3: 0 | SJ3: 0 | SK3: 0 | SL3: 0 | SM3: 0 | SN3: 0 | SO3: 0 | SP3: 0 | SQ3: 0 | SR3: 0 | SS3: 0 | ST3: 0 | SU3: 0 | SV3: 0
A4: 稻草人 | B4: 边界村 | C4: 801 | L4: 250000 | M4: 301 | N4: 金创药(小量) | O4: 10 | P4: 120000 | Q4: 321 | R4: 魔法药(小量) | S4: 4.8 | V4: 0 | W4: 0 | Z4: 0 | AA4: 0 | AD4: 0 | AE4: 0 | AH4: 0 | AI4: 0 | AL4: 0 | AM4: 0 | AN4: 15000 | AO4: 99900001 | AP4: 木剑 | AQ4: 0.4 | AR4: 15000 | AS4: 99900002 | AT4: 匕首 | AU4: 3.8 | AX4: 0 | AY4: 0 | AZ4: 10000 | BA4: 99920001 | BB4: 金项链 | BC4: 2.5 | BD4: 10000 | BE4: 99930001 | BF4: 古铜戒指 | BG4: 2.5 | BH4: 10000 | BI4: 99940001 | BJ4: 铁手镯 | BK4: 4 | BL4: 10000 | BM4: 99920002 | BN4: 传统项链 | BO4: 5 | BP4: 15000 | BQ4: 99980113 | BR4: 布衣 | BS4: 0.9 | BT4: 15000 | BU4: 99990113 | BV4: 布衣6 | BW4: 0.9 | BZ4: 0 | CA4: 0 | CD4: 0 | CE4: 0 | CH4: 0 | CI4: 0 | CL4: 0 | CM4: 0 | CP4: 0 | CQ4: 0 | CT4: 0 | CU4: 0 | CX4: 0 | CY4: 0 | DB4: 0 | DC4: 0 | DF4: 0 | DG4: 0 | DJ4: 0 | DK4: 0 | DN4: 0 | DO4: 0 | DR4: 0 | DS4: 0 | DV4: 0 | DW4: 0 | DZ4: 0 | EA4: 0 | ED4: 0 | EE4: 0 | EH4: 0 | EI4: 0 | EL4: 0 | EM4: 0 | EP4: 0 | EQ4: 0 | ET4: 0 | EU4: 0 | EX4: 0 | EY4: 0 | FB4: 0 | FC4: 0 | FF4: 0 | FG4: 0 | FJ4: 0 | FK4: 0 | FN4: 0 | FO4: 0 | FR4: 0 | FS4: 0 | FV4: 0 | FW4: 0 | FZ4: 0 | GA4: 0 | GD4: 0 | GE4: 0 | GH4: 0 | GI4: 0 | GL4: 0 | GM4: 0 | GP4: 0 | GQ4: 0 | GT4: 0 | GU4: 0 | GX4: 0 | GY4: 0 | HB4: 0 | HC4: 0 | HF4: 0 | HG4: 0 | HJ4: 0 | HK4: 0 | HN4: 0 | HO4: 0 | HR4: 0 | HS4: 0 | HV4: 0 | HW4: 0 | HZ4: 0 | IA4: 0 | ID4: 0 | IE4: 0 | IH4: 0 | II4: 0 | IL4: 0 | IM4: 0 | IP4: 0 | IQ4: 0 | IT4: 0 | IU4: 0 | IX4: 0 | IY4: 0 | JB4: 0 | JC4: 0 | JF4: 0 | JG4: 0 | JJ4: 0 | JK4: 0 | JN4: 0 | JO4: 0 | JR4: 0 | JS4: 0 | JV4: 0 | JW4: 0 | JZ4: 0 | KA4: 0 | KD4: 0 | KE4: 0 | KH4: 0 | KI4: 0 | KL4: 0 | KM4: 0 | KP4: 0 | KQ4: 0 | KT4: 0 | KU4: 0 | KX4: 0 | KY4: 0 | LB4: 0 | LC4: 0 | LF4: 0 | LG4: 0 | LJ4: 0 | LK4: 0 | LN4: 0 | LO4: 0 | LR4: 0 | LS4: 0 | LV4: 0 | LW4: 0 | LZ4: 0 | MA4: 0 | MD4: 0 | ME4: 0 | MH4: 0 | MI4: 0 | ML4: 0 | MM4: 0 | MP4: 0 | MQ4: 0 | MT4: 0 | MU4: 0 | MX4: 0 | MY4: 0 | NB4: 0 | NC4: 0 | NF4: 0 | NG4: 0 | NJ4: 0 | NK4: 0 | NN4: 0 | NO4: 0 | NR4: 0 | NS4: 0 | NV4: 0 | NW4: 0 | NZ4: 0 | OA4: 0 | OD4: 0 | OE4: 0 | OH4: 0 | OI4: 0 | OL4: 0 | OM4: 0 | OP4: 0 | OQ4: 0 | OT4: 0 | OU4: 0 | OX4: 0 | OY4: 0 | PB4: 0 | PC4: 0 | PF4: 0 | PG4: 0 | PJ4: 0 | PK4: 0 | PN4: 0 | PO4: 0 | PR4: 0 | PS4: 0 | PV4: 0 | PW4: 0 | PZ4: 0 | QA4: 0 | QD4: 0 | QE4: 0 | QH4: 0 | QI4: 0 | QL4: 0 | QM4: 0 | QP4: 0 | QQ4: 0 | QT4: 0 | QU4: 0 | QX4: 0 | QY4: 0 | RB4: 0 | RC4: 0 | RF4: 0 | RG4: 0 | RJ4: 0 | RK4: 0 | RN4: 0 | RO4: 0 | RR4: 0 | RS4: 0 | RV4: 0 | RW4: 0 | RZ4: 0 | SA4: 0 | SD4: 0 | SE4: 0 | SH4: 0 | SI4: 0 | SL4: 0 | SM4: 0 | SP4: 0 | SQ4: 0 | ST4: 0 | SU4: =ROUND(SR4/1000000*IF(SS4=0,0,VLOOKUP(SS4,名称和价格索引!$A$4:$C$834,3,FALSE)),1) -> 0 | SV4: {=SUM(VLOOKUP(D4,D4:SU4,ROW($1:$128)*4,0))} -> #N/A
A5: 钉耙猫 | B5: 边界村 | C5: 802 | N5: 0 | O5: 0 | R5: 0 | S5: 0 | V5: 0 | W5: 0 | Z5: 0 | AA5: 0 | AD5: 0 | AE5: 0 | AH5: 0 | AI5: 0 | AL5: 0 | AM5: 0 | AN5: 15000 | AO5: 99900001 | AP5: 木剑 | AQ5: 0.4 | AR5: 15000 | AS5: 99900002 | AT5: 匕首 | AU5: 3.8 | AX5: 0 | AY5: 0 | AZ5: 15000 | BA5: 99920001 | BB5: 金项链 | BC5: 3.8 | BD5: 15000 | BE5: 99930001 | BF5: 古铜戒指 | BG5: 3.8 | BH5: 15000 | BI5: 99940001 | BJ5: 铁手镯 | BK5: 6 | BL5: 15000 | BM5: 99920002 | BN5: 传统项链 | BO5: 7.5 | BP5: 15000 | BQ5: 99980113 | BR5: 布衣 | BS5: 0.9 | BT5: 15000 | BU5: 99990113 | BV5: 布衣6 | BW5: 0.9 | BZ5: 0 | CA5: 0 | CD5: 0 | CE5: 0 | CH5: 0 | CI5: 0 | CL5: 0 | CM5: 0 | CP5: 0 | CQ5: 0 | CT5: 0 | CU5: 0 | CX5: 0 | CY5: 0 | DB5: 0 | DC5: 0 | DF5: 0 | DG5: 0 | DJ5: 0 | DK5: 0 | DN5: 0 | DO5: 0 | DR5: 0 | DS5: 0 | DV5: 0 | DW5: 0 | DZ5: 0 | EA5: 0 | ED5: 0 | EE5: 0 | EH5: 0 | EI5: 0 | EL5: 0 | EM5: 0 | EP5: 0 | EQ5: 0 | ET5: 0 | EU5: 0 | EX5: 0 | EY5: 0 | FB5: 0 | FC5: 0 | FF5: 0 | FG5: 0 | FJ5: 0 | FK5: 0 | FN5: 0 | FO5: 0 | FR5: 0 | FS5: 0 | FV5: 0 | FW5: 0 | FZ5: 0 | GA5: 0 | GD5: 0 | GE5: 0 | GH5: 0 | GI5: 0 | GL5: 0 | GM5: 0 | GP5: 0 | GQ5: 0 | GT5: 0 | GU5: 0 | GX5: 0 | GY5: 0 | HB5: 0 | HC5: 0 | HF5: 0 | HG5: 0 | HJ5: 0 | HK5: 0 | HN5: 0 | HO5: 0 | HR5: 0 | HS5: 0 | HV5: 0 | HW5: 0 | HZ5: 0 | IA5: 0 | ID5: 0 | IE5: 0 | IH5: 0 | II5: 0 | IL5: 0 | IM5: 0 | IP5: 0 | IQ5: 0 | IT5: 0 | IU5: 0 | IX5: 0 | IY5: 0 | JB5: 0 | JC5: 0 | JF5: 0 | JG5: 0 | JJ5: 0 | JK5: 0 | JN5: 0 | JO5: 0 | JR5: 0 | JS5: 0 | JV5: 0 | JW5: 0 | JZ5: 0 | KA5: 0 | KD5: 0 | KE5: 0 | KH5: 0 | KI5: 0 | KL5: 0 | KM5: 0 | KP5: 0 | KQ5: 0 | KT5: 0 | KU5: 0 | KX5: 0 | KY5: 0 | LB5: 0 | LC5: 0 | LF5: 0 | LG5: 0 | LJ5: 0 | LK5: 0 | LN5: 0 | LO5: 0 | LR5: 0 | LS5: 0 | LV5: 0 | LW5: 0 | LZ5: 0 | MA5: 0 | MD5: 0 | ME5: 0 | MH5: 0 | MI5: 0 | ML5: 0 | MM5: 0 | MP5: 0 | MQ5: 0 | MT5: 0 | MU5: 0 | MX5: 0 | MY5: 0 | NB5: 0 | NC5: 0 | NF5: 0 | NG5: 0 | NJ5: 0 | NK5: 0 | NN5: 0 | NO5: 0 | NR5: 0 | NS5: 0 | NV5: 0 | NW5: 0 | NZ5: 0 | OA5: 0 | OD5: 0 | OE5: 0 | OH5: 0 | OI5: 0 | OL5: 0 | OM5: 0 | OP5: 0 | OQ5: 0 | OT5: 0 | OU5: 0 | OX5: 0 | OY5: 0 | PB5: 0 | PC5: 0 | PF5: 0 | PG5: 0 | PJ5: 0 | PK5: 0 | PN5: 0 | PO5: 0 | PR5: 0 | PS5: 0 | PV5: 0 | PW5: 0 | PZ5: 0 | QA5: 0 | QD5: 0 | QE5: 0 | QH5: 0 | QI5: 0 | QL5: 0 | QM5: 0 | QP5: 0 | QQ5: 0 | QT5: 0 | QU5: 0 | QX5: 0 | QY5: 0 | RB5: 0 | RC5: 0 | RF5: 0 | RG5: 0 | RJ5: 0 | RK5: 0 | RN5: 0 | RO5: 0 | RR5: 0 | RS5: 0 | RV5: 0 | RW5: 0 | RZ5: 0 | SA5: 0 | SD5: 0 | SE5: 0 | SH5: 0 | SI5: 0 | SL5: 0 | SM5: 0 | SP5: 0 | SQ5: 0 | ST5: 0 | SU5: =ROUND(SR5/1000000*IF(SS5=0,0,VLOOKUP(SS5,名称和价格索引!$A$4:$C$834,3,FALSE)),1) -> 0 | SV5: {=SUM(VLOOKUP(D5,D5:SU5,ROW($1:$128)*4,0))} -> #N/A
A6: 鹿 | B6: 边界村 | C6: 823 | N6: 0 | O6: 0 | R6: 0 | S6: 0 | V6: 0 | W6: 0 | Z6: 0 | AA6: 0 | AD6: 0 | AE6: 0 | AH6: 0 | AI6: 0 | AL6: 0 | AM6: 0 | AP6: 0 | AQ6: 0 | AT6: 0 | AU6: 0 | AX6: 0 | AY6: 0 | BB6: 0 | BC6: 0 | BF6: 0 | BG6: 0 | BJ6: 0 | BK6: 0 | BN6: 0 | BO6: 0 | BR6: 0 | BS6: 0 | BV6: 0 | BW6: 0 | BZ6: 0 | CA6: 0 | CD6: 0 | CE6: 0 | CH6: 0 | CI6: 0 | CL6: 0 | CM6: 0 | CP6: 0 | CQ6: 0 | CT6: 0 | CU6: 0 | CX6: 0 | CY6: 0 | DB6: 0 | DC6: 0 | DF6: 0 | DG6: 0 | DJ6: 0 | DK6: 0 | DN6: 0 | DO6: 0 | DR6: 0 | DS6: 0 | DV6: 0 | DW6: 0 | DZ6: 0 | EA6: 0 | ED6: 0 | EE6: 0 | EH6: 0 | EI6: 0 | EL6: 0 | EM6: 0 | EP6: 0 | EQ6: 0 | ET6: 0 | EU6: 0 | EX6: 0 | EY6: 0 | FB6: 0 | FC6: 0 | FF6: 0 | FG6: 0 | FJ6: 0 | FK6: 0 | FN6: 0 | FO6: 0 | FR6: 0 | FS6: 0 | FV6: 0 | FW6: 0 | FZ6: 0 | GA6: 0 | GD6: 0 | GE6: 0 | GH6: 0 | GI6: 0 | GL6: 0 | GM6: 0 | GP6: 0 | GQ6: 0 | GT6: 0 | GU6: 0 | GX6: 0 | GY6: 0 | HB6: 0 | HC6: 0 | HF6: 0 | HG6: 0 | HJ6: 0 | HK6: 0 | HN6: 0 | HO6: 0 | HR6: 0 | HS6: 0 | HV6: 0 | HW6: 0 | HZ6: 0 | IA6: 0 | ID6: 0 | IE6: 0 | IH6: 0 | II6: 0 | IL6: 0 | IM6: 0 | IP6: 0 | IQ6: 0 | IT6: 0 | IU6: 0 | IX6: 0 | IY6: 0 | JB6: 0 | JC6: 0 | JF6: 0 | JG6: 0 | JJ6: 0 | JK6: 0 | JN6: 0 | JO6: 0 | JR6: 0 | JS6: 0 | JV6: 0 | JW6: 0 | JZ6: 0 | KA6: 0 | KD6: 0 | KE6: 0 | KH6: 0 | KI6: 0 | KL6: 0 | KM6: 0 | KP6: 0 | KQ6: 0 | KT6: 0 | KU6: 0 | KX6: 0 | KY6: 0 | LB6: 0 | LC6: 0 | LF6: 0 | LG6: 0 | LJ6: 0 | LK6: 0 | LN6: 0 | LO6: 0 | LR6: 0 | LS6: 0 | LV6: 0 | LW6: 0 | LZ6: 0 | MA6: 0 | MD6: 0 | ME6: 0 | MH6: 0 | MI6: 0 | ML6: 0 | MM6: 0 | MP6: 0 | MQ6: 0 | MT6: 0 | MU6: 0 | MX6: 0 | MY6: 0 | NB6: 0 | NC6: 0 | NF6: 0 | NG6: 0 | NJ6: 0 | NK6: 0 | NN6: 0 | NO6: 0 | NR6: 0 | NS6: 0 | NV6: 0 | NW6: 0 | NZ6: 0 | OA6: 0 | OD6: 0 | OE6: 0 | OH6: 0 | OI6: 0 | OL6: 0 | OM6: 0 | OP6: 0 | OQ6: 0 | OT6: 0 | OU6: 0 | OX6: 0 | OY6: 0 | PB6: 0 | PC6: 0 | PF6: 0 | PG6: 0 | PJ6: 0 | PK6: 0 | PN6: 0 | PO6: 0 | PR6: 0 | PS6: 0 | PV6: 0 | PW6: 0 | PZ6: 0 | QA6: 0 | QD6: 0 | QE6: 0 | QH6: 0 | QI6: 0 | QL6: 0 | QM6: 0 | QP6: 0 | QQ6: 0 | QT6: 0 | QU6: 0 | QX6: 0 | QY6: 0 | RB6: 0 | RC6: 0 | RF6: 0 | RG6: 0 | RJ6: 0 | RK6: 0 | RN6: 0 | RO6: 0 | RR6: 0 | RS6: 0 | RV6: 0 | RW6: 0 | RZ6: 0 | SA6: 0 | SD6: 0 | SE6: 0 | SH6: 0 | SI6: 0 | SL6: 0 | SM6: 0 | SP6: 0 | SQ6: 0 | ST6: 0 | SU6: =ROUND(SR6/1000000*IF(SS6=0,0,VLOOKUP(SS6,名称和价格索引!$A$4:$C$834,3,FALSE)),1) -> 0 | SV6: {=SUM(VLOOKUP(D6,D6:SU6,ROW($1:$128)*4,0))} -> #N/A
A7: 半兽人 | B7: 边界村 | C7: 803 | L7: 50000 | M7: 301 | N7: 金创药(小量) | O7: 2 | P7: 50000 | Q7: 321 | R7: 魔法药(小量) | S7: 2 | V7: 0 | W7: 0 | X7: 3000 | Y7: 99900004 | Z7: 青铜剑 | AA7: 1.4 | AB7: 3000 | AC7: 99940002 | AD7: 小手镯 | AE7: 1.5 | AF7: 3000 | AG7: 99930002 | AH7: 玻璃戒指 | AI7: 1.2 | AJ7: 3000 | AK7: 99930003 | AL7: 六角戒指 | AM7: 1.2 | AN7: 3000 | AO7: 99940017 | AP7: 皮制手套 | AQ7: 2.3 | AR7: 3000 | AS7: 99940003 | AT7: 银手镯 | AU7: 2.3 | AX7: 0 | AY7: 0 | BB7: 0 | BC7: 0 | BF7: 0 | BG7: 0 | BH7: 6000 | BI7: 99980113 | BJ7: 布衣 | BK7: 0.4 | BL7: 6000 | BM7: 99990113 | BN7: 布衣6 | BO7: 0.4 | BP7: 6000 | BQ7: 99900001 | BR7: 木剑 | BS7: 0.2 | BT7: 6000 | BU7: 99900002 | BV7: 匕首 | BW7: 1.5 | BZ7: 0 | CA7: 0 | CB7: 6000 | CC7: 99920001 | CD7: 金项链 | CE7: 1.5 | CF7: 6000 | CG7: 99930001 | CH7: 古铜戒指 | CI7: 1.5 | CJ7: 6000 | CK7: 99940001 | CL7: 铁手镯 | CM7: 2.4 | CN7: 6000 | CO7: 99920002 | CP7: 传统项链 | CQ7: 3 | CT7: 0 | CU7: 0 | CX7: 0 | CY7: 0 | DB7: 0 | DC7: 0 | DF7: 0 | DG7: 0 | DJ7: 0 | DK7: 0 | DN7: 0 | DO7: 0 | DR7: 0 | DS7: 0 | DV7: 0 | DW7: 0 | DZ7: 0 | EA7: 0 | ED7: 0 | EE7: 0 | EH7: 0 | EI7: 0 | EL7: 0 | EM7: 0 | EP7: 0 | EQ7: 0 | ET7: 0 | EU7: 0 | EX7: 0 | EY7: 0 | FB7: 0 | FC7: 0 | FF7: 0 | FG7: 0 | FJ7: 0 | FK7: 0 | FN7: 0 | FO7: 0 | FR7: 0 | FS7: 0 | FV7: 0 | FW7: 0 | FZ7: 0 | GA7: 0 | GD7: 0 | GE7: 0 | GH7: 0 | GI7: 0 | GL7: 0 | GM7: 0 | GP7: 0 | GQ7: 0 | GT7: 0 | GU7: 0 | GX7: 0 | GY7: 0 | HB7: 0 | HC7: 0 | HF7: 0 | HG7: 0 | HJ7: 0 | HK7: 0 | HN7: 0 | HO7: 0 | HR7: 0 | HS7: 0 | HV7: 0 | HW7: 0 | HZ7: 0 | IA7: 0 | ID7: 0 | IE7: 0 | IH7: 0 | II7: 0 | IL7: 0 | IM7: 0 | IP7: 0 | IQ7: 0 | IT7: 0 | IU7: 0 | IX7: 0 | IY7: 0 | JB7: 0 | JC7: 0 | JF7: 0 | JG7: 0 | JJ7: 0 | JK7: 0 | JN7: 0 | JO7: 0 | JR7: 0 | JS7: 0 | JV7: 0 | JW7: 0 | JZ7: 0 | KA7: 0 | KD7: 0 | KE7: 0 | KH7: 0 | KI7: 0 | KL7: 0 | KM7: 0 | KP7: 0 | KQ7: 0 | KT7: 0 | KU7: 0 | KX7: 0 | KY7: 0 | LB7: 0 | LC7: 0 | LF7: 0 | LG7: 0 | LJ7: 0 | LK7: 0 | LN7: 0 | LO7: 0 | LR7: 0 | LS7: 0 | LV7: 0 | LW7: 0 | LZ7: 0 | MA7: 0 | MD7: 0 | ME7: 0 | MH7: 0 | MI7: 0 | ML7: 0 | MM7: 0 | MP7: 0 | MQ7: 0 | MT7: 0 | MU7: 0 | MX7: 0 | MY7: 0 | NB7: 0 | NC7: 0 | NF7: 0 | NG7: 0 | NJ7: 0 | NK7: 0 | NN7: 0 | NO7: 0 | NR7: 0 | NS7: 0 | NV7: 0 | NW7: 0 | NZ7: 0 | OA7: 0 | OD7: 0 | OE7: 0 | OH7: 0 | OI7: 0 | OL7: 0 | OM7: 0 | OP7: 0 | OQ7: 0 | OT7: 0 | OU7: 0 | OX7: 0 | OY7: 0 | PB7: 0 | PC7: 0 | PF7: 0 | PG7: 0 | PJ7: 0 | PK7: 0 | PN7: 0 | PO7: 0 | PR7: 0 | PS7: 0 | PV7: 0 | PW7: 0 | PZ7: 0 | QA7: 0 | QD7: 0 | QE7: 0 | QH7: 0 | QI7: 0 | QL7: 0 | QM7: 0 | QP7: 0 | QQ7: 0 | QT7: 0 | QU7: 0 | QX7: 0 | QY7: 0 | RB7: 0 | RC7: 0 | RF7: 0 | RG7: 0 | RJ7: 0 | RK7: 0 | RN7: 0 | RO7: 0 | RR7: 0 | RS7: 0 | RV7: 0 | RW7: 0 | RZ7: 0 | SA7: 0 | SD7: 0 | SE7: 0 | SH7: 0 | SI7: 0 | SL7: 0 | SM7: 0 | SP7: 0 | SQ7: 0 | ST7: 0 | SU7: =ROUND(SR7/1000000*IF(SS7=0,0,VLOOKUP(SS7,名称和价格索引!$A$4:$C$834,3,FALSE)),1) -> 0 | SV7: {=SUM(VLOOKUP(D7,D7:SU7,ROW($1:$128)*4,0))} -> #N/A
A8: 半兽人战士 | B8: 边界村 | C8: 804 | L8: 50000 | M8: 301 | N8: 金创药(小量) | O8: 2 | P8: 50000 | Q8: 321 | R8: 魔法药(小量) | S8: 2 | V8: 0 | W8: 0 | X8: 5000 | Y8: 99900004 | Z8: 青铜剑 | AA8: 2.3 | AB8: 5000 | AC8: 99940002 | AD8: 小手镯 | AE8: 2.5 | AF8: 5000 | AG8: 99930002 | AH8: 玻璃戒指 | AI8: 2 | AJ8: 5000 | AK8: 99930003 | AL8: 六角戒指 | AM8: 2 | AN8: 5000 | AO8: 99940017 | AP8: 皮制手套 | AQ8: 3.8 | AR8: 5000 | AS8: 99940003 | AT8: 银手镯 | AU8: 3.8 | AX8: 0 | AY8: 0 | BB8: 0 | BC8: 0 | BF8: 0 | BG8: 0 | BH8: 10000 | BI8: 99980113 | BJ8: 布衣 | BK8: 0.6 | BL8: 10000 | BM8: 99990113 | BN8: 布衣6 | BO8: 0.6 | BP8: 10000 | BQ8: 99900001 | BR8: 木剑 | BS8: 0.3 | BT8: 10000 | BU8: 99900002 | BV8: 匕首 | BW8: 2.5 | BZ8: 0 | CA8: 0 | CB8: 10000 | CC8: 99920001 | CD8: 金项链 | CE8: 2.5 | CF8: 10000 | CG8: 99930001 | CH8: 古铜戒指 | CI8: 2.5 | CJ8: 10000 | CK8: 99940001 | CL8: 铁手镯 | CM8: 4 | CN8: 10000 | CO8: 99920002 | CP8: 传统项链 | CQ8: 5 | CT8: 0 | CU8: 0 | CX8: 0 | CY8: 0 | DB8: 0 | DC8: 0 | DF8: 0 | DG8: 0 | DJ8: 0 | DK8: 0 | DN8: 0 | DO8: 0 | DR8: 0 | DS8: 0 | DV8: 0 | DW8: 0 | DZ8: 0 | EA8: 0 | ED8: 0 | EE8: 0 | EH8: 0 | EI8: 0 | EL8: 0 | EM8: 0 | EP8: 0 | EQ8: 0 | ET8: 0 | EU8: 0 | EX8: 0 | EY8: 0 | FB8: 0 | FC8: 0 | FF8: 0 | FG8: 0 | FJ8: 0 | FK8: 0 | FN8: 0 | FO8: 0 | FR8: 0 | FS8: 0 | FV8: 0 | FW8: 0 | FZ8: 0 | GA8: 0 | GD8: 0 | GE8: 0 | GH8: 0 | GI8: 0 | GL8: 0 | GM8: 0 | GP8: 0 | GQ8: 0 | GT8: 0 | GU8: 0 | GX8: 0 | GY8: 0 | HB8: 0 | HC8: 0 | HF8: 0 | HG8: 0 | HJ8: 0 | HK8: 0 | HN8: 0 | HO8: 0 | HR8: 0 | HS8: 0 | HV8: 0 | HW8: 0 | HZ8: 0 | IA8: 0 | ID8: 0 | IE8: 0 | IH8: 0 | II8: 0 | IL8: 0 | IM8: 0 | IP8: 0 | IQ8: 0 | IT8: 0 | IU8: 0 | IX8: 0 | IY8: 0 | JB8: 0 | JC8: 0 | JF8: 0 | JG8: 0 | JJ8: 0 | JK8: 0 | JN8: 0 | JO8: 0 | JR8: 0 | JS8: 0 | JV8: 0 | JW8: 0 | JZ8: 0 | KA8: 0 | KD8: 0 | KE8: 0 | KH8: 0 | KI8: 0 | KL8: 0 | KM8: 0 | KP8: 0 | KQ8: 0 | KT8: 0 | KU8: 0 | KX8: 0 | KY8: 0 | LB8: 0 | LC8: 0 | LF8: 0 | LG8: 0 | LJ8: 0 | LK8: 0 | LN8: 0 | LO8: 0 | LR8: 0 | LS8: 0 | LV8: 0 | LW8: 0 | LZ8: 0 | MA8: 0 | MD8: 0 | ME8: 0 | MH8: 0 | MI8: 0 | ML8: 0 | MM8: 0 | MP8: 0 | MQ8: 0 | MT8: 0 | MU8: 0 | MX8: 0 | MY8: 0 | NB8: 0 | NC8: 0 | NF8: 0 | NG8: 0 | NJ8: 0 | NK8: 0 | NN8: 0 | NO8: 0 | NR8: 0 | NS8: 0 | NV8: 0 | NW8: 0 | NZ8: 0 | OA8: 0 | OD8: 0 | OE8: 0 | OH8: 0 | OI8: 0 | OL8: 0 | OM8: 0 | OP8: 0 | OQ8: 0 | OT8: 0 | OU8: 0 | OX8: 0 | OY8: 0 | PB8: 0 | PC8: 0 | PF8: 0 | PG8: 0 | PJ8: 0 | PK8: 0 | PN8: 0 | PO8: 0 | PR8: 0 | PS8: 0 | PV8: 0 | PW8: 0 | PZ8: 0 | QA8: 0 | QD8: 0 | QE8: 0 | QH8: 0 | QI8: 0 | QL8: 0 | QM8: 0 | QP8: 0 | QQ8: 0 | QT8: 0 | QU8: 0 | QX8: 0 | QY8: 0 | RB8: 0 | RC8: 0 | RF8: 0 | RG8: 0 | RJ8: 0 | RK8: 0 | RN8: 0 | RO8: 0 | RR8: 0 | RS8: 0 | RV8: 0 | RW8: 0 | RZ8: 0 | SA8: 0 | SD8: 0 | SE8: 0 | SH8: 0 | SI8: 0 | SL8: 0 | SM8: 0 | SP8: 0 | SQ8: 0 | ST8: 0 | SU8: =ROUND(SR8/1000000*IF(SS8=0,0,VLOOKUP(SS8,名称和价格索引!$A$4:$C$834,3,FALSE)),1) -> 0 | SV8: {=SUM(VLOOKUP(D8,D8:SU8,ROW($1:$128)*4,0))} -> #N/A
A9: 海蟹 | B9: 边界村 | C9: 821 | J9: 0 | K9: 0 | L9: 20000 | M9: 301 | N9: 金创药(小量) | O9: 0.8 | P9: 20000 | Q9: 321 | R9: 魔法药(小量) | S9: 0.8 | V9: 0 | W9: 0 | X9: 2000 | Y9: 99900004 | Z9: 青铜剑 | AA9: 0.9 | AB9: 2000 | AC9: 99940002 | AD9: 小手镯 | AE9: 1 | AF9: 2000 | AG9: 99930002 | AH9: 玻璃戒指 | AI9: 0.8 | AJ9: 2000 | AK9: 99930003 | AL9: 六角戒指 | AM9: 0.8 | AN9: 2000 | AO9: 99940017 | AP9: 皮制手套 | AQ9: 1.5 | AR9: 2000 | AS9: 99940003 | AT9: 银手镯 | AU9: 1.5 | AX9: 0 | AY9: 0 | BB9: 0 | BC9: 0 | BF9: 0 | BG9: 0 | BH9: 6000 | BI9: 99980113 | BJ9: 布衣 | BK9: 0.4 | BL9: 6000 | BM9: 99990113 | BN9: 布衣6 | BO9: 0.4 | BP9: 6000 | BQ9: 99900001 | BR9: 木剑 | BS9: 0.2 | BT9: 6000 | BU9: 99900002 | BV9: 匕首 | BW9: 1.5 | BZ9: 0 | CA9: 0 | CB9: 6000 | CC9: 99920001 | CD9: 金项链 | CE9: 1.5 | CF9: 6000 | CG9: 99930001 | CH9: 古铜戒指 | CI9: 1.5 | CJ9: 6000 | CK9: 99940001 | CL9: 铁手镯 | CM9: 2.4 | CN9: 6000 | CO9: 99920002 | CP9: 传统项链 | CQ9: 3 | CT9: 0 | CU9: 0 | CX9: 0 | CY9: 0 | DB9: 0 | DC9: 0 | DF9: 0 | DG9: 0 | DJ9: 0 | DK9: 0 | DN9: 0 | DO9: 0 | DR9: 0 | DS9: 0 | DV9: 0 | DW9: 0 | DZ9: 0 | EA9: 0 | ED9: 0 | EE9: 0 | EH9: 0 | EI9: 0 | EL9: 0 | EM9: 0 | EP9: 0 | EQ9: 0 | ET9: 0 | EU9: 0 | EX9: 0 | EY9: 0 | FB9: 0 | FC9: 0 | FF9: 0 | FG9: 0 | FJ9: 0 | FK9: 0 | FN9: 0 | FO9: 0 | FR9: 0 | FS9: 0 | FV9: 0 | FW9: 0 | FZ9: 0 | GA9: 0 | GD9: 0 | GE9: 0 | GH9: 0 | GI9: 0 | GL9: 0 | GM9: 0 | GP9: 0 | GQ9: 0 | GT9: 0 | GU9: 0 | GX9: 0 | GY9: 0 | HB9: 0 | HC9: 0 | HF9: 0 | HG9: 0 | HJ9: 0 | HK9: 0 | HN9: 0 | HO9: 0 | HR9: 0 | HS9: 0 | HV9: 0 | HW9: 0 | HZ9: 0 | IA9: 0 | ID9: 0 | IE9: 0 | IH9: 0 | II9: 0 | IL9: 0 | IM9: 0 | IP9: 0 | IQ9: 0 | IT9: 0 | IU9: 0 | IX9: 0 | IY9: 0 | JB9: 0 | JC9: 0 | JF9: 0 | JG9: 0 | JJ9: 0 | JK9: 0 | JN9: 0 | JO9: 0 | JR9: 0 | JS9: 0 | JV9: 0 | JW9: 0 | JZ9: 0 | KA9: 0 | KD9: 0 | KE9: 0 | KH9: 0 | KI9: 0 | KL9: 0 | KM9: 0 | KP9: 0 | KQ9: 0 | KT9: 0 | KU9: 0 | KX9: 0 | KY9: 0 | LB9: 0 | LC9: 0 | LF9: 0 | LG9: 0 | LJ9: 0 | LK9: 0 | LN9: 0 | LO9: 0 | LR9: 0 | LS9: 0 | LV9: 0 | LW9: 0 | LZ9: 0 | MA9: 0 | MD9: 0 | ME9: 0 | MH9: 0 | MI9: 0 | ML9: 0 | MM9: 0 | MP9: 0 | MQ9: 0 | MT9: 0 | MU9: 0 | MX9: 0 | MY9: 0 | NB9: 0 | NC9: 0 | NF9: 0 | NG9: 0 | NJ9: 0 | NK9: 0 | NN9: 0 | NO9: 0 | NR9: 0 | NS9: 0 | NV9: 0 | NW9: 0 | NZ9: 0 | OA9: 0 | OD9: 0 | OE9: 0 | OH9: 0 | OI9: 0 | OL9: 0 | OM9: 0 | OP9: 0 | OQ9: 0 | OT9: 0 | OU9: 0 | OX9: 0 | OY9: 0 | PB9: 0 | PC9: 0 | PF9: 0 | PG9: 0 | PJ9: 0 | PK9: 0 | PN9: 0 | PO9: 0 | PR9: 0 | PS9: 0 | PV9: 0 | PW9: 0 | PZ9: 0 | QA9: 0 | QD9: 0 | QE9: 0 | QH9: 0 | QI9: 0 | QL9: 0 | QM9: 0 | QP9: 0 | QQ9: 0 | QT9: 0 | QU9: 0 | QX9: 0 | QY9: 0 | RB9: 0 | RC9: 0 | RF9: 0 | RG9: 0 | RJ9: 0 | RK9: 0 | RN9: 0 | RO9: 0 | RR9: 0 | RS9: 0 | RV9: 0 | RW9: 0 | RZ9: 0 | SA9: 0 | SD9: 0 | SE9: 0 | SH9: 0 | SI9: 0 | SL9: 0 | SM9: 0 | SP9: 0 | SQ9: 0 | ST9: 0 | SU9: =ROUND(SR9/1000000*IF(SS9=0,0,VLOOKUP(SS9,名称和价格索引!$A$4:$C$834,3,FALSE)),1) -> 0 | SV9: {=SUM(VLOOKUP(D9,D9:SU9,ROW($1:$128)*4,0))} -> #N/A
A10: 半兽人 刀疤 | B10: 边界村 | C10: 838 | D10: 1000000 | E10: 200200 | F10: 200 | G10: 200 | H10: 1000000 | I10: 301 | J10: 金创药(小量) | K10: 40 | L10: 1000000 | M10: 301 | N10: 金创药(小量) | O10: 40 | P10: 500000 | Q10: 301 | R10: 金创药(小量) | S10: 20 | V10: 0 | W10: 0 | X10: 1000000 | Y10: 321 | Z10: 魔法药(小量) | AA10: 40 | AB10: 500000 | AC10: 321 | AD10: 魔法药(小量) | AE10: 20 | AH10: 0 | AI10: 0 | AL10: 0 | AM10: 0 | AP10: 0 | AQ10: 0 | AR10: 50000 | AS10: 99940002 | AT10: 小手镯 | AU10: 25 | AV10: 50000 | AW10: 99930002 | AX10: 玻璃戒指 | AY10: 20 | AZ10: 50000 | BA10: 99930003 | BB10: 六角戒指 | BC10: 20 | BD10: 50000 | BE10: 99940017 | BF10: 皮制手套 | BG10: 37.5 | BH10: 50000 | BI10: 99940003 | BJ10: 银手镯 | BK10: 37.5 | BN10: 0 | BO10: 0 | BR10: 0 | BS10: 0 | BT10: 80000 | BU10: 99980113 | BV10: 布衣 | BW10: 4.8 | BX10: 80000 | BY10: 99980113 | BZ10: 布衣 | CA10: 4.8 | CB10: 80000 | CC10: 99900001 | CD10: 木剑 | CE10: 2 | CF10: 80000 | CG10: 99900002 | CH10: 匕首 | CI10: 20 | CL10: 0 | CM10: 0 | CN10: 80000 | CO10: 99920001 | CP10: 金项链 | CQ10: 20 | CR10: 80000 | CS10: 99930001 | CT10: 古铜戒指 | CU10: 20 | CV10: 80000 | CW10: 99940001 | CX10: 铁手镯 | CY10: 32 | CZ10: 80000 | DA10: 99920002 | DB10: 传统项链 | DC10: 40 | DF10: 0 | DG10: 0 | DJ10: 0 | DK10: 0 | DN10: 0 | DO10: 0 | DR10: 0 | DS10: 0 | DV10: 0 | DW10: 0 | DZ10: 0 | EA10: 0 | ED10: 0 | EE10: 0 | EH10: 0 | EI10: 0 | EL10: 0 | EM10: 0 | EP10: 0 | EQ10: 0 | ET10: 0 | EU10: 0 | EX10: 0 | EY10: 0 | FB10: 0 | FC10: 0 | FF10: 0 | FG10: 0 | FJ10: 0 | FK10: 0 | FN10: 0 | FO10: 0 | FR10: 0 | FS10: 0 | FV10: 0 | FW10: 0 | FZ10: 0 | GA10: 0 | GD10: 0 | GE10: 0 | GH10: 0 | GI10: 0 | GL10: 0 | GM10: 0 | GP10: 0 | GQ10: 0 | GT10: 0 | GU10: 0 | GX10: 0 | GY10: 0 | HB10: 0 | HC10: 0 | HF10: 0 | HG10: 0 | HJ10: 0 | HK10: 0 | HN10: 0 | HO10: 0 | HR10: 0 | HS10: 0 | HV10: 0 | HW10: 0 | HZ10: 0 | IA10: 0 | ID10: 0 | IE10: 0 | IH10: 0 | II10: 0 | IL10: 0 | IM10: 0 | IP10: 0 | IQ10: 0 | IT10: 0 | IU10: 0 | IX10: 0 | IY10: 0 | JB10: 0 | JC10: 0 | JF10: 0 | JG10: 0 | JJ10: 0 | JK10: 0 | JN10: 0 | JO10: 0 | JR10: 0 | JS10: 0 | JV10: 0 | JW10: 0 | JZ10: 0 | KA10: 0 | KD10: 0 | KE10: 0 | KH10: 0 | KI10: 0 | KL10: 0 | KM10: 0 | KP10: 0 | KQ10: 0 | KT10: 0 | KU10: 0 | KX10: 0 | KY10: 0 | LB10: 0 | LC10: 0 | LF10: 0 | LG10: 0 | LJ10: 0 | LK10: 0 | LN10: 0 | LO10: 0 | LR10: 0 | LS10: 0 | LV10: 0 | LW10: 0 | LZ10: 0 | MA10: 0 | MD10: 0 | ME10: 0 | MH10: 0 | MI10: 0 | ML10: 0 | MM10: 0 | MP10: 0 | MQ10: 0 | MT10: 0 | MU10: 0 | MX10: 0 | MY10: 0 | NB10: 0 | NC10: 0 | NF10: 0 | NG10: 0 | NJ10: 0 | NK10: 0 | NN10: 0 | NO10: 0 | NR10: 0 | NS10: 0 | NV10: 0 | NW10: 0 | NZ10: 0 | OA10: 0 | OD10: 0 | OE10: 0 | OH10: 0 | OI10: 0 | OL10: 0 | OM10: 0 | OP10: 0 | OQ10: 0 | OT10: 0 | OU10: 0 | OX10: 0 | OY10: 0 | PB10: 0 | PC10: 0 | PF10: 0 | PG10: 0 | PJ10: 0 | PK10: 0 | PN10: 0 | PO10: 0 | PR10: 0 | PS10: 0 | PV10: 0 | PW10: 0 | PZ10: 0 | QA10: 0 | QD10: 0 | QE10: 0 | QH10: 0 | QI10: 0 | QL10: 0 | QM10: 0 | QP10: 0 | QQ10: 0 | QT10: 0 | QU10: 0 | QX10: 0 | QY10: 0 | RB10: 0 | RC10: 0 | RF10: 0 | RG10: 0 | RJ10: 0 | RK10: 0 | RN10: 0 | RO10: 0 | RR10: 0 | RS10: 0 | RV10: 0 | RW10: 0 | RZ10: 0 | SA10: 0 | SD10: 0 | SE10: 0 | SH10: 0 | SI10: 0 | SL10: 0 | SM10: 0 | SP10: 0 | SQ10: 0 | ST10: 0 | SU10: =ROUND(SR10/1000000*IF(SS10=0,0,VLOOKUP(SS10,名称和价格索引!$A$4:$C$834,3,FALSE)),1) -> 0 | SV10: {=SUM(VLOOKUP(D10,D10:SU10,ROW($1:$128)*4,0))} -> 643.6
A11: 钉耙猫 九命 | B11: 边界村 | C11: 839 | D11: 1000000 | E11: 200200 | F11: 200 | G11: 200 | H11: 1000000 | I11: 301 | J11: 金创药(小量) | K11: 40 | L11: 1000000 | M11: 301 | N11: 金创药(小量) | O11: 40 | P11: 500000 | Q11: 301 | R11: 金创药(小量) | S11: 20 | V11: 0 | W11: 0 | X11: 1000000 | Y11: 321 | Z11: 魔法药(小量) | AA11: 40 | AB11: 500000 | AC11: 321 | AD11: 魔法药(小量) | AE11: 20 | AH11: 0 | AI11: 0 | AL11: 0 | AM11: 0 | AP11: 0 | AQ11: 0 | AR11: 50000 | AS11: 99940002 | AT11: 小手镯 | AU11: 25 | AV11: 50000 | AW11: 99930002 | AX11: 玻璃戒指 | AY11: 20 | AZ11: 50000 | BA11: 99930003 | BB11: 六角戒指 | BC11: 20 | BD11: 50000 | BE11: 99940017 | BF11: 皮制手套 | BG11: 37.5 | BH11: 50000 | BI11: 99940003 | BJ11: 银手镯 | BK11: 37.5 | BN11: 0 | BO11: 0 | BR11: 0 | BS11: 0 | BT11: 80000 | BU11: 99980113 | BV11: 布衣 | BW11: 4.8 | BX11: 80000 | BY11: 99980113 | BZ11: 布衣 | CA11: 4.8 | CB11: 80000 | CC11: 99900001 | CD11: 木剑 | CE11: 2 | CF11: 80000 | CG11: 99900002 | CH11: 匕首 | CI11: 20 | CL11: 0 | CM11: 0 | CN11: 80000 | CO11: 99920001 | CP11: 金项链 | CQ11: 20 | CR11: 80000 | CS11: 99930001 | CT11: 古铜戒指 | CU11: 20 | CV11: 80000 | CW11: 99940001 | CX11: 铁手镯 | CY11: 32 | CZ11: 80000 | DA11: 99920002 | DB11: 传统项链 | DC11: 40 | DF11: 0 | DG11: 0 | DJ11: 0 | DK11: 0 | DN11: 0 | DO11: 0 | DR11: 0 | DS11: 0 | DV11: 0 | DW11: 0 | DZ11: 0 | EA11: 0 | ED11: 0 | EE11: 0 | EH11: 0 | EI11: 0 | EL11: 0 | EM11: 0 | EP11: 0 | EQ11: 0 | ET11: 0 | EU11: 0 | EX11: 0 | EY11: 0 | FB11: 0 | FC11: 0 | FF11: 0 | FG11: 0 | FJ11: 0 | FK11: 0 | FN11: 0 | FO11: 0 | FR11: 0 | FS11: 0 | FV11: 0 | FW11: 0 | FZ11: 0 | GA11: 0 | GD11: 0 | GE11: 0 | GH11: 0 | GI11: 0 | GL11: 0 | GM11: 0 | GP11: 0 | GQ11: 0 | GT11: 0 | GU11: 0 | GX11: 0 | GY11: 0 | HB11: 0 | HC11: 0 | HF11: 0 | HG11: 0 | HJ11: 0 | HK11: 0 | HN11: 0 | HO11: 0 | HR11: 0 | HS11: 0 | HV11: 0 | HW11: 0 | HZ11: 0 | IA11: 0 | ID11: 0 | IE11: 0 | IH11: 0 | II11: 0 | IL11: 0 | IM11: 0 | IP11: 0 | IQ11: 0 | IT11: 0 | IU11: 0 | IX11: 0 | IY11: 0 | JB11: 0 | JC11: 0 | JF11: 0 | JG11: 0 | JJ11: 0 | JK11: 0 | JN11: 0 | JO11: 0 | JR11: 0 | JS11: 0 | JV11: 0 | JW11: 0 | JZ11: 0 | KA11: 0 | KD11: 0 | KE11: 0 | KH11: 0 | KI11: 0 | KL11: 0 | KM11: 0 | KP11: 0 | KQ11: 0 | KT11: 0 | KU11: 0 | KX11: 0 | KY11: 0 | LB11: 0 | LC11: 0 | LF11: 0 | LG11: 0 | LJ11: 0 | LK11: 0 | LN11: 0 | LO11: 0 | LR11: 0 | LS11: 0 | LV11: 0 | LW11: 0 | LZ11: 0 | MA11: 0 | MD11: 0 | ME11: 0 | MH11: 0 | MI11: 0 | ML11: 0 | MM11: 0 | MP11: 0 | MQ11: 0 | MT11: 0 | MU11: 0 | MX11: 0 | MY11: 0 | NB11: 0 | NC11: 0 | NF11: 0 | NG11: 0 | NJ11: 0 | NK11: 0 | NN11: 0 | NO11: 0 | NR11: 0 | NS11: 0 | NV11: 0 | NW11: 0 | NZ11: 0 | OA11: 0 | OD11: 0 | OE11: 0 | OH11: 0 | OI11: 0 | OL11: 0 | OM11: 0 | OP11: 0 | OQ11: 0 | OT11: 0 | OU11: 0 | OX11: 0 | OY11: 0 | PB11: 0 | PC11: 0 | PF11: 0 | PG11: 0 | PJ11: 0 | PK11: 0 | PN11: 0 | PO11: 0 | PR11: 0 | PS11: 0 | PV11: 0 | PW11: 0 | PZ11: 0 | QA11: 0 | QD11: 0 | QE11: 0 | QH11: 0 | QI11: 0 | QL11: 0 | QM11: 0 | QP11: 0 | QQ11: 0 | QT11: 0 | QU11: 0 | QX11: 0 | QY11: 0 | RB11: 0 | RC11: 0 | RF11: 0 | RG11: 0 | RJ11: 0 | RK11: 0 | RN11: 0 | RO11: 0 | RR11: 0 | RS11: 0 | RV11: 0 | RW11: 0 | RZ11: 0 | SA11: 0 | SD11: 0 | SE11: 0 | SH11: 0 | SI11: 0 | SL11: 0 | SM11: 0 | SP11: 0 | SQ11: 0 | ST11: 0 | SU11: =ROUND(SR11/1000000*IF(SS11=0,0,VLOOKUP(SS11,名称和价格索引!$A$4:$C$834,3,FALSE)),1) -> 0 | SV11: {=SUM(VLOOKUP(D11,D11:SU11,ROW($1:$128)*4,0))} -> 643.6
A12: 兵俑 铁皮 | B12: 边界村 | C12: 841 | D12: 1000000 | E12: 200200 | F12: 200 | G12: 200 | H12: 1000000 | I12: 301 | J12: 金创药(小量) | K12: 40 | L12: 1000000 | M12: 301 | N12: 金创药(小量) | O12: 40 | P12: 500000 | Q12: 301 | R12: 金创药(小量) | S12: 20 | V12: 0 | W12: 0 | X12: 1000000 | Y12: 321 | Z12: 魔法药(小量) | AA12: 40 | AB12: 500000 | AC12: 321 | AD12: 魔法药(小量) | AE12: 20 | AH12: 0 | AI12: 0 | AL12: 0 | AM12: 0 | AP12: 0 | AQ12: 0 | AR12: 50000 | AS12: 99940002 | AT12: 小手镯 | AU12: 25 | AV12: 50000 | AW12: 99930002 | AX12: 玻璃戒指 | AY12: 20 | AZ12: 50000 | BA12: 99930003 | BB12: 六角戒指 | BC12: 20 | BD12: 50000 | BE12: 99940017 | BF12: 皮制手套 | BG12: 37.5 | BH12: 50000 | BI12: 99940003 | BJ12: 银手镯 | BK12: 37.5 | BN12: 0 | BO12: 0 | BR12: 0 | BS12: 0 | BT12: 80000 | BU12: 99980113 | BV12: 布衣 | BW12: 4.8 | BX12: 80000 | BY12: 99980113 | BZ12: 布衣 | CA12: 4.8 | CB12: 80000 | CC12: 99900001 | CD12: 木剑 | CE12: 2 | CF12: 80000 | CG12: 99900002 | CH12: 匕首 | CI12: 20 | CL12: 0 | CM12: 0 | CN12: 80000 | CO12: 99920001 | CP12: 金项链 | CQ12: 20 | CR12: 80000 | CS12: 99930001 | CT12: 古铜戒指 | CU12: 20 | CV12: 80000 | CW12: 99940001 | CX12: 铁手镯 | CY12: 32 | CZ12: 80000 | DA12: 99920002 | DB12: 传统项链 | DC12: 40 | DF12: 0 | DG12: 0 | DJ12: 0 | DK12: 0 | DN12: 0 | DO12: 0 | DR12: 0 | DS12: 0 | DV12: 0 | DW12: 0 | DZ12: 0 | EA12: 0 | ED12: 0 | EE12: 0 | EH12: 0 | EI12: 0 | EL12: 0 | EM12: 0 | EP12: 0 | EQ12: 0 | ET12: 0 | EU12: 0 | EX12: 0 | EY12: 0 | FB12: 0 | FC12: 0 | FF12: 0 | FG12: 0 | FJ12: 0 | FK12: 0 | FN12: 0 | FO12: 0 | FR12: 0 | FS12: 0 | FV12: 0 | FW12: 0 | FZ12: 0 | GA12: 0 | GD12: 0 | GE12: 0 | GH12: 0 | GI12: 0 | GL12: 0 | GM12: 0 | GP12: 0 | GQ12: 0 | GT12: 0 | GU12: 0 | GX12: 0 | GY12: 0 | HB12: 0 | HC12: 0 | HF12: 0 | HG12: 0 | HJ12: 0 | HK12: 0 | HN12: 0 | HO12: 0 | HR12: 0 | HS12: 0 | HV12: 0 | HW12: 0 | HZ12: 0 | IA12: 0 | ID12: 0 | IE12: 0 | IH12: 0 | II12: 0 | IL12: 0 | IM12: 0 | IP12: 0 | IQ12: 0 | IT12: 0 | IU12: 0 | IX12: 0 | IY12: 0 | JB12: 0 | JC12: 0 | JF12: 0 | JG12: 0 | JJ12: 0 | JK12: 0 | JN12: 0 | JO12: 0 | JR12: 0 | JS12: 0 | JV12: 0 | JW12: 0 | JZ12: 0 | KA12: 0 | KD12: 0 | KE12: 0 | KH12: 0 | KI12: 0 | KL12: 0 | KM12: 0 | KP12: 0 | KQ12: 0 | KT12: 0 | KU12: 0 | KX12: 0 | KY12: 0 | LB12: 0 | LC12: 0 | LF12: 0 | LG12: 0 | LJ12: 0 | LK12: 0 | LN12: 0 | LO12: 0 | LR12: 0 | LS12: 0 | LV12: 0 | LW12: 0 | LZ12: 0 | MA12: 0 | MD12: 0 | ME12: 0 | MH12: 0 | MI12: 0 | ML12: 0 | MM12: 0 | MP12: 0 | MQ12: 0 | MT12: 0 | MU12: 0 | MX12: 0 | MY12: 0 | NB12: 0 | NC12: 0 | NF12: 0 | NG12: 0 | NJ12: 0 | NK12: 0 | NN12: 0 | NO12: 0 | NR12: 0 | NS12: 0 | NV12: 0 | NW12: 0 | NZ12: 0 | OA12: 0 | OD12: 0 | OE12: 0 | OH12: 0 | OI12: 0 | OL12: 0 | OM12: 0 | OP12: 0 | OQ12: 0 | OT12: 0 | OU12: 0 | OX12: 0 | OY12: 0 | PB12: 0 | PC12: 0 | PF12: 0 | PG12: 0 | PJ12: 0 | PK12: 0 | PN12: 0 | PO12: 0 | PR12: 0 | PS12: 0 | PV12: 0 | PW12: 0 | PZ12: 0 | QA12: 0 | QD12: 0 | QE12: 0 | QH12: 0 | QI12: 0 | QL12: 0 | QM12: 0 | QP12: 0 | QQ12: 0 | QT12: 0 | QU12: 0 | QX12: 0 | QY12: 0 | RB12: 0 | RC12: 0 | RF12: 0 | RG12: 0 | RJ12: 0 | RK12: 0 | RN12: 0 | RO12: 0 | RR12: 0 | RS12: 0 | RV12: 0 | RW12: 0 | RZ12: 0 | SA12: 0 | SD12: 0 | SE12: 0 | SH12: 0 | SI12: 0 | SL12: 0 | SM12: 0 | SP12: 0 | SQ12: 0 | ST12: 0 | SU12: =ROUND(SR12/1000000*IF(SS12=0,0,VLOOKUP(SS12,名称和价格索引!$A$4:$C$834,3,FALSE)),1) -> 0 | SV12: {=SUM(VLOOKUP(D12,D12:SU12,ROW($1:$128)*4,0))} -> 643.6
A13: 稻草人 符命 | B13: 边界村 | C13: 842 | D13: 1000000 | E13: 200200 | F13: 200 | G13: 200 | H13: 1000000 | I13: 301 | J13: 金创药(小量) | K13: 40 | L13: 1000000 | M13: 301 | N13: 金创药(小量) | O13: 40 | P13: 500000 | Q13: 301 | R13: 金创药(小量) | S13: 20 | V13: 0 | W13: 0 | X13: 1000000 | Y13: 321 | Z13: 魔法药(小量) | AA13: 40 | AB13: 500000 | AC13: 321 | AD13: 魔法药(小量) | AE13: 20 | AH13: 0 | AI13: 0 | AL13: 0 | AM13: 0 | AP13: 0 | AQ13: 0 | AR13: 50000 | AS13: 99940002 | AT13: 小手镯 | AU13: 25 | AV13: 50000 | AW13: 99930002 | AX13: 玻璃戒指 | AY13: 20 | AZ13: 50000 | BA13: 99930003 | BB13: 六角戒指 | BC13: 20 | BD13: 50000 | BE13: 99940017 | BF13: 皮制手套 | BG13: 37.5 | BH13: 50000 | BI13: 99940003 | BJ13: 银手镯 | BK13: 37.5 | BN13: 0 | BO13: 0 | BR13: 0 | BS13: 0 | BT13: 80000 | BU13: 99980113 | BV13: 布衣 | BW13: 4.8 | BX13: 80000 | BY13: 99980113 | BZ13: 布衣 | CA13: 4.8 | CB13: 80000 | CC13: 99900001 | CD13: 木剑 | CE13: 2 | CF13: 80000 | CG13: 99900002 | CH13: 匕首 | CI13: 20 | CL13: 0 | CM13: 0 | CN13: 80000 | CO13: 99920001 | CP13: 金项链 | CQ13: 20 | CR13: 80000 | CS13: 99930001 | CT13: 古铜戒指 | CU13: 20 | CV13: 80000 | CW13: 99940001 | CX13: 铁手镯 | CY13: 32 | CZ13: 80000 | DA13: 99920002 | DB13: 传统项链 | DC13: 40 | DF13: 0 | DG13: 0 | DJ13: 0 | DK13: 0 | DN13: 0 | DO13: 0 | DR13: 0 | DS13: 0 | DV13: 0 | DW13: 0 | DZ13: 0 | EA13: 0 | ED13: 0 | EE13: 0 | EH13: 0 | EI13: 0 | EL13: 0 | EM13: 0 | EP13: 0 | EQ13: 0 | ET13: 0 | EU13: 0 | EX13: 0 | EY13: 0 | FB13: 0 | FC13: 0 | FF13: 0 | FG13: 0 | FJ13: 0 | FK13: 0 | FN13: 0 | FO13: 0 | FR13: 0 | FS13: 0 | FV13: 0 | FW13: 0 | FZ13: 0 | GA13: 0 | GD13: 0 | GE13: 0 | GH13: 0 | GI13: 0 | GL13: 0 | GM13: 0 | GP13: 0 | GQ13: 0 | GT13: 0 | GU13: 0 | GX13: 0 | GY13: 0 | HB13: 0 | HC13: 0 | HF13: 0 | HG13: 0 | HJ13: 0 | HK13: 0 | HN13: 0 | HO13: 0 | HR13: 0 | HS13: 0 | HV13: 0 | HW13: 0 | HZ13: 0 | IA13: 0 | ID13: 0 | IE13: 0 | IH13: 0 | II13: 0 | IL13: 0 | IM13: 0 | IP13: 0 | IQ13: 0 | IT13: 0 | IU13: 0 | IX13: 0 | IY13: 0 | JB13: 0 | JC13: 0 | JF13: 0 | JG13: 0 | JJ13: 0 | JK13: 0 | JN13: 0 | JO13: 0 | JR13: 0 | JS13: 0 | JV13: 0 | JW13: 0 | JZ13: 0 | KA13: 0 | KD13: 0 | KE13: 0 | KH13: 0 | KI13: 0 | KL13: 0 | KM13: 0 | KP13: 0 | KQ13: 0 | KT13: 0 | KU13: 0 | KX13: 0 | KY13: 0 | LB13: 0 | LC13: 0 | LF13: 0 | LG13: 0 | LJ13: 0 | LK13: 0 | LN13: 0 | LO13: 0 | LR13: 0 | LS13: 0 | LV13: 0 | LW13: 0 | LZ13: 0 | MA13: 0 | MD13: 0 | ME13: 0 | MH13: 0 | MI13: 0 | ML13: 0 | MM13: 0 | MP13: 0 | MQ13: 0 | MT13: 0 | MU13: 0 | MX13: 0 | MY13: 0 | NB13: 0 | NC13: 0 | NF13: 0 | NG13: 0 | NJ13: 0 | NK13: 0 | NN13: 0 | NO13: 0 | NR13: 0 | NS13: 0 | NV13: 0 | NW13: 0 | NZ13: 0 | OA13: 0 | OD13: 0 | OE13: 0 | OH13: 0 | OI13: 0 | OL13: 0 | OM13: 0 | OP13: 0 | OQ13: 0 | OT13: 0 | OU13: 0 | OX13: 0 | OY13: 0 | PB13: 0 | PC13: 0 | PF13: 0 | PG13: 0 | PJ13: 0 | PK13: 0 | PN13: 0 | PO13: 0 | PR13: 0 | PS13: 0 | PV13: 0 | PW13: 0 | PZ13: 0 | QA13: 0 | QD13: 0 | QE13: 0 | QH13: 0 | QI13: 0 | QL13: 0 | QM13: 0 | QP13: 0 | QQ13: 0 | QT13: 0 | QU13: 0 | QX13: 0 | QY13: 0 | RB13: 0 | RC13: 0 | RF13: 0 | RG13: 0 | RJ13: 0 | RK13: 0 | RN13: 0 | RO13: 0 | RR13: 0 | RS13: 0 | RV13: 0 | RW13: 0 | RZ13: 0 | SA13: 0 | SD13: 0 | SE13: 0 | SH13: 0 | SI13: 0 | SL13: 0 | SM13: 0 | SP13: 0 | SQ13: 0 | ST13: 0 | SU13: =ROUND(SR13/1000000*IF(SS13=0,0,VLOOKUP(SS13,名称和价格索引!$A$4:$C$834,3,FALSE)),1) -> 0 | SV13: {=SUM(VLOOKUP(D13,D13:SU13,ROW($1:$128)*4,0))} -> 643.6
A14: 稻草人 巧魔 | B14: 边界村 | C14: 845 | D14: 1000000 | E14: 200200 | F14: 200 | G14: 200 | H14: 1000000 | I14: 301 | J14: 金创药(小量) | K14: 40 | L14: 1000000 | M14: 301 | N14: 金创药(小量) | O14: 40 | P14: 500000 | Q14: 301 | R14: 金创药(小量) | S14: 20 | V14: 0 | W14: 0 | X14: 1000000 | Y14: 321 | Z14: 魔法药(小量) | AA14: 40 | AB14: 500000 | AC14: 321 | AD14: 魔法药(小量) | AE14: 20 | AH14: 0 | AI14: 0 | AL14: 0 | AM14: 0 | AP14: 0 | AQ14: 0 | AR14: 50000 | AS14: 99940002 | AT14: 小手镯 | AU14: 25 | AV14: 50000 | AW14: 99930002 | AX14: 玻璃戒指 | AY14: 20 | AZ14: 50000 | BA14: 99930003 | BB14: 六角戒指 | BC14: 20 | BD14: 50000 | BE14: 99940017 | BF14: 皮制手套 | BG14: 37.5 | BH14: 50000 | BI14: 99940003 | BJ14: 银手镯 | BK14: 37.5 | BN14: 0 | BO14: 0 | BR14: 0 | BS14: 0 | BT14: 80000 | BU14: 99980113 | BV14: 布衣 | BW14: 4.8 | BX14: 80000 | BY14: 99980113 | BZ14: 布衣 | CA14: 4.8 | CB14: 80000 | CC14: 99900001 | CD14: 木剑 | CE14: 2 | CF14: 80000 | CG14: 99900002 | CH14: 匕首 | CI14: 20 | CL14: 0 | CM14: 0 | CN14: 80000 | CO14: 99920001 | CP14: 金项链 | CQ14: 20 | CR14: 80000 | CS14: 99930001 | CT14: 古铜戒指 | CU14: 20 | CV14: 80000 | CW14: 99940001 | CX14: 铁手镯 | CY14: 32 | CZ14: 80000 | DA14: 99920002 | DB14: 传统项链 | DC14: 40 | DF14: 0 | DG14: 0 | DJ14: 0 | DK14: 0 | DN14: 0 | DO14: 0 | DR14: 0 | DS14: 0 | DV14: 0 | DW14: 0 | DZ14: 0 | EA14: 0 | ED14: 0 | EE14: 0 | EH14: 0 | EI14: 0 | EL14: 0 | EM14: 0 | EP14: 0 | EQ14: 0 | ET14: 0 | EU14: 0 | EX14: 0 | EY14: 0 | FB14: 0 | FC14: 0 | FF14: 0 | FG14: 0 | FJ14: 0 | FK14: 0 | FN14: 0 | FO14: 0 | FR14: 0 | FS14: 0 | FV14: 0 | FW14: 0 | FZ14: 0 | GA14: 0 | GD14: 0 | GE14: 0 | GH14: 0 | GI14: 0 | GL14: 0 | GM14: 0 | GP14: 0 | GQ14: 0 | GT14: 0 | GU14: 0 | GX14: 0 | GY14: 0 | HB14: 0 | HC14: 0 | HF14: 0 | HG14: 0 | HJ14: 0 | HK14: 0 | HN14: 0 | HO14: 0 | HR14: 0 | HS14: 0 | HV14: 0 | HW14: 0 | HZ14: 0 | IA14: 0 | ID14: 0 | IE14: 0 | IH14: 0 | II14: 0 | IL14: 0 | IM14: 0 | IP14: 0 | IQ14: 0 | IT14: 0 | IU14: 0 | IX14: 0 | IY14: 0 | JB14: 0 | JC14: 0 | JF14: 0 | JG14: 0 | JJ14: 0 | JK14: 0 | JN14: 0 | JO14: 0 | JR14: 0 | JS14: 0 | JV14: 0 | JW14: 0 | JZ14: 0 | KA14: 0 | KD14: 0 | KE14: 0 | KH14: 0 | KI14: 0 | KL14: 0 | KM14: 0 | KP14: 0 | KQ14: 0 | KT14: 0 | KU14: 0 | KX14: 0 | KY14: 0 | LB14: 0 | LC14: 0 | LF14: 0 | LG14: 0 | LJ14: 0 | LK14: 0 | LN14: 0 | LO14: 0 | LR14: 0 | LS14: 0 | LV14: 0 | LW14: 0 | LZ14: 0 | MA14: 0 | MD14: 0 | ME14: 0 | MH14: 0 | MI14: 0 | ML14: 0 | MM14: 0 | MP14: 0 | MQ14: 0 | MT14: 0 | MU14: 0 | MX14: 0 | MY14: 0 | NB14: 0 | NC14: 0 | NF14: 0 | NG14: 0 | NJ14: 0 | NK14: 0 | NN14: 0 | NO14: 0 | NR14: 0 | NS14: 0 | NV14: 0 | NW14: 0 | NZ14: 0 | OA14: 0 | OD14: 0 | OE14: 0 | OH14: 0 | OI14: 0 | OL14: 0 | OM14: 0 | OP14: 0 | OQ14: 0 | OT14: 0 | OU14: 0 | OX14: 0 | OY14: 0 | PB14: 0 | PC14: 0 | PF14: 0 | PG14: 0 | PJ14: 0 | PK14: 0 | PN14: 0 | PO14: 0 | PR14: 0 | PS14: 0 | PV14: 0 | PW14: 0 | PZ14: 0 | QA14: 0 | QD14: 0 | QE14: 0 | QH14: 0 | QI14: 0 | QL14: 0 | QM14: 0 | QP14: 0 | QQ14: 0 | QT14: 0 | QU14: 0 | QX14: 0 | QY14: 0 | RB14: 0 | RC14: 0 | RF14: 0 | RG14: 0 | RJ14: 0 | RK14: 0 | RN14: 0 | RO14: 0 | RR14: 0 | RS14: 0 | RV14: 0 | RW14: 0 | RZ14: 0 | SA14: 0 | SD14: 0 | SE14: 0 | SH14: 0 | SI14: 0 | SL14: 0 | SM14: 0 | SP14: 0 | SQ14: 0 | ST14: 0 | SU14: =ROUND(SR14/1000000*IF(SS14=0,0,VLOOKUP(SS14,名称和价格索引!$A$4:$C$834,3,FALSE)),1) -> 0 | SV14: {=SUM(VLOOKUP(D14,D14:SU14,ROW($1:$128)*4,0))} -> 643.6
A15: 稻草人 魂十五 | B15: 边界村 | C15: 848 | D15: 1000000 | E15: 200200 | F15: 200 | G15: 200 | H15: 1000000 | I15: 301 | J15: 金创药(小量) | K15: 40 | L15: 1000000 | M15: 301 | N15: 金创药(小量) | O15: 40 | P15: 500000 | Q15: 301 | R15: 金创药(小量) | S15: 20 | V15: 0 | W15: 0 | X15: 1000000 | Y15: 321 | Z15: 魔法药(小量) | AA15: 40 | AB15: 500000 | AC15: 321 | AD15: 魔法药(小量) | AE15: 20 | AH15: 0 | AI15: 0 | AL15: 0 | AM15: 0 | AP15: 0 | AQ15: 0 | AR15: 50000 | AS15: 99940002 | AT15: 小手镯 | AU15: 25 | AV15: 50000 | AW15: 99930002 | AX15: 玻璃戒指 | AY15: 20 | AZ15: 50000 | BA15: 99930003 | BB15: 六角戒指 | BC15: 20 | BD15: 50000 | BE15: 99940017 | BF15: 皮制手套 | BG15: 37.5 | BH15: 50000 | BI15: 99940003 | BJ15: 银手镯 | BK15: 37.5 | BN15: 0 | BO15: 0 | BR15: 0 | BS15: 0 | BT15: 80000 | BU15: 99980113 | BV15: 布衣 | BW15: 4.8 | BX15: 80000 | BY15: 99980113 | BZ15: 布衣 | CA15: 4.8 | CB15: 80000 | CC15: 99900001 | CD15: 木剑 | CE15: 2 | CF15: 80000 | CG15: 99900002 | CH15: 匕首 | CI15: 20 | CL15: 0 | CM15: 0 | CN15: 80000 | CO15: 99920001 | CP15: 金项链 | CQ15: 20 | CR15: 80000 | CS15: 99930001 | CT15: 古铜戒指 | CU15: 20 | CV15: 80000 | CW15: 99940001 | CX15: 铁手镯 | CY15: 32 | CZ15: 80000 | DA15: 99920002 | DB15: 传统项链 | DC15: 40 | DF15: 0 | DG15: 0 | DJ15: 0 | DK15: 0 | DN15: 0 | DO15: 0 | DR15: 0 | DS15: 0 | DV15: 0 | DW15: 0 | DZ15: 0 | EA15: 0 | ED15: 0 | EE15: 0 | EH15: 0 | EI15: 0 | EL15: 0 | EM15: 0 | EP15: 0 | EQ15: 0 | ET15: 0 | EU15: 0 | EX15: 0 | EY15: 0 | FB15: 0 | FC15: 0 | FF15: 0 | FG15: 0 | FJ15: 0 | FK15: 0 | FN15: 0 | FO15: 0 | FR15: 0 | FS15: 0 | FV15: 0 | FW15: 0 | FZ15: 0 | GA15: 0 | GD15: 0 | GE15: 0 | GH15: 0 | GI15: 0 | GL15: 0 | GM15: 0 | GP15: 0 | GQ15: 0 | GT15: 0 | GU15: 0 | GX15: 0 | GY15: 0 | HB15: 0 | HC15: 0 | HF15: 0 | HG15: 0 | HJ15: 0 | HK15: 0 | HN15: 0 | HO15: 0 | HR15: 0 | HS15: 0 | HV15: 0 | HW15: 0 | HZ15: 0 | IA15: 0 | ID15: 0 | IE15: 0 | IH15: 0 | II15: 0 | IL15: 0 | IM15: 0 | IP15: 0 | IQ15: 0 | IT15: 0 | IU15: 0 | IX15: 0 | IY15: 0 | JB15: 0 | JC15: 0 | JF15: 0 | JG15: 0 | JJ15: 0 | JK15: 0 | JN15: 0 | JO15: 0 | JR15: 0 | JS15: 0 | JV15: 0 | JW15: 0 | JZ15: 0 | KA15: 0 | KD15: 0 | KE15: 0 | KH15: 0 | KI15: 0 | KL15: 0 | KM15: 0 | KP15: 0 | KQ15: 0 | KT15: 0 | KU15: 0 | KX15: 0 | KY15: 0 | LB15: 0 | LC15: 0 | LF15: 0 | LG15: 0 | LJ15: 0 | LK15: 0 | LN15: 0 | LO15: 0 | LR15: 0 | LS15: 0 | LV15: 0 | LW15: 0 | LZ15: 0 | MA15: 0 | MD15: 0 | ME15: 0 | MH15: 0 | MI15: 0 | ML15: 0 | MM15: 0 | MP15: 0 | MQ15: 0 | MT15: 0 | MU15: 0 | MX15: 0 | MY15: 0 | NB15: 0 | NC15: 0 | NF15: 0 | NG15: 0 | NJ15: 0 | NK15: 0 | NN15: 0 | NO15: 0 | NR15: 0 | NS15: 0 | NV15: 0 | NW15: 0 | NZ15: 0 | OA15: 0 | OD15: 0 | OE15: 0 | OH15: 0 | OI15: 0 | OL15: 0 | OM15: 0 | OP15: 0 | OQ15: 0 | OT15: 0 | OU15: 0 | OX15: 0 | OY15: 0 | PB15: 0 | PC15: 0 | PF15: 0 | PG15: 0 | PJ15: 0 | PK15: 0 | PN15: 0 | PO15: 0 | PR15: 0 | PS15: 0 | PV15: 0 | PW15: 0 | PZ15: 0 | QA15: 0 | QD15: 0 | QE15: 0 | QH15: 0 | QI15: 0 | QL15: 0 | QM15: 0 | QP15: 0 | QQ15: 0 | QT15: 0 | QU15: 0 | QX15: 0 | QY15: 0 | RB15: 0 | RC15: 0 | RF15: 0 | RG15: 0 | RJ15: 0 | RK15: 0 | RN15: 0 | RO15: 0 | RR15: 0 | RS15: 0 | RV15: 0 | RW15: 0 | RZ15: 0 | SA15: 0 | SD15: 0 | SE15: 0 | SH15: 0 | SI15: 0 | SL15: 0 | SM15: 0 | SP15: 0 | SQ15: 0 | ST15: 0 | SU15: =ROUND(SR15/1000000*IF(SS15=0,0,VLOOKUP(SS15,名称和价格索引!$A$4:$C$834,3,FALSE)),1) -> 0 | SV15: {=SUM(VLOOKUP(D15,D15:SU15,ROW($1:$128)*4,0))} -> 643.6
