Workbook

Sheet guild_building
A1: ID | B1: Name | C1: Level | D1: MaxLevel | E1: MaxNum | F1: Prosperity | G1: MoneyConsumption | H1: TotalMoneyConsumption | I1: HerbConsumption | J1: TotalHerbConsumption | K1: WoodConsumption | L1: TotalWoodConsumption | M1: CrystalConsumption | N1: TotalCrystalConsumption | O1: SilverConsumption | P1: TotalSilverConsumption | Q1: UpgradeTime | R1: RoutineConsumption | S1: CdtnBaseNpcID | T1: ConditionBuildingID | U1: ConditionBuildingLvl | V1: UpgradingSpellID | W1: NpcTemplateID | X1: DeadNpcTemplateID | Y1: ReviveTime | Z1: Param1 | AA1: Param2 | AB1: Param3 | AC1: Param4 | AD1: Param5 | AE1: IntruderMsgID | AF1: DefenderMsgID | AG1: FewMembersReward | AH1: SomeMembersReward | AI1: ManyMembersReward | AJ1: Effect | AK1: Description
A2: Both | B2: Client | C2: Both | D2: Both | E2: Both | F2: Server | G2: Both | H2: Server | I2: Both | J2: Server | K2: Both | L2: Server | M2: Both | N2: Server | O2: Both | P2: Server | Q2: Both | R2: Both | S2: Both | T2: Both | U2: Both | V2: Both | W2: Both | X2: Server | Y2: Server | Z2: Both | AA2: Both | AB2: Both | AC2: Both | AD2: Both | AE2: Server | AF2: Server | AG2: Server | AH2: Server | AI2: Server | AJ2: Both | AK2: Client
A3: 0 | B3: 0 | C3: 0 | D3: 0 | G3: 0 | I3: 0 | K3: 0 | L3: 0 | M3: 0 | N3: 0 | O3: 0 | P3: 0 | Q3: 0 | R3: 0 | S3: 0 | T3: 0 | U3: 0 | V3: 0 | W3: 0 | X3: 0 | Z3: 0 | AA3: 0 | AB3: 0 | AC3: 0 | AD3: 0 | AJ3: 0 | AK3: 0
A4: 1 | B4: 主殿 | C4: 0 | D4: 5 | E4: 1 | F4: 100 | G4: =VLOOKUP(A4,资源索引!$A$2:$F$29,2,FALSE)*VLOOKUP(C4+1,资源索引!$I$1:$J$6,2,FALSE) -> 400000 | H4: =SUM(G$4:G4) -> 400000 | I4: =VLOOKUP(A4,资源索引!$A$2:$F$29,3,FALSE)*VLOOKUP(C4+1,资源索引!$I$1:$J$6,2,FALSE) -> 200000 | J4: =SUM(I$4:I4) -> 200000 | K4: =VLOOKUP(A4,资源索引!$A$2:$F$29,4,FALSE)*VLOOKUP(C4+1,资源索引!$I$1:$J$6,2,FALSE) -> 200000 | L4: =SUM(K$4:K4) -> 200000 | M4: =VLOOKUP(A4,资源索引!$A$2:$F$29,5,FALSE)*VLOOKUP(C4+1,资源索引!$I$1:$J$6,2,FALSE) -> 200000 | N4: =SUM(M$4:M4) -> 200000 | O4: =VLOOKUP(A4,资源索引!$A$2:$F$29,6,FALSE)*VLOOKUP(C4+1,资源索引!$I$1:$J$6,2,FALSE) -> 200000 | P4: =SUM(O$4:O4) -> 200000 | Q4: 2 | R4: 0 | S4: 9945 | T4: 0 | U4: 0 | V4: 0 | W4: 9945 | X4: 4859 | Z4: 100000 | AA4: 50000 | AB4: 50000 | AC4: 50000 | AD4: 50000 | AE4: 1020 | AF4: 1060 | AJ4: 0 | AK4: 主殿是公会核心建筑，升级主殿能提升公会等级，使其能建造更多其他建筑。
A5: 1 | B5: 主殿 | C5: 1 | D5: 5 | E5: 1 | F5: 150 | G5: =VLOOKUP(A5,资源索引!$A$2:$F$29,2,FALSE)*VLOOKUP(C5+1,资源索引!$I$1:$J$6,2,FALSE) -> 700000 | H5: =SUM(G$4:G5) -> 1100000 | I5: =VLOOKUP(A5,资源索引!$A$2:$F$29,3,FALSE)*VLOOKUP(C5+1,资源索引!$I$1:$J$6,2,FALSE) -> 350000 | J5: =SUM(I$4:I5) -> 550000 | K5: =VLOOKUP(A5,资源索引!$A$2:$F$29,4,FALSE)*VLOOKUP(C5+1,资源索引!$I$1:$J$6,2,FALSE) -> 350000 | L5: =SUM(K$4:K5) -> 550000 | M5: =VLOOKUP(A5,资源索引!$A$2:$F$29,5,FALSE)*VLOOKUP(C5+1,资源索引!$I$1:$J$6,2,FALSE) -> 350000 | N5: =SUM(M$4:M5) -> 550000 | O5: =VLOOKUP(A5,资源索引!$A$2:$F$29,6,FALSE)*VLOOKUP(C5+1,资源索引!$I$1:$J$6,2,FALSE) -> 350000 | P5: =SUM(O$4:O5) -> 550000 | Q5: 2 | R5: 0 | S5: 9945 | T5: 0 | U5: 0 | V5: 0 | W5: 9801 | X5: 4859 | Z5: 100000 | AA5: 50000 | AB5: 50000 | AC5: 50000 | AD5: 50000 | AE5: 1020 | AF5: 1060 | AG5: 361 | AH5: 362 | AI5: 363 | AJ5: 0 | AK5: 主殿是公会核心建筑，升级主殿能提升公会等级，使其能建造更多其他建筑。
A6: 1 | B6: 主殿 | C6: 2 | D6: 5 | E6: 1 | F6: 200 | G6: =VLOOKUP(A6,资源索引!$A$2:$F$29,2,FALSE)*VLOOKUP(C6+1,资源索引!$I$1:$J$6,2,FALSE) -> 1300000 | H6: =SUM(G$4:G6) -> 2400000 | I6: =VLOOKUP(A6,资源索引!$A$2:$F$29,3,FALSE)*VLOOKUP(C6+1,资源索引!$I$1:$J$6,2,FALSE) -> 650000 | J6: =SUM(I$4:I6) -> 1200000 | K6: =VLOOKUP(A6,资源索引!$A$2:$F$29,4,FALSE)*VLOOKUP(C6+1,资源索引!$I$1:$J$6,2,FALSE) -> 650000 | L6: =SUM(K$4:K6) -> 1200000 | M6: =VLOOKUP(A6,资源索引!$A$2:$F$29,5,FALSE)*VLOOKUP(C6+1,资源索引!$I$1:$J$6,2,FALSE) -> 650000 | N6: =SUM(M$4:M6) -> 1200000 | O6: =VLOOKUP(A6,资源索引!$A$2:$F$29,6,FALSE)*VLOOKUP(C6+1,资源索引!$I$1:$J$6,2,FALSE) -> 650000 | P6: =SUM(O$4:O6) -> 1200000 | Q6: 2 | R6: 0 | S6: 9945 | T6: 0 | U6: 0 | V6: 0 | W6: 9802 | X6: 4859 | Z6: 100000 | AA6: 50000 | AB6: 50000 | AC6: 50000 | AD6: 50000 | AE6: 1020 | AF6: 1060 | AG6: 361 | AH6: 362 | AI6: 363 | AJ6: 0 | AK6: 主殿是公会核心建筑，升级主殿能提升公会等级，使其能建造更多其他建筑。
A7: 1 | B7: 主殿 | C7: 3 | D7: 5 | E7: 1 | F7: 250 | G7: =VLOOKUP(A7,资源索引!$A$2:$F$29,2,FALSE)*VLOOKUP(C7+1,资源索引!$I$1:$J$6,2,FALSE) -> 2400000 | H7: =SUM(G$4:G7) -> 4800000 | I7: =VLOOKUP(A7,资源索引!$A$2:$F$29,3,FALSE)*VLOOKUP(C7+1,资源索引!$I$1:$J$6,2,FALSE) -> 1200000 | J7: =SUM(I$4:I7) -> 2400000 | K7: =VLOOKUP(A7,资源索引!$A$2:$F$29,4,FALSE)*VLOOKUP(C7+1,资源索引!$I$1:$J$6,2,FALSE) -> 1200000 | L7: =SUM(K$4:K7) -> 2400000 | M7: =VLOOKUP(A7,资源索引!$A$2:$F$29,5,FALSE)*VLOOKUP(C7+1,资源索引!$I$1:$J$6,2,FALSE) -> 1200000 | N7: =SUM(M$4:M7) -> 2400000 | O7: =VLOOKUP(A7,资源索引!$A$2:$F$29,6,FALSE)*VLOOKUP(C7+1,资源索引!$I$1:$J$6,2,FALSE) -> 1200000 | P7: =SUM(O$4:O7) -> 2400000 | Q7: 2 | R7: 0 | S7: 9945 | T7: 0 | U7: 0 | V7: 0 | W7: 9803 | X7: 4859 | Z7: 100000 | AA7: 50000 | AB7: 50000 | AC7: 50000 | AD7: 50000 | AE7: 1020 | AF7: 1060 | AG7: 364 | AH7: 365 | AI7: 366 | AJ7: 0 | AK7: 主殿是公会核心建筑，升级主殿能提升公会等级，使其能建造更多其他建筑。
A8: 1 | B8: 主殿 | C8: 4 | D8: 5 | E8: 1 | F8: 300 | G8: =VLOOKUP(A8,资源索引!$A$2:$F$29,2,FALSE)*VLOOKUP(C8+1,资源索引!$I$1:$J$6,2,FALSE) -> 4000000 | H8: =SUM(G$4:G8) -> 8800000 | I8: =VLOOKUP(A8,资源索引!$A$2:$F$29,3,FALSE)*VLOOKUP(C8+1,资源索引!$I$1:$J$6,2,FALSE) -> 2000000 | J8: =SUM(I$4:I8) -> 4400000 | K8: =VLOOKUP(A8,资源索引!$A$2:$F$29,4,FALSE)*VLOOKUP(C8+1,资源索引!$I$1:$J$6,2,FALSE) -> 2000000 | L8: =SUM(K$4:K8) -> 4400000 | M8: =VLOOKUP(A8,资源索引!$A$2:$F$29,5,FALSE)*VLOOKUP(C8+1,资源索引!$I$1:$J$6,2,FALSE) -> 2000000 | N8: =SUM(M$4:M8) -> 4400000 | O8: =VLOOKUP(A8,资源索引!$A$2:$F$29,6,FALSE)*VLOOKUP(C8+1,资源索引!$I$1:$J$6,2,FALSE) -> 2000000 | P8: =SUM(O$4:O8) -> 4400000 | Q8: 2 | R8: 0 | S8: 9945 | T8: 0 | U8: 0 | V8: 0 | W8: 9804 | X8: 4859 | Z8: 100000 | AA8: 50000 | AB8: 50000 | AC8: 50000 | AD8: 50000 | AE8: 1020 | AF8: 1060 | AG8: 364 | AH8: 365 | AI8: 366 | AJ8: 0 | AK8: 主殿是公会核心建筑，升级主殿能提升公会等级，使其能建造更多其他建筑。
A9: 1 | B9: 主殿 | C9: 5 | D9: 5 | E9: 1 | F9: 350 | G9: =VLOOKUP(A9,资源索引!$A$2:$F$29,2,FALSE)*VLOOKUP(C9+1,资源索引!$I$1:$J$6,2,FALSE) -> 7200000 | H9: =SUM(G$4:G9) -> 16000000 | I9: =VLOOKUP(A9,资源索引!$A$2:$F$29,3,FALSE)*VLOOKUP(C9+1,资源索引!$I$1:$J$6,2,FALSE) -> 3600000 | J9: =SUM(I$4:I9) -> 8000000 | K9: =VLOOKUP(A9,资源索引!$A$2:$F$29,4,FALSE)*VLOOKUP(C9+1,资源索引!$I$1:$J$6,2,FALSE) -> 3600000 | L9: =SUM(K$4:K9) -> 8000000 | M9: =VLOOKUP(A9,资源索引!$A$2:$F$29,5,FALSE)*VLOOKUP(C9+1,资源索引!$I$1:$J$6,2,FALSE) -> 3600000 | N9: =SUM(M$4:M9) -> 8000000 | O9: =VLOOKUP(A9,资源索引!$A$2:$F$29,6,FALSE)*VLOOKUP(C9+1,资源索引!$I$1:$J$6,2,FALSE) -> 3600000 | P9: =SUM(O$4:O9) -> 8000000 | Q9: 2 | R9: 0 | S9: 9945 | T9: 0 | U9: 0 | V9: 0 | W9: 9805 | X9: 4859 | Z9: 100000 | AA9: 50000 | AB9: 50000 | AC9: 50000 | AD9: 50000 | AE9: 1020 | AF9: 1060 | AG9: 367 | AH9: 368 | AI9: 369 | AJ9: 0 | AK9: 主殿是公会核心建筑，升级主殿能提升公会等级，使其能建造更多其他建筑。
A10: 2 | B10: 商会 | C10: 0 | D10: 5 | E10: 1 | F10: 50 | G10: =VLOOKUP(A10,资源索引!$A$2:$F$29,2,FALSE)*VLOOKUP(C10+1,资源索引!$I$1:$J$6,2,FALSE) -> 120000 | H10: =SUM(G$10:G10) -> 120000 | I10: =VLOOKUP(A10,资源索引!$A$2:$F$29,3,FALSE)*VLOOKUP(C10+1,资源索引!$I$1:$J$6,2,FALSE) -> 120000 | J10: =SUM(I$10:I10) -> 120000 | K10: =VLOOKUP(A10,资源索引!$A$2:$F$29,4,FALSE)*VLOOKUP(C10+1,资源索引!$I$1:$J$6,2,FALSE) -> 100000 | L10: =SUM(K$10:K10) -> 100000 | M10: =VLOOKUP(A10,资源索引!$A$2:$F$29,5,FALSE)*VLOOKUP(C10+1,资源索引!$I$1:$J$6,2,FALSE) -> 100000 | N10: =SUM(M$10:M10) -> 100000 | O10: =VLOOKUP(A10,资源索引!$A$2:$F$29,6,FALSE)*VLOOKUP(C10+1,资源索引!$I$1:$J$6,2,FALSE) -> 40000 | P10: =SUM(O$10:O10) -> 40000 | Q10: 2 | R10: 0 | S10: 9946 | T10: 1 | U10: 1 | V10: 0 | W10: 9946 | X10: 8594 | Z10: 0 | AA10: 0 | AB10: 0 | AC10: 0 | AD10: 0 | AE10: 1021 | AF10: 1061 | AJ10: 0 | AK10: 商会是开启护送的重要建筑，商会等级越高，可以护送的货物也就越高。
A11: 2 | B11: 商会 | C11: 1 | D11: 5 | E11: 1 | F11: 80 | G11: =VLOOKUP(A11,资源索引!$A$2:$F$29,2,FALSE)*VLOOKUP(C11+1,资源索引!$I$1:$J$6,2,FALSE) -> 210000 | H11: =SUM(G$10:G11) -> 330000 | I11: =VLOOKUP(A11,资源索引!$A$2:$F$29,3,FALSE)*VLOOKUP(C11+1,资源索引!$I$1:$J$6,2,FALSE) -> 210000 | J11: =SUM(I$10:I11) -> 330000 | K11: =VLOOKUP(A11,资源索引!$A$2:$F$29,4,FALSE)*VLOOKUP(C11+1,资源索引!$I$1:$J$6,2,FALSE) -> 175000 | L11: =SUM(K$10:K11) -> 275000 | M11: =VLOOKUP(A11,资源索引!$A$2:$F$29,5,FALSE)*VLOOKUP(C11+1,资源索引!$I$1:$J$6,2,FALSE) -> 175000 | N11: =SUM(M$10:M11) -> 275000 | O11: =VLOOKUP(A11,资源索引!$A$2:$F$29,6,FALSE)*VLOOKUP(C11+1,资源索引!$I$1:$J$6,2,FALSE) -> 70000 | P11: =SUM(O$10:O11) -> 110000 | Q11: 2 | R11: 0 | S11: 9946 | T11: 1 | U11: 2 | V11: 0 | W11: 9807 | X11: 8594 | Z11: 0 | AA11: 0 | AB11: 0 | AC11: 0 | AD11: 0 | AE11: 1021 | AF11: 1061 | AG11: 379 | AH11: 380 | AI11: 381 | AJ11: 0 | AK11: 商会是开启护送的重要建筑，商会等级越高，可以护送的货物也就越高。
A12: 2 | B12: 商会 | C12: 2 | D12: 5 | E12: 1 | F12: 110 | G12: =VLOOKUP(A12,资源索引!$A$2:$F$29,2,FALSE)*VLOOKUP(C12+1,资源索引!$I$1:$J$6,2,FALSE) -> 390000 | H12: =SUM(G$10:G12) -> 720000 | I12: =VLOOKUP(A12,资源索引!$A$2:$F$29,3,FALSE)*VLOOKUP(C12+1,资源索引!$I$1:$J$6,2,FALSE) -> 390000 | J12: =SUM(I$10:I12) -> 720000 | K12: =VLOOKUP(A12,资源索引!$A$2:$F$29,4,FALSE)*VLOOKUP(C12+1,资源索引!$I$1:$J$6,2,FALSE) -> 325000 | L12: =SUM(K$10:K12) -> 600000 | M12: =VLOOKUP(A12,资源索引!$A$2:$F$29,5,FALSE)*VLOOKUP(C12+1,资源索引!$I$1:$J$6,2,FALSE) -> 325000 | N12: =SUM(M$10:M12) -> 600000 | O12: =VLOOKUP(A12,资源索引!$A$2:$F$29,6,FALSE)*VLOOKUP(C12+1,资源索引!$I$1:$J$6,2,FALSE) -> 130000 | P12: =SUM(O$10:O12) -> 240000 | Q12: 2 | R12: 0 | S12: 9946 | T12: 1 | U12: 3 | V12: 0 | W12: 9808 | X12: 8594 | Z12: 0 | AA12: 0 | AB12: 0 | AC12: 0 | AD12: 0 | AE12: 1021 | AF12: 1061 | AG12: 379 | AH12: 380 | AI12: 381 | AJ12: 0 | AK12: 商会是开启护送的重要建筑，商会等级越高，可以护送的货物也就越高。
A13: 2 | B13: 商会 | C13: 3 | D13: 5 | E13: 1 | F13: 140 | G13: =VLOOKUP(A13,资源索引!$A$2:$F$29,2,FALSE)*VLOOKUP(C13+1,资源索引!$I$1:$J$6,2,FALSE) -> 720000 | H13: =SUM(G$10:G13) -> 1440000 | I13: =VLOOKUP(A13,资源索引!$A$2:$F$29,3,FALSE)*VLOOKUP(C13+1,资源索引!$I$1:$J$6,2,FALSE) -> 720000 | J13: =SUM(I$10:I13) -> 1440000 | K13: =VLOOKUP(A13,资源索引!$A$2:$F$29,4,FALSE)*VLOOKUP(C13+1,资源索引!$I$1:$J$6,2,FALSE) -> 600000 | L13: =SUM(K$10:K13) -> 1200000 | M13: =VLOOKUP(A13,资源索引!$A$2:$F$29,5,FALSE)*VLOOKUP(C13+1,资源索引!$I$1:$J$6,2,FALSE) -> 600000 | N13: =SUM(M$10:M13) -> 1200000 | O13: =VLOOKUP(A13,资源索引!$A$2:$F$29,6,FALSE)*VLOOKUP(C13+1,资源索引!$I$1:$J$6,2,FALSE) -> 240000 | P13: =SUM(O$10:O13) -> 480000 | Q13: 2 | R13: 0 | S13: 9946 | T13: 1 | U13: 4 | V13: 0 | W13: 9809 | X13: 8594 | Z13: 0 | AA13: 0 | AB13: 0 | AC13: 0 | AD13: 0 | AE13: 1021 | AF13: 1061 | AG13: 382 | AH13: 383 | AI13: 384 | AJ13: 0 | AK13: 商会是开启护送的重要建筑，商会等级越高，可以护送的货物也就越高。
A14: 2 | B14: 商会 | C14: 4 | D14: 5 | E14: 1 | F14: 170 | G14: =VLOOKUP(A14,资源索引!$A$2:$F$29,2,FALSE)*VLOOKUP(C14+1,资源索引!$I$1:$J$6,2,FALSE) -> 1200000 | H14: =SUM(G$10:G14) -> 2640000 | I14: =VLOOKUP(A14,资源索引!$A$2:$F$29,3,FALSE)*VLOOKUP(C14+1,资源索引!$I$1:$J$6,2,FALSE) -> 1200000 | J14: =SUM(I$10:I14) -> 2640000 | K14: =VLOOKUP(A14,资源索引!$A$2:$F$29,4,FALSE)*VLOOKUP(C14+1,资源索引!$I$1:$J$6,2,FALSE) -> 1000000 | L14: =SUM(K$10:K14) -> 2200000 | M14: =VLOOKUP(A14,资源索引!$A$2:$F$29,5,FALSE)*VLOOKUP(C14+1,资源索引!$I$1:$J$6,2,FALSE) -> 1000000 | N14: =SUM(M$10:M14) -> 2200000 | O14: =VLOOKUP(A14,资源索引!$A$2:$F$29,6,FALSE)*VLOOKUP(C14+1,资源索引!$I$1:$J$6,2,FALSE) -> 400000 | P14: =SUM(O$10:O14) -> 880000 | Q14: 2 | R14: 0 | S14: 9946 | T14: 1 | U14: 5 | V14: 0 | W14: 9810 | X14: 8594 | Z14: 0 | AA14: 0 | AB14: 0 | AC14: 0 | AD14: 0 | AE14: 1021 | AF14: 1061 | AG14: 382 | AH14: 383 | AI14: 384 | AJ14: 0 | AK14: 商会是开启护送的重要建筑，商会等级越高，可以护送的货物也就越高。
A15: 2 | B15: 商会 | C15: 5 | D15: 5 | E15: 1 | F15: 200 | G15: =VLOOKUP(A15,资源索引!$A$2:$F$29,2,FALSE)*VLOOKUP(C15+1,资源索引!$I$1:$J$6,2,FALSE) -> 2160000 | H15: =SUM(G$10:G15) -> 4800000 | I15: =VLOOKUP(A15,资源索引!$A$2:$F$29,3,FALSE)*VLOOKUP(C15+1,资源索引!$I$1:$J$6,2,FALSE) -> 2160000 | J15: =SUM(I$10:I15) -> 4800000 | K15: =VLOOKUP(A15,资源索引!$A$2:$F$29,4,FALSE)*VLOOKUP(C15+1,资源索引!$I$1:$J$6,2,FALSE) -> 1800000 | L15: =SUM(K$10:K15) -> 4000000 | M15: =VLOOKUP(A15,资源索引!$A$2:$F$29,5,FALSE)*VLOOKUP(C15+1,资源索引!$I$1:$J$6,2,FALSE) -> 1800000 | N15: =SUM(M$10:M15) -> 4000000 | O15: =VLOOKUP(A15,资源索引!$A$2:$F$29,6,FALSE)*VLOOKUP(C15+1,资源索引!$I$1:$J$6,2,FALSE) -> 720000 | P15: =SUM(O$10:O15) -> 1600000 | Q15: 2 | R15: 0 | S15: 9946 | T15: 1 | U15: 6 | V15: 0 | W15: 9811 | X15: 8594 | Z15: 0 | AA15: 0 | AB15: 0 | AC15: 0 | AD15: 0 | AE15: 1021 | AF15: 1061 | AG15: 385 | AH15: 386 | AI15: 387 | AJ15: 0 | AK15: 商会是开启护送的重要建筑，商会等级越高，可以护送的货物也就越高。
A16: 3 | B16: 神坛 | C16: 0 | D16: 5 | E16: 1 | F16: 50 | G16: =VLOOKUP(A16,资源索引!$A$2:$F$29,2,FALSE)*VLOOKUP(C16+1,资源索引!$I$1:$J$6,2,FALSE) -> 240000 | H16: =SUM(G$16:G16) -> 240000 | I16: =VLOOKUP(A16,资源索引!$A$2:$F$29,3,FALSE)*VLOOKUP(C16+1,资源索引!$I$1:$J$6,2,FALSE) -> 60000 | J16: =SUM(I$16:I16) -> 60000 | K16: =VLOOKUP(A16,资源索引!$A$2:$F$29,4,FALSE)*VLOOKUP(C16+1,资源索引!$I$1:$J$6,2,FALSE) -> 140000 | L16: =SUM(K$16:K16) -> 140000 | M16: =VLOOKUP(A16,资源索引!$A$2:$F$29,5,FALSE)*VLOOKUP(C16+1,资源索引!$I$1:$J$6,2,FALSE) -> 140000 | N16: =SUM(M$16:M16) -> 140000 | O16: =VLOOKUP(A16,资源索引!$A$2:$F$29,6,FALSE)*VLOOKUP(C16+1,资源索引!$I$1:$J$6,2,FALSE) -> 140000 | P16: =SUM(O$16:O16) -> 140000 | Q16: 2 | R16: 0 | S16: 9946 | T16: 1 | U16: 1 | V16: 0 | W16: 9946 | X16: 8591 | Z16: 0 | AA16: 0 | AB16: 0 | AC16: 0 | AD16: 0 | AE16: 1022 | AF16: 1062 | AJ16: 0 | AK16: 神坛是洗炼铭文的重要建筑，神坛等级越高，可以洗炼的铭文种类就越多。
A17: 3 | B17: 神坛 | C17: 1 | D17: 5 | E17: 1 | F17: 80 | G17: =VLOOKUP(A17,资源索引!$A$2:$F$29,2,FALSE)*VLOOKUP(C17+1,资源索引!$I$1:$J$6,2,FALSE) -> 420000 | H17: =SUM(G$16:G17) -> 660000 | I17: =VLOOKUP(A17,资源索引!$A$2:$F$29,3,FALSE)*VLOOKUP(C17+1,资源索引!$I$1:$J$6,2,FALSE) -> 105000 | J17: =SUM(I$16:I17) -> 165000 | K17: =VLOOKUP(A17,资源索引!$A$2:$F$29,4,FALSE)*VLOOKUP(C17+1,资源索引!$I$1:$J$6,2,FALSE) -> 245000 | L17: =SUM(K$16:K17) -> 385000 | M17: =VLOOKUP(A17,资源索引!$A$2:$F$29,5,FALSE)*VLOOKUP(C17+1,资源索引!$I$1:$J$6,2,FALSE) -> 245000 | N17: =SUM(M$16:M17) -> 385000 | O17: =VLOOKUP(A17,资源索引!$A$2:$F$29,6,FALSE)*VLOOKUP(C17+1,资源索引!$I$1:$J$6,2,FALSE) -> 245000 | P17: =SUM(O$16:O17) -> 385000 | Q17: 2 | R17: 0 | S17: 9946 | T17: 1 | U17: 2 | V17: 0 | W17: 9813 | X17: 8591 | Z17: 0 | AA17: 0 | AB17: 0 | AC17: 0 | AD17: 0 | AE17: 1022 | AF17: 1062 | AG17: 379 | AH17: 380 | AI17: 381 | AJ17: 0 | AK17: 神坛是洗炼铭文的重要建筑，神坛等级越高，可以洗炼的铭文种类就越多。
A18: 3 | B18: 神坛 | C18: 2 | D18: 5 | E18: 1 | F18: 110 | G18: =VLOOKUP(A18,资源索引!$A$2:$F$29,2,FALSE)*VLOOKUP(C18+1,资源索引!$I$1:$J$6,2,FALSE) -> 780000 | H18: =SUM(G$16:G18) -> 1440000 | I18: =VLOOKUP(A18,资源索引!$A$2:$F$29,3,FALSE)*VLOOKUP(C18+1,资源索引!$I$1:$J$6,2,FALSE) -> 195000 | J18: =SUM(I$16:I18) -> 360000 | K18: =VLOOKUP(A18,资源索引!$A$2:$F$29,4,FALSE)*VLOOKUP(C18+1,资源索引!$I$1:$J$6,2,FALSE) -> 455000 | L18: =SUM(K$16:K18) -> 840000 | M18: =VLOOKUP(A18,资源索引!$A$2:$F$29,5,FALSE)*VLOOKUP(C18+1,资源索引!$I$1:$J$6,2,FALSE) -> 455000 | N18: =SUM(M$16:M18) -> 840000 | O18: =VLOOKUP(A18,资源索引!$A$2:$F$29,6,FALSE)*VLOOKUP(C18+1,资源索引!$I$1:$J$6,2,FALSE) -> 455000 | P18: =SUM(O$16:O18) -> 840000 | Q18: 2 | R18: 0 | S18: 9946 | T18: 1 | U18: 3 | V18: 0 | W18: 9814 | X18: 8591 | Z18: 0 | AA18: 0 | AB18: 0 | AC18: 0 | AD18: 0 | AE18: 1022 | AF18: 1062 | AG18: 379 | AH18: 380 | AI18: 381 | AJ18: 0 | AK18: 神坛是洗炼铭文的重要建筑，神坛等级越高，可以洗炼的铭文种类就越多。
A19: 3 | B19: 神坛 | C19: 3 | D19: 5 | E19: 1 | F19: 140 | G19: =VLOOKUP(A19,资源索引!$A$2:$F$29,2,FALSE)*VLOOKUP(C19+1,资源索引!$I$1:$J$6,2,FALSE) -> 1440000 | H19: =SUM(G$16:G19) -> 2880000 | I19: =VLOOKUP(A19,资源索引!$A$2:$F$29,3,FALSE)*VLOOKUP(C19+1,资源索引!$I$1:$J$6,2,FALSE) -> 360000 | J19: =SUM(I$16:I19) -> 720000 | K19: =VLOOKUP(A19,资源索引!$A$2:$F$29,4,FALSE)*VLOOKUP(C19+1,资源索引!$I$1:$J$6,2,FALSE) -> 840000 | L19: =SUM(K$16:K19) -> 1680000 | M19: =VLOOKUP(A19,资源索引!$A$2:$F$29,5,FALSE)*VLOOKUP(C19+1,资源索引!$I$1:$J$6,2,FALSE) -> 840000 | N19: =SUM(M$16:M19) -> 1680000 | O19: =VLOOKUP(A19,资源索引!$A$2:$F$29,6,FALSE)*VLOOKUP(C19+1,资源索引!$I$1:$J$6,2,FALSE) -> 840000 | P19: =SUM(O$16:O19) -> 1680000 | Q19: 2 | R19: 0 | S19: 9946 | T19: 1 | U19: 4 | V19: 0 | W19: 9815 | X19: 8591 | Z19: 0 | AA19: 0 | AB19: 0 | AC19: 0 | AD19: 0 | AE19: 1022 | AF19: 1062 | AG19: 382 | AH19: 383 | AI19: 384 | AJ19: 0 | AK19: 神坛是洗炼铭文的重要建筑，神坛等级越高，可以洗炼的铭文种类就越多。
A20: 3 | B20: 神坛 | C20: 4 | D20: 5 | E20: 1 | F20: 170 | G20: =VLOOKUP(A20,资源索引!$A$2:$F$29,2,FALSE)*VLOOKUP(C20+1,资源索引!$I$1:$J$6,2,FALSE) -> 2400000 | H20: =SUM(G$16:G20) -> 5280000 | I20: =VLOOKUP(A20,资源索引!$A$2:$F$29,3,FALSE)*VLOOKUP(C20+1,资源索引!$I$1:$J$6,2,FALSE) -> 600000 | J20: =SUM(I$16:I20) -> 1320000 | K20: =VLOOKUP(A20,资源索引!$A$2:$F$29,4,FALSE)*VLOOKUP(C20+1,资源索引!$I$1:$J$6,2,FALSE) -> 1400000 | L20: =SUM(K$16:K20) -> 3080000 | M20: =VLOOKUP(A20,资源索引!$A$2:$F$29,5,FALSE)*VLOOKUP(C20+1,资源索引!$I$1:$J$6,2,FALSE) -> 1400000 | N20: =SUM(M$16:M20) -> 3080000 | O20: =VLOOKUP(A20,资源索引!$A$2:$F$29,6,FALSE)*VLOOKUP(C20+1,资源索引!$I$1:$J$6,2,FALSE) -> 1400000 | P20: =SUM(O$16:O20) -> 3080000 | Q20: 2 | R20: 0 | S20: 9946 | T20: 1 | U20: 5 | V20: 0 | W20: 9816 | X20: 8591 | Z20: 0 | AA20: 0 | AB20: 0 | AC20: 0 | AD20: 0 | AE20: 1022 | AF20: 1062 | AG20: 382 | AH20: 383 | AI20: 384 | AJ20: 0 | AK20: 神坛是洗炼铭文的重要建筑，神坛等级越高，可以洗炼的铭文种类就越多。
A21: 3 | B21: 神坛 | C21: 5 | D21: 5 | E21: 1 | F21: 200 | G21: =VLOOKUP(A21,资源索引!$A$2:$F$29,2,FALSE)*VLOOKUP(C21+1,资源索引!$I$1:$J$6,2,FALSE) -> 4320000 | H21: =SUM(G$16:G21) -> 9600000 | I21: =VLOOKUP(A21,资源索引!$A$2:$F$29,3,FALSE)*VLOOKUP(C21+1,资源索引!$I$1:$J$6,2,FALSE) -> 1080000 | J21: =SUM(I$16:I21) -> 2400000 | K21: =VLOOKUP(A21,资源索引!$A$2:$F$29,4,FALSE)*VLOOKUP(C21+1,资源索引!$I$1:$J$6,2,FALSE) -> 2520000 | L21: =SUM(K$16:K21) -> 5600000 | M21: =VLOOKUP(A21,资源索引!$A$2:$F$29,5,FALSE)*VLOOKUP(C21+1,资源索引!$I$1:$J$6,2,FALSE) -> 2520000 | N21: =SUM(M$16:M21) -> 5600000 | O21: =VLOOKUP(A21,资源索引!$A$2:$F$29,6,FALSE)*VLOOKUP(C21+1,资源索引!$I$1:$J$6,2,FALSE) -> 2520000 | P21: =SUM(O$16:O21) -> 5600000 | Q21: 2 | R21: 0 | S21: 9946 | T21: 1 | U21: 6 | V21: 0 | W21: 9817 | X21: 8591 | Z21: 0 | AA21: 0 | AB21: 0 | AC21: 0 | AD21: 0 | AE21: 1022 | AF21: 1062 | AG21: 385 | AH21: 386 | AI21: 387 | AJ21: 0 | AK21: 神坛是洗炼铭文的重要建筑，神坛等级越高，可以洗炼的铭文种类就越多。
A22: 4 | B22: 居所 | C22: 0 | D22: 5 | E22: 1 | F22: 50 | G22: =VLOOKUP(A22,资源索引!$A$2:$F$29,2,FALSE)*VLOOKUP(C22+1,资源索引!$I$1:$J$6,2,FALSE) -> 200000 | H22: =SUM(G$22:G22) -> 200000 | I22: =VLOOKUP(A22,资源索引!$A$2:$F$29,3,FALSE)*VLOOKUP(C22+1,资源索引!$I$1:$J$6,2,FALSE) -> 280000 | J22: =SUM(I$22:I22) -> 280000 | K22: =VLOOKUP(A22,资源索引!$A$2:$F$29,4,FALSE)*VLOOKUP(C22+1,资源索引!$I$1:$J$6,2,FALSE) -> 160000 | L22: =SUM(K$22:K22) -> 160000 | M22: =VLOOKUP(A22,资源索引!$A$2:$F$29,5,FALSE)*VLOOKUP(C22+1,资源索引!$I$1:$J$6,2,FALSE) -> 200000 | N22: =SUM(M$22:M22) -> 200000 | O22: =VLOOKUP(A22,资源索引!$A$2:$F$29,6,FALSE)*VLOOKUP(C22+1,资源索引!$I$1:$J$6,2,FALSE) -> 120000 | P22: =SUM(O$22:O22) -> 120000 | Q22: 2 | R22: 0 | S22: 9946 | T22: 1 | U22: 1 | V22: 0 | W22: 9946 | X22: 8597 | Z22: 100 | AA22: 0 | AB22: 0 | AC22: 0 | AD22: 0 | AE22: 1023 | AF22: 1063 | AJ22: 0 | AK22: 居所是决定公会人数的建筑，居所等级越高，公会能招收的成员也越多。
A23: 4 | B23: 居所 | C23: 1 | D23: 5 | E23: 1 | F23: 80 | G23: =VLOOKUP(A23,资源索引!$A$2:$F$29,2,FALSE)*VLOOKUP(C23+1,资源索引!$I$1:$J$6,2,FALSE) -> 350000 | H23: =SUM(G$22:G23) -> 550000 | I23: =VLOOKUP(A23,资源索引!$A$2:$F$29,3,FALSE)*VLOOKUP(C23+1,资源索引!$I$1:$J$6,2,FALSE) -> 490000 | J23: =SUM(I$22:I23) -> 770000 | K23: =VLOOKUP(A23,资源索引!$A$2:$F$29,4,FALSE)*VLOOKUP(C23+1,资源索引!$I$1:$J$6,2,FALSE) -> 280000 | L23: =SUM(K$22:K23) -> 440000 | M23: =VLOOKUP(A23,资源索引!$A$2:$F$29,5,FALSE)*VLOOKUP(C23+1,资源索引!$I$1:$J$6,2,FALSE) -> 350000 | N23: =SUM(M$22:M23) -> 550000 | O23: =VLOOKUP(A23,资源索引!$A$2:$F$29,6,FALSE)*VLOOKUP(C23+1,资源索引!$I$1:$J$6,2,FALSE) -> 210000 | P23: =SUM(O$22:O23) -> 330000 | Q23: 2 | R23: 0 | S23: 9946 | T23: 1 | U23: 2 | V23: 0 | W23: 9819 | X23: 8597 | Z23: 130 | AA23: 0 | AB23: 0 | AC23: 0 | AD23: 0 | AE23: 1023 | AF23: 1063 | AG23: 379 | AH23: 380 | AI23: 381 | AJ23: 0 | AK23: 居所是决定公会人数的建筑，居所等级越高，公会能招收的成员也越多。
A24: 4 | B24: 居所 | C24: 2 | D24: 5 | E24: 1 | F24: 110 | G24: =VLOOKUP(A24,资源索引!$A$2:$F$29,2,FALSE)*VLOOKUP(C24+1,资源索引!$I$1:$J$6,2,FALSE) -> 650000 | H24: =SUM(G$22:G24) -> 1200000 | I24: =VLOOKUP(A24,资源索引!$A$2:$F$29,3,FALSE)*VLOOKUP(C24+1,资源索引!$I$1:$J$6,2,FALSE) -> 910000 | J24: =SUM(I$22:I24) -> 1680000 | K24: =VLOOKUP(A24,资源索引!$A$2:$F$29,4,FALSE)*VLOOKUP(C24+1,资源索引!$I$1:$J$6,2,FALSE) -> 520000 | L24: =SUM(K$22:K24) -> 960000 | M24: =VLOOKUP(A24,资源索引!$A$2:$F$29,5,FALSE)*VLOOKUP(C24+1,资源索引!$I$1:$J$6,2,FALSE) -> 650000 | N24: =SUM(M$22:M24) -> 1200000 | O24: =VLOOKUP(A24,资源索引!$A$2:$F$29,6,FALSE)*VLOOKUP(C24+1,资源索引!$I$1:$J$6,2,FALSE) -> 390000 | P24: =SUM(O$22:O24) -> 720000 | Q24: 2 | R24: 0 | S24: 9946 | T24: 1 | U24: 3 | V24: 0 | W24: 9820 | X24: 8597 | Z24: 160 | AA24: 0 | AB24: 0 | AC24: 0 | AD24: 0 | AE24: 1023 | AF24: 1063 | AG24: 379 | AH24: 380 | AI24: 381 | AJ24: 0 | AK24: 居所是决定公会人数的建筑，居所等级越高，公会能招收的成员也越多。
A25: 4 | B25: 居所 | C25: 3 | D25: 5 | E25: 1 | F25: 140 | G25: =VLOOKUP(A25,资源索引!$A$2:$F$29,2,FALSE)*VLOOKUP(C25+1,资源索引!$I$1:$J$6,2,FALSE) -> 1200000 | H25: =SUM(G$22:G25) -> 2400000 | I25: =VLOOKUP(A25,资源索引!$A$2:$F$29,3,FALSE)*VLOOKUP(C25+1,资源索引!$I$1:$J$6,2,FALSE) -> 1680000 | J25: =SUM(I$22:I25) -> 3360000 | K25: =VLOOKUP(A25,资源索引!$A$2:$F$29,4,FALSE)*VLOOKUP(C25+1,资源索引!$I$1:$J$6,2,FALSE) -> 960000 | L25: =SUM(K$22:K25) -> 1920000 | M25: =VLOOKUP(A25,资源索引!$A$2:$F$29,5,FALSE)*VLOOKUP(C25+1,资源索引!$I$1:$J$6,2,FALSE) -> 1200000 | N25: =SUM(M$22:M25) -> 2400000 | O25: =VLOOKUP(A25,资源索引!$A$2:$F$29,6,FALSE)*VLOOKUP(C25+1,资源索引!$I$1:$J$6,2,FALSE) -> 720000 | P25: =SUM(O$22:O25) -> 1440000 | Q25: 2 | R25: 0 | S25: 9946 | T25: 1 | U25: 4 | V25: 0 | W25: 9821 | X25: 8597 | Z25: 190 | AA25: 0 | AB25: 0 | AC25: 0 | AD25: 0 | AE25: 1023 | AF25: 1063 | AG25: 382 | AH25: 383 | AI25: 384 | AJ25: 0 | AK25: 居所是决定公会人数的建筑，居所等级越高，公会能招收的成员也越多。
A26: 4 | B26: 居所 | C26: 4 | D26: 5 | E26: 1 | F26: 170 | G26: =VLOOKUP(A26,资源索引!$A$2:$F$29,2,FALSE)*VLOOKUP(C26+1,资源索引!$I$1:$J$6,2,FALSE) -> 2000000 | H26: =SUM(G$22:G26) -> 4400000 | I26: =VLOOKUP(A26,资源索引!$A$2:$F$29,3,FALSE)*VLOOKUP(C26+1,资源索引!$I$1:$J$6,2,FALSE) -> 2800000 | J26: =SUM(I$22:I26) -> 6160000 | K26: =VLOOKUP(A26,资源索引!$A$2:$F$29,4,FALSE)*VLOOKUP(C26+1,资源索引!$I$1:$J$6,2,FALSE) -> 1600000 | L26: =SUM(K$22:K26) -> 3520000 | M26: =VLOOKUP(A26,资源索引!$A$2:$F$29,5,FALSE)*VLOOKUP(C26+1,资源索引!$I$1:$J$6,2,FALSE) -> 2000000 | N26: =SUM(M$22:M26) -> 4400000 | O26: =VLOOKUP(A26,资源索引!$A$2:$F$29,6,FALSE)*VLOOKUP(C26+1,资源索引!$I$1:$J$6,2,FALSE) -> 1200000 | P26: =SUM(O$22:O26) -> 2640000 | Q26: 2 | R26: 0 | S26: 9946 | T26: 1 | U26: 5 | V26: 0 | W26: 9822 | X26: 8597 | Z26: 220 | AA26: 0 | AB26: 0 | AC26: 0 | AD26: 0 | AE26: 1023 | AF26: 1063 | AG26: 382 | AH26: 383 | AI26: 384 | AJ26: 0 | AK26: 居所是决定公会人数的建筑，居所等级越高，公会能招收的成员也越多。
A27: 4 | B27: 居所 | C27: 5 | D27: 5 | E27: 1 | F27: 200 | G27: =VLOOKUP(A27,资源索引!$A$2:$F$29,2,FALSE)*VLOOKUP(C27+1,资源索引!$I$1:$J$6,2,FALSE) -> 3600000 | H27: =SUM(G$22:G27) -> 8000000 | I27: =VLOOKUP(A27,资源索引!$A$2:$F$29,3,FALSE)*VLOOKUP(C27+1,资源索引!$I$1:$J$6,2,FALSE) -> 5040000 | J27: =SUM(I$22:I27) -> 11200000 | K27: =VLOOKUP(A27,资源索引!$A$2:$F$29,4,FALSE)*VLOOKUP(C27+1,资源索引!$I$1:$J$6,2,FALSE) -> 2880000 | L27: =SUM(K$22:K27) -> 6400000 | M27: =VLOOKUP(A27,资源索引!$A$2:$F$29,5,FALSE)*VLOOKUP(C27+1,资源索引!$I$1:$J$6,2,FALSE) -> 3600000 | N27: =SUM(M$22:M27) -> 8000000 | O27: =VLOOKUP(A27,资源索引!$A$2:$F$29,6,FALSE)*VLOOKUP(C27+1,资源索引!$I$1:$J$6,2,FALSE) -> 2160000 | P27: =SUM(O$22:O27) -> 4800000 | Q27: 2 | R27: 0 | S27: 9946 | T27: 1 | U27: 6 | V27: 0 | W27: 9823 | X27: 8597 | Z27: 250 | AA27: 0 | AB27: 0 | AC27: 0 | AD27: 0 | AE27: 1023 | AF27: 1063 | AG27: 385 | AH27: 386 | AI27: 387 | AJ27: 0 | AK27: 居所是决定公会人数的建筑，居所等级越高，公会能招收的成员也越多。
A28: 5 | B28: 金库 | C28: 0 | D28: 5 | E28: 1 | F28: 50 | G28: =VLOOKUP(A28,资源索引!$A$2:$F$29,2,FALSE)*VLOOKUP(C28+1,资源索引!$I$1:$J$6,2,FALSE) -> 200000 | H28: =SUM(G$28:G28) -> 200000 | I28: =VLOOKUP(A28,资源索引!$A$2:$F$29,3,FALSE)*VLOOKUP(C28+1,资源索引!$I$1:$J$6,2,FALSE) -> 80000 | J28: =SUM(I$28:I28) -> 80000 | K28: =VLOOKUP(A28,资源索引!$A$2:$F$29,4,FALSE)*VLOOKUP(C28+1,资源索引!$I$1:$J$6,2,FALSE) -> 40000 | L28: =SUM(K$28:K28) -> 40000 | M28: =VLOOKUP(A28,资源索引!$A$2:$F$29,5,FALSE)*VLOOKUP(C28+1,资源索引!$I$1:$J$6,2,FALSE) -> 80000 | N28: =SUM(M$28:M28) -> 80000 | O28: =VLOOKUP(A28,资源索引!$A$2:$F$29,6,FALSE)*VLOOKUP(C28+1,资源索引!$I$1:$J$6,2,FALSE) -> 80000 | P28: =SUM(O$28:O28) -> 80000 | Q28: 2 | R28: 0 | S28: 9946 | T28: 4 | U28: 1 | V28: 0 | W28: 9946 | X28: 8593 | Z28: 1000000 | AA28: 0 | AB28: 0 | AC28: 0 | AD28: 0 | AE28: 1024 | AF28: 1064 | AJ28: 0 | AK28: 金库是存放公会资金的建筑，金库等级越高，公会资金上限也越大。
A29: 5 | B29: 金库 | C29: 1 | D29: 5 | E29: 1 | F29: 80 | G29: =VLOOKUP(A29,资源索引!$A$2:$F$29,2,FALSE)*VLOOKUP(C29+1,资源索引!$I$1:$J$6,2,FALSE) -> 350000 | H29: =SUM(G$28:G29) -> 550000 | I29: =VLOOKUP(A29,资源索引!$A$2:$F$29,3,FALSE)*VLOOKUP(C29+1,资源索引!$I$1:$J$6,2,FALSE) -> 140000 | J29: =SUM(I$28:I29) -> 220000 | K29: =VLOOKUP(A29,资源索引!$A$2:$F$29,4,FALSE)*VLOOKUP(C29+1,资源索引!$I$1:$J$6,2,FALSE) -> 70000 | L29: =SUM(K$28:K29) -> 110000 | M29: =VLOOKUP(A29,资源索引!$A$2:$F$29,5,FALSE)*VLOOKUP(C29+1,资源索引!$I$1:$J$6,2,FALSE) -> 140000 | N29: =SUM(M$28:M29) -> 220000 | O29: =VLOOKUP(A29,资源索引!$A$2:$F$29,6,FALSE)*VLOOKUP(C29+1,资源索引!$I$1:$J$6,2,FALSE) -> 140000 | P29: =SUM(O$28:O29) -> 220000 | Q29: 2 | R29: 0 | S29: 9946 | T29: 4 | U29: 2 | V29: 0 | W29: 9825 | X29: 8593 | Z29: 2000000 | AA29: 0 | AB29: 0 | AC29: 0 | AD29: 0 | AE29: 1024 | AF29: 1064 | AG29: 379 | AH29: 380 | AI29: 381 | AJ29: 0 | AK29: 金库是存放公会资金的建筑，金库等级越高，公会资金上限也越大。
A30: 5 | B30: 金库 | C30: 2 | D30: 5 | E30: 1 | F30: 110 | G30: =VLOOKUP(A30,资源索引!$A$2:$F$29,2,FALSE)*VLOOKUP(C30+1,资源索引!$I$1:$J$6,2,FALSE) -> 650000 | H30: =SUM(G$28:G30) -> 1200000 | I30: =VLOOKUP(A30,资源索引!$A$2:$F$29,3,FALSE)*VLOOKUP(C30+1,资源索引!$I$1:$J$6,2,FALSE) -> 260000 | J30: =SUM(I$28:I30) -> 480000 | K30: =VLOOKUP(A30,资源索引!$A$2:$F$29,4,FALSE)*VLOOKUP(C30+1,资源索引!$I$1:$J$6,2,FALSE) -> 130000 | L30: =SUM(K$28:K30) -> 240000 | M30: =VLOOKUP(A30,资源索引!$A$2:$F$29,5,FALSE)*VLOOKUP(C30+1,资源索引!$I$1:$J$6,2,FALSE) -> 260000 | N30: =SUM(M$28:M30) -> 480000 | O30: =VLOOKUP(A30,资源索引!$A$2:$F$29,6,FALSE)*VLOOKUP(C30+1,资源索引!$I$1:$J$6,2,FALSE) -> 260000 | P30: =SUM(O$28:O30) -> 480000 | Q30: 2 | R30: 0 | S30: 9946 | T30: 4 | U30: 3 | V30: 0 | W30: 9826 | X30: 8593 | Z30: 4000000 | AA30: 0 | AB30: 0 | AC30: 0 | AD30: 0 | AE30: 1024 | AF30: 1064 | AG30: 379 | AH30: 380 | AI30: 381 | AJ30: 0 | AK30: 金库是存放公会资金的建筑，金库等级越高，公会资金上限也越大。
A31: 5 | B31: 金库 | C31: 3 | D31: 5 | E31: 1 | F31: 140 | G31: =VLOOKUP(A31,资源索引!$A$2:$F$29,2,FALSE)*VLOOKUP(C31+1,资源索引!$I$1:$J$6,2,FALSE) -> 1200000 | H31: =SUM(G$28:G31) -> 2400000 | I31: =VLOOKUP(A31,资源索引!$A$2:$F$29,3,FALSE)*VLOOKUP(C31+1,资源索引!$I$1:$J$6,2,FALSE) -> 480000 | J31: =SUM(I$28:I31) -> 960000 | K31: =VLOOKUP(A31,资源索引!$A$2:$F$29,4,FALSE)*VLOOKUP(C31+1,资源索引!$I$1:$J$6,2,FALSE) -> 240000 | L31: =SUM(K$28:K31) -> 480000 | M31: =VLOOKUP(A31,资源索引!$A$2:$F$29,5,FALSE)*VLOOKUP(C31+1,资源索引!$I$1:$J$6,2,FALSE) -> 480000 | N31: =SUM(M$28:M31) -> 960000 | O31: =VLOOKUP(A31,资源索引!$A$2:$F$29,6,FALSE)*VLOOKUP(C31+1,资源索引!$I$1:$J$6,2,FALSE) -> 480000 | P31: =SUM(O$28:O31) -> 960000 | Q31: 2 | R31: 0 | S31: 9946 | T31: 4 | U31: 4 | V31: 0 | W31: 9827 | X31: 8593 | Z31: 7000000 | AA31: 0 | AB31: 0 | AC31: 0 | AD31: 0 | AE31: 1024 | AF31: 1064 | AG31: 382 | AH31: 383 | AI31: 384 | AJ31: 0 | AK31: 金库是存放公会资金的建筑，金库等级越高，公会资金上限也越大。
A32: 5 | B32: 金库 | C32: 4 | D32: 5 | E32: 1 | F32: 170 | G32: =VLOOKUP(A32,资源索引!$A$2:$F$29,2,FALSE)*VLOOKUP(C32+1,资源索引!$I$1:$J$6,2,FALSE) -> 2000000 | H32: =SUM(G$28:G32) -> 4400000 | I32: =VLOOKUP(A32,资源索引!$A$2:$F$29,3,FALSE)*VLOOKUP(C32+1,资源索引!$I$1:$J$6,2,FALSE) -> 800000 | J32: =SUM(I$28:I32) -> 1760000 | K32: =VLOOKUP(A32,资源索引!$A$2:$F$29,4,FALSE)*VLOOKUP(C32+1,资源索引!$I$1:$J$6,2,FALSE) -> 400000 | L32: =SUM(K$28:K32) -> 880000 | M32: =VLOOKUP(A32,资源索引!$A$2:$F$29,5,FALSE)*VLOOKUP(C32+1,资源索引!$I$1:$J$6,2,FALSE) -> 800000 | N32: =SUM(M$28:M32) -> 1760000 | O32: =VLOOKUP(A32,资源索引!$A$2:$F$29,6,FALSE)*VLOOKUP(C32+1,资源索引!$I$1:$J$6,2,FALSE) -> 800000 | P32: =SUM(O$28:O32) -> 1760000 | Q32: 2 | R32: 0 | S32: 9946 | T32: 4 | U32: 5 | V32: 0 | W32: 9828 | X32: 8593 | Z32: 30000000 | AA32: 0 | AB32: 0 | AC32: 0 | AD32: 0 | AE32: 1024 | AF32: 1064 | AG32: 382 | AH32: 383 | AI32: 384 | AJ32: 0 | AK32: 金库是存放公会资金的建筑，金库等级越高，公会资金上限也越大。
A33: 5 | B33: 金库 | C33: 5 | D33: 5 | E33: 1 | F33: 200 | G33: =VLOOKUP(A33,资源索引!$A$2:$F$29,2,FALSE)*VLOOKUP(C33+1,资源索引!$I$1:$J$6,2,FALSE) -> 3600000 | H33: =SUM(G$28:G33) -> 8000000 | I33: =VLOOKUP(A33,资源索引!$A$2:$F$29,3,FALSE)*VLOOKUP(C33+1,资源索引!$I$1:$J$6,2,FALSE) -> 1440000 | J33: =SUM(I$28:I33) -> 3200000 | K33: =VLOOKUP(A33,资源索引!$A$2:$F$29,4,FALSE)*VLOOKUP(C33+1,资源索引!$I$1:$J$6,2,FALSE) -> 720000 | L33: =SUM(K$28:K33) -> 1600000 | M33: =VLOOKUP(A33,资源索引!$A$2:$F$29,5,FALSE)*VLOOKUP(C33+1,资源索引!$I$1:$J$6,2,FALSE) -> 1440000 | N33: =SUM(M$28:M33) -> 3200000 | O33: =VLOOKUP(A33,资源索引!$A$2:$F$29,6,FALSE)*VLOOKUP(C33+1,资源索引!$I$1:$J$6,2,FALSE) -> 1440000 | P33: =SUM(O$28:O33) -> 3200000 | Q33: 2 | R33: 0 | S33: 9946 | T33: 4 | U33: 6 | V33: 0 | W33: 9829 | X33: 8593 | Z33: 100000000 | AA33: 0 | AB33: 0 | AC33: 0 | AD33: 0 | AE33: 1024 | AF33: 1064 | AG33: 385 | AH33: 386 | AI33: 387 | AJ33: 0 | AK33: 金库是存放公会资金的建筑，金库等级越高，公会资金上限也越大。
A34: 6 | B34: 战事厅 | C34: 0 | D34: 5 | E34: 1 | F34: 50 | G34: =VLOOKUP(A34,资源索引!$A$2:$F$29,2,FALSE)*VLOOKUP(C34+1,资源索引!$I$1:$J$6,2,FALSE) -> 160000 | H34: =SUM(G$34:G34) -> 160000 | I34: =VLOOKUP(A34,资源索引!$A$2:$F$29,3,FALSE)*VLOOKUP(C34+1,资源索引!$I$1:$J$6,2,FALSE) -> 140000 | J34: =SUM(I$34:I34) -> 140000 | K34: =VLOOKUP(A34,资源索引!$A$2:$F$29,4,FALSE)*VLOOKUP(C34+1,资源索引!$I$1:$J$6,2,FALSE) -> 100000 | L34: =SUM(K$34:K34) -> 100000 | M34: =VLOOKUP(A34,资源索引!$A$2:$F$29,5,FALSE)*VLOOKUP(C34+1,资源索引!$I$1:$J$6,2,FALSE) -> 80000 | N34: =SUM(M$34:M34) -> 80000 | O34: =VLOOKUP(A34,资源索引!$A$2:$F$29,6,FALSE)*VLOOKUP(C34+1,资源索引!$I$1:$J$6,2,FALSE) -> 120000 | P34: =SUM(O$34:O34) -> 120000 | Q34: 2 | R34: 0 | S34: 0 | T34: 0 | U34: 1 | V34: 0 | W34: 9946 | X34: 8593 | Z34: 0 | AA34: 0 | AB34: 0 | AC34: 0 | AD34: 0 | AE34: 1025 | AF34: 1065 | AJ34: 0 | AK34: 战事厅功能暂未开放。
A35: 6 | B35: 战事厅 | C35: 1 | D35: 5 | E35: 1 | F35: 80 | G35: =VLOOKUP(A35,资源索引!$A$2:$F$29,2,FALSE)*VLOOKUP(C35+1,资源索引!$I$1:$J$6,2,FALSE) -> 280000 | H35: =SUM(G$34:G35) -> 440000 | I35: =VLOOKUP(A35,资源索引!$A$2:$F$29,3,FALSE)*VLOOKUP(C35+1,资源索引!$I$1:$J$6,2,FALSE) -> 245000 | J35: =SUM(I$34:I35) -> 385000 | K35: =VLOOKUP(A35,资源索引!$A$2:$F$29,4,FALSE)*VLOOKUP(C35+1,资源索引!$I$1:$J$6,2,FALSE) -> 175000 | L35: =SUM(K$34:K35) -> 275000 | M35: =VLOOKUP(A35,资源索引!$A$2:$F$29,5,FALSE)*VLOOKUP(C35+1,资源索引!$I$1:$J$6,2,FALSE) -> 140000 | N35: =SUM(M$34:M35) -> 220000 | O35: =VLOOKUP(A35,资源索引!$A$2:$F$29,6,FALSE)*VLOOKUP(C35+1,资源索引!$I$1:$J$6,2,FALSE) -> 210000 | P35: =SUM(O$34:O35) -> 330000 | Q35: 2 | R35: 0 | S35: 0 | T35: 0 | U35: 2 | V35: 0 | W35: 9831 | Z35: 0 | AA35: 0 | AB35: 0 | AC35: 0 | AD35: 0 | AE35: 1025 | AF35: 1065 | AG35: 379 | AH35: 380 | AI35: 381 | AJ35: 0 | AK35: 战事厅功能暂未开放。
A36: 6 | B36: 战事厅 | C36: 2 | D36: 5 | E36: 1 | F36: 110 | G36: =VLOOKUP(A36,资源索引!$A$2:$F$29,2,FALSE)*VLOOKUP(C36+1,资源索引!$I$1:$J$6,2,FALSE) -> 520000 | H36: =SUM(G$34:G36) -> 960000 | I36: =VLOOKUP(A36,资源索引!$A$2:$F$29,3,FALSE)*VLOOKUP(C36+1,资源索引!$I$1:$J$6,2,FALSE) -> 455000 | J36: =SUM(I$34:I36) -> 840000 | K36: =VLOOKUP(A36,资源索引!$A$2:$F$29,4,FALSE)*VLOOKUP(C36+1,资源索引!$I$1:$J$6,2,FALSE) -> 325000 | L36: =SUM(K$34:K36) -> 600000 | M36: =VLOOKUP(A36,资源索引!$A$2:$F$29,5,FALSE)*VLOOKUP(C36+1,资源索引!$I$1:$J$6,2,FALSE) -> 260000 | N36: =SUM(M$34:M36) -> 480000 | O36: =VLOOKUP(A36,资源索引!$A$2:$F$29,6,FALSE)*VLOOKUP(C36+1,资源索引!$I$1:$J$6,2,FALSE) -> 390000 | P36: =SUM(O$34:O36) -> 720000 | Q36: 2 | R36: 0 | S36: 0 | T36: 0 | U36: 3 | V36: 0 | W36: 9832 | Z36: 0 | AA36: 0 | AB36: 0 | AC36: 0 | AD36: 0 | AE36: 1025 | AF36: 1065 | AG36: 379 | AH36: 380 | AI36: 381 | AJ36: 0 | AK36: 战事厅功能暂未开放。
A37: 6 | B37: 战事厅 | C37: 3 | D37: 5 | E37: 1 | F37: 140 | G37: =VLOOKUP(A37,资源索引!$A$2:$F$29,2,FALSE)*VLOOKUP(C37+1,资源索引!$I$1:$J$6,2,FALSE) -> 960000 | H37: =SUM(G$34:G37) -> 1920000 | I37: =VLOOKUP(A37,资源索引!$A$2:$F$29,3,FALSE)*VLOOKUP(C37+1,资源索引!$I$1:$J$6,2,FALSE) -> 840000 | J37: =SUM(I$34:I37) -> 1680000 | K37: =VLOOKUP(A37,资源索引!$A$2:$F$29,4,FALSE)*VLOOKUP(C37+1,资源索引!$I$1:$J$6,2,FALSE) -> 600000 | L37: =SUM(K$34:K37) -> 1200000 | M37: =VLOOKUP(A37,资源索引!$A$2:$F$29,5,FALSE)*VLOOKUP(C37+1,资源索引!$I$1:$J$6,2,FALSE) -> 480000 | N37: =SUM(M$34:M37) -> 960000 | O37: =VLOOKUP(A37,资源索引!$A$2:$F$29,6,FALSE)*VLOOKUP(C37+1,资源索引!$I$1:$J$6,2,FALSE) -> 720000 | P37: =SUM(O$34:O37) -> 1440000 | Q37: 2 | R37: 0 | S37: 0 | T37: 0 | U37: 4 | V37: 0 | W37: 9833 | Z37: 0 | AA37: 0 | AB37: 0 | AC37: 0 | AD37: 0 | AE37: 1025 | AF37: 1065 | AG37: 382 | AH37: 383 | AI37: 384 | AJ37: 0 | AK37: 战事厅功能暂未开放。
A38: 6 | B38: 战事厅 | C38: 4 | D38: 5 | E38: 1 | F38: 170 | G38: =VLOOKUP(A38,资源索引!$A$2:$F$29,2,FALSE)*VLOOKUP(C38+1,资源索引!$I$1:$J$6,2,FALSE) -> 1600000 | H38: =SUM(G$34:G38) -> 3520000 | I38: =VLOOKUP(A38,资源索引!$A$2:$F$29,3,FALSE)*VLOOKUP(C38+1,资源索引!$I$1:$J$6,2,FALSE) -> 1400000 | J38: =SUM(I$34:I38) -> 3080000 | K38: =VLOOKUP(A38,资源索引!$A$2:$F$29,4,FALSE)*VLOOKUP(C38+1,资源索引!$I$1:$J$6,2,FALSE) -> 1000000 | L38: =SUM(K$34:K38) -> 2200000 | M38: =VLOOKUP(A38,资源索引!$A$2:$F$29,5,FALSE)*VLOOKUP(C38+1,资源索引!$I$1:$J$6,2,FALSE) -> 800000 | N38: =SUM(M$34:M38) -> 1760000 | O38: =VLOOKUP(A38,资源索引!$A$2:$F$29,6,FALSE)*VLOOKUP(C38+1,资源索引!$I$1:$J$6,2,FALSE) -> 1200000 | P38: =SUM(O$34:O38) -> 2640000 | Q38: 2 | R38: 0 | S38: 0 | T38: 0 | U38: 5 | V38: 0 | W38: 9834 | Z38: 0 | AA38: 0 | AB38: 0 | AC38: 0 | AD38: 0 | AE38: 1025 | AF38: 1065 | AG38: 382 | AH38: 383 | AI38: 384 | AJ38: 0 | AK38: 战事厅功能暂未开放。
A39: 6 | B39: 战事厅 | C39: 5 | D39: 5 | E39: 1 | F39: 200 | G39: =VLOOKUP(A39,资源索引!$A$2:$F$29,2,FALSE)*VLOOKUP(C39+1,资源索引!$I$1:$J$6,2,FALSE) -> 2880000 | H39: =SUM(G$34:G39) -> 6400000 | I39: =VLOOKUP(A39,资源索引!$A$2:$F$29,3,FALSE)*VLOOKUP(C39+1,资源索引!$I$1:$J$6,2,FALSE) -> 2520000 | J39: =SUM(I$34:I39) -> 5600000 | K39: =VLOOKUP(A39,资源索引!$A$2:$F$29,4,FALSE)*VLOOKUP(C39+1,资源索引!$I$1:$J$6,2,FALSE) -> 1800000 | L39: =SUM(K$34:K39) -> 4000000 | M39: =VLOOKUP(A39,资源索引!$A$2:$F$29,5,FALSE)*VLOOKUP(C39+1,资源索引!$I$1:$J$6,2,FALSE) -> 1440000 | N39: =SUM(M$34:M39) -> 3200000 | O39: =VLOOKUP(A39,资源索引!$A$2:$F$29,6,FALSE)*VLOOKUP(C39+1,资源索引!$I$1:$J$6,2,FALSE) -> 2160000 | P39: =SUM(O$34:O39) -> 4800000 | Q39: 2 | R39: 0 | S39: 0 | T39: 0 | U39: 6 | V39: 0 | W39: 9835 | Z39: 0 | AA39: 0 | AB39: 0 | AC39: 0 | AD39: 0 | AE39: 1025 | AF39: 1065 | AG39: 385 | AH39: 386 | AI39: 387 | AJ39: 0 | AK39: 战事厅功能暂未开放。
A40: 7 | B40: 神鼎 | C40: 0 | D40: 5 | E40: 1 | F40: 50 | G40: =VLOOKUP(A40,资源索引!$A$2:$F$29,2,FALSE)*VLOOKUP(C40+1,资源索引!$I$1:$J$6,2,FALSE) -> 160000 | H40: =SUM(G$40:G40) -> 160000 | I40: =VLOOKUP(A40,资源索引!$A$2:$F$29,3,FALSE)*VLOOKUP(C40+1,资源索引!$I$1:$J$6,2,FALSE) -> 40000 | J40: =SUM(I$40:I40) -> 40000 | K40: =VLOOKUP(A40,资源索引!$A$2:$F$29,4,FALSE)*VLOOKUP(C40+1,资源索引!$I$1:$J$6,2,FALSE) -> 200000 | L40: =SUM(K$40:K40) -> 200000 | M40: =VLOOKUP(A40,资源索引!$A$2:$F$29,5,FALSE)*VLOOKUP(C40+1,资源索引!$I$1:$J$6,2,FALSE) -> 100000 | N40: =SUM(M$40:M40) -> 100000 | O40: =VLOOKUP(A40,资源索引!$A$2:$F$29,6,FALSE)*VLOOKUP(C40+1,资源索引!$I$1:$J$6,2,FALSE) -> 100000 | P40: =SUM(O$40:O40) -> 100000 | Q40: 2 | R40: 0 | S40: 9947 | T40: 1 | U40: 1 | V40: 0 | W40: 9947 | X40: 4860 | Z40: 0 | AA40: 0 | AB40: 0 | AC40: 0 | AD40: 0 | AE40: 1026 | AF40: 1066 | AJ40: 0 | AK40: 神鼎是公会的标志建筑，公会战期间，神鼎被摧毁即公会战失败。
...

Sheet Define
A1: 字段名称 | B1: 字段解释 | C1: 备注
A2: ID | B2: 建筑ID
A3: Name | B3: 建筑名称
A4: Level | B4: 建筑等级
A5: MaxLevel | B5: 最高等级
A6: MaxNum | B6: 最大建造数量
A7: Prosperity | B7: 建筑繁荣度
A8: MoneyConsumption | B8: 消耗公会资金
A9: TotalMoneyConsumption | B9: 总消耗资金 | C9: 当前等级之前的所有等级之和（包括当前等级）
A10: HerbConsumption | B10: 消耗粮食
A11: TotalHerbConsumption | B11: 总消耗粮食 | C11: 同上
A12: WoodConsumption | B12: 消耗木材
A13: TotalWoodConsumption | B13: 总消耗木材 | C13: 同上
A14: CrystalConsumption | B14: 消耗石头
A15: TotalCrystalConsumption | B15: 总消耗石头 | C15: 同上
A16: SilverConsumption | B16: 消耗铁矿
A17: TotalSilverConsumption | B17: 总消总铁矿 | C17: 同上
A18: UpgradeTime | B18: 升级时间 | C18: 单位：秒
A19: RoutineConsumption | B19: 维护费用 | C19: 每小时扣除
A20: CdtnBaseNpcID | B20: 基座ID
A21: ConditionBuildingID | B21: 前置建筑ID
A22: ConditionBuildingLvl | B22: 前置建筑等级
A23: UpgradingSpellID | B23: 升级时调用技能
A24: NpcTemplateID | B24: 建筑模型NPCID
A25: ReviveTime | B25: 重生时间
A26: Param1 | B26: 建筑参数 | C26: 居所：P1=增加人员上限 金库：P1=公会资金上限 场地建筑：P1=产量/每小时 仓库建筑：P1=增加资源存储上限
A27: Param2
A28: Param3
A29: Param4
A30: IntruderMsgID | B30: 摧毁后进攻方消息
A31: DefenderMsgID | B31: 摧毁后防守方消息
A32: FewMembersReward | B32: 初级宝箱 | C32: 防守方人数1/3以下
A33: SomeMembersReward | B33: 中级宝箱 | C33: 防守方人数1/3到2/3
A34: ManyMembersReward | B34: 高级宝箱 | C34: 防守方人数2/3以上
A35: Effect
A36: Description | B36: 建筑描述

Sheet Sheet1
A1: ID | B1: Name | C1: Level | D1: MaxLevel | E1: MaxNum | F1: Prosperity | G1: MoneyConsumption | H1: TotalMoneyConsumption | I1: HerbConsumption | J1: TotalHerbConsumption | K1: WoodConsumption | L1: TotalWoodConsumption | M1: CrystalConsumption | N1: TotalCrystalConsumption | O1: SilverConsumption | P1: TotalSilverConsumption | Q1: UpgradeTime | R1: RoutineConsumption | S1: CdtnBaseNpcID | T1: ConditionBuildingID | U1: ConditionBuildingLvl | V1: UpgradingSpellID | W1: NpcTemplateID | X1: DeadNpcTemplateID | Y1: ReviveTime | Z1: Param1 | AA1: Param2 | AB1: Param3 | AC1: Param4 | AD1: IntruderMsgID | AE1: DefenderMsgID | AF1: FewMembersReward | AG1: SomeMembersReward | AH1: ManyMembersReward | AI1: Effect | AJ1: Description
A2: Both | B2: Client | C2: Both | D2: Both | E2: Both | F2: Server | G2: Both | H2: Server | I2: Both | J2: Server | K2: Both | L2: Server | M2: Both | N2: Server | O2: Both | P2: Server | Q2: Both | R2: Both | S2: Both | T2: Both | U2: Both | V2: Both | W2: Both | X2: Server | Y2: Server | Z2: Both | AA2: Both | AB2: Both | AC2: Both | AD2: Server | AE2: Server | AF2: Server | AG2: Server | AH2: Server | AI2: Both | AJ2: Client
A3: 0 | B3: 0 | C3: 0 | D3: 0 | G3: 0 | I3: 0 | K3: 0 | L3: 0 | M3: 0 | N3: 0 | O3: 0 | P3: 0 | Q3: 0 | R3: 0 | S3: 0 | T3: 0 | U3: 0 | V3: 0 | W3: 0 | X3: 0 | Z3: 0 | AA3: 0 | AB3: 0 | AC3: 0 | AI3: 0 | AJ3: 0
A4: 1 | B4: 主殿 | C4: 0 | D4: 6 | E4: 1 | F4: 100 | G4: 0 | H4: 0 | I4: 10 | J4: 0 | K4: 10 | L4: 0 | M4: 10 | N4: 0 | O4: 10 | P4: 0 | Q4: 60 | R4: 0 | S4: 9945 | T4: 0 | U4: 0 | V4: 0 | W4: 9945 | X4: 4859 | Z4: 0 | AA4: 0 | AB4: 0 | AC4: 0 | AD4: 1020 | AE4: 1060 | AI4: 0 | AJ4: 主殿是公会的最核心建筑，升级主殿能提升公会等级，使其能建造更多其他建筑
A5: 1 | B5: 主殿 | C5: 1 | D5: 6 | E5: 1 | F5: 150 | G5: 0 | H5: 0 | I5: 10 | J5: =I4 -> 10 | K5: 10 | L5: =K4 -> 10 | M5: 10 | N5: =M4 -> 10 | O5: 10 | P5: =O4 -> 10 | Q5: 60 | R5: 0 | S5: 9945 | T5: 0 | U5: 0 | V5: 0 | W5: 9801 | X5: 4859 | Z5: 0 | AA5: 0 | AB5: 0 | AC5: 0 | AD5: 1020 | AE5: 1060 | AF5: 361 | AG5: 362 | AH5: 363 | AI5: 0 | AJ5: 主殿是公会的最核心建筑，升级主殿能提升公会等级，使其能建造更多其他建筑
A6: 1 | B6: 主殿 | C6: 2 | D6: 6 | E6: 1 | F6: 200 | G6: 0 | H6: 0 | I6: 50 | J6: =I4+I5 -> 20 | K6: 50 | L6: =K4+K5 -> 20 | M6: 50 | N6: =M4+M5 -> 20 | O6: 50 | P6: =O4+O5 -> 20 | Q6: 120 | R6: 0 | S6: 9945 | T6: 0 | U6: 0 | V6: 0 | W6: 9802 | X6: 4859 | Z6: 0 | AA6: 0 | AB6: 0 | AC6: 0 | AD6: 1020 | AE6: 1060 | AF6: 361 | AG6: 362 | AH6: 363 | AI6: 0 | AJ6: 主殿是公会的最核心建筑，升级主殿能提升公会等级，使其能建造更多其他建筑
A7: 1 | B7: 主殿 | C7: 3 | D7: 6 | E7: 1 | F7: 250 | G7: 0 | H7: 0 | I7: 200 | J7: =I5+I6 -> 60 | K7: 200 | L7: =K5+K6 -> 60 | M7: 200 | N7: =M5+M6 -> 60 | O7: 200 | P7: =O5+O6 -> 60 | Q7: 300 | R7: 0 | S7: 9945 | T7: 0 | U7: 0 | V7: 0 | W7: 9803 | X7: 4859 | Z7: 0 | AA7: 0 | AB7: 0 | AC7: 0 | AD7: 1020 | AE7: 1060 | AF7: 364 | AG7: 365 | AH7: 366 | AI7: 0 | AJ7: 主殿是公会的最核心建筑，升级主殿能提升公会等级，使其能建造更多其他建筑
A8: 1 | B8: 主殿 | C8: 4 | D8: 6 | E8: 1 | F8: 300 | G8: 0 | H8: 0 | I8: 600 | J8: =I6+I7 -> 250 | K8: 600 | L8: =K6+K7 -> 250 | M8: 600 | N8: =M6+M7 -> 250 | O8: 600 | P8: =O6+O7 -> 250 | Q8: 600 | R8: 0 | S8: 9945 | T8: 0 | U8: 0 | V8: 0 | W8: 9804 | X8: 4859 | Z8: 0 | AA8: 0 | AB8: 0 | AC8: 0 | AD8: 1020 | AE8: 1060 | AF8: 364 | AG8: 365 | AH8: 366 | AI8: 0 | AJ8: 主殿是公会的最核心建筑，升级主殿能提升公会等级，使其能建造更多其他建筑
A9: 1 | B9: 主殿 | C9: 5 | D9: 6 | E9: 1 | F9: 350 | G9: 0 | H9: 0 | I9: 2000 | J9: =I7+I8 -> 800 | K9: 2000 | L9: =K7+K8 -> 800 | M9: 2000 | N9: =M7+M8 -> 800 | O9: 2000 | P9: =O7+O8 -> 800 | Q9: 1200 | R9: 0 | S9: 9945 | T9: 0 | U9: 0 | V9: 0 | W9: 9805 | X9: 4859 | Z9: 0 | AA9: 0 | AB9: 0 | AC9: 0 | AD9: 1020 | AE9: 1060 | AF9: 367 | AG9: 368 | AH9: 369 | AI9: 0 | AJ9: 主殿是公会的最核心建筑，升级主殿能提升公会等级，使其能建造更多其他建筑
A10: 1 | B10: 主殿 | C10: 6 | D10: 6 | E10: 1 | F10: 400 | G10: 0 | H10: 0 | I10: 10000 | J10: =I8+I9 -> 2600 | K10: 10000 | L10: =K8+K9 -> 2600 | M10: 10000 | N10: =M8+M9 -> 2600 | O10: 10000 | P10: =O8+O9 -> 2600 | Q10: 3000 | R10: 0 | S10: 9945 | T10: 0 | U10: 0 | V10: 0 | W10: 9806 | X10: 4859 | Z10: 0 | AA10: 0 | AB10: 0 | AC10: 0 | AD10: 1020 | AE10: 1060 | AF10: 367 | AG10: 368 | AH10: 369 | AI10: 0 | AJ10: 主殿是公会的最核心建筑，升级主殿能提升公会等级，使其能建造更多其他建筑
A11: 2 | B11: 商会 | C11: 0 | D11: 6 | E11: 1 | F11: 50 | G11: 0 | H11: 0 | I11: 5 | J11: 0 | K11: 5 | L11: 0 | M11: 5 | N11: 0 | O11: 5 | P11: 0 | Q11: 60 | R11: 0 | S11: 9946 | T11: 1 | U11: 1 | V11: 0 | W11: 9946 | X11: 8594 | Z11: 0 | AA11: 0 | AB11: 0 | AC11: 0 | AD11: 1021 | AE11: 1061 | AI11: 0 | AJ11: 商会是开启护送的重要建筑，商会等级越高，可以护送的货物也就越高
A12: 2 | B12: 商会 | C12: 1 | D12: 6 | E12: 1 | F12: 80 | G12: 0 | H12: 0 | I12: 5 | J12: =I11 -> 5 | K12: 5 | L12: =K11 -> 5 | M12: 5 | N12: =M11 -> 5 | O12: 5 | P12: =O11 -> 5 | Q12: 60 | R12: 0 | S12: 9946 | T12: 1 | U12: 1 | V12: 0 | W12: 9807 | X12: 8594 | Z12: 0 | AA12: 0 | AB12: 0 | AC12: 0 | AD12: 1021 | AE12: 1061 | AF12: 379 | AG12: 380 | AH12: 381 | AI12: 0 | AJ12: 商会是开启护送的重要建筑，商会等级越高，可以护送的货物也就越高
A13: 2 | B13: 商会 | C13: 2 | D13: 6 | E13: 1 | F13: 110 | G13: 0 | H13: 0 | I13: 10 | J13: =I11+I12 -> 10 | K13: 10 | L13: =K11+K12 -> 10 | M13: 10 | N13: =M11+M12 -> 10 | O13: 10 | P13: =O11+O12 -> 10 | Q13: 120 | R13: 0 | S13: 9946 | T13: 1 | U13: 2 | V13: 0 | W13: 9808 | X13: 8594 | Z13: 0 | AA13: 0 | AB13: 0 | AC13: 0 | AD13: 1021 | AE13: 1061 | AF13: 379 | AG13: 380 | AH13: 381 | AI13: 0 | AJ13: 商会是开启护送的重要建筑，商会等级越高，可以护送的货物也就越高
A14: 2 | B14: 商会 | C14: 3 | D14: 6 | E14: 1 | F14: 140 | G14: 0 | H14: 0 | I14: 50 | J14: =I12+I13 -> 15 | K14: 50 | L14: =K12+K13 -> 15 | M14: 50 | N14: =M12+M13 -> 15 | O14: 50 | P14: =O12+O13 -> 15 | Q14: 300 | R14: 0 | S14: 9946 | T14: 1 | U14: 3 | V14: 0 | W14: 9809 | X14: 8594 | Z14: 0 | AA14: 0 | AB14: 0 | AC14: 0 | AD14: 1021 | AE14: 1061 | AF14: 382 | AG14: 383 | AH14: 384 | AI14: 0 | AJ14: 商会是开启护送的重要建筑，商会等级越高，可以护送的货物也就越高
A15: 2 | B15: 商会 | C15: 4 | D15: 6 | E15: 1 | F15: 170 | G15: 0 | H15: 0 | I15: 100 | J15: =I13+I14 -> 60 | K15: 100 | L15: =K13+K14 -> 60 | M15: 100 | N15: =M13+M14 -> 60 | O15: 100 | P15: =O13+O14 -> 60 | Q15: 600 | R15: 0 | S15: 9946 | T15: 1 | U15: 4 | V15: 0 | W15: 9810 | X15: 8594 | Z15: 0 | AA15: 0 | AB15: 0 | AC15: 0 | AD15: 1021 | AE15: 1061 | AF15: 382 | AG15: 383 | AH15: 384 | AI15: 0 | AJ15: 商会是开启护送的重要建筑，商会等级越高，可以护送的货物也就越高
A16: 2 | B16: 商会 | C16: 5 | D16: 6 | E16: 1 | F16: 200 | G16: 0 | H16: 0 | I16: 200 | J16: =I14+I15 -> 150 | K16: 200 | L16: =K14+K15 -> 150 | M16: 200 | N16: =M14+M15 -> 150 | O16: 200 | P16: =O14+O15 -> 150 | Q16: 1200 | R16: 0 | S16: 9946 | T16: 1 | U16: 5 | V16: 0 | W16: 9811 | X16: 8594 | Z16: 0 | AA16: 0 | AB16: 0 | AC16: 0 | AD16: 1021 | AE16: 1061 | AF16: 385 | AG16: 386 | AH16: 387 | AI16: 0 | AJ16: 商会是开启护送的重要建筑，商会等级越高，可以护送的货物也就越高
A17: 2 | B17: 商会 | C17: 6 | D17: 6 | E17: 1 | F17: 230 | G17: 0 | H17: 0 | I17: 500 | J17: =I15+I16 -> 300 | K17: 500 | L17: =K15+K16 -> 300 | M17: 500 | N17: =M15+M16 -> 300 | O17: 500 | P17: =O15+O16 -> 300 | Q17: 3000 | R17: 0 | S17: 9946 | T17: 1 | U17: 6 | V17: 0 | W17: 9812 | X17: 8594 | Z17: 0 | AA17: 0 | AB17: 0 | AC17: 0 | AD17: 1021 | AE17: 1061 | AF17: 385 | AG17: 386 | AH17: 387 | AI17: 0 | AJ17: 商会是开启护送的重要建筑，商会等级越高，可以护送的货物也就越高
A18: 3 | B18: 神坛 | C18: 0 | D18: 6 | E18: 1 | F18: 50 | G18: 0 | H18: 0 | I18: 5 | J18: 0 | K18: 5 | L18: 0 | M18: 5 | N18: 0 | O18: 5 | P18: 0 | Q18: 60 | R18: 0 | S18: 9946 | T18: 1 | U18: 1 | V18: 0 | W18: 9946 | X18: 8591 | Z18: 0 | AA18: 0 | AB18: 0 | AC18: 0 | AD18: 1022 | AE18: 1062 | AI18: 0 | AJ18: 神坛是洗炼铭文的重要建筑，神坛等级越高，可以洗炼的铭文种类就越多
A19: 3 | B19: 神坛 | C19: 1 | D19: 6 | E19: 1 | F19: 80 | G19: 0 | H19: 0 | I19: 5 | J19: =I18 -> 5 | K19: 5 | L19: =K18 -> 5 | M19: 5 | N19: =M18 -> 5 | O19: 5 | P19: =O18 -> 5 | Q19: 60 | R19: 0 | S19: 9946 | T19: 1 | U19: 1 | V19: 0 | W19: 9813 | X19: 8591 | Z19: 0 | AA19: 0 | AB19: 0 | AC19: 0 | AD19: 1022 | AE19: 1062 | AF19: 379 | AG19: 380 | AH19: 381 | AI19: 0 | AJ19: 神坛是洗炼铭文的重要建筑，神坛等级越高，可以洗炼的铭文种类就越多
A20: 3 | B20: 神坛 | C20: 2 | D20: 6 | E20: 1 | F20: 110 | G20: 0 | H20: 0 | I20: 10 | J20: =I18+I19 -> 10 | K20: 10 | L20: =K18+K19 -> 10 | M20: 10 | N20: =M18+M19 -> 10 | O20: 10 | P20: =O18+O19 -> 10 | Q20: 120 | R20: 0 | S20: 9946 | T20: 1 | U20: 2 | V20: 0 | W20: 9814 | X20: 8591 | Z20: 0 | AA20: 0 | AB20: 0 | AC20: 0 | AD20: 1022 | AE20: 1062 | AF20: 379 | AG20: 380 | AH20: 381 | AI20: 0 | AJ20: 神坛是洗炼铭文的重要建筑，神坛等级越高，可以洗炼的铭文种类就越多
A21: 3 | B21: 神坛 | C21: 3 | D21: 6 | E21: 1 | F21: 140 | G21: 0 | H21: 0 | I21: 50 | J21: =I19+I20 -> 15 | K21: 50 | L21: =K19+K20 -> 15 | M21: 50 | N21: =M19+M20 -> 15 | O21: 50 | P21: =O19+O20 -> 15 | Q21: 300 | R21: 0 | S21: 9946 | T21: 1 | U21: 3 | V21: 0 | W21: 9815 | X21: 8591 | Z21: 0 | AA21: 0 | AB21: 0 | AC21: 0 | AD21: 1022 | AE21: 1062 | AF21: 382 | AG21: 383 | AH21: 384 | AI21: 0 | AJ21: 神坛是洗炼铭文的重要建筑，神坛等级越高，可以洗炼的铭文种类就越多
A22: 3 | B22: 神坛 | C22: 4 | D22: 6 | E22: 1 | F22: 170 | G22: 0 | H22: 0 | I22: 100 | J22: =I20+I21 -> 60 | K22: 100 | L22: =K20+K21 -> 60 | M22: 100 | N22: =M20+M21 -> 60 | O22: 100 | P22: =O20+O21 -> 60 | Q22: 600 | R22: 0 | S22: 9946 | T22: 1 | U22: 4 | V22: 0 | W22: 9816 | X22: 8591 | Z22: 0 | AA22: 0 | AB22: 0 | AC22: 0 | AD22: 1022 | AE22: 1062 | AF22: 382 | AG22: 383 | AH22: 384 | AI22: 0 | AJ22: 神坛是洗炼铭文的重要建筑，神坛等级越高，可以洗炼的铭文种类就越多
A23: 3 | B23: 神坛 | C23: 5 | D23: 6 | E23: 1 | F23: 200 | G23: 0 | H23: 0 | I23: 200 | J23: =I21+I22 -> 150 | K23: 200 | L23: =K21+K22 -> 150 | M23: 200 | N23: =M21+M22 -> 150 | O23: 200 | P23: =O21+O22 -> 150 | Q23: 1200 | R23: 0 | S23: 9946 | T23: 1 | U23: 5 | V23: 0 | W23: 9817 | X23: 8591 | Z23: 0 | AA23: 0 | AB23: 0 | AC23: 0 | AD23: 1022 | AE23: 1062 | AF23: 385 | AG23: 386 | AH23: 387 | AI23: 0 | AJ23: 神坛是洗炼铭文的重要建筑，神坛等级越高，可以洗炼的铭文种类就越多
A24: 3 | B24: 神坛 | C24: 6 | D24: 6 | E24: 1 | F24: 230 | G24: 0 | H24: 0 | I24: 500 | J24: =I22+I23 -> 300 | K24: 500 | L24: =K22+K23 -> 300 | M24: 500 | N24: =M22+M23 -> 300 | O24: 500 | P24: =O22+O23 -> 300 | Q24: 3000 | R24: 0 | S24: 9946 | T24: 1 | U24: 6 | V24: 0 | W24: 9818 | X24: 8591 | Z24: 0 | AA24: 0 | AB24: 0 | AC24: 0 | AD24: 1022 | AE24: 1062 | AF24: 385 | AG24: 386 | AH24: 387 | AI24: 0 | AJ24: 神坛是洗炼铭文的重要建筑，神坛等级越高，可以洗炼的铭文种类就越多
A25: 4 | B25: 居所 | C25: 0 | D25: 6 | E25: 1 | F25: 50 | G25: 0 | H25: 0 | I25: 5 | J25: 0 | K25: 5 | L25: 0 | M25: 5 | N25: 0 | O25: 5 | P25: 0 | Q25: 60 | R25: 0 | S25: 9946 | T25: 1 | U25: 1 | V25: 0 | W25: 9946 | X25: 8597 | Z25: 250 | AA25: 0 | AB25: 0 | AC25: 0 | AD25: 1023 | AE25: 1063 | AI25: 0 | AJ25: 居所是决定公会人数的建筑，居所等级越高，公会能招收的成员也越多
A26: 4 | B26: 居所 | C26: 1 | D26: 6 | E26: 1 | F26: 80 | G26: 0 | H26: 0 | I26: 5 | J26: =I25 -> 5 | K26: 5 | L26: =K25 -> 5 | M26: 5 | N26: =M25 -> 5 | O26: 5 | P26: =O25 -> 5 | Q26: 60 | R26: 0 | S26: 9946 | T26: 1 | U26: 1 | V26: 0 | W26: 9819 | X26: 8597 | Z26: 250 | AA26: 0 | AB26: 0 | AC26: 0 | AD26: 1023 | AE26: 1063 | AF26: 379 | AG26: 380 | AH26: 381 | AI26: 0 | AJ26: 居所是决定公会人数的建筑，居所等级越高，公会能招收的成员也越多
A27: 4 | B27: 居所 | C27: 2 | D27: 6 | E27: 1 | F27: 110 | G27: 0 | H27: 0 | I27: 10 | J27: =I25+I26 -> 10 | K27: 10 | L27: =K25+K26 -> 10 | M27: 10 | N27: =M25+M26 -> 10 | O27: 10 | P27: =O25+O26 -> 10 | Q27: 120 | R27: 0 | S27: 9946 | T27: 1 | U27: 2 | V27: 0 | W27: 9820 | X27: 8597 | Z27: 250 | AA27: 0 | AB27: 0 | AC27: 0 | AD27: 1023 | AE27: 1063 | AF27: 379 | AG27: 380 | AH27: 381 | AI27: 0 | AJ27: 居所是决定公会人数的建筑，居所等级越高，公会能招收的成员也越多
A28: 4 | B28: 居所 | C28: 3 | D28: 6 | E28: 1 | F28: 140 | G28: 0 | H28: 0 | I28: 50 | J28: =I26+I27 -> 15 | K28: 50 | L28: =K26+K27 -> 15 | M28: 50 | N28: =M26+M27 -> 15 | O28: 50 | P28: =O26+O27 -> 15 | Q28: 300 | R28: 0 | S28: 9946 | T28: 1 | U28: 3 | V28: 0 | W28: 9821 | X28: 8597 | Z28: 250 | AA28: 0 | AB28: 0 | AC28: 0 | AD28: 1023 | AE28: 1063 | AF28: 382 | AG28: 383 | AH28: 384 | AI28: 0 | AJ28: 居所是决定公会人数的建筑，居所等级越高，公会能招收的成员也越多
A29: 4 | B29: 居所 | C29: 4 | D29: 6 | E29: 1 | F29: 170 | G29: 0 | H29: 0 | I29: 100 | J29: =I27+I28 -> 60 | K29: 100 | L29: =K27+K28 -> 60 | M29: 100 | N29: =M27+M28 -> 60 | O29: 100 | P29: =O27+O28 -> 60 | Q29: 600 | R29: 0 | S29: 9946 | T29: 1 | U29: 4 | V29: 0 | W29: 9822 | X29: 8597 | Z29: 250 | AA29: 0 | AB29: 0 | AC29: 0 | AD29: 1023 | AE29: 1063 | AF29: 382 | AG29: 383 | AH29: 384 | AI29: 0 | AJ29: 居所是决定公会人数的建筑，居所等级越高，公会能招收的成员也越多
A30: 4 | B30: 居所 | C30: 5 | D30: 6 | E30: 1 | F30: 200 | G30: 0 | H30: 0 | I30: 200 | J30: =I28+I29 -> 150 | K30: 200 | L30: =K28+K29 -> 150 | M30: 200 | N30: =M28+M29 -> 150 | O30: 200 | P30: =O28+O29 -> 150 | Q30: 1200 | R30: 0 | S30: 9946 | T30: 1 | U30: 5 | V30: 0 | W30: 9823 | X30: 8597 | Z30: 250 | AA30: 0 | AB30: 0 | AC30: 0 | AD30: 1023 | AE30: 1063 | AF30: 385 | AG30: 386 | AH30: 387 | AI30: 0 | AJ30: 居所是决定公会人数的建筑，居所等级越高，公会能招收的成员也越多
A31: 4 | B31: 居所 | C31: 6 | D31: 6 | E31: 1 | F31: 230 | G31: 0 | H31: 0 | I31: 500 | J31: =I29+I30 -> 300 | K31: 500 | L31: =K29+K30 -> 300 | M31: 500 | N31: =M29+M30 -> 300 | O31: 500 | P31: =O29+O30 -> 300 | Q31: 3000 | R31: 0 | S31: 9946 | T31: 1 | U31: 6 | V31: 0 | W31: 9824 | X31: 8597 | Z31: 250 | AA31: 0 | AB31: 0 | AC31: 0 | AD31: 1023 | AE31: 1063 | AF31: 385 | AG31: 386 | AH31: 387 | AI31: 0 | AJ31: 居所是决定公会人数的建筑，居所等级越高，公会能招收的成员也越多
A32: 5 | B32: 金库 | C32: 0 | D32: 6 | E32: 1 | F32: 50 | G32: 0 | H32: 0 | I32: 5 | J32: 0 | K32: 5 | L32: 0 | M32: 5 | N32: 0 | O32: 5 | P32: 0 | Q32: 60 | R32: 0 | S32: 9946 | T32: 4 | U32: 1 | V32: 0 | W32: 9946 | X32: 8593 | Z32: 500000 | AA32: 0 | AB32: 0 | AC32: 0 | AD32: 1024 | AE32: 1064 | AI32: 0 | AJ32: 金库是存放公会资金的建筑，金库等级越高，公会资金上限也越大。公会战期间，可以通过对方金库来掠夺对方公会资金
A33: 5 | B33: 金库 | C33: 1 | D33: 6 | E33: 1 | F33: 80 | G33: 0 | H33: 0 | I33: 5 | J33: =I32 -> 5 | K33: 5 | L33: =K32 -> 5 | M33: 5 | N33: =M32 -> 5 | O33: 5 | P33: =O32 -> 5 | Q33: 60 | R33: 0 | S33: 9946 | T33: 4 | U33: 1 | V33: 0 | W33: 9825 | X33: 8593 | Z33: 1000000 | AA33: 0 | AB33: 0 | AC33: 0 | AD33: 1024 | AE33: 1064 | AF33: 379 | AG33: 380 | AH33: 381 | AI33: 0 | AJ33: 金库是存放公会资金的建筑，金库等级越高，公会资金上限也越大。公会战期间，可以通过对方金库来掠夺对方公会资金
A34: 5 | B34: 金库 | C34: 2 | D34: 6 | E34: 1 | F34: 110 | G34: 0 | H34: 0 | I34: 10 | J34: =I32+I33 -> 10 | K34: 10 | L34: =K32+K33 -> 10 | M34: 10 | N34: =M32+M33 -> 10 | O34: 10 | P34: =O32+O33 -> 10 | Q34: 120 | R34: 0 | S34: 9946 | T34: 4 | U34: 2 | V34: 0 | W34: 9826 | X34: 8593 | Z34: 2000000 | AA34: 0 | AB34: 0 | AC34: 0 | AD34: 1024 | AE34: 1064 | AF34: 379 | AG34: 380 | AH34: 381 | AI34: 0 | AJ34: 金库是存放公会资金的建筑，金库等级越高，公会资金上限也越大。公会战期间，可以通过对方金库来掠夺对方公会资金
A35: 5 | B35: 金库 | C35: 3 | D35: 6 | E35: 1 | F35: 140 | G35: 0 | H35: 0 | I35: 50 | J35: =I33+I34 -> 15 | K35: 50 | L35: =K33+K34 -> 15 | M35: 50 | N35: =M33+M34 -> 15 | O35: 50 | P35: =O33+O34 -> 15 | Q35: 300 | R35: 0 | S35: 9946 | T35: 4 | U35: 3 | V35: 0 | W35: 9827 | X35: 8593 | Z35: 5000000 | AA35: 0 | AB35: 0 | AC35: 0 | AD35: 1024 | AE35: 1064 | AF35: 382 | AG35: 383 | AH35: 384 | AI35: 0 | AJ35: 金库是存放公会资金的建筑，金库等级越高，公会资金上限也越大。公会战期间，可以通过对方金库来掠夺对方公会资金
A36: 5 | B36: 金库 | C36: 4 | D36: 6 | E36: 1 | F36: 170 | G36: 0 | H36: 0 | I36: 100 | J36: =I34+I35 -> 60 | K36: 100 | L36: =K34+K35 -> 60 | M36: 100 | N36: =M34+M35 -> 60 | O36: 100 | P36: =O34+O35 -> 60 | Q36: 600 | R36: 0 | S36: 9946 | T36: 4 | U36: 4 | V36: 0 | W36: 9828 | X36: 8593 | Z36: 10000000 | AA36: 0 | AB36: 0 | AC36: 0 | AD36: 1024 | AE36: 1064 | AF36: 382 | AG36: 383 | AH36: 384 | AI36: 0 | AJ36: 金库是存放公会资金的建筑，金库等级越高，公会资金上限也越大。公会战期间，可以通过对方金库来掠夺对方公会资金
A37: 5 | B37: 金库 | C37: 5 | D37: 6 | E37: 1 | F37: 200 | G37: 0 | H37: 0 | I37: 200 | J37: =I35+I36 -> 150 | K37: 200 | L37: =K35+K36 -> 150 | M37: 200 | N37: =M35+M36 -> 150 | O37: 200 | P37: =O35+O36 -> 150 | Q37: 1200 | R37: 0 | S37: 9946 | T37: 4 | U37: 5 | V37: 0 | W37: 9829 | X37: 8593 | Z37: 20000000 | AA37: 0 | AB37: 0 | AC37: 0 | AD37: 1024 | AE37: 1064 | AF37: 385 | AG37: 386 | AH37: 387 | AI37: 0 | AJ37: 金库是存放公会资金的建筑，金库等级越高，公会资金上限也越大。公会战期间，可以通过对方金库来掠夺对方公会资金
A38: 5 | B38: 金库 | C38: 6 | D38: 6 | E38: 1 | F38: 230 | G38: 0 | H38: 0 | I38: 500 | J38: =I36+I37 -> 300 | K38: 500 | L38: =K36+K37 -> 300 | M38: 500 | N38: =M36+M37 -> 300 | O38: 500 | P38: =O36+O37 -> 300 | Q38: 3000 | R38: 0 | S38: 9946 | T38: 4 | U38: 6 | V38: 0 | W38: 9830 | X38: 8593 | Z38: 50000000 | AA38: 0 | AB38: 0 | AC38: 0 | AD38: 1024 | AE38: 1064 | AF38: 385 | AG38: 386 | AH38: 387 | AI38: 0 | AJ38: 金库是存放公会资金的建筑，金库等级越高，公会资金上限也越大。公会战期间，可以通过对方金库来掠夺对方公会资金
A39: 6 | B39: 战事厅 | C39: 0 | D39: 6 | E39: 1 | F39: 50 | G39: 0 | H39: 0 | I39: 5 | J39: 0 | K39: 5 | L39: 0 | M39: 5 | N39: 0 | O39: 5 | P39: 0 | Q39: 60 | R39: 0 | S39: 9946 | T39: 1 | U39: 1 | V39: 0 | W39: 9946 | X39: 8593 | Z39: 0 | AA39: 0 | AB39: 0 | AC39: 0 | AD39: 1025 | AE39: 1065 | AI39: 0 | AJ39: 战事厅功能暂未开放
A40: 6 | B40: 战事厅 | C40: 1 | D40: 6 | E40: 1 | F40: 80 | G40: 0 | H40: 0 | I40: 5 | J40: =I39 -> 5 | K40: 5 | L40: =K39 -> 5 | M40: 5 | N40: =M39 -> 5 | O40: 5 | P40: =O39 -> 5 | Q40: 60 | R40: 0 | S40: 9946 | T40: 1 | U40: 1 | V40: 0 | W40: 9831 | Z40: 0 | AA40: 0 | AB40: 0 | AC40: 0 | AD40: 1025 | AE40: 1065 | AF40: 379 | AG40: 380 | AH40: 381 | AI40: 0 | AJ40: 战事厅功能暂未开放
...

Sheet 资源索引
B1: 升级公会资金 | C1: 升级粮食 | D1: 升级木材 | E1: 升级石料 | F1: 升级铁矿 | I1: 1 | J1: 0.04
A2: 1 | B2: 10000000 | C2: 5000000 | D2: 5000000 | E2: 5000000 | F2: 5000000 | G2: 主殿 | I2: 2 | J2: 0.07
A3: 2 | B3: 3000000 | C3: 3000000 | D3: 2500000 | E3: 2500000 | F3: 1000000 | G3: 商会 | I3: 3 | J3: 0.13
A4: 3 | B4: 6000000 | C4: 1500000 | D4: 3500000 | E4: 3500000 | F4: 3500000 | G4: 神坛 | I4: 4 | J4: 0.24
A5: 4 | B5: 5000000 | C5: 7000000 | D5: 4000000 | E5: 5000000 | F5: 3000000 | G5: 居所 | I5: 5 | J5: 0.4
A6: 6 | B6: 4000000 | C6: 3500000 | D6: 2500000 | E6: 2000000 | F6: 3000000 | G6: 战事厅 | I6: 6 | J6: 0.72
A7: 18 | B7: 1000000 | C7: 1000000 | D7: 1000000 | E7: 1000000 | F7: 1000000 | G7: 兵工厂
A8: 24 | B8: 1000000 | C8: 1000000 | D8: 1000000 | E8: 1000000 | F8: 1000000 | G8: 路障
A9: 7 | B9: 4000000 | C9: 1000000 | D9: 5000000 | E9: 2500000 | F9: 2500000 | G9: 图腾
A10: 19 | B10: 1500000 | C10: 1000000 | D10: 1000000 | E10: 1000000 | F10: 3000000 | G10: 天魔塔
A11: 20 | B11: 2000000 | C11: 1000000 | D11: 1000000 | E11: 1000000 | F11: 2500000 | G11: 劲弩塔
A12: 21 | B12: 3000000 | C12: 1000000 | D12: 1000000 | E12: 1000000 | F12: 1500000 | G12: 天诛塔
A13: 22 | B13: 2500000 | C13: 1000000 | D13: 1500000 | E13: 1500000 | F13: 1000000 | G13: 玄魔塔
A14: 23 | B14: 3000000 | C14: 1000000 | D14: 1000000 | E14: 1500000 | F14: 1000000 | G14: 轻羽塔
A15: 5 | B15: 5000000 | C15: 2000000 | D15: 1000000 | E15: 2000000 | F15: 2000000 | G15: 金库
A16: 8 | B16: 1000000 | C16: 1000000 | D16: 1000000 | E16: 1000000 | F16: 1000000 | G16: 农场
A17: 9 | B17: 1000000 | C17: 1000000 | D17: 1000000 | E17: 1000000 | F17: 1000000 | G17: 林场
A18: 10 | B18: 1000000 | C18: 1000000 | D18: 1000000 | E18: 1000000 | F18: 1000000 | G18: 石场
... A26: 25 | B26: 1000000 | C26: 1000000 | D26: 1000000 | E26: 1000000 | F26: 1000000 | G26: 公会神兽
