Workbook

Sheet handbook
A1: HandbookID | B1: HandbookType | C1: HandbookIndex | D1: ID | E1: Name | F1: AchievementId | G1: Text0 | H1: Text1 | I1: Text2 | J1: Data0 | K1: Data1 | L1: Sound | M1: Icon | N1: Scale
A2: both | B2: both | C2: both | D2: both | E2: client | F2: client | G2: client | H2: client | I2: client | J2: client | K2: client | L2: client | M2: client | N2: both
A3: 0 | B3: htInvalid | C3: 0 | D3: 0 | E3: 0 | F3: 0 | G3: 0 | H3: 0 | I3: 0 | J3: 0 | K3: 0 | L3: 0 | M3: 0 | N3: 0
A4: 1 | B4: htNpc_Normal | C4: 0 | D4: 801,855 | E4: 稻草人 | F4: 0 | G4: 1~8 | H4: 边界村、比奇省 | I4: 天尊昔日曾以符纸降服稻草人，令它们帮助村民看守农田。最近却不知为何符纸失效，这些魔力稻草人又陷入混乱之中。 | J4: 0 | K4: 0 | L4: SoundCue'NPC_XueQianXun.61_XueQianXun_S_Cue' | M4: img://UI_Handbook.monster_31 | N4: 1
A5: 2 | B5: htNpc_Normal | C5: 1 | D5: 802,856 | E5: 钉耙猫 | F5: 0 | G5: 1~8 | H5: 边界村、比奇省 | I5: 十几年前边界村曾被钉耙猫占据。它们生性贪婪，经常偷盗居民财物。村民在铁牛的组织下成立了‘除猫大队’，立志要消灭它们。 | J5: 0 | K5: 0 | L5: SoundCue'NPC_XueQianXun.62_XueQianXun_S_Cue' | M5: img://UI_Handbook.monster_7 | N5: 0.9
A6: 3 | B6: htNpc_Normal | C6: 2 | D6: 823,873,3132 | E6: 鹿 | F6: 0 | G6: 1~13 | H6: 边界村、比奇省、沃玛森林 | I6: 性情温顺的野鹿，通常不会主动攻击人，但若被惹急了也会用角猛力顶撞，不可小觑。 | J6: 0 | K6: 0 | M6: img://UI_Handbook.lu | N6: 0.6
A7: 4 | B7: htNpc_Normal | C7: 3 | D7: 803,857,922 | E7: 半兽人 | F7: 0 | G7: 1~13 | H7: 边界村、比奇省、沃玛森林 | I7: 半兽人长期生活在战斗和劫掠中，在它们眼中，年长的半兽人意味着有更丰富的战斗经验，是主要的战斗力。 | J7: 0 | K7: 0 | L7: SoundCue'NPC_XueQianXun.63_XueQianXun_S_Cue' | M7: img://UI_Handbook.monster_5 | N7: 1.3
A8: 5 | B8: htNpc_Normal | C8: 4 | D8: 804,858,923 | E8: 半兽人战士 | F8: 0 | G8: 1~13 | H8: 边界村、比奇省、沃玛森林 | I8: 半兽人长期生活在战斗和劫掠中，在它们眼中，年长的半兽人意味着有更丰富的战斗经验，是主要的战斗力。 | J8: 0 | K8: 0 | L8: 0 | M8: img://UI_Handbook.monster_4 | N8: 1.2
A9: 6 | B9: htNpc_Normal | C9: 5 | D9: 821,3133 | E9: 海蟹 | F9: 0 | G9: 1~13 | H9: 边界村、沃玛森林 | I9: 原本集聚沿海的蟹类，后因地壳迁徙而往内陆发展，喜欢在稻田中捣乱，挥舞两只大钳子横行无忌，让人十分头疼。 | J9: 0 | K9: 0 | L9: 0 | M9: img://UI_Handbook.jijuxie | N9: 0.8
A10: 7 | B10: htNpc_Normal | C10: 6 | D10: 3131 | E10: 熊 | F10: 0 | G10: 8~13 | H10: 沃玛森林 | I10: 受沃玛教主复活的影响，森林中的野熊也开始变得狂暴不安。它们攻击力极高而且身手敏捷，一掌下去非死即伤。 | J10: 0 | K10: 0 | L10: 0 | M10: img://UI_Handbook.youxiong | N10: 1.1
A11: 8 | B11: htNpc_Normal | C11: 7 | D11: 3134,962 | E11: 狼 | F11: 0 | G11: 8~18 | H11: 沃玛森林、盟重省 | I11: 土狼本性极为凶残，被沃玛教主收为爪牙后越发凶狠毒辣，一旦锁定攻击目标便极力追逐，两败俱伤也绝不松口。 | J11: 0 | K11: 0 | L11: 0 | M11: img://UI_Handbook.monster_40 | N11: 1
A12: 9 | B12: htNpc_Normal | C12: 8 | D12: 3135 | E12: 树妖 | F12: 0 | G12: 8~13 | H12: 沃玛森林 | I12: 原本生活在沃玛森林中的纯洁树妖，却被沃玛教主奴役了灵魂，变成只知道破坏、以他人痛苦为乐的妖怪。 | J12: 0 | K12: 0 | L12: 0 | M12: img://UI_Handbook.gebulin | N12: 1.2
A13: 10 | B13: htNpc_Normal | C13: 9 | D13: 961 | E13: 盔甲虫 | F13: 0 | G13: 14~18 | H13: 盟重省 | I13: 本是一种极为普通的昆虫，当屠龙刀在盟重铸成时，魔气四溢而被感染，变得形体巨大且极具攻击性。 | J13: 0 | K13: 0 | L13: 0 | M13: img://UI_Handbook.monster_26 | N13: 1.2
A14: 11 | B14: htNpc_Normal | C14: 10 | D14: 963 | E14: 多角虫 | F14: 0 | G14: 14~18 | H14: 盟重省 | I14: 本是一种极为普通的昆虫，当屠龙刀在盟重铸成时，魔气四溢而被感染，变得形体巨大且极具攻击性。 | J14: 0 | K14: 0 | L14: 0 | M14: img://UI_Handbook.monster_8 | N14: 0.8
A15: 12 | B15: htNpc_Normal | C15: 11 | D15: 901 | E15: 僵尸 | F15: 0 | G15: 19~23 | H15: 比奇矿区 | I15: 从比奇矿区溢出的腐朽尸气，感染了矿工，让它们的身体变成一截截僵硬的尸块，只能在泥土中爬行，无止境的杀戮。 | J15: 0 | K15: 0 | L15: 0 | M15: img://UI_Handbook.monster_23 | N15: 1
A16: 13 | B16: htNpc_Normal | C16: 12 | D16: 902 | E16: 僵尸 | F16: 0 | G16: 19~23 | H16: 比奇矿区 | I16: 蹒跚在矿井附近的僵尸，没有思想，没有意识，只剩下杀戮的欲望。一旦被它们缠上，定然不死不休。 | J16: 0 | K16: 0 | L16: 0 | M16: img://UI_Handbook.monster_24 | N16: 1
A17: 14 | B17: htNpc_Normal | C17: 13 | D17: 903 | E17: 僵尸 | F17: 0 | G17: 19~23 | H17: 比奇矿区 | I17: 蹒跚在矿井附近的僵尸，没有思想，没有意识，只剩下杀戮的欲望。一旦被它们缠上，定然不死不休。 | J17: 0 | K17: 0 | L17: 0 | M17: img://UI_Handbook.monster_21 | N17: 1
A18: 15 | B18: htNpc_Normal | C18: 14 | D18: 904,908 | E18: 僵尸 | F18: 0 | G18: 19~23 | H18: 比奇矿区 | I18: 由比奇城主聘请的和尚，前往矿洞净化尸毒，却感染尸毒而变异，从头到脚渗透出毒液，让人畏惧。 | J18: 0 | K18: 0 | L18: 0 | M18: img://UI_Handbook.monster_22 | N18: 0.9
A19: 16 | B19: htNpc_Normal | C19: 15 | D19: 905, | E19: 僵尸 | F19: 0 | G19: 19~23 | H19: 比奇矿区 | I19: 由比奇城主聘请的道士，前往矿洞净化尸毒，却被矿洞中的惨景吓疯，引爆雷电之术，对视线范围内的一切进行毁灭。 | J19: 0 | K19: 0 | L19: 0 | M19: img://UI_Handbook.monster_20 | N19: 1
A20: 17 | B20: htNpc_Normal | C20: 16 | D20: 3110,948 | E20: 山洞蝙蝠 | F20: 0 | G20: 19~27 | H20: 比奇矿区、沃玛寺庙 | I20: 在山洞深处筑巢的嗜血蝙蝠，无法满足吸血的愿望，因此变得越发狂躁，见人而噬。 | J20: 0 | K20: 0 | L20: 0 | M20: img://UI_Handbook.bianfu | N20: 0.8
A21: 18 | B21: htNpc_Normal | C21: 17 | D21: 3118 | E21: 雷术鬼尸 | F21: 0 | G21: 19~23 | H21: 比奇矿区 | I21: 身具雷术属性，不论从那个方面来看都是令人生畏的怪物，有脑子的冒险者都不会想去招惹它。 | J21: 0 | K21: 0 | L21: 0 | M21: img://UI_Handbook.monster_20 | N21: 1
A22: 19 | B22: htNpc_Normal | C22: 18 | D22: 941 | E22: 暗黑战士 | F22: 0 | G22: 24~27 | H22: 沃玛寺庙 | I22: 沃玛教主对于教中的叛徒和逃兵处罚极为严酷：斩去牛角，打断脊骨，变成不惧死亡的战士，没有人能轻易突破它们的防线。 | J22: 0 | K22: 0 | L22: 0 | M22: img://UI_Handbook.monster_1 | N22: 0.6
A23: 20 | B23: htNpc_Normal | C23: 19 | D23: 949,1031 | E23: 恶蛆 | F23: 0 | G23: 24~35 | H23: 沃玛寺庙、石墓 | I23: 石墓中死去的蛆虫，在感染到虹魔猪妖复活的魔气后，也再次复活。它们保持着尸体的蜷曲状，行动犹如飞轮，让人难以攻击。 | J23: 0 | K23: 0 | L23: 0 | M23: img://UI_Handbook.monster_9 | N23: 0.8
A24: 21 | B24: htNpc_Normal | C24: 20 | D24: 942 | E24: 沃玛战士 | F24: 0 | G24: 24~27 | H24: 沃玛寺庙 | I24: 沃玛半兽人自出生起就是沃玛教主的忠实奴仆，在渡过幼年期的考验后，便被大祭司烙上带有魔力的烙印，训练成只为教主而战的勇士。 | J24: 0 | K24: 0 | L24: 0 | M24: img://UI_Handbook.monster_35 | N24: 0.8
A25: 22 | B25: htNpc_Normal | C25: 21 | D25: 943 | E25: 沃玛勇士 | F25: 0 | G25: 24~27 | H25: 沃玛寺庙 | I25: 沃玛半兽人自出生起就是沃玛教主的忠实奴仆，在渡过幼年期的考验后，便被大祭司烙上带有魔力的烙印，训练成只为教主而战的勇士。 | J25: 0 | K25: 0 | L25: 0 | M25: img://UI_Handbook.monster_36 | N25: 0.8
A26: 23 | B26: htNpc_Normal | C26: 22 | D26: 944 | E26: 沃玛战将 | F26: 0 | G26: 24~27 | H26: 沃玛寺庙 | I26: 沃玛半兽人自出生起就是沃玛教主的忠实奴仆，在渡过幼年期的考验后，便被大祭司烙上带有魔力的烙印，训练成只为教主而战的勇士。 | J26: 0 | K26: 0 | L26: 0 | M26: img://UI_Handbook.monster_37 | N26: 0.8
A27: 24 | B27: htNpc_Normal | C27: 23 | D27: 951 | E27: 火焰沃玛 | F27: 0 | G27: 24~27 | H27: 沃玛寺庙 | I27: 沃玛半兽人自出生起就是沃玛教主的忠实奴仆，在渡过幼年期的考验后，便被大祭司烙上带有魔力的烙印，训练成只为教主而战的勇士。 | J27: 0 | K27: 0 | L27: 0 | M27: img://UI_Handbook.monster_16 | N27: 1.1
A28: 25 | B28: htNpc_Normal | C28: 24 | D28: 953 | E28: 毒针魔战士 | F28: 0 | G28: 19~23 | H28: 沃玛寺庙 | I28: 它们身前曾是最英勇的人类战士，却在死后被沃玛教主变成了如此模样，或许死亡是解除它们桎梏的最好方法。 | J28: 0 | K28: 0 | L28: 0 | M28: img://UI_Handbook.monster_1 | N28: 0.6
A29: 26 | B29: htNpc_Normal | C29: 25 | D29: 1011 | E29: 蜈蚣 | F29: 0 | G29: 28~31 | H29: 死亡峡谷 | I29: 死亡山谷的别名‘蜈蚣洞’，远比它的正名更令人震慑，而这便是来源于遍布山谷中的剧毒蜈蚣们。 | J29: 0 | K29: 0 | L29: 0 | M29: img://UI_Handbook.monster_38 | N29: 0.6
A30: 27 | B30: htNpc_Normal | C30: 26 | D30: 1012 | E30: 巨型蠕虫 | F30: 0 | G30: 28~31 | H30: 死亡峡谷 | I30: 蠕虫经过操虫师一族几十年间的驯化，原本温顺无比。但随着爱弥儿的叛乱，这些巨大蠕虫也随之失去控制，散布谷中，为害一方。 | J30: 0 | K30: 0 | L30: 0 | M30: img://UI_Handbook.monster_18 | N30: 0.6
A31: 28 | B31: htNpc_Normal | C31: 27 | D31: 1013 | E31: 钳虫 | F31: 0 | G31: 28~31 | H31: 死亡峡谷 | I31: 操虫师们在驯化蜈蚣时，变异产生的魔法生物。它们的体节更短，但身躯极为坚固，在失去操虫师的钳制后，成为让来往行人头疼的生物。 | J31: 0 | K31: 0 | L31: 0 | M31: img://UI_Handbook.monster_28 | N31: 1
A32: 29 | B32: htNpc_Normal | C32: 28 | D32: 1014 | E32: 跳跳蜂 | F32: 0 | G32: 28~31 | H32: 死亡峡谷 | I32: 被某些操虫师改造的魔法产物，将山谷中的巨大蜂群变化成靠跳跃行进的跳跳蜂。没人能预估它们的下一次进攻是从哪个方向而来。 | J32: 0 | K32: 0 | L32: 0 | M32: img://UI_Handbook.monster_30 | N32: 0.8
A33: 30 | B33: htNpc_Normal | C33: 29 | D33: 3227 | E33: 摄魂跳跳蜂 | F33: 0 | G33: 14~18 | H33: 死亡峡谷 | I33: 注意，它们可不是普通的跳跳蜂，那赤红的眼睛和羽翼无一不彰显着它变异的事实。总而言之，远离就对了。 | J33: 0 | K33: 0 | L33: 0 | M33: img://UI_Handbook.monster_30 | N33: 0.8
A34: 31 | B34: htNpc_Normal | C34: 30 | D34: 1032 | E34: 红野猪 | F34: 0 | G34: 32~35 | H34: 石墓 | I34: 石墓中猪妖和野猪群产下的生物，具有粗浅的智慧，甚至懂得设陷阱围攻敌人。它们皮糙肉厚，最喜以人肉为食。 | J34: 0 | K34: 0 | L34: 0 | M34: img://UI_Handbook.monster_11 | N34: 1
A35: 32 | B35: htNpc_Normal | C35: 31 | D35: 1033 | E35: 黑野猪 | F35: 0 | G35: 32~35 | H35: 石墓 | I35: 石墓中猪妖和野猪群产下的生物，具有粗浅的智慧，甚至懂得设陷阱围攻敌人。它们皮糙肉厚，最喜以人肉为食。 | J35: 0 | K35: 0 | L35: 0 | M35: img://UI_Handbook.monster_10 | N35: 1
A36: 33 | B36: htNpc_Normal | C36: 32 | D36: 1034 | E36: 白野猪 | F36: 0 | G36: 32~35 | H36: 石墓 | I36: 石墓中猪妖和野猪群产下的生物，具有粗浅的智慧，甚至懂得设陷阱围攻敌人。它们皮糙肉厚，最喜以人肉为食。 | J36: 0 | K36: 0 | L36: 0 | M36: img://UI_Handbook.monster_2 | N36: 0.9
A37: 34 | B37: htNpc_Normal | C37: 33 | D37: 3248 | E37: 白野猪暴徒 | F37: 0 | G37: 19~23 | H37: 石墓 | I37: 这些曾被虹魔教徒打败过的白野猪，死而复生后都变成了虹魔教的忠实信徒，并且更加狂暴了。 | J37: 0 | K37: 0 | L37: 0 | M37: img://UI_Handbook.monster_2 | N37: 0.9
A38: 35 | B38: htNpc_Normal | C38: 34 | D38: 2119 | E38: 饥饿僵尸 | F38: 0 | G38: 1~8 | H38: 九层妖塔 | I38: 生前就从没吃饱过的穷人，被猪妖欺骗后关入妖塔，在魔气的侵染下变成永远饥饿的僵尸。 | J38: 0 | K38: 0 | L38: 0 | M38: img://UI_Handbook.monster_23 | N38: 1
A39: 36 | B39: htNpc_Normal | C39: 35 | D39: 2120 | E39: 怨恨僵尸 | F39: 0 | G39: 1~8 | H39: 九层妖塔 | I39: 生前被人抛弃，沦为猪妖的食物，让这些僵尸体内充满怨恨，光是靠近就忍不住浑身战栗起来。 | J39: 0 | K39: 0 | L39: 0 | M39: img://UI_Handbook.monster_24 | N39: 1
A40: 37 | B40: htNpc_Normal | C40: 36 | D40: 2121 | E40: 脏污僵尸 | F40: 0 | G40: 1~13 | H40: 九层妖塔 | I40: 虽然没见过会洗澡的僵尸，但这些怪物也实在太肮脏了点，也许生前都是无家可归的乞丐吧。 | J40: 0 | K40: 0 | L40: 0 | M40: img://UI_Handbook.monster_23 | N40: 1
...

Sheet Sheet2
B7: 基本剑术[旋风] | C7: 10311 | D7: =LEFT(C7,4) -> 1031 | E7: =RIGHT(C7) -> 1 | F7: {=VLOOKUP(D7&E7,IF({1,0},[3]spell_var!$A$3:$A$16841&[3]spell_var!$B$3:$B$16841,[3]spell_var!$L$3:$L$16841),2,FALSE)} -> 旋风印 | G7: {=VLOOKUP(D7&0,IF({1,0},[3]spell_var!$A$3:$A$16841&[3]spell_var!$B$3:$B$16841,[3]spell_var!$L$3:$L$16841),2,FALSE)} -> 基本剑术 | H7: =G7&"["&F7&"]" -> 基本剑术[旋风印] | I7: 基本剑术 | J7: 旋风印
B8: 基本剑术[主宰] | C8: 10312 | D8: =LEFT(C8,4) -> 1031 | E8: =RIGHT(C8) -> 2 | F8: {=VLOOKUP(D8&E8,IF({1,0},[3]spell_var!$A$3:$A$16841&[3]spell_var!$B$3:$B$16841,[3]spell_var!$L$3:$L$16841),2,FALSE)} -> 主宰印 | G8: {=VLOOKUP(D8&0,IF({1,0},[3]spell_var!$A$3:$A$16841&[3]spell_var!$B$3:$B$16841,[3]spell_var!$L$3:$L$16841),2,FALSE)} -> 基本剑术 | H8: =G8&"["&F8&"]" -> 基本剑术[主宰印] | I8: 基本剑术 | J8: 主宰印
B9: 基本剑术[幽速] | C9: 10313 | D9: =LEFT(C9,4) -> 1031 | E9: =RIGHT(C9) -> 3 | F9: {=VLOOKUP(D9&E9,IF({1,0},[3]spell_var!$A$3:$A$16841&[3]spell_var!$B$3:$B$16841,[3]spell_var!$L$3:$L$16841),2,FALSE)} -> 幽速印 | G9: {=VLOOKUP(D9&0,IF({1,0},[3]spell_var!$A$3:$A$16841&[3]spell_var!$B$3:$B$16841,[3]spell_var!$L$3:$L$16841),2,FALSE)} -> 基本剑术 | H9: =G9&"["&F9&"]" -> 基本剑术[幽速印] | I9: 基本剑术 | J9: 幽速印
B10: 基本剑术[压制] | C10: 10314 | D10: =LEFT(C10,4) -> 1031 | E10: =RIGHT(C10) -> 4 | F10: {=VLOOKUP(D10&E10,IF({1,0},[3]spell_var!$A$3:$A$16841&[3]spell_var!$B$3:$B$16841,[3]spell_var!$L$3:$L$16841),2,FALSE)} -> 压制印 | G10: {=VLOOKUP(D10&0,IF({1,0},[3]spell_var!$A$3:$A$16841&[3]spell_var!$B$3:$B$16841,[3]spell_var!$L$3:$L$16841),2,FALSE)} -> 基本剑术 | H10: =G10&"["&F10&"]" -> 基本剑术[压制印] | I10: 基本剑术 | J10: 压制印
B11: 攻杀剑术[暴君] | C11: 10321 | D11: =LEFT(C11,4) -> 1032 | E11: =RIGHT(C11) -> 1 | F11: {=VLOOKUP(D11&E11,IF({1,0},[3]spell_var!$A$3:$A$16841&[3]spell_var!$B$3:$B$16841,[3]spell_var!$L$3:$L$16841),2,FALSE)} -> 暴君印 | G11: {=VLOOKUP(D11&0,IF({1,0},[3]spell_var!$A$3:$A$16841&[3]spell_var!$B$3:$B$16841,[3]spell_var!$L$3:$L$16841),2,FALSE)} -> 攻杀剑术 | H11: =G11&"["&F11&"]" -> 攻杀剑术[暴君印] | I11: 攻杀剑术 | J11: 暴君印
B12: 攻杀剑术[银光] | C12: 10322 | D12: =LEFT(C12,4) -> 1032 | E12: =RIGHT(C12) -> 2 | F12: {=VLOOKUP(D12&E12,IF({1,0},[3]spell_var!$A$3:$A$16841&[3]spell_var!$B$3:$B$16841,[3]spell_var!$L$3:$L$16841),2,FALSE)} -> 银光印 | G12: {=VLOOKUP(D12&0,IF({1,0},[3]spell_var!$A$3:$A$16841&[3]spell_var!$B$3:$B$16841,[3]spell_var!$L$3:$L$16841),2,FALSE)} -> 攻杀剑术 | H12: =G12&"["&F12&"]" -> 攻杀剑术[银光印] | I12: 攻杀剑术 | J12: 银光印
B13: 攻杀剑术[血杀] | C13: 10323 | D13: =LEFT(C13,4) -> 1032 | E13: =RIGHT(C13) -> 3 | F13: {=VLOOKUP(D13&E13,IF({1,0},[3]spell_var!$A$3:$A$16841&[3]spell_var!$B$3:$B$16841,[3]spell_var!$L$3:$L$16841),2,FALSE)} -> 血杀印 | G13: {=VLOOKUP(D13&0,IF({1,0},[3]spell_var!$A$3:$A$16841&[3]spell_var!$B$3:$B$16841,[3]spell_var!$L$3:$L$16841),2,FALSE)} -> 攻杀剑术 | H13: =G13&"["&F13&"]" -> 攻杀剑术[血杀印] | I13: 攻杀剑术 | J13: 血杀印
B14: 攻杀剑术[碧落] | C14: 10324 | D14: =LEFT(C14,4) -> 1032 | E14: =RIGHT(C14) -> 4 | F14: {=VLOOKUP(D14&E14,IF({1,0},[3]spell_var!$A$3:$A$16841&[3]spell_var!$B$3:$B$16841,[3]spell_var!$L$3:$L$16841),2,FALSE)} -> 煌龙印 | G14: {=VLOOKUP(D14&0,IF({1,0},[3]spell_var!$A$3:$A$16841&[3]spell_var!$B$3:$B$16841,[3]spell_var!$L$3:$L$16841),2,FALSE)} -> 攻杀剑术 | H14: =G14&"["&F14&"]" -> 攻杀剑术[煌龙印] | I14: 攻杀剑术 | J14: 煌龙印
B15: 刺杀剑术[破法] | C15: 10331 | D15: =LEFT(C15,4) -> 1033 | E15: =RIGHT(C15) -> 1 | F15: {=VLOOKUP(D15&E15,IF({1,0},[3]spell_var!$A$3:$A$16841&[3]spell_var!$B$3:$B$16841,[3]spell_var!$L$3:$L$16841),2,FALSE)} -> 破法印 | G15: {=VLOOKUP(D15&0,IF({1,0},[3]spell_var!$A$3:$A$16841&[3]spell_var!$B$3:$B$16841,[3]spell_var!$L$3:$L$16841),2,FALSE)} -> 刺杀剑术 | H15: =G15&"["&F15&"]" -> 刺杀剑术[破法印] | I15: 刺杀剑术 | J15: 破法印
B16: 刺杀剑术[耀光] | C16: 10332 | D16: =LEFT(C16,4) -> 1033 | E16: =RIGHT(C16) -> 2 | F16: {=VLOOKUP(D16&E16,IF({1,0},[3]spell_var!$A$3:$A$16841&[3]spell_var!$B$3:$B$16841,[3]spell_var!$L$3:$L$16841),2,FALSE)} -> 耀光印 | G16: {=VLOOKUP(D16&0,IF({1,0},[3]spell_var!$A$3:$A$16841&[3]spell_var!$B$3:$B$16841,[3]spell_var!$L$3:$L$16841),2,FALSE)} -> 刺杀剑术 | H16: =G16&"["&F16&"]" -> 刺杀剑术[耀光印] | I16: 刺杀剑术 | J16: 耀光印
B17: 刺杀剑术[破山] | C17: 10333 | D17: =LEFT(C17,4) -> 1033 | E17: =RIGHT(C17) -> 3 | F17: {=VLOOKUP(D17&E17,IF({1,0},[3]spell_var!$A$3:$A$16841&[3]spell_var!$B$3:$B$16841,[3]spell_var!$L$3:$L$16841),2,FALSE)} -> 破山印 | G17: {=VLOOKUP(D17&0,IF({1,0},[3]spell_var!$A$3:$A$16841&[3]spell_var!$B$3:$B$16841,[3]spell_var!$L$3:$L$16841),2,FALSE)} -> 刺杀剑术 | H17: =G17&"["&F17&"]" -> 刺杀剑术[破山印] | I17: 刺杀剑术 | J17: 破山印
B18: 半月弯刀[月华] | C18: 10341 | D18: =LEFT(C18,4) -> 1034 | E18: =RIGHT(C18) -> 1 | F18: {=VLOOKUP(D18&E18,IF({1,0},[3]spell_var!$A$3:$A$16841&[3]spell_var!$B$3:$B$16841,[3]spell_var!$L$3:$L$16841),2,FALSE)} -> 月华印 | G18: {=VLOOKUP(D18&0,IF({1,0},[3]spell_var!$A$3:$A$16841&[3]spell_var!$B$3:$B$16841,[3]spell_var!$L$3:$L$16841),2,FALSE)} -> 半月弯刀 | H18: =G18&"["&F18&"]" -> 半月弯刀[月华印] | I18: 半月弯刀 | J18: 月华印
... B96: 噬血术[夺魂] | C96: 30102 | D96: =LEFT(C96,4) -> 3010 | E96: =RIGHT(C96) -> 2 | F96: {=VLOOKUP(D96&E96,IF({1,0},[3]spell_var!$A$3:$A$16841&[3]spell_var!$B$3:$B$16841,[3]spell_var!$L$3:$L$16841),2,FALSE)} -> 夺魂印 | G96: {=VLOOKUP(D96&0,IF({1,0},[3]spell_var!$A$3:$A$16841&[3]spell_var!$B$3:$B$16841,[3]spell_var!$L$3:$L$16841),2,FALSE)} -> 噬血术 | H96: =G96&"["&F96&"]" -> 噬血术[夺魂印] | I96: 噬血术 | J96: 夺魂印
B101: 10110 | C101: =VLOOKUP(B101,[1]item!$A$4:$BB$894,2,FALSE) -> 驭朱灵石1级
B102: 10120 | C102: =VLOOKUP(B102,[1]item!$A$4:$BB$894,2,FALSE) -> 命朱灵石1级
B103: 10220 | C103: =VLOOKUP(B103,[1]item!$A$4:$BB$894,2,FALSE) -> 守阳灵石1级
B104: 10320 | C104: =VLOOKUP(B104,[1]item!$A$4:$BB$894,2,FALSE) -> 蔚蓝灵石1级
B105: 10420 | C105: =VLOOKUP(B105,[1]item!$A$4:$BB$894,2,FALSE) -> 精绿灵石1级
B106: 10520 | C106: =VLOOKUP(B106,[1]item!$A$4:$BB$894,2,FALSE) -> 纯紫灵石1级

Sheet Sheet3
A1: 6682 | B1: =VLOOKUP(A1,J1:N1178,5,FALSE) -> 朴无界 | C1: =VLOOKUP(A1,J1:O1178,6,FALSE) -> 书店 | J1: TemplateID | K1: NameID | L1: Level | M1: GroupID | N1: DisplayName | O1: IdentityName
A2: 6679 | B2: =VLOOKUP(A2,J2:N1179,5,FALSE) -> 王大锤 | C2: =VLOOKUP(A2,J2:O1179,6,FALSE) -> 0 | J2: Both | K2: Both | L2: Both | M2: Both | N2: Both | O2: Client
A3: 6672 | B3: =VLOOKUP(A3,J3:N1180,5,FALSE) -> 王铁匠 | C3: =VLOOKUP(A3,J3:O1180,6,FALSE) -> 武器店 | J3: 0 | K3: 0 | N3: N/A
A4: 6662 | B4: =VLOOKUP(A4,J4:N1181,5,FALSE) -> 白玉兰 | C4: =VLOOKUP(A4,J4:O1181,6,FALSE) -> 防具店 | J4: 6911 | K4: 沙巴克报名官 | L4: 1 | M4: 0 | N4: 沙巴克报名官
A5: 6663 | B5: =VLOOKUP(A5,J5:N1182,5,FALSE) -> 药老 | C5: =VLOOKUP(A5,J5:O1182,6,FALSE) -> 药店 | J5: 6912 | K5: 沙巴克饰品店 | L5: 1 | M5: 0 | N5: 沙巴克饰品店
A6: 6664 | B6: =VLOOKUP(A6,J6:N1183,5,FALSE) -> 醉爷 | C6: =VLOOKUP(A6,J6:O1183,6,FALSE) -> 杂货店 | J6: 6913 | K6: 沙巴克武器店 | L6: 1 | M6: 0 | N6: 沙巴克武器店
A7: 6665 | B7: =VLOOKUP(A7,J7:N1184,5,FALSE) -> 阿吉 | C7: =VLOOKUP(A7,J7:O1184,6,FALSE) -> 仓库 | J7: 6914 | K7: 沙巴克书店 | L7: 1 | M7: 0 | N7: 沙巴克书店
A8: 6666 | B8: =VLOOKUP(A8,J8:N1185,5,FALSE) -> 公会使者 | C8: =VLOOKUP(A8,J8:O1185,6,FALSE) -> 公会 | J8: 6915 | K8: 沙巴克服装店 | L8: 1 | M8: 0 | N8: 沙巴克服装店
A9: 6667 | B9: =VLOOKUP(A9,J9:N1186,5,FALSE) -> 百火 | C9: =VLOOKUP(A9,J9:O1186,6,FALSE) -> 公会仓库 | J9: 6916 | K9: 沙巴克仓库 | L9: 1 | M9: 0 | N9: 沙巴克仓库
A10: 6668 | B10: =VLOOKUP(A10,J10:N1187,5,FALSE) -> 金银手 | C10: =VLOOKUP(A10,J10:O1187,6,FALSE) -> 公会银库 | J10: 6917 | K10: 沙巴克药店 | L10: 1 | M10: 0 | N10: 沙巴克药店
A11: 6670 | B11: =VLOOKUP(A11,J11:N1188,5,FALSE) -> 洛儿 | C11: =VLOOKUP(A11,J11:O1188,6,FALSE) -> 拍卖 | J11: 6918 | K11: 沙巴克杂货店 | L11: 1 | M11: 0 | N11: 沙巴克杂货店
A12: 6713 | B12: =VLOOKUP(A12,J12:N1189,5,FALSE) -> 丘伯 | C12: =VLOOKUP(A12,J12:O1189,6,FALSE) -> 铭文洗练 | J12: 6919 | K12: 沙巴克工会使者 | L12: 1 | M12: 0 | N12: 沙巴克工会使者
A13: 6714 | B13: =VLOOKUP(A13,J13:N1190,5,FALSE) -> 紫容 | C13: =VLOOKUP(A13,J13:O1190,6,FALSE) -> 灵石镶嵌 | J13: 8611 | K13: 雕像 | L13: 1 | M13: 0 | N13: 雕像
A14: 6716 | B14: =VLOOKUP(A14,J14:N1191,5,FALSE) -> 齐山 | C14: =VLOOKUP(A14,J14:O1191,6,FALSE) -> 成就商店 | J14: 8610 | K14: 皇宫门2 | L14: 1 | M14: 0 | N14: 皇宫门2
A15: 6717 | B15: =VLOOKUP(A15,J15:N1192,5,FALSE) -> 香毒 | C15: =VLOOKUP(A15,J15:O1192,6,FALSE) -> 药店 | J15: 8609 | K15: 沙巴克城门2 | L15: 1 | M15: 0 | N15: 沙巴克城门2
... A55: 6816 | B55: =VLOOKUP(A55,J55:N1232,5,FALSE) -> 胡大福 | C55: =VLOOKUP(A55,J55:O1232,6,FALSE) -> 首饰 | J55: 5287 | K55: 触龙神01 | L55: 60 | M55: 0 | N55: 触龙神01
B56: =VLOOKUP(A56,J56:N1233,5,FALSE) -> #N/A | C56: =VLOOKUP(A56,J56:O1233,6,FALSE) -> #N/A | J56: 5268 | K56: 尸王01 | L56: 45 | M56: 10006 | N56: 尸王01
B57: =VLOOKUP(A57,J57:N1234,5,FALSE) -> #N/A | C57: =VLOOKUP(A57,J57:O1234,6,FALSE) -> #N/A | J57: 5270 | K57: 诅咒之棺02 | L57: 25 | M57: 0 | N57: 诅咒之棺02
B58: =VLOOKUP(A58,J58:N1235,5,FALSE) -> #N/A | C58: =VLOOKUP(A58,J58:O1235,6,FALSE) -> #N/A | J58: 5266 | K58: 怨毒和尚僵尸01 | L58: 25 | M58: 10006 | N58: 怨毒和尚僵尸01
B59: =VLOOKUP(A59,J59:N1236,5,FALSE) -> #N/A | C59: =VLOOKUP(A59,J59:O1236,6,FALSE) -> #N/A | J59: 5267 | K59: 怨毒闪电僵尸02 | L59: 25 | M59: 10006 | N59: 怨毒闪电僵尸02
A60: 6661 | B60: =VLOOKUP(A60,J60:N1237,5,FALSE) -> 玲月04 | C60: =VLOOKUP(A60,J60:O1237,6,FALSE) -> 0 | J60: 5269 | K60: 怨毒利爪僵尸03 | L60: 25 | M60: 10006 | N60: 怨毒利爪僵尸03
A61: 6685 | B61: =VLOOKUP(A61,J61:N1238,5,FALSE) -> 朴十八 | C61: =VLOOKUP(A61,J61:O1238,6,FALSE) -> 信差 | J61: 5271 | K61: 稀有双头金刚02 | L61: 50 | M61: 0 | N61: 双头金刚02
A62: 6686 | B62: =VLOOKUP(A62,J62:N1239,5,FALSE) -> 铁牛 | C62: =VLOOKUP(A62,J62:O1239,6,FALSE) -> 除猫队队长 | J62: 5272 | K62: 稀有半兽人头领03 | L62: 50 | M62: 10009 | N62: 半兽人统领03
A63: 6683 | B63: =VLOOKUP(A63,J63:N1240,5,FALSE) -> 南苍公 | C63: =VLOOKUP(A63,J63:O1240,6,FALSE) -> 村长 | J63: 5273 | K63: 黄泉教主01 | L63: 60 | M63: 0 | N63: 黄泉教主01
A64: 6684 | B64: =VLOOKUP(A64,J64:N1241,5,FALSE) -> 阿九08 | C64: =VLOOKUP(A64,J64:O1241,6,FALSE) -> 0 | J64: 5276 | K64: 稀有沃玛护卫01 | L64: 50 | M64: 10012 | N64: 稀有沃玛护卫01
A65: 6669 | B65: =VLOOKUP(A65,J65:N1242,5,FALSE) -> 边界村老兵02 | C65: =VLOOKUP(A65,J65:O1242,6,FALSE) -> 师徒 | J65: 5277 | K65: 稀有火焰沃玛01 | L65: 50 | M65: 10012 | N65: 稀有火焰沃玛01
A66: 6691 | B66: =VLOOKUP(A66,J66:N1243,5,FALSE) -> 城门守将 | C66: =VLOOKUP(A66,J66:O1243,6,FALSE) -> 卫士头领 | J66: 5278 | K66: 沃玛教主01 | L66: 60 | M66: 10012 | N66: 沃玛教主01
A67: 6692 | B67: =VLOOKUP(A67,J67:N1244,5,FALSE) -> 龙相君 | C67: =VLOOKUP(A67,J67:O1244,6,FALSE) -> 城主 | J67: 3159 | K67: 稀有沃玛护卫1 | L67: 50 | M67: 10012 | N67: 烈焰神卫 炽目
A68: 6693 | B68: =VLOOKUP(A68,J68:N1245,5,FALSE) -> 奇云公 | C68: =VLOOKUP(A68,J68:O1245,6,FALSE) -> 书店 | J68: 3160 | K68: 稀有沃玛护卫2 | L68: 50 | M68: 10012 | N68: 鬼刃焰魔 炎足
A69: 6694 | B69: =VLOOKUP(A69,J69:N1246,5,FALSE) -> 防务官 | C69: =VLOOKUP(A69,J69:O1246,6,FALSE) -> 防务 | J69: 3161 | K69: 稀有沃玛护卫3 | L69: 50 | M69: 10012 | N69: 熔火守护者 沸血
A70: 6695 | B70: =VLOOKUP(A70,J70:N1247,5,FALSE) -> 卫常 | C70: =VLOOKUP(A70,J70:O1247,6,FALSE) -> 马夫 | J70: 3162 | K70: 稀有火焰沃玛1 | L70: 50 | M70: 10012 | N70: 炎角煞星 折锐
A71: 6741 | B71: =VLOOKUP(A71,J71:N1248,5,FALSE) -> 飞虎 | C71: =VLOOKUP(A71,J71:O1248,6,FALSE) -> 护卫 | J71: 3163 | K71: 稀有火焰沃玛2 | L71: 50 | M71: 10012 | N71: 狂野之翼 风吼
... A92: 6820 | B92: =VLOOKUP(A92,J92:N1269,5,FALSE) -> 女战士03 | C92: =VLOOKUP(A92,J92:O1269,6,FALSE) -> 女战士 | J92: 5160 | K92: 人形态石目 | L92: 1 | M92: 0 | N92: 石目09
J93: 5156 | K93: 独角鲸人头目 | L93: 1 | M93: 0 | N93: 独角鲸人头目02
J94: 5159 | K94: 海盗女法师头目 | L94: 1 | M94: 0 | N94: 海盗女法师头目
J95: 5161 | K95: 佣兵男射手头目 | L95: 1 | M95: 0 | N95: 佣兵男射手头目
J96: 5162 | K96: 镰蟹03 | L96: 1 | M96: 0 | N96: 海怪镰蟹03
J97: 5176 | K97: 蜃龙兽（大） | L97: 1 | M97: 0 | N97: 蜃龙
J98: 5177 | K98: 稀有剑盾海盗僵尸 | L98: 1 | M98: 0 | N98: 稀有剑盾海盗僵尸09
J99: 5179 | K99: 人形态石目2 | L99: 1 | M99: 0 | N99: 石目10
...
