Workbook

Sheet item
A1: ID | B1: Name | C1: Type | D1: SubType | E1: RequireLevel | F1: RequireClass | G1: RequireGender | H1: MaxEquip | I1: MaxOwn | J1: Color | K1: BindType | L1: DurType | M1: Dur | N1: Weight | O1: SpellID | P1: SpellLevel | Q1: SelfCoolDown | R1: GroupCoolDown | S1: Price | T1: UsedStatus | U1: CanDecompose | V1: CanDrop | W1: Storage | X1: Script | Y1: DisplayIcon | Z1: Description | AA1: DropMesh | AB1: SoundMaterialType | AC1: SoundActionType | AD1: ClothNoiseType | AE1: ItemLevel | AF1: CanSell | AG1: DisplayLargeIcon | AH1: DisplayLargeIconFemale | AI1: LimitDuration0 | AJ1: LimitCount0 | AK1: LimitDuration1 | AL1: LimitCount1 | AM1: LimitDuration2 | AN1: LimitCount2 | AO1: ServerStart | AP1: Log | AQ1: Stat | AR1: Expensive | AS1: DropBroadcast | AT1: PkDrop | AU1: CanUseInArena | AV1: TeamAuction | AW1: Auction | AX1: AuctionFee | AY1: AuctionFee1 | AZ1: AuctionFee2 | BA1: AuctionFee3 | BB1: AuctionType | BC1: AuctionSubType | BD1: AuctionDefaultPrice | BE1: PlayerDropTime | BF1: DropGroupID | BG1: ShopTypeSell | BH1: TradeNeedIntimacy | BI1: ItemPack | BJ1: ItemPack2 | BK1: ClearGambleCount | BL1: TradeOverWeight | BM1: Resource
A2: Both | B2: Both | C2: Both | D2: Both | E2: Both | F2: Both | G2: Both | H2: Client | I2: Client | J2: Both | K2: Both | L2: Both | M2: Both | N2: Both | O2: Both | P2: Both | Q2: Both | R2: Both | S2: Both | T2: Server | U2: Both | V2: Both | W2: Server | X2: Both | Y2: Client | Z2: Client | AA2: Client | AB2: Client | AC2: Client | AD2: Client | AE2: Both | AF2: Both | AG2: Client | AH2: Client | AI2: Server | AJ2: Server | AK2: Server | AL2: Server | AM2: Server | AN2: Server | AO2: Server | AP2: Server | AQ2: Server | AR2: Both | AS2: Server | AT2: Server | AU2: Server | AV2: Server | AW2: Both | AY2: Both | AZ2: Both | BA2: Both | BB2: Both | BC2: Both | BD2: Both | BE2: Server | BF2: Server | BG2: Both | BH2: Both | BI2: Both | BJ2: Both | BK2: Server | BL2: Server | BM2: Both
A3: -1 | C3: 0 | D3: 0 | E3: 1 | F3: 0 | G3: 0 | H3: 0 | I3: 0 | J3: 0 | K3: 0 | L3: 0 | M3: 0 | N3: 0 | O3: 0 | P3: 0 | Q3: 0 | R3: 0 | S3: 0 | T3: 0 | U3: 0 | V3: 0 | W3: 0 | AE3: 0 | AF3: 0 | AI3: 0 | AJ3: 0 | AK3: 0 | AL3: 0 | AM3: 0 | AN3: 0 | AO3: 0 | AP3: 0 | AQ3: 0 | AR3: 0 | AS3: 0 | AT3: 0 | AU3: 1 | AV3: 0 | AW3: 0 | AY3: 0 | AZ3: 0 | BA3: 0 | BB3: 0 | BC3: 0 | BD3: 0 | BE3: 60 | BF3: 0 | BG3: 0 | BH3: 0 | BK3: 0 | BL3: 0 | BM3: 0
A4: 0 | B4: 未知道具 | C4: ITEMTYPE_MISC | D4: ITEMSUBTYPE_MISC_DEFAULT | E4: 1 | F4: clsWarrior,clsMage,clsRogue,clsArcher,clsTaoist | G4: 0 | H4: 0 | I4: 0 | J4: 0 | K4: 0 | L4: DURTYPE_STACK | M4: 0 | P4: 0 | Q4: 0 | S4: 1 | T4: 0 | V4: 0 | W4: 0 | Y4: Texture2D MMO_ItemIcon_Supplies.img_BindMoney | AA4: StaticMesh Money.Copper_3 | AB4: 0 | AC4: 7 | AD4: 0 | AE4: 0 | AF4: 0 | AI4: 0 | AJ4: 0 | AK4: 0 | AL4: 0 | AM4: 0 | AN4: 0 | AP4: 0 | AR4: 0 | AS4: 0 | BE4: 240 | BL4: 0
A5: 1 | B5: 金币 | C5: ITEMTYPE_MISC | D5: ITEMSUBTYPE_MISC_DEFAULT | E5: 1 | F5: clsWarrior,clsMage,clsRogue,clsArcher,clsTaoist | G5: 0 | H5: 0 | I5: 0 | J5: 0 | K5: 0 | L5: DURTYPE_STACK | M5: 0 | P5: 0 | Q5: 0 | S5: 1 | T5: 0 | V5: 0 | W5: 0 | Y5: Texture2D MMO_ItemIcon_Supplies.img_Money | AA5: StaticMesh Money.Dro_Gold_4 | AB5: 0 | AC5: 7 | AD5: 0 | AE5: 0 | AF5: 0 | AI5: 0 | AJ5: 0 | AK5: 0 | AL5: 0 | AM5: 0 | AN5: 0 | AP5: 0 | AR5: 0 | AS5: 0 | AY5: 1 | BE5: 240 | BL5: 0
A6: 10 | B6: 经验 | C6: ITEMTYPE_MISC | D6: ITEMSUBTYPE_MISC_DEFAULT | E6: 1 | F6: clsWarrior,clsMage,clsRogue,clsArcher,clsTaoist | G6: 0 | H6: 0 | I6: 0 | J6: 0 | K6: 0 | L6: DURTYPE_STACK | M6: 0 | P6: 0 | Q6: 0 | S6: 1 | T6: 0 | V6: 0 | W6: 0 | Y6: Texture2D MMO_ItemIcon_Supplies.item_144 | AA6: StaticMesh Money.Dro_Gold_4 | AB6: 0 | AC6: 7 | AD6: 0 | AE6: 0 | AF6: 0 | AI6: 0 | AJ6: 0 | AK6: 0 | AL6: 0 | AM6: 0 | AN6: 0 | AP6: 0 | AR6: 0 | AS6: 0 | BE6: 240 | BL6: 0
A7: 15 | B7: 擂台积分 | C7: ITEMTYPE_MISC | D7: ITEMSUBTYPE_MISC_DEFAULT | E7: 1 | F7: clsWarrior,clsMage,clsRogue,clsArcher,clsTaoist | G7: 0 | H7: 0 | I7: 0 | J7: 0 | K7: 0 | L7: DURTYPE_STACK | M7: 0 | P7: 0 | Q7: 0 | S7: 1 | T7: 0 | V7: 0 | W7: 0 | Y7: Texture2D MMO_ItemIcon_Supplies.Item_190 | AA7: StaticMesh Money.Dro_Gold_4 | AB7: 0 | AC7: 7 | AD7: 0 | AE7: 0 | AF7: 0 | AI7: 0 | AJ7: 0 | AK7: 0 | AL7: 0 | AM7: 0 | AN7: 0 | AP7: 0 | AR7: 0 | AS7: 0 | BE7: 240 | BL7: 0
A8: 16 | B8: 声威值 | C8: ITEMTYPE_MISC | D8: ITEMSUBTYPE_MISC_DEFAULT | E8: 1 | F8: clsWarrior,clsMage,clsRogue,clsArcher,clsTaoist | G8: 0 | H8: 0 | I8: 0 | J8: 0 | K8: 0 | L8: DURTYPE_STACK | M8: 0 | P8: 0 | Q8: 0 | S8: 1 | T8: 0 | V8: 0 | W8: 0 | Y8: Texture2D MMO_ItemIcon_Supplies.Item_191 | AA8: StaticMesh Money.Dro_Gold_4 | AB8: 0 | AC8: 7 | AD8: 0 | AE8: 0 | AF8: 0 | AI8: 0 | AJ8: 0 | AK8: 0 | AL8: 0 | AM8: 0 | AN8: 0 | AP8: 0 | AR8: 0 | AS8: 0 | BE8: 240 | BL8: 0
A9: 20 | B9: 公会贡献 | C9: ITEMTYPE_MISC | D9: ITEMSUBTYPE_MISC_DEFAULT | E9: 1 | F9: clsWarrior,clsMage,clsRogue,clsArcher,clsTaoist | G9: 0 | H9: 0 | I9: 0 | J9: 0 | K9: 0 | L9: DURTYPE_STACK | M9: 0 | P9: 0 | Q9: 0 | S9: 1 | T9: 0 | V9: 0 | W9: 0 | Y9: Texture2D MMO_ItemIcon_Supplies.gonghuigongxian | AA9: StaticMesh Money.Dro_Gold_4 | AB9: 0 | AC9: 7 | AD9: 0 | AE9: 0 | AF9: 0 | AI9: 0 | AJ9: 0 | AK9: 0 | AL9: 0 | AM9: 0 | AN9: 0 | AP9: 0 | AR9: 0 | AS9: 0 | BE9: 240 | BL9: 0
A10: 301 | B10: 金创药(小量) | C10: ITEMTYPE_USABLE | D10: ITEMSUBTYPE_USABLE_POTION | E10: 1 | F10: clsWarrior,clsMage,clsRogue,clsArcher,clsTaoist | G10: 0 | H10: 0 | I10: 99999 | J10: 0 | K10: 0 | L10: DURTYPE_STACK | M10: 1 | N10: 1 | O10: 4562 | P10: 0 | Q10: 0 | S10: 40 | T10: 0 | V10: 1 | W10: 1 | Y10: Texture2D MMO_ItemIcon_Supplies.medicament.jcy1 | Z10: 恢复20点体力值。 | AA10: StaticMesh Bottle.Dro_Posin_Gold_1 | AB10: 0 | AC10: 15 | AD10: 0 | AE10: 0 | AF10: 1 | AI10: 0 | AJ10: 0 | AK10: 0 | AL10: 0 | AM10: 0 | AN10: 0 | AP10: 0 | AR10: 0 | AS10: 0 | BE10: 240 | BG10: 1 | BI10: 361 | BL10: 1
A11: 302 | B11: 金创药(中量) | C11: ITEMTYPE_USABLE | D11: ITEMSUBTYPE_USABLE_POTION | E11: 1 | F11: clsWarrior,clsMage,clsRogue,clsArcher,clsTaoist | G11: 0 | H11: 0 | I11: 99999 | J11: 0 | K11: 0 | L11: DURTYPE_STACK | M11: 1 | N11: 2 | O11: 4563 | P11: 0 | Q11: 0 | S11: 130 | T11: 0 | V11: 1 | W11: 1 | Y11: Texture2D MMO_ItemIcon_Supplies.medicament.jcy2 | Z11: 恢复50点体力值。 | AA11: StaticMesh Bottle.Dro_Posin_Gold_1 | AB11: 0 | AC11: 15 | AD11: 0 | AE11: 0 | AF11: 1 | AI11: 0 | AJ11: 0 | AK11: 0 | AL11: 0 | AM11: 0 | AN11: 0 | AP11: 0 | AQ11: 1 | AR11: 0 | AS11: 0 | BE11: 240 | BG11: 1 | BI11: 362 | BL11: 1
A12: 303 | B12: 强效金创药 | C12: ITEMTYPE_USABLE | D12: ITEMSUBTYPE_USABLE_POTION | E12: 1 | F12: clsWarrior,clsMage,clsRogue,clsArcher,clsTaoist | G12: 0 | H12: 0 | I12: 99999 | J12: 0 | K12: 0 | L12: DURTYPE_STACK | M12: 1 | N12: 3 | O12: 4564 | P12: 0 | Q12: 0 | S12: 350 | T12: 0 | V12: 1 | W12: 1 | Y12: Texture2D MMO_ItemIcon_Supplies.medicament.jcy3 | Z12: 恢复90点体力值。 | AA12: StaticMesh lsy.Dro_lsy01 | AB12: 0 | AC12: 15 | AD12: 0 | AE12: 0 | AF12: 1 | AI12: 0 | AJ12: 0 | AK12: 0 | AL12: 0 | AM12: 0 | AN12: 0 | AP12: 0 | AQ12: 1 | AR12: 0 | AS12: 0 | BE12: 240 | BG12: 1 | BI12: 363 | BL12: 1
A13: 304 | B13: 超强金创药（占位） | C13: ITEMTYPE_USABLE | D13: ITEMSUBTYPE_USABLE_POTION | E13: 1 | F13: clsWarrior,clsMage,clsRogue,clsArcher,clsTaoist | G13: 0 | H13: 0 | I13: 99999 | J13: 0 | K13: 0 | L13: DURTYPE_STACK | M13: 1 | N13: 1 | P13: 0 | Q13: 0 | S13: 1 | T13: 0 | V13: 1 | W13: 1 | Y13: Texture2D MMO_ItemIcon_Supplies.medicament.jcy4 | Z13: 恢复91点体力值。 | AA13: StaticMesh Bottle.Dro_Posin_Gold_1 | AB13: 0 | AC13: 15 | AD13: 0 | AE13: 0 | AF13: 1 | AI13: 0 | AJ13: 0 | AK13: 0 | AL13: 0 | AM13: 0 | AN13: 0 | AP13: 0 | AR13: 0 | AS13: 0 | BE13: 240 | BG13: 1 | BL13: 1
A14: 305 | B14: 金创药（占位） | C14: ITEMTYPE_USABLE | D14: ITEMSUBTYPE_USABLE_POTION | E14: 1 | F14: clsWarrior,clsMage,clsRogue,clsArcher,clsTaoist | G14: 0 | H14: 0 | I14: 99999 | J14: 0 | K14: 0 | L14: DURTYPE_STACK | M14: 1 | N14: 1 | P14: 0 | Q14: 0 | S14: 1 | T14: 0 | V14: 1 | W14: 1 | Y14: Texture2D MMO_ItemIcon_Supplies.medicament.jcy5 | Z14: 恢复92点体力值。 | AA14: StaticMesh Bottle.Dro_Posin_Gold_1 | AB14: 0 | AC14: 15 | AD14: 0 | AE14: 0 | AF14: 1 | AI14: 0 | AJ14: 0 | AK14: 0 | AL14: 0 | AM14: 0 | AN14: 0 | AP14: 0 | AR14: 0 | AS14: 0 | BE14: 240 | BG14: 1 | BL14: 1
A15: 306 | B15: 金创药(小量)1 | C15: ITEMTYPE_USABLE | D15: ITEMSUBTYPE_USABLE_POTION | E15: 1 | F15: clsWarrior,clsMage,clsRogue,clsArcher,clsTaoist | G15: 0 | H15: 0 | I15: 99999 | J15: 0 | K15: 3 | L15: DURTYPE_STACK | M15: 1 | N15: 1 | O15: 4562 | P15: 0 | Q15: 0 | S15: 40 | T15: 0 | V15: 1 | W15: 1 | Y15: Texture2D MMO_ItemIcon_Supplies.medicament.jcy1 | Z15: 恢复20点体力值。 | AA15: StaticMesh Bottle.Dro_Posin_Gold_1 | AB15: 0 | AC15: 15 | AD15: 0 | AE15: 0 | AF15: 1 | AI15: 0 | AJ15: 0 | AK15: 0 | AL15: 0 | AM15: 0 | AN15: 0 | AP15: 0 | AR15: 0 | AS15: 0 | BE15: 240 | BG15: 1 | BI15: 366 | BL15: 1
A16: 307 | B16: 金创药(中量)1 | C16: ITEMTYPE_USABLE | D16: ITEMSUBTYPE_USABLE_POTION | E16: 1 | F16: clsWarrior,clsMage,clsRogue,clsArcher,clsTaoist | G16: 0 | H16: 0 | I16: 99999 | J16: 0 | K16: 3 | L16: DURTYPE_STACK | M16: 1 | N16: 2 | O16: 4563 | P16: 0 | Q16: 0 | S16: 130 | T16: 0 | V16: 1 | W16: 1 | Y16: Texture2D MMO_ItemIcon_Supplies.medicament.jcy2 | Z16: 恢复50点体力值。 | AA16: StaticMesh Bottle.Dro_Posin_Gold_1 | AB16: 0 | AC16: 15 | AD16: 0 | AE16: 0 | AF16: 1 | AI16: 0 | AJ16: 0 | AK16: 0 | AL16: 0 | AM16: 0 | AN16: 0 | AP16: 0 | AQ16: 1 | AR16: 0 | AS16: 0 | BE16: 240 | BG16: 1 | BI16: 367 | BL16: 1
A17: 308 | B17: 强效金创药1 | C17: ITEMTYPE_USABLE | D17: ITEMSUBTYPE_USABLE_POTION | E17: 1 | F17: clsWarrior,clsMage,clsRogue,clsArcher,clsTaoist | G17: 0 | H17: 0 | I17: 99999 | J17: 0 | K17: 3 | L17: DURTYPE_STACK | M17: 1 | N17: 3 | O17: 4564 | P17: 0 | Q17: 0 | S17: 350 | T17: 0 | V17: 1 | W17: 1 | Y17: Texture2D MMO_ItemIcon_Supplies.medicament.jcy3 | Z17: 恢复90点体力值。 | AA17: StaticMesh lsy.Dro_lsy01 | AB17: 0 | AC17: 15 | AD17: 0 | AE17: 0 | AF17: 1 | AI17: 0 | AJ17: 0 | AK17: 0 | AL17: 0 | AM17: 0 | AN17: 0 | AP17: 0 | AQ17: 1 | AR17: 0 | AS17: 0 | BE17: 240 | BG17: 1 | BI17: 368 | BL17: 1
A18: 311 | B18: 小金创药(绑定) | C18: ITEMTYPE_USABLE | D18: ITEMSUBTYPE_USABLE_POTION | E18: 1 | F18: clsWarrior,clsMage,clsRogue,clsArcher,clsTaoist | G18: 0 | H18: 0 | I18: 99999 | J18: 0 | K18: 3 | L18: DURTYPE_STACK | M18: 1 | N18: 1 | O18: 4562 | P18: 0 | Q18: 0 | S18: 1 | T18: 0 | V18: 1 | W18: 1 | Y18: Texture2D MMO_ItemIcon_Supplies.medicament.jcy1 | Z18: 恢复20点体力值 。 | AA18: StaticMesh Bottle.Dro_Posin_Gold_1 | AB18: 0 | AC18: 15 | AD18: 0 | AE18: 0 | AF18: 0 | AI18: 0 | AJ18: 0 | AK18: 0 | AL18: 0 | AM18: 0 | AN18: 0 | AP18: 0 | AR18: 0 | AS18: 0 | AT18: 1 | BE18: 240 | BG18: 1 | BL18: 1
A19: 312 | B19: 中金创药(绑定) | C19: ITEMTYPE_USABLE | D19: ITEMSUBTYPE_USABLE_POTION | E19: 1 | F19: clsWarrior,clsMage,clsRogue,clsArcher,clsTaoist | G19: 0 | H19: 0 | I19: 99999 | J19: 0 | K19: 3 | L19: DURTYPE_STACK | M19: 1 | N19: 2 | O19: 4563 | P19: 0 | Q19: 0 | S19: 1 | T19: 0 | V19: 1 | W19: 1 | Y19: Texture2D MMO_ItemIcon_Supplies.medicament.jcy2 | Z19: 恢复50点体力值。 | AA19: StaticMesh Bottle.Dro_Posin_Gold_1 | AB19: 0 | AC19: 15 | AD19: 0 | AE19: 0 | AF19: 0 | AI19: 0 | AJ19: 0 | AK19: 0 | AL19: 0 | AM19: 0 | AN19: 0 | AP19: 0 | AR19: 0 | AS19: 0 | AT19: 1 | BE19: 240 | BG19: 1 | BL19: 1
A20: 321 | B20: 魔法药(小量) | C20: ITEMTYPE_USABLE | D20: ITEMSUBTYPE_USABLE_POTION | E20: 1 | F20: clsWarrior,clsMage,clsRogue,clsArcher,clsTaoist | G20: 0 | H20: 0 | I20: 99999 | J20: 0 | K20: 0 | L20: DURTYPE_STACK | M20: 1 | N20: 1 | O20: 4565 | P20: 0 | Q20: 0 | S20: 40 | T20: 0 | V20: 1 | W20: 1 | Y20: Texture2D MMO_ItemIcon_Supplies.medicament.mfy1 | Z20: 恢复30点魔法值。 | AA20: StaticMesh Bottle.Dro_Posin_Magic_1 | AB20: 0 | AC20: 15 | AD20: 0 | AE20: 0 | AF20: 1 | AI20: 0 | AJ20: 0 | AK20: 0 | AL20: 0 | AM20: 0 | AN20: 0 | AP20: 0 | AR20: 0 | AS20: 0 | BE20: 240 | BG20: 1 | BI20: 371 | BL20: 1
A21: 322 | B21: 魔法药(中量) | C21: ITEMTYPE_USABLE | D21: ITEMSUBTYPE_USABLE_POTION | E21: 1 | F21: clsWarrior,clsMage,clsRogue,clsArcher,clsTaoist | G21: 0 | H21: 0 | I21: 99999 | J21: 0 | K21: 0 | L21: DURTYPE_STACK | M21: 1 | N21: 2 | O21: 4566 | P21: 0 | Q21: 0 | S21: 130 | T21: 0 | V21: 1 | W21: 1 | Y21: Texture2D MMO_ItemIcon_Supplies.medicament.mfy2 | Z21: 恢复80点魔法值。 | AA21: StaticMesh Bottle.Dro_Posin_Magic_1 | AB21: 0 | AC21: 15 | AD21: 0 | AE21: 0 | AF21: 1 | AI21: 0 | AJ21: 0 | AK21: 0 | AL21: 0 | AM21: 0 | AN21: 0 | AP21: 0 | AQ21: 1 | AR21: 0 | AS21: 0 | BE21: 240 | BG21: 1 | BI21: 372 | BL21: 1
A22: 323 | B22: 强效魔法药 | C22: ITEMTYPE_USABLE | D22: ITEMSUBTYPE_USABLE_POTION | E22: 1 | F22: clsWarrior,clsMage,clsRogue,clsArcher,clsTaoist | G22: 0 | H22: 0 | I22: 99999 | J22: 0 | K22: 0 | L22: DURTYPE_STACK | M22: 1 | N22: 3 | O22: 4567 | P22: 0 | Q22: 0 | S22: 350 | T22: 0 | V22: 1 | W22: 1 | Y22: Texture2D MMO_ItemIcon_Supplies.medicament.mfy3 | Z22: 恢复150点魔法值。 | AA22: StaticMesh Bottle.Dro_Posin_Magic_1 | AB22: 0 | AC22: 15 | AD22: 0 | AE22: 0 | AF22: 1 | AI22: 0 | AJ22: 0 | AK22: 0 | AL22: 0 | AM22: 0 | AN22: 0 | AP22: 0 | AQ22: 1 | AR22: 0 | AS22: 0 | BE22: 240 | BG22: 1 | BI22: 373 | BL22: 1
A23: 326 | B23: 魔法药(小量)1 | C23: ITEMTYPE_USABLE | D23: ITEMSUBTYPE_USABLE_POTION | E23: 1 | F23: clsWarrior,clsMage,clsRogue,clsArcher,clsTaoist | G23: 0 | H23: 0 | I23: 99999 | J23: 0 | K23: 3 | L23: DURTYPE_STACK | M23: 1 | N23: 1 | O23: 4565 | P23: 0 | Q23: 0 | S23: 40 | T23: 0 | V23: 1 | W23: 1 | Y23: Texture2D MMO_ItemIcon_Supplies.medicament.mfy1 | Z23: 恢复30点魔法值。 | AA23: StaticMesh Bottle.Dro_Posin_Magic_1 | AB23: 0 | AC23: 15 | AD23: 0 | AE23: 0 | AF23: 1 | AI23: 0 | AJ23: 0 | AK23: 0 | AL23: 0 | AM23: 0 | AN23: 0 | AP23: 0 | AR23: 0 | AS23: 0 | BE23: 240 | BG23: 1 | BI23: 376 | BL23: 1
A24: 327 | B24: 魔法药(中量)1 | C24: ITEMTYPE_USABLE | D24: ITEMSUBTYPE_USABLE_POTION | E24: 1 | F24: clsWarrior,clsMage,clsRogue,clsArcher,clsTaoist | G24: 0 | H24: 0 | I24: 99999 | J24: 0 | K24: 3 | L24: DURTYPE_STACK | M24: 1 | N24: 2 | O24: 4566 | P24: 0 | Q24: 0 | S24: 130 | T24: 0 | V24: 1 | W24: 1 | Y24: Texture2D MMO_ItemIcon_Supplies.medicament.mfy2 | Z24: 恢复80点魔法值。 | AA24: StaticMesh Bottle.Dro_Posin_Magic_1 | AB24: 0 | AC24: 15 | AD24: 0 | AE24: 0 | AF24: 1 | AI24: 0 | AJ24: 0 | AK24: 0 | AL24: 0 | AM24: 0 | AN24: 0 | AP24: 0 | AQ24: 1 | AR24: 0 | AS24: 0 | BE24: 240 | BG24: 1 | BI24: 377 | BL24: 1
A25: 328 | B25: 强效魔法药1 | C25: ITEMTYPE_USABLE | D25: ITEMSUBTYPE_USABLE_POTION | E25: 1 | F25: clsWarrior,clsMage,clsRogue,clsArcher,clsTaoist | G25: 0 | H25: 0 | I25: 99999 | J25: 0 | K25: 3 | L25: DURTYPE_STACK | M25: 1 | N25: 3 | O25: 4567 | P25: 0 | Q25: 0 | S25: 350 | T25: 0 | V25: 1 | W25: 1 | Y25: Texture2D MMO_ItemIcon_Supplies.medicament.mfy3 | Z25: 恢复150点魔法值。 | AA25: StaticMesh Bottle.Dro_Posin_Magic_1 | AB25: 0 | AC25: 15 | AD25: 0 | AE25: 0 | AF25: 1 | AI25: 0 | AJ25: 0 | AK25: 0 | AL25: 0 | AM25: 0 | AN25: 0 | AP25: 0 | AQ25: 1 | AR25: 0 | AS25: 0 | BE25: 240 | BG25: 1 | BI25: 378 | BL25: 1
A26: 324 | B26: 超强魔法药(占位） | C26: ITEMTYPE_USABLE | D26: ITEMSUBTYPE_USABLE_POTION | E26: 1 | F26: clsWarrior,clsMage,clsRogue,clsArcher,clsTaoist | G26: 0 | H26: 0 | I26: 99999 | J26: 0 | K26: 0 | L26: DURTYPE_STACK | M26: 1 | N26: 1 | P26: 0 | Q26: 0 | S26: 1 | T26: 0 | V26: 1 | W26: 1 | Y26: Texture2D MMO_ItemIcon_Supplies.medicament.mfy4 | Z26: 恢复152点魔法值。 | AA26: StaticMesh Bottle.Dro_Posin_GMagic_1 | AB26: 0 | AC26: 15 | AD26: 0 | AE26: 0 | AF26: 1 | AI26: 0 | AJ26: 0 | AK26: 0 | AL26: 0 | AM26: 0 | AN26: 0 | AP26: 0 | AR26: 0 | AS26: 0 | BE26: 240 | BG26: 1 | BL26: 1
A27: 331 | B27: 新手药水(绑定) | C27: ITEMTYPE_USABLE | D27: ITEMSUBTYPE_USABLE_POTION | E27: 1 | F27: clsWarrior,clsMage,clsRogue,clsArcher,clsTaoist | G27: 0 | H27: 0 | I27: 99999 | J27: 0 | K27: 3 | L27: DURTYPE_STACK | M27: 1 | N27: 1 | O27: 4562 | P27: 0 | Q27: 0 | S27: 1 | T27: 0 | V27: 1 | W27: 1 | Y27: Texture2D MMO_ItemIcon_Supplies.Item_68 | Z27: 恢复20点体力值。 | AA27: StaticMesh Bottle.Dro_Posin_Gold_1 | AB27: 0 | AC27: 15 | AD27: 0 | AE27: 0 | AF27: 0 | AI27: 0 | AJ27: 0 | AK27: 0 | AL27: 0 | AM27: 0 | AN27: 0 | AP27: 0 | AR27: 0 | AS27: 0 | AT27: 1 | BE27: 240 | BG27: 1 | BL27: 1
A28: 351 | B28: 太阳水 | C28: ITEMTYPE_USABLE | D28: ITEMSUBTYPE_USABLE_POTION | E28: 1 | F28: clsWarrior,clsMage,clsRogue,clsArcher,clsTaoist | G28: 0 | H28: 0 | I28: 99999 | J28: 0 | K28: 0 | L28: DURTYPE_STACK | M28: 1 | N28: 1 | O28: 4560 | P28: 0 | Q28: 0 | S28: 500 | T28: 0 | V28: 1 | W28: 1 | Y28: Texture2D MMO_ItemIcon_Supplies.medicament.tys1 | Z28: 立刻恢复30点体力，40点魔法。 | AA28: StaticMesh Bottle.Dro_Posin_Sun_1 | AB28: 0 | AC28: 15 | AD28: 0 | AE28: 0 | AF28: 1 | AI28: 0 | AJ28: 0 | AK28: 0 | AL28: 0 | AM28: 0 | AN28: 0 | AP28: 0 | AQ28: 1 | AR28: 0 | AS28: 0 | BE28: 240 | BG28: 1 | BI28: 381 | BL28: 1
A29: 352 | B29: 强效太阳水 | C29: ITEMTYPE_USABLE | D29: ITEMSUBTYPE_USABLE_POTION | E29: 1 | F29: clsWarrior,clsMage,clsRogue,clsArcher,clsTaoist | G29: 0 | H29: 0 | I29: 99999 | J29: 0 | K29: 0 | L29: DURTYPE_STACK | M29: 1 | N29: 2 | O29: 4561 | P29: 0 | Q29: 0 | S29: 1250 | T29: 0 | V29: 1 | W29: 1 | Y29: Texture2D MMO_ItemIcon_Supplies.medicament.tys2 | Z29: 立刻恢复50点体力，80点魔法。 | AA29: StaticMesh Bottle.Dro_Posin_Sun_1 | AB29: 0 | AC29: 15 | AD29: 0 | AE29: 0 | AF29: 1 | AI29: 0 | AJ29: 0 | AK29: 0 | AL29: 0 | AM29: 0 | AN29: 0 | AP29: 0 | AQ29: 1 | AR29: 0 | AS29: 0 | BE29: 240 | BG29: 1 | BI29: 382 | BL29: 1
A30: 353 | B30: 疗伤药 | C30: ITEMTYPE_USABLE | D30: ITEMSUBTYPE_USABLE_POTION | E30: 1 | F30: clsWarrior,clsMage,clsRogue,clsArcher,clsTaoist | G30: 0 | H30: 0 | I30: 99999 | J30: 0 | K30: 0 | L30: DURTYPE_STACK | M30: 1 | N30: 1 | O30: 4568 | P30: 0 | Q30: 0 | S30: 2500 | T30: 0 | V30: 1 | W30: 1 | Y30: Texture2D MMO_ItemIcon_Supplies.medicament.lsy | Z30: 立刻恢复100点体力，160点魔法。 | AA30: StaticMesh lsy.Dro_lsy01 | AB30: 0 | AC30: 15 | AD30: 0 | AE30: 0 | AF30: 1 | AI30: 0 | AJ30: 0 | AK30: 0 | AL30: 0 | AM30: 0 | AN30: 0 | AP30: 1 | AQ30: 1 | AR30: 0 | AS30: 0 | BE30: 240 | BG30: 1 | BI30: 383 | BL30: 1
A31: 354 | B31: 万年雪霜 | C31: ITEMTYPE_USABLE | D31: ITEMSUBTYPE_USABLE_POTION | E31: 1 | F31: clsWarrior,clsMage,clsRogue,clsArcher,clsTaoist | G31: 0 | H31: 0 | I31: 99999 | J31: 0 | K31: 0 | L31: DURTYPE_STACK | M31: 1 | N31: 1 | O31: 4576 | P31: 0 | Q31: 0 | S31: 2000 | T31: 0 | V31: 1 | W31: 1 | Y31: Texture2D MMO_ItemIcon_Supplies.medicament.wnxs | Z31: 立刻恢复100点体力，100点魔法。 | AA31: StaticMesh ginseng.Dro_ginseng | AB31: 0 | AC31: 15 | AD31: 0 | AE31: 0 | AF31: 1 | AI31: 0 | AJ31: 0 | AK31: 0 | AL31: 0 | AM31: 0 | AN31: 0 | AP31: 1 | AQ31: 1 | AR31: 0 | AS31: 0 | BE31: 240 | BG31: 1 | BI31: 384 | BL31: 1
A32: 356 | B32: 太阳水1 | C32: ITEMTYPE_USABLE | D32: ITEMSUBTYPE_USABLE_POTION | E32: 1 | F32: clsWarrior,clsMage,clsRogue,clsArcher,clsTaoist | G32: 0 | H32: 0 | I32: 99999 | J32: 0 | K32: 3 | L32: DURTYPE_STACK | M32: 1 | N32: 1 | O32: 4560 | P32: 0 | Q32: 0 | S32: 500 | T32: 0 | V32: 1 | W32: 1 | Y32: Texture2D MMO_ItemIcon_Supplies.medicament.tys1 | Z32: 立刻恢复30点体力，40点魔法。 | AA32: StaticMesh Bottle.Dro_Posin_Sun_1 | AB32: 0 | AC32: 15 | AD32: 0 | AE32: 0 | AF32: 1 | AI32: 0 | AJ32: 0 | AK32: 0 | AL32: 0 | AM32: 0 | AN32: 0 | AP32: 0 | AQ32: 1 | AR32: 0 | AS32: 0 | BE32: 240 | BG32: 1 | BI32: 386 | BL32: 1
A33: 357 | B33: 强效太阳水1 | C33: ITEMTYPE_USABLE | D33: ITEMSUBTYPE_USABLE_POTION | E33: 1 | F33: clsWarrior,clsMage,clsRogue,clsArcher,clsTaoist | G33: 0 | H33: 0 | I33: 99999 | J33: 0 | K33: 3 | L33: DURTYPE_STACK | M33: 1 | N33: 2 | O33: 4561 | P33: 0 | Q33: 0 | S33: 1250 | T33: 0 | V33: 1 | W33: 1 | Y33: Texture2D MMO_ItemIcon_Supplies.medicament.tys2 | Z33: 立刻恢复50点体力，80点魔法。 | AA33: StaticMesh Bottle.Dro_Posin_Sun_1 | AB33: 0 | AC33: 15 | AD33: 0 | AE33: 0 | AF33: 1 | AI33: 0 | AJ33: 0 | AK33: 0 | AL33: 0 | AM33: 0 | AN33: 0 | AP33: 0 | AQ33: 1 | AR33: 0 | AS33: 0 | BE33: 240 | BG33: 1 | BI33: 387 | BL33: 1
A34: 358 | B34: 疗伤药1 | C34: ITEMTYPE_USABLE | D34: ITEMSUBTYPE_USABLE_POTION | E34: 1 | F34: clsWarrior,clsMage,clsRogue,clsArcher,clsTaoist | G34: 0 | H34: 0 | I34: 99999 | J34: 0 | K34: 3 | L34: DURTYPE_STACK | M34: 1 | N34: 1 | O34: 4568 | P34: 0 | Q34: 0 | S34: 2500 | T34: 0 | V34: 1 | W34: 1 | Y34: Texture2D MMO_ItemIcon_Supplies.medicament.lsy | Z34: 立刻恢复100点体力，160点魔法。 | AA34: StaticMesh lsy.Dro_lsy01 | AB34: 0 | AC34: 15 | AD34: 0 | AE34: 0 | AF34: 1 | AI34: 0 | AJ34: 0 | AK34: 0 | AL34: 0 | AM34: 0 | AN34: 0 | AP34: 1 | AQ34: 1 | AR34: 0 | AS34: 0 | BE34: 240 | BG34: 1 | BI34: 388 | BL34: 1
A35: 359 | B35: 万年雪霜1 | C35: ITEMTYPE_USABLE | D35: ITEMSUBTYPE_USABLE_POTION | E35: 1 | F35: clsWarrior,clsMage,clsRogue,clsArcher,clsTaoist | G35: 0 | H35: 0 | I35: 99999 | J35: 0 | K35: 3 | L35: DURTYPE_STACK | M35: 1 | N35: 1 | O35: 4576 | P35: 0 | Q35: 0 | S35: 2000 | T35: 0 | V35: 1 | W35: 1 | Y35: Texture2D MMO_ItemIcon_Supplies.medicament.wnxs | Z35: 立刻恢复100点体力，100点魔法。 | AA35: StaticMesh ginseng.Dro_ginseng | AB35: 0 | AC35: 15 | AD35: 0 | AE35: 0 | AF35: 1 | AI35: 0 | AJ35: 0 | AK35: 0 | AL35: 0 | AM35: 0 | AN35: 0 | AP35: 1 | AQ35: 1 | AR35: 0 | AS35: 0 | BE35: 240 | BG35: 1 | BI35: 389 | BL35: 1
A36: 361 | B36: 金创药(小)包 | C36: ITEMTYPE_USABLE | D36: ITEMSUBTYPE_USABLE_MISC | E36: 1 | F36: clsWarrior,clsMage,clsRogue,clsArcher,clsTaoist | G36: 0 | H36: 0 | I36: 99999 | J36: 0 | K36: 0 | L36: DURTYPE_STACK | M36: 1 | N36: 7 | P36: 0 | Q36: 0 | S36: 240 | T36: 0 | V36: 1 | W36: 1 | X36: jcybao1 | Y36: Texture2D MMO_ItemIcon_Supplies.medicament.jcy11 | Z36: 解开成为6个金创药(小量)。 | AA36: StaticMesh Bottle.Dro_Posin_03_all | AB36: 0 | AC36: 15 | AD36: 0 | AE36: 0 | AF36: 1 | AI36: 0 | AJ36: 0 | AK36: 0 | AL36: 0 | AM36: 0 | AN36: 0 | AP36: 0 | AR36: 0 | AS36: 0 | BE36: 240 | BG36: 1 | BL36: 1
A37: 362 | B37: 金创药(中)包 | C37: ITEMTYPE_USABLE | D37: ITEMSUBTYPE_USABLE_MISC | E37: 1 | F37: clsWarrior,clsMage,clsRogue,clsArcher,clsTaoist | G37: 0 | H37: 0 | I37: 99999 | J37: 0 | K37: 0 | L37: DURTYPE_STACK | M37: 1 | N37: 14 | P37: 0 | Q37: 0 | S37: 780 | T37: 0 | V37: 1 | W37: 1 | X37: jcybao2 | Y37: Texture2D MMO_ItemIcon_Supplies.medicament.jcy21 | Z37: 解开成为6个金创药(中量)。 | AA37: StaticMesh Bottle.Dro_Posin_03_all | AB37: 0 | AC37: 15 | AD37: 0 | AE37: 0 | AF37: 1 | AI37: 0 | AJ37: 0 | AK37: 0 | AL37: 0 | AM37: 0 | AN37: 0 | AP37: 0 | AQ37: 1 | AR37: 0 | AS37: 0 | BE37: 240 | BG37: 1 | BL37: 1
A38: 363 | B38: 超级金创药 | C38: ITEMTYPE_USABLE | D38: ITEMSUBTYPE_USABLE_MISC | E38: 1 | F38: clsWarrior,clsMage,clsRogue,clsArcher,clsTaoist | G38: 0 | H38: 0 | I38: 99999 | J38: 0 | K38: 0 | L38: DURTYPE_STACK | M38: 1 | N38: 21 | P38: 0 | Q38: 0 | S38: 2100 | T38: 0 | V38: 1 | W38: 1 | X38: jcybao3 | Y38: Texture2D MMO_ItemIcon_Supplies.medicament.jcy31 | Z38: 解开成为6个强效金创药。 | AA38: StaticMesh lsy.Dro_lsy02 | AB38: 0 | AC38: 15 | AD38: 0 | AE38: 0 | AF38: 1 | AI38: 0 | AJ38: 0 | AK38: 0 | AL38: 0 | AM38: 0 | AN38: 0 | AP38: 0 | AQ38: 1 | AR38: 0 | AS38: 0 | BE38: 240 | BG38: 1 | BL38: 1
A39: 366 | B39: 金创药(小)包1 | C39: ITEMTYPE_USABLE | D39: ITEMSUBTYPE_USABLE_MISC | E39: 1 | F39: clsWarrior,clsMage,clsRogue,clsArcher,clsTaoist | G39: 0 | H39: 0 | I39: 99999 | J39: 0 | K39: 0 | L39: DURTYPE_STACK | M39: 1 | N39: 7 | P39: 0 | Q39: 0 | S39: 240 | T39: 0 | V39: 1 | W39: 1 | X39: jcybao6 | Y39: Texture2D MMO_ItemIcon_Supplies.medicament.jcy11 | Z39: 解开成为6个金创药(小量)。 | AA39: StaticMesh Bottle.Dro_Posin_03_all | AB39: 0 | AC39: 15 | AD39: 0 | AE39: 0 | AF39: 1 | AI39: 0 | AJ39: 0 | AK39: 0 | AL39: 0 | AM39: 0 | AN39: 0 | AP39: 0 | AR39: 0 | AS39: 0 | BE39: 240 | BG39: 1 | BL39: 1
A40: 367 | B40: 金创药(中)包1 | C40: ITEMTYPE_USABLE | D40: ITEMSUBTYPE_USABLE_MISC | E40: 1 | F40: clsWarrior,clsMage,clsRogue,clsArcher,clsTaoist | G40: 0 | H40: 0 | I40: 99999 | J40: 0 | K40: 0 | L40: DURTYPE_STACK | M40: 1 | N40: 14 | P40: 0 | Q40: 0 | S40: 780 | T40: 0 | V40: 1 | W40: 1 | X40: jcybao7 | Y40: Texture2D MMO_ItemIcon_Supplies.medicament.jcy21 | Z40: 解开成为6个金创药(中量)。 | AA40: StaticMesh Bottle.Dro_Posin_03_all | AB40: 0 | AC40: 15 | AD40: 0 | AE40: 0 | AF40: 1 | AI40: 0 | AJ40: 0 | AK40: 0 | AL40: 0 | AM40: 0 | AN40: 0 | AP40: 0 | AQ40: 1 | AR40: 0 | AS40: 0 | BE40: 240 | BG40: 1 | BL40: 1
...

Sheet Sheet2
A1: Texture2D MMO_ItemIcon_Supplies.Item_06 | C1: Texture2D MMO_ItemIcon_Supplies.Item_11
A2: Texture2D MMO_ItemIcon_Supplies.Item_07 | C2: Texture2D MMO_ItemIcon_Supplies.Item_12
A3: Texture2D MMO_ItemIcon_Supplies.Item_08 | C3: Texture2D MMO_ItemIcon_Supplies.Item_13
A4: Texture2D MMO_ItemIcon_Supplies.Item_09 | C4: Texture2D MMO_ItemIcon_Supplies.Item_14
A5: Texture2D MMO_ItemIcon_Supplies.Item_10 | C5: Texture2D MMO_ItemIcon_Supplies.Item_15
A6: Texture2D MMO_ItemIcon_Supplies.Item_10 | C6: Texture2D MMO_ItemIcon_Supplies.Item_15
A7: Texture2D MMO_ItemIcon_Supplies.Item_10 | C7: Texture2D MMO_ItemIcon_Supplies.Item_15
A8: Texture2D MMO_ItemIcon_Supplies.Item_10 | C8: Texture2D MMO_ItemIcon_Supplies.Item_15
A9: Texture2D MMO_ItemIcon_Supplies.Item_10 | C9: Texture2D MMO_ItemIcon_Supplies.Item_15
A10: Texture2D MMO_ItemIcon_Supplies.Item_10 | C10: Texture2D MMO_ItemIcon_Supplies.Item_15
A11: Texture2D MMO_ItemIcon_Supplies.Item_06 | C11: Texture2D MMO_ItemIcon_Supplies.Item_11
A12: Texture2D MMO_ItemIcon_Supplies.Item_07 | C12: Texture2D MMO_ItemIcon_Supplies.Item_12
... A30: Texture2D MMO_ItemIcon_Supplies.Item_10 | C30: Texture2D MMO_ItemIcon_Supplies.Item_15

Sheet Sheet1
A1: ID | B1: Name | C1: Type | D1: SubType | E1: RequireLevel | F1: RequireClass | G1: RequireGender | H1: MaxEquip | I1: MaxOwn | J1: Color | K1: BindType | L1: DurType | M1: Dur | N1: SpellID | O1: SpellLevel | P1: SelfCoolDown | Q1: GroupCoolDown | R1: SubSubType | S1: Price | T1: UsedStatus | U1: CanDrop | V1: Trade | W1: Storage | X1: Script | Y1: DisplayIcon | AA1: Description | AC1: MaxStackNum | AD1: DropMesh | AE1: SoundMaterialType | AF1: SoundActionType | AG1: ClothNoiseType | AH1: ItemLevel | AI1: CanSell | AJ1: DisplayLargeIcon | AK1: DisplayLargeIconFemale | AL1: LimitDuration | AM1: LimitCount | AN1: Log | AO1: Expensive | AP1: PkDrop
A2: 0 | C2: 0 | D2: 0 | E2: 0 | F2: 0 | G2: 0 | H2: 0 | I2: 0 | J2: 0 | K2: 0 | L2: 0 | M2: 0 | N2: 0 | O2: 0 | P2: 0 | Q2: 0 | R2: 0 | S2: 0 | T2: 0 | U2: 0 | V2: 0 | W2: 0 | AH2: 0 | AI2: 0 | AL2: 0 | AM2: 0 | AN2: 0 | AO2: 0 | AP2: 0
A3: 10100 | B3: 蛮力朱砂灵石1级 | C3: ITEMTYPE_SOUL | D3: ITEMSUBTYPE_SOUL_DEFAULT | E3: 1 | F3: 15 | G3: 0 | H3: 0 | I3: 99999 | J3: 0 | K3: 0 | L3: 2 | M3: 99 | O3: 0 | P3: 0 | R3: None | S3: 100 | T3: 0 | U3: 1 | V3: 1 | W3: 1 | Y3: Texture2D MMO_ItemIcon_Supplies.Item_01 | Z3: 最小攻击+1 | AA3: <br><font color='#43FF98'> 力量 6<br><br><font color='#F2F2F2'>封印强大灵魂能量的红色灵石，可镶入装备的红色插槽中提升装备属性<br><font color='#B2B2B2'> [按下<font color='#FFa500'>I<font color='#B2B2B2'>键打开灵魂镶嵌界面] | AB3: =LEFT(AA3,52)&Z3&RIGHT(AA3,157) -> <br><font color='#43FF98'> 最小攻击+1<br><br><font color='#F2F2F2'>封印强大灵魂能量的红色灵石，可镶入装备的红色插槽中提升装备属性<br><font color='#B2B2B2'> [按下<font color='#FFa500'>I<font color='#B2B2B2'>键打开灵魂镶嵌界面] | AC3: 20 | AD3: StaticMesh Bottle.Dro_Bottle03 | AE3: 0 | AF3: 15 | AG3: 0 | AH3: 0 | AI3: 1 | AL3: 0 | AM3: 0 | AN3: 0
A4: 10101 | B4: 蛮力朱砂灵石2级 | C4: ITEMTYPE_SOUL | D4: ITEMSUBTYPE_SOUL_DEFAULT | E4: 1 | F4: 15 | G4: 0 | H4: 0 | I4: 99999 | J4: 1 | K4: 0 | L4: 2 | M4: 99 | O4: 0 | P4: 0 | R4: None | S4: 200 | T4: 0 | U4: 1 | V4: 1 | W4: 1 | Y4: Texture2D MMO_ItemIcon_Supplies.Item_02 | Z4: 最小攻击+2 | AA4: <br><font color='#43FF98'> 力量 12<br><br><font color='#F2F2F2'>封印强大灵魂能量的红色灵石，可镶入装备的红色插槽中提升装备属性<br><font color='#B2B2B2'> [按下<font color='#FFa500'>I<font color='#B2B2B2'>键打开灵魂镶嵌界面] | AB4: =LEFT(AA4,52)&Z4&RIGHT(AA4,157) -> <br><font color='#43FF98'> 最小攻击+2<br><br><font color='#F2F2F2'>封印强大灵魂能量的红色灵石，可镶入装备的红色插槽中提升装备属性<br><font color='#B2B2B2'> [按下<font color='#FFa500'>I<font color='#B2B2B2'>键打开灵魂镶嵌界面] | AC4: 20 | AD4: StaticMesh Bottle.Dro_Bottle03 | AE4: 0 | AF4: 15 | AG4: 0 | AH4: 0 | AI4: 1 | AL4: 0 | AM4: 0 | AN4: 0
A5: 10102 | B5: 蛮力朱砂灵石3级 | C5: ITEMTYPE_SOUL | D5: ITEMSUBTYPE_SOUL_DEFAULT | E5: 1 | F5: 15 | G5: 0 | H5: 0 | I5: 99999 | J5: 1 | K5: 0 | L5: 2 | M5: 99 | O5: 0 | P5: 0 | R5: None | S5: 400 | T5: 0 | U5: 1 | V5: 1 | W5: 1 | Y5: Texture2D MMO_ItemIcon_Supplies.Item_03 | Z5: 最小攻击+3 | AA5: <br><font color='#43FF98'> 力量 19<br><br><font color='#F2F2F2'>封印强大灵魂能量的红色灵石，可镶入装备的红色插槽中提升装备属性<br><font color='#B2B2B2'> [按下<font color='#FFa500'>I<font color='#B2B2B2'>键打开灵魂镶嵌界面] | AB5: =LEFT(AA5,52)&Z5&RIGHT(AA5,157) -> <br><font color='#43FF98'> 最小攻击+3<br><br><font color='#F2F2F2'>封印强大灵魂能量的红色灵石，可镶入装备的红色插槽中提升装备属性<br><font color='#B2B2B2'> [按下<font color='#FFa500'>I<font color='#B2B2B2'>键打开灵魂镶嵌界面] | AC5: 20 | AD5: StaticMesh Bottle.Dro_Bottle03 | AE5: 0 | AF5: 15 | AG5: 0 | AH5: 0 | AI5: 1 | AL5: 0 | AM5: 0 | AN5: 0
A6: 10103 | B6: 蛮力朱砂灵石4级 | C6: ITEMTYPE_SOUL | D6: ITEMSUBTYPE_SOUL_DEFAULT | E6: 1 | F6: 15 | G6: 0 | H6: 0 | I6: 99999 | J6: 1 | K6: 0 | L6: 2 | M6: 99 | O6: 0 | P6: 0 | R6: None | S6: 800 | T6: 0 | U6: 1 | V6: 1 | W6: 1 | Y6: Texture2D MMO_ItemIcon_Supplies.Item_04 | Z6: 最小攻击+5 | AA6: <br><font color='#43FF98'> 力量 28<br><br><font color='#F2F2F2'>封印强大灵魂能量的红色灵石，可镶入装备的红色插槽中提升装备属性<br><font color='#B2B2B2'> [按下<font color='#FFa500'>I<font color='#B2B2B2'>键打开灵魂镶嵌界面] | AB6: =LEFT(AA6,52)&Z6&RIGHT(AA6,157) -> <br><font color='#43FF98'> 最小攻击+5<br><br><font color='#F2F2F2'>封印强大灵魂能量的红色灵石，可镶入装备的红色插槽中提升装备属性<br><font color='#B2B2B2'> [按下<font color='#FFa500'>I<font color='#B2B2B2'>键打开灵魂镶嵌界面] | AC6: 20 | AD6: StaticMesh Bottle.Dro_Bottle03 | AE6: 0 | AF6: 15 | AG6: 0 | AH6: 0 | AI6: 1 | AL6: 0 | AM6: 0 | AN6: 0 | AO6: 1
A7: 10104 | B7: 蛮力朱砂灵石5级 | C7: ITEMTYPE_SOUL | D7: ITEMSUBTYPE_SOUL_DEFAULT | E7: 1 | F7: 15 | G7: 0 | H7: 0 | I7: 99999 | J7: 2 | K7: 0 | L7: 2 | M7: 99 | O7: 0 | P7: 0 | R7: None | S7: 1600 | T7: 0 | U7: 1 | V7: 1 | W7: 1 | Y7: Texture2D MMO_ItemIcon_Supplies.Item_05 | Z7: 最小攻击+7 | AA7: <br><font color='#43FF98'> 力量 39<br><br><font color='#F2F2F2'>封印强大灵魂能量的红色灵石，可镶入装备的红色插槽中提升装备属性<br><font color='#B2B2B2'> [按下<font color='#FFa500'>I<font color='#B2B2B2'>键打开灵魂镶嵌界面] | AB7: =LEFT(AA7,52)&Z7&RIGHT(AA7,157) -> <br><font color='#43FF98'> 最小攻击+7<br><br><font color='#F2F2F2'>封印强大灵魂能量的红色灵石，可镶入装备的红色插槽中提升装备属性<br><font color='#B2B2B2'> [按下<font color='#FFa500'>I<font color='#B2B2B2'>键打开灵魂镶嵌界面] | AC7: 20 | AD7: StaticMesh Bottle.Dro_Bottle03 | AE7: 0 | AF7: 15 | AG7: 0 | AH7: 0 | AI7: 1 | AL7: 0 | AM7: 0 | AN7: 0 | AO7: 1
A8: 10105 | B8: 蛮力朱砂灵石6级 | C8: ITEMTYPE_SOUL | D8: ITEMSUBTYPE_SOUL_DEFAULT | E8: 1 | F8: 15 | G8: 0 | H8: 0 | I8: 99999 | J8: 2 | K8: 0 | L8: 2 | M8: 99 | O8: 0 | P8: 0 | R8: None | S8: 100 | T8: 0 | U8: 1 | V8: 1 | W8: 1 | Y8: Texture2D MMO_ItemIcon_Supplies.Item_05 | Z8: 最小攻击+10 | AA8: <br><font color='#43FF98'> 力量 52<br><br><font color='#F2F2F2'>封印强大灵魂能量的红色灵石，可镶入装备的红色插槽中提升装备属性<br><font color='#B2B2B2'> [按下<font color='#FFa500'>I<font color='#B2B2B2'>键打开灵魂镶嵌界面] | AB8: =LEFT(AA8,52)&Z8&RIGHT(AA8,157) -> <br><font color='#43FF98'> 最小攻击+10<br><br><font color='#F2F2F2'>封印强大灵魂能量的红色灵石，可镶入装备的红色插槽中提升装备属性<br><font color='#B2B2B2'> [按下<font color='#FFa500'>I<font color='#B2B2B2'>键打开灵魂镶嵌界面] | AC8: 20 | AD8: StaticMesh Bottle.Dro_Bottle03 | AE8: 0 | AF8: 15 | AG8: 0 | AH8: 0 | AI8: 1 | AL8: 0 | AM8: 0 | AN8: 0 | AO8: 1
A9: 10106 | B9: 蛮力朱砂灵石7级 | C9: ITEMTYPE_SOUL | D9: ITEMSUBTYPE_SOUL_DEFAULT | E9: 1 | F9: 15 | G9: 0 | H9: 0 | I9: 99999 | J9: 2 | K9: 0 | L9: 2 | M9: 99 | O9: 0 | P9: 0 | R9: None | S9: 200 | T9: 0 | U9: 1 | V9: 1 | W9: 1 | Y9: Texture2D MMO_ItemIcon_Supplies.Item_05 | Z9: 最小攻击+13 | AA9: <br><font color='#43FF98'> 力量 67<br><br><font color='#F2F2F2'>封印强大灵魂能量的红色灵石，可镶入装备的红色插槽中提升装备属性<br><font color='#B2B2B2'> [按下<font color='#FFa500'>I<font color='#B2B2B2'>键打开灵魂镶嵌界面] | AB9: =LEFT(AA9,52)&Z9&RIGHT(AA9,157) -> <br><font color='#43FF98'> 最小攻击+13<br><br><font color='#F2F2F2'>封印强大灵魂能量的红色灵石，可镶入装备的红色插槽中提升装备属性<br><font color='#B2B2B2'> [按下<font color='#FFa500'>I<font color='#B2B2B2'>键打开灵魂镶嵌界面] | AC9: 20 | AD9: StaticMesh Bottle.Dro_Bottle03 | AE9: 0 | AF9: 15 | AG9: 0 | AH9: 0 | AI9: 1 | AL9: 0 | AM9: 0 | AN9: 0 | AO9: 1
A10: 10107 | B10: 蛮力朱砂灵石8级 | C10: ITEMTYPE_SOUL | D10: ITEMSUBTYPE_SOUL_DEFAULT | E10: 1 | F10: 15 | G10: 0 | H10: 0 | I10: 99999 | J10: 3 | K10: 0 | L10: 2 | M10: 99 | O10: 0 | P10: 0 | R10: None | S10: 400 | T10: 0 | U10: 1 | V10: 1 | W10: 1 | Y10: Texture2D MMO_ItemIcon_Supplies.Item_05 | Z10: 最小攻击+17 | AA10: <br><font color='#43FF98'> 力量 85<br><br><font color='#F2F2F2'>封印强大灵魂能量的红色灵石，可镶入装备的红色插槽中提升装备属性<br><font color='#B2B2B2'> [按下<font color='#FFa500'>I<font color='#B2B2B2'>键打开灵魂镶嵌界面] | AB10: =LEFT(AA10,52)&Z10&RIGHT(AA10,157) -> <br><font color='#43FF98'> 最小攻击+17<br><br><font color='#F2F2F2'>封印强大灵魂能量的红色灵石，可镶入装备的红色插槽中提升装备属性<br><font color='#B2B2B2'> [按下<font color='#FFa500'>I<font color='#B2B2B2'>键打开灵魂镶嵌界面] | AC10: 20 | AD10: StaticMesh Bottle.Dro_Bottle03 | AE10: 0 | AF10: 15 | AG10: 0 | AH10: 0 | AI10: 1 | AL10: 0 | AM10: 0 | AN10: 0 | AO10: 1
A11: 10108 | B11: 蛮力朱砂灵石9级 | C11: ITEMTYPE_SOUL | D11: ITEMSUBTYPE_SOUL_DEFAULT | E11: 1 | F11: 15 | G11: 0 | H11: 0 | I11: 99999 | J11: 3 | K11: 0 | L11: 2 | M11: 99 | O11: 0 | P11: 0 | R11: None | S11: 800 | T11: 0 | U11: 1 | V11: 1 | W11: 1 | Y11: Texture2D MMO_ItemIcon_Supplies.Item_05 | Z11: 最小攻击+22 | AA11: <br><font color='#43FF98'> 力量 107<br><br><font color='#F2F2F2'>封印强大灵魂能量的红色灵石，可镶入装备的红色插槽中提升装备属性<br><font color='#B2B2B2'> [按下<font color='#FFa500'>I<font color='#B2B2B2'>键打开灵魂镶嵌界面] | AB11: =LEFT(AA11,52)&Z11&RIGHT(AA11,157) -> <br><font color='#43FF98'> 最小攻击+22<br><br><font color='#F2F2F2'>封印强大灵魂能量的红色灵石，可镶入装备的红色插槽中提升装备属性<br><font color='#B2B2B2'> [按下<font color='#FFa500'>I<font color='#B2B2B2'>键打开灵魂镶嵌界面] | AC11: 20 | AD11: StaticMesh Bottle.Dro_Bottle03 | AE11: 0 | AF11: 15 | AG11: 0 | AH11: 0 | AI11: 1 | AL11: 0 | AM11: 0 | AN11: 0 | AO11: 1
A12: 10109 | B12: 蛮力朱砂灵石10级 | C12: ITEMTYPE_SOUL | D12: ITEMSUBTYPE_SOUL_DEFAULT | E12: 1 | F12: 15 | G12: 0 | H12: 0 | I12: 99999 | J12: 3 | K12: 0 | L12: 2 | M12: 99 | O12: 0 | P12: 0 | R12: None | S12: 1600 | T12: 0 | U12: 1 | V12: 1 | W12: 1 | Y12: Texture2D MMO_ItemIcon_Supplies.Item_05 | Z12: 最小攻击+28 | AA12: <br><font color='#43FF98'> 力量 133<br><br><font color='#F2F2F2'>封印强大灵魂能量的红色灵石，可镶入装备的红色插槽中提升装备属性<br><font color='#B2B2B2'> [按下<font color='#FFa500'>I<font color='#B2B2B2'>键打开灵魂镶嵌界面] | AB12: =LEFT(AA12,52)&Z12&RIGHT(AA12,157) -> <br><font color='#43FF98'> 最小攻击+28<br><br><font color='#F2F2F2'>封印强大灵魂能量的红色灵石，可镶入装备的红色插槽中提升装备属性<br><font color='#B2B2B2'> [按下<font color='#FFa500'>I<font color='#B2B2B2'>键打开灵魂镶嵌界面] | AC12: 20 | AD12: StaticMesh Bottle.Dro_Bottle03 | AE12: 0 | AF12: 15 | AG12: 0 | AH12: 0 | AI12: 1 | AL12: 0 | AM12: 0 | AN12: 0 | AO12: 1
A13: 10110 | B13: 统御朱砂灵石1级 | C13: ITEMTYPE_SOUL | D13: ITEMSUBTYPE_SOUL_DEFAULT | E13: 1 | F13: 15 | G13: 0 | H13: 0 | I13: 99999 | J13: 0 | K13: 0 | L13: 2 | M13: 99 | O13: 0 | P13: 0 | R13: None | S13: 100 | T13: 0 | U13: 1 | V13: 1 | W13: 1 | Y13: Texture2D MMO_ItemIcon_Supplies.Item_01 | Z13: #N/A | AA13: <br><font color='#43FF98'> 格挡值 6<br><br><font color='#F2F2F2'>封印强大灵魂能量的红色灵石，可镶入装备的红色插槽中提升装备属性<br><font color='#B2B2B2'> [按下<font color='#FFa500'>I<font color='#B2B2B2'>键打开灵魂镶嵌界面] | AB13: =LEFT(AA13,52)&Z13&RIGHT(AA13,157) -> #N/A | AC13: 20 | AD13: StaticMesh Bottle.Dro_Bottle03 | AE13: 0 | AF13: 15 | AG13: 0 | AH13: 0 | AI13: 1 | AL13: 0 | AM13: 0 | AN13: 0
A14: 10111 | B14: 统御朱砂灵石2级 | C14: ITEMTYPE_SOUL | D14: ITEMSUBTYPE_SOUL_DEFAULT | E14: 1 | F14: 15 | G14: 0 | H14: 0 | I14: 99999 | J14: 1 | K14: 0 | L14: 2 | M14: 99 | O14: 0 | P14: 0 | R14: None | S14: 200 | T14: 0 | U14: 1 | V14: 1 | W14: 1 | Y14: Texture2D MMO_ItemIcon_Supplies.Item_02 | Z14: #N/A | AA14: <br><font color='#43FF98'> 格挡值 12<br><br><font color='#F2F2F2'>封印强大灵魂能量的红色灵石，可镶入装备的红色插槽中提升装备属性<br><font color='#B2B2B2'> [按下<font color='#FFa500'>I<font color='#B2B2B2'>键打开灵魂镶嵌界面] | AB14: =LEFT(AA14,52)&Z14&RIGHT(AA14,157) -> #N/A | AC14: 20 | AD14: StaticMesh Bottle.Dro_Bottle03 | AE14: 0 | AF14: 15 | AG14: 0 | AH14: 0 | AI14: 1 | AL14: 0 | AM14: 0 | AN14: 0
A15: 10112 | B15: 统御朱砂灵石3级 | C15: ITEMTYPE_SOUL | D15: ITEMSUBTYPE_SOUL_DEFAULT | E15: 1 | F15: 15 | G15: 0 | H15: 0 | I15: 99999 | J15: 1 | K15: 0 | L15: 2 | M15: 99 | O15: 0 | P15: 0 | R15: None | S15: 400 | T15: 0 | U15: 1 | V15: 1 | W15: 1 | Y15: Texture2D MMO_ItemIcon_Supplies.Item_03 | Z15: #N/A | AA15: <br><font color='#43FF98'> 格挡值 19<br><br><font color='#F2F2F2'>封印强大灵魂能量的红色灵石，可镶入装备的红色插槽中提升装备属性<br><font color='#B2B2B2'> [按下<font color='#FFa500'>I<font color='#B2B2B2'>键打开灵魂镶嵌界面] | AB15: =LEFT(AA15,52)&Z15&RIGHT(AA15,157) -> #N/A | AC15: 20 | AD15: StaticMesh Bottle.Dro_Bottle03 | AE15: 0 | AF15: 15 | AG15: 0 | AH15: 0 | AI15: 1 | AL15: 0 | AM15: 0 | AN15: 0
A16: 10113 | B16: 统御朱砂灵石4级 | C16: ITEMTYPE_SOUL | D16: ITEMSUBTYPE_SOUL_DEFAULT | E16: 1 | F16: 15 | G16: 0 | H16: 0 | I16: 99999 | J16: 1 | K16: 0 | L16: 2 | M16: 99 | O16: 0 | P16: 0 | R16: None | S16: 800 | T16: 0 | U16: 1 | V16: 1 | W16: 1 | Y16: Texture2D MMO_ItemIcon_Supplies.Item_04 | Z16: #N/A | AA16: <br><font color='#43FF98'> 格挡值 28<br><br><font color='#F2F2F2'>封印强大灵魂能量的红色灵石，可镶入装备的红色插槽中提升装备属性<br><font color='#B2B2B2'> [按下<font color='#FFa500'>I<font color='#B2B2B2'>键打开灵魂镶嵌界面] | AB16: =LEFT(AA16,52)&Z16&RIGHT(AA16,157) -> #N/A | AC16: 20 | AD16: StaticMesh Bottle.Dro_Bottle03 | AE16: 0 | AF16: 15 | AG16: 0 | AH16: 0 | AI16: 1 | AL16: 0 | AM16: 0 | AN16: 0 | AO16: 1
A17: 10114 | B17: 统御朱砂灵石5级 | C17: ITEMTYPE_SOUL | D17: ITEMSUBTYPE_SOUL_DEFAULT | E17: 1 | F17: 15 | G17: 0 | H17: 0 | I17: 99999 | J17: 2 | K17: 0 | L17: 2 | M17: 99 | O17: 0 | P17: 0 | R17: None | S17: 1600 | T17: 0 | U17: 1 | V17: 1 | W17: 1 | Y17: Texture2D MMO_ItemIcon_Supplies.Item_05 | Z17: #N/A | AA17: <br><font color='#43FF98'> 格挡值 39<br><br><font color='#F2F2F2'>封印强大灵魂能量的红色灵石，可镶入装备的红色插槽中提升装备属性<br><font color='#B2B2B2'> [按下<font color='#FFa500'>I<font color='#B2B2B2'>键打开灵魂镶嵌界面] | AB17: =LEFT(AA17,52)&Z17&RIGHT(AA17,157) -> #N/A | AC17: 20 | AD17: StaticMesh Bottle.Dro_Bottle03 | AE17: 0 | AF17: 15 | AG17: 0 | AH17: 0 | AI17: 1 | AL17: 0 | AM17: 0 | AN17: 0 | AO17: 1
A18: 10115 | B18: 统御朱砂灵石6级 | C18: ITEMTYPE_SOUL | D18: ITEMSUBTYPE_SOUL_DEFAULT | E18: 1 | F18: 15 | G18: 0 | H18: 0 | I18: 99999 | J18: 2 | K18: 0 | L18: 2 | M18: 99 | O18: 0 | P18: 0 | R18: None | S18: 100 | T18: 0 | U18: 1 | V18: 1 | W18: 1 | Y18: Texture2D MMO_ItemIcon_Supplies.Item_05 | Z18: #N/A | AA18: <br><font color='#43FF98'> 格挡值 52<br><br><font color='#F2F2F2'>封印强大灵魂能量的红色灵石，可镶入装备的红色插槽中提升装备属性<br><font color='#B2B2B2'> [按下<font color='#FFa500'>I<font color='#B2B2B2'>键打开灵魂镶嵌界面] | AB18: =LEFT(AA18,52)&Z18&RIGHT(AA18,157) -> #N/A | AC18: 20 | AD18: StaticMesh Bottle.Dro_Bottle03 | AE18: 0 | AF18: 15 | AG18: 0 | AH18: 0 | AI18: 1 | AL18: 0 | AM18: 0 | AN18: 0 | AO18: 1
A19: 10116 | B19: 统御朱砂灵石7级 | C19: ITEMTYPE_SOUL | D19: ITEMSUBTYPE_SOUL_DEFAULT | E19: 1 | F19: 15 | G19: 0 | H19: 0 | I19: 99999 | J19: 2 | K19: 0 | L19: 2 | M19: 99 | O19: 0 | P19: 0 | R19: None | S19: 200 | T19: 0 | U19: 1 | V19: 1 | W19: 1 | Y19: Texture2D MMO_ItemIcon_Supplies.Item_05 | Z19: #N/A | AA19: <br><font color='#43FF98'> 格挡值 67<br><br><font color='#F2F2F2'>封印强大灵魂能量的红色灵石，可镶入装备的红色插槽中提升装备属性<br><font color='#B2B2B2'> [按下<font color='#FFa500'>I<font color='#B2B2B2'>键打开灵魂镶嵌界面] | AB19: =LEFT(AA19,52)&Z19&RIGHT(AA19,157) -> #N/A | AC19: 20 | AD19: StaticMesh Bottle.Dro_Bottle03 | AE19: 0 | AF19: 15 | AG19: 0 | AH19: 0 | AI19: 1 | AL19: 0 | AM19: 0 | AN19: 0 | AO19: 1
A20: 10117 | B20: 统御朱砂灵石8级 | C20: ITEMTYPE_SOUL | D20: ITEMSUBTYPE_SOUL_DEFAULT | E20: 1 | F20: 15 | G20: 0 | H20: 0 | I20: 99999 | J20: 3 | K20: 0 | L20: 2 | M20: 99 | O20: 0 | P20: 0 | R20: None | S20: 400 | T20: 0 | U20: 1 | V20: 1 | W20: 1 | Y20: Texture2D MMO_ItemIcon_Supplies.Item_05 | Z20: #N/A | AA20: <br><font color='#43FF98'> 格挡值 85<br><br><font color='#F2F2F2'>封印强大灵魂能量的红色灵石，可镶入装备的红色插槽中提升装备属性<br><font color='#B2B2B2'> [按下<font color='#FFa500'>I<font color='#B2B2B2'>键打开灵魂镶嵌界面] | AB20: =LEFT(AA20,52)&Z20&RIGHT(AA20,157) -> #N/A | AC20: 20 | AD20: StaticMesh Bottle.Dro_Bottle03 | AE20: 0 | AF20: 15 | AG20: 0 | AH20: 0 | AI20: 1 | AL20: 0 | AM20: 0 | AN20: 0 | AO20: 1
A21: 10118 | B21: 统御朱砂灵石9级 | C21: ITEMTYPE_SOUL | D21: ITEMSUBTYPE_SOUL_DEFAULT | E21: 1 | F21: 15 | G21: 0 | H21: 0 | I21: 99999 | J21: 3 | K21: 0 | L21: 2 | M21: 99 | O21: 0 | P21: 0 | R21: None | S21: 800 | T21: 0 | U21: 1 | V21: 1 | W21: 1 | Y21: Texture2D MMO_ItemIcon_Supplies.Item_05 | Z21: #N/A | AA21: <br><font color='#43FF98'> 格挡值 107<br><br><font color='#F2F2F2'>封印强大灵魂能量的红色灵石，可镶入装备的红色插槽中提升装备属性<br><font color='#B2B2B2'> [按下<font color='#FFa500'>I<font color='#B2B2B2'>键打开灵魂镶嵌界面] | AB21: =LEFT(AA21,52)&Z21&RIGHT(AA21,157) -> #N/A | AC21: 20 | AD21: StaticMesh Bottle.Dro_Bottle03 | AE21: 0 | AF21: 15 | AG21: 0 | AH21: 0 | AI21: 1 | AL21: 0 | AM21: 0 | AN21: 0 | AO21: 1
A22: 10119 | B22: 统御朱砂灵石10级 | C22: ITEMTYPE_SOUL | D22: ITEMSUBTYPE_SOUL_DEFAULT | E22: 1 | F22: 15 | G22: 0 | H22: 0 | I22: 99999 | J22: 3 | K22: 0 | L22: 2 | M22: 99 | O22: 0 | P22: 0 | R22: None | S22: 1600 | T22: 0 | U22: 1 | V22: 1 | W22: 1 | Y22: Texture2D MMO_ItemIcon_Supplies.Item_05 | Z22: #N/A | AA22: <br><font color='#43FF98'> 格挡值 133<br><br><font color='#F2F2F2'>封印强大灵魂能量的红色灵石，可镶入装备的红色插槽中提升装备属性<br><font color='#B2B2B2'> [按下<font color='#FFa500'>I<font color='#B2B2B2'>键打开灵魂镶嵌界面] | AB22: =LEFT(AA22,52)&Z22&RIGHT(AA22,157) -> #N/A | AC22: 20 | AD22: StaticMesh Bottle.Dro_Bottle03 | AE22: 0 | AF22: 15 | AG22: 0 | AH22: 0 | AI22: 1 | AL22: 0 | AM22: 0 | AN22: 0 | AO22: 1
A23: 10120 | B23: 灵敏朱砂灵石1级 | C23: ITEMTYPE_SOUL | D23: ITEMSUBTYPE_SOUL_DEFAULT | E23: 1 | F23: 15 | G23: 0 | H23: 0 | I23: 99999 | J23: 0 | K23: 0 | L23: 2 | M23: 99 | O23: 0 | P23: 0 | R23: None | S23: 100 | T23: 0 | U23: 1 | V23: 1 | W23: 1 | Y23: Texture2D MMO_ItemIcon_Supplies.Item_01 | Z23: 最大道术+1 | AA23: <br><font color='#43FF98'> 敏捷 1%<br><br><font color='#F2F2F2'>封印强大灵魂能量的红色灵石，可镶入装备的红色插槽中提升装备属性<br><font color='#B2B2B2'> [按下<font color='#FFa500'>I<font color='#B2B2B2'>键打开灵魂镶嵌界面] | AB23: =LEFT(AA23,52)&Z23&RIGHT(AA23,157) -> <br><font color='#43FF98'> 最大道术+1<br><br><font color='#F2F2F2'>封印强大灵魂能量的红色灵石，可镶入装备的红色插槽中提升装备属性<br><font color='#B2B2B2'> [按下<font color='#FFa500'>I<font color='#B2B2B2'>键打开灵魂镶嵌界面] | AC23: 20 | AD23: StaticMesh Bottle.Dro_Bottle03 | AE23: 0 | AF23: 15 | AG23: 0 | AH23: 0 | AI23: 1 | AL23: 0 | AM23: 0 | AN23: 0
A24: 10121 | B24: 灵敏朱砂灵石2级 | C24: ITEMTYPE_SOUL | D24: ITEMSUBTYPE_SOUL_DEFAULT | E24: 1 | F24: 15 | G24: 0 | H24: 0 | I24: 99999 | J24: 1 | K24: 0 | L24: 2 | M24: 99 | O24: 0 | P24: 0 | R24: None | S24: 200 | T24: 0 | U24: 1 | V24: 1 | W24: 1 | Y24: Texture2D MMO_ItemIcon_Supplies.Item_02 | Z24: 最大道术+2 | AA24: <br><font color='#43FF98'> 敏捷 2%<br><br><font color='#F2F2F2'>封印强大灵魂能量的红色灵石，可镶入装备的红色插槽中提升装备属性<br><font color='#B2B2B2'> [按下<font color='#FFa500'>I<font color='#B2B2B2'>键打开灵魂镶嵌界面] | AB24: =LEFT(AA24,52)&Z24&RIGHT(AA24,157) -> <br><font color='#43FF98'> 最大道术+2<br><br><font color='#F2F2F2'>封印强大灵魂能量的红色灵石，可镶入装备的红色插槽中提升装备属性<br><font color='#B2B2B2'> [按下<font color='#FFa500'>I<font color='#B2B2B2'>键打开灵魂镶嵌界面] | AC24: 20 | AD24: StaticMesh Bottle.Dro_Bottle03 | AE24: 0 | AF24: 15 | AG24: 0 | AH24: 0 | AI24: 1 | AL24: 0 | AM24: 0 | AN24: 0
A25: 10122 | B25: 灵敏朱砂灵石3级 | C25: ITEMTYPE_SOUL | D25: ITEMSUBTYPE_SOUL_DEFAULT | E25: 1 | F25: 15 | G25: 0 | H25: 0 | I25: 99999 | J25: 1 | K25: 0 | L25: 2 | M25: 99 | O25: 0 | P25: 0 | R25: None | S25: 400 | T25: 0 | U25: 1 | V25: 1 | W25: 1 | Y25: Texture2D MMO_ItemIcon_Supplies.Item_03 | Z25: 最大道术+3 | AA25: <br><font color='#43FF98'> 敏捷 3%<br><br><font color='#F2F2F2'>封印强大灵魂能量的红色灵石，可镶入装备的红色插槽中提升装备属性<br><font color='#B2B2B2'> [按下<font color='#FFa500'>I<font color='#B2B2B2'>键打开灵魂镶嵌界面] | AB25: =LEFT(AA25,52)&Z25&RIGHT(AA25,157) -> <br><font color='#43FF98'> 最大道术+3<br><br><font color='#F2F2F2'>封印强大灵魂能量的红色灵石，可镶入装备的红色插槽中提升装备属性<br><font color='#B2B2B2'> [按下<font color='#FFa500'>I<font color='#B2B2B2'>键打开灵魂镶嵌界面] | AC25: 20 | AD25: StaticMesh Bottle.Dro_Bottle03 | AE25: 0 | AF25: 15 | AG25: 0 | AH25: 0 | AI25: 1 | AL25: 0 | AM25: 0 | AN25: 0
A26: 10123 | B26: 灵敏朱砂灵石4级 | C26: ITEMTYPE_SOUL | D26: ITEMSUBTYPE_SOUL_DEFAULT | E26: 1 | F26: 15 | G26: 0 | H26: 0 | I26: 99999 | J26: 1 | K26: 0 | L26: 2 | M26: 99 | O26: 0 | P26: 0 | R26: None | S26: 800 | T26: 0 | U26: 1 | V26: 1 | W26: 1 | Y26: Texture2D MMO_ItemIcon_Supplies.Item_04 | Z26: 最大道术+5 | AA26: <br><font color='#43FF98'> 敏捷 4%<br><br><font color='#F2F2F2'>封印强大灵魂能量的红色灵石，可镶入装备的红色插槽中提升装备属性<br><font color='#B2B2B2'> [按下<font color='#FFa500'>I<font color='#B2B2B2'>键打开灵魂镶嵌界面] | AB26: =LEFT(AA26,52)&Z26&RIGHT(AA26,157) -> <br><font color='#43FF98'> 最大道术+5<br><br><font color='#F2F2F2'>封印强大灵魂能量的红色灵石，可镶入装备的红色插槽中提升装备属性<br><font color='#B2B2B2'> [按下<font color='#FFa500'>I<font color='#B2B2B2'>键打开灵魂镶嵌界面] | AC26: 20 | AD26: StaticMesh Bottle.Dro_Bottle03 | AE26: 0 | AF26: 15 | AG26: 0 | AH26: 0 | AI26: 1 | AL26: 0 | AM26: 0 | AN26: 0 | AO26: 1
A27: 10124 | B27: 灵敏朱砂灵石5级 | C27: ITEMTYPE_SOUL | D27: ITEMSUBTYPE_SOUL_DEFAULT | E27: 1 | F27: 15 | G27: 0 | H27: 0 | I27: 99999 | J27: 2 | K27: 0 | L27: 2 | M27: 99 | O27: 0 | P27: 0 | R27: None | S27: 1600 | T27: 0 | U27: 1 | V27: 1 | W27: 1 | Y27: Texture2D MMO_ItemIcon_Supplies.Item_05 | Z27: 最大道术+7 | AA27: <br><font color='#43FF98'> 敏捷 5%<br><br><font color='#F2F2F2'>封印强大灵魂能量的红色灵石，可镶入装备的红色插槽中提升装备属性<br><font color='#B2B2B2'> [按下<font color='#FFa500'>I<font color='#B2B2B2'>键打开灵魂镶嵌界面] | AB27: =LEFT(AA27,52)&Z27&RIGHT(AA27,157) -> <br><font color='#43FF98'> 最大道术+7<br><br><font color='#F2F2F2'>封印强大灵魂能量的红色灵石，可镶入装备的红色插槽中提升装备属性<br><font color='#B2B2B2'> [按下<font color='#FFa500'>I<font color='#B2B2B2'>键打开灵魂镶嵌界面] | AC27: 20 | AD27: StaticMesh Bottle.Dro_Bottle03 | AE27: 0 | AF27: 15 | AG27: 0 | AH27: 0 | AI27: 1 | AL27: 0 | AM27: 0 | AN27: 0 | AO27: 1
A28: 10125 | B28: 灵敏朱砂灵石6级 | C28: ITEMTYPE_SOUL | D28: ITEMSUBTYPE_SOUL_DEFAULT | E28: 1 | F28: 15 | G28: 0 | H28: 0 | I28: 99999 | J28: 2 | K28: 0 | L28: 2 | M28: 99 | O28: 0 | P28: 0 | R28: None | S28: 100 | T28: 0 | U28: 1 | V28: 1 | W28: 1 | Y28: Texture2D MMO_ItemIcon_Supplies.Item_05 | Z28: 最大道术+10 | AA28: <br><font color='#43FF98'> 敏捷 6%<br><br><font color='#F2F2F2'>封印强大灵魂能量的红色灵石，可镶入装备的红色插槽中提升装备属性<br><font color='#B2B2B2'> [按下<font color='#FFa500'>I<font color='#B2B2B2'>键打开灵魂镶嵌界面] | AB28: =LEFT(AA28,52)&Z28&RIGHT(AA28,157) -> <br><font color='#43FF98'> 最大道术+10<br><br><font color='#F2F2F2'>封印强大灵魂能量的红色灵石，可镶入装备的红色插槽中提升装备属性<br><font color='#B2B2B2'> [按下<font color='#FFa500'>I<font color='#B2B2B2'>键打开灵魂镶嵌界面] | AC28: 20 | AD28: StaticMesh Bottle.Dro_Bottle03 | AE28: 0 | AF28: 15 | AG28: 0 | AH28: 0 | AI28: 1 | AL28: 0 | AM28: 0 | AN28: 0 | AO28: 1
A29: 10126 | B29: 灵敏朱砂灵石7级 | C29: ITEMTYPE_SOUL | D29: ITEMSUBTYPE_SOUL_DEFAULT | E29: 1 | F29: 15 | G29: 0 | H29: 0 | I29: 99999 | J29: 2 | K29: 0 | L29: 2 | M29: 99 | O29: 0 | P29: 0 | R29: None | S29: 200 | T29: 0 | U29: 1 | V29: 1 | W29: 1 | Y29: Texture2D MMO_ItemIcon_Supplies.Item_05 | Z29: 最大道术+13 | AA29: <br><font color='#43FF98'> 敏捷 7%<br><br><font color='#F2F2F2'>封印强大灵魂能量的红色灵石，可镶入装备的红色插槽中提升装备属性<br><font color='#B2B2B2'> [按下<font color='#FFa500'>I<font color='#B2B2B2'>键打开灵魂镶嵌界面] | AB29: =LEFT(AA29,52)&Z29&RIGHT(AA29,157) -> <br><font color='#43FF98'> 最大道术+13<br><br><font color='#F2F2F2'>封印强大灵魂能量的红色灵石，可镶入装备的红色插槽中提升装备属性<br><font color='#B2B2B2'> [按下<font color='#FFa500'>I<font color='#B2B2B2'>键打开灵魂镶嵌界面] | AC29: 20 | AD29: StaticMesh Bottle.Dro_Bottle03 | AE29: 0 | AF29: 15 | AG29: 0 | AH29: 0 | AI29: 1 | AL29: 0 | AM29: 0 | AN29: 0 | AO29: 1
A30: 10127 | B30: 灵敏朱砂灵石8级 | C30: ITEMTYPE_SOUL | D30: ITEMSUBTYPE_SOUL_DEFAULT | E30: 1 | F30: 15 | G30: 0 | H30: 0 | I30: 99999 | J30: 3 | K30: 0 | L30: 2 | M30: 99 | O30: 0 | P30: 0 | R30: None | S30: 400 | T30: 0 | U30: 1 | V30: 1 | W30: 1 | Y30: Texture2D MMO_ItemIcon_Supplies.Item_05 | Z30: 最大道术+17 | AA30: <br><font color='#43FF98'> 敏捷 8%<br><br><font color='#F2F2F2'>封印强大灵魂能量的红色灵石，可镶入装备的红色插槽中提升装备属性<br><font color='#B2B2B2'> [按下<font color='#FFa500'>I<font color='#B2B2B2'>键打开灵魂镶嵌界面] | AB30: =LEFT(AA30,52)&Z30&RIGHT(AA30,157) -> <br><font color='#43FF98'> 最大道术+17<br><br><font color='#F2F2F2'>封印强大灵魂能量的红色灵石，可镶入装备的红色插槽中提升装备属性<br><font color='#B2B2B2'> [按下<font color='#FFa500'>I<font color='#B2B2B2'>键打开灵魂镶嵌界面] | AC30: 20 | AD30: StaticMesh Bottle.Dro_Bottle03 | AE30: 0 | AF30: 15 | AG30: 0 | AH30: 0 | AI30: 1 | AL30: 0 | AM30: 0 | AN30: 0 | AO30: 1
A31: 10128 | B31: 灵敏朱砂灵石9级 | C31: ITEMTYPE_SOUL | D31: ITEMSUBTYPE_SOUL_DEFAULT | E31: 1 | F31: 15 | G31: 0 | H31: 0 | I31: 99999 | J31: 3 | K31: 0 | L31: 2 | M31: 99 | O31: 0 | P31: 0 | R31: None | S31: 800 | T31: 0 | U31: 1 | V31: 1 | W31: 1 | Y31: Texture2D MMO_ItemIcon_Supplies.Item_05 | Z31: 最大道术+22 | AA31: <br><font color='#43FF98'> 敏捷 9%<br><br><font color='#F2F2F2'>封印强大灵魂能量的红色灵石，可镶入装备的红色插槽中提升装备属性<br><font color='#B2B2B2'> [按下<font color='#FFa500'>I<font color='#B2B2B2'>键打开灵魂镶嵌界面] | AB31: =LEFT(AA31,52)&Z31&RIGHT(AA31,157) -> <br><font color='#43FF98'> 最大道术+22<br><br><font color='#F2F2F2'>封印强大灵魂能量的红色灵石，可镶入装备的红色插槽中提升装备属性<br><font color='#B2B2B2'> [按下<font color='#FFa500'>I<font color='#B2B2B2'>键打开灵魂镶嵌界面] | AC31: 20 | AD31: StaticMesh Bottle.Dro_Bottle03 | AE31: 0 | AF31: 15 | AG31: 0 | AH31: 0 | AI31: 1 | AL31: 0 | AM31: 0 | AN31: 0 | AO31: 1
A32: 10129 | B32: 灵敏朱砂灵石10级 | C32: ITEMTYPE_SOUL | D32: ITEMSUBTYPE_SOUL_DEFAULT | E32: 1 | F32: 15 | G32: 0 | H32: 0 | I32: 99999 | J32: 3 | K32: 0 | L32: 2 | M32: 99 | O32: 0 | P32: 0 | R32: None | S32: 1600 | T32: 0 | U32: 1 | V32: 1 | W32: 1 | Y32: Texture2D MMO_ItemIcon_Supplies.Item_05 | Z32: 最大道术+28 | AA32: <br><font color='#43FF98'> 敏捷 10%<br><br><font color='#F2F2F2'>封印强大灵魂能量的红色灵石，可镶入装备的红色插槽中提升装备属性<br><font color='#B2B2B2'> [按下<font color='#FFa500'>I<font color='#B2B2B2'>键打开灵魂镶嵌界面] | AB32: =LEFT(AA32,52)&Z32&RIGHT(AA32,157) -> <br><font color='#43FF98'> 最大道术+28<br><br><font color='#F2F2F2'>封印强大灵魂能量的红色灵石，可镶入装备的红色插槽中提升装备属性<br><font color='#B2B2B2'> [按下<font color='#FFa500'>I<font color='#B2B2B2'>键打开灵魂镶嵌界面] | AC32: 20 | AD32: StaticMesh Bottle.Dro_Bottle03 | AE32: 0 | AF32: 15 | AG32: 0 | AH32: 0 | AI32: 1 | AL32: 0 | AM32: 0 | AN32: 0 | AO32: 1
A33: 10200 | B33: 迅捷日光灵石1级 | C33: ITEMTYPE_SOUL | D33: ITEMSUBTYPE_SOUL_DEFAULT | E33: 1 | F33: 15 | G33: 0 | H33: 0 | I33: 99999 | J33: 0 | K33: 0 | L33: 2 | M33: 99 | O33: 0 | P33: 0 | R33: None | S33: 100 | T33: 0 | U33: 1 | V33: 1 | W33: 1 | Y33: Texture2D MMO_ItemIcon_Supplies.Item_11 | Z33: 最大攻击+1 | AA33: <br><font color='#43FF98'> 敏捷 6<br><br><font color='#F2F2F2'>封印强大灵魂能量的红色灵石，可镶入装备的红色插槽中提升装备属性<br><font color='#B2B2B2'> [按下<font color='#FFa500'>I<font color='#B2B2B2'>键打开灵魂镶嵌界面] | AB33: =LEFT(AA33,52)&Z33&RIGHT(AA33,157) -> <br><font color='#43FF98'> 最大攻击+1<br><br><font color='#F2F2F2'>封印强大灵魂能量的红色灵石，可镶入装备的红色插槽中提升装备属性<br><font color='#B2B2B2'> [按下<font color='#FFa500'>I<font color='#B2B2B2'>键打开灵魂镶嵌界面] | AC33: 20 | AD33: StaticMesh Bottle.Dro_Bottle03 | AE33: 0 | AF33: 15 | AG33: 0 | AH33: 0 | AI33: 1 | AL33: 0 | AM33: 0 | AN33: 0
A34: 10201 | B34: 迅捷日光灵石2级 | C34: ITEMTYPE_SOUL | D34: ITEMSUBTYPE_SOUL_DEFAULT | E34: 1 | F34: 15 | G34: 0 | H34: 0 | I34: 99999 | J34: 1 | K34: 0 | L34: 2 | M34: 99 | O34: 0 | P34: 0 | R34: None | S34: 200 | T34: 0 | U34: 1 | V34: 1 | W34: 1 | Y34: Texture2D MMO_ItemIcon_Supplies.Item_12 | Z34: 最大攻击+2 | AA34: <br><font color='#43FF98'> 敏捷 12<br><br><font color='#F2F2F2'>封印强大灵魂能量的红色灵石，可镶入装备的红色插槽中提升装备属性<br><font color='#B2B2B2'> [按下<font color='#FFa500'>I<font color='#B2B2B2'>键打开灵魂镶嵌界面] | AB34: =LEFT(AA34,52)&Z34&RIGHT(AA34,157) -> <br><font color='#43FF98'> 最大攻击+2<br><br><font color='#F2F2F2'>封印强大灵魂能量的红色灵石，可镶入装备的红色插槽中提升装备属性<br><font color='#B2B2B2'> [按下<font color='#FFa500'>I<font color='#B2B2B2'>键打开灵魂镶嵌界面] | AC34: 20 | AD34: StaticMesh Bottle.Dro_Bottle03 | AE34: 0 | AF34: 15 | AG34: 0 | AH34: 0 | AI34: 1 | AL34: 0 | AM34: 0 | AN34: 0
A35: 10202 | B35: 迅捷日光灵石3级 | C35: ITEMTYPE_SOUL | D35: ITEMSUBTYPE_SOUL_DEFAULT | E35: 1 | F35: 15 | G35: 0 | H35: 0 | I35: 99999 | J35: 1 | K35: 0 | L35: 2 | M35: 99 | O35: 0 | P35: 0 | R35: None | S35: 400 | T35: 0 | U35: 1 | V35: 1 | W35: 1 | Y35: Texture2D MMO_ItemIcon_Supplies.Item_13 | Z35: 最大攻击+3 | AA35: <br><font color='#43FF98'> 敏捷 19<br><br><font color='#F2F2F2'>封印强大灵魂能量的红色灵石，可镶入装备的红色插槽中提升装备属性<br><font color='#B2B2B2'> [按下<font color='#FFa500'>I<font color='#B2B2B2'>键打开灵魂镶嵌界面] | AB35: =LEFT(AA35,52)&Z35&RIGHT(AA35,157) -> <br><font color='#43FF98'> 最大攻击+3<br><br><font color='#F2F2F2'>封印强大灵魂能量的红色灵石，可镶入装备的红色插槽中提升装备属性<br><font color='#B2B2B2'> [按下<font color='#FFa500'>I<font color='#B2B2B2'>键打开灵魂镶嵌界面] | AC35: 20 | AD35: StaticMesh Bottle.Dro_Bottle03 | AE35: 0 | AF35: 15 | AG35: 0 | AH35: 0 | AI35: 1 | AL35: 0 | AM35: 0 | AN35: 0
A36: 10203 | B36: 迅捷日光灵石4级 | C36: ITEMTYPE_SOUL | D36: ITEMSUBTYPE_SOUL_DEFAULT | E36: 1 | F36: 15 | G36: 0 | H36: 0 | I36: 99999 | J36: 1 | K36: 0 | L36: 2 | M36: 99 | O36: 0 | P36: 0 | R36: None | S36: 800 | T36: 0 | U36: 1 | V36: 1 | W36: 1 | Y36: Texture2D MMO_ItemIcon_Supplies.Item_14 | Z36: 最大攻击+5 | AA36: <br><font color='#43FF98'> 敏捷 28<br><br><font color='#F2F2F2'>封印强大灵魂能量的红色灵石，可镶入装备的红色插槽中提升装备属性<br><font color='#B2B2B2'> [按下<font color='#FFa500'>I<font color='#B2B2B2'>键打开灵魂镶嵌界面] | AB36: =LEFT(AA36,52)&Z36&RIGHT(AA36,157) -> <br><font color='#43FF98'> 最大攻击+5<br><br><font color='#F2F2F2'>封印强大灵魂能量的红色灵石，可镶入装备的红色插槽中提升装备属性<br><font color='#B2B2B2'> [按下<font color='#FFa500'>I<font color='#B2B2B2'>键打开灵魂镶嵌界面] | AC36: 20 | AD36: StaticMesh Bottle.Dro_Bottle03 | AE36: 0 | AF36: 15 | AG36: 0 | AH36: 0 | AI36: 1 | AL36: 0 | AM36: 0 | AN36: 0 | AO36: 1
A37: 10204 | B37: 迅捷日光灵石5级 | C37: ITEMTYPE_SOUL | D37: ITEMSUBTYPE_SOUL_DEFAULT | E37: 1 | F37: 15 | G37: 0 | H37: 0 | I37: 99999 | J37: 2 | K37: 0 | L37: 2 | M37: 99 | O37: 0 | P37: 0 | R37: None | S37: 1600 | T37: 0 | U37: 1 | V37: 1 | W37: 1 | Y37: Texture2D MMO_ItemIcon_Supplies.Item_15 | Z37: 最大攻击+7 | AA37: <br><font color='#43FF98'> 敏捷 39<br><br><font color='#F2F2F2'>封印强大灵魂能量的红色灵石，可镶入装备的红色插槽中提升装备属性<br><font color='#B2B2B2'> [按下<font color='#FFa500'>I<font color='#B2B2B2'>键打开灵魂镶嵌界面] | AB37: =LEFT(AA37,52)&Z37&RIGHT(AA37,157) -> <br><font color='#43FF98'> 最大攻击+7<br><br><font color='#F2F2F2'>封印强大灵魂能量的红色灵石，可镶入装备的红色插槽中提升装备属性<br><font color='#B2B2B2'> [按下<font color='#FFa500'>I<font color='#B2B2B2'>键打开灵魂镶嵌界面] | AC37: 20 | AD37: StaticMesh Bottle.Dro_Bottle03 | AE37: 0 | AF37: 15 | AG37: 0 | AH37: 0 | AI37: 1 | AL37: 0 | AM37: 0 | AN37: 0 | AO37: 1
A38: 10205 | B38: 迅捷日光灵石6级 | C38: ITEMTYPE_SOUL | D38: ITEMSUBTYPE_SOUL_DEFAULT | E38: 1 | F38: 15 | G38: 0 | H38: 0 | I38: 99999 | J38: 2 | K38: 0 | L38: 2 | M38: 99 | O38: 0 | P38: 0 | R38: None | S38: 100 | T38: 0 | U38: 1 | V38: 1 | W38: 1 | Y38: Texture2D MMO_ItemIcon_Supplies.Item_15 | Z38: 最大攻击+10 | AA38: <br><font color='#43FF98'> 敏捷 52<br><br><font color='#F2F2F2'>封印强大灵魂能量的红色灵石，可镶入装备的红色插槽中提升装备属性<br><font color='#B2B2B2'> [按下<font color='#FFa500'>I<font color='#B2B2B2'>键打开灵魂镶嵌界面] | AB38: =LEFT(AA38,52)&Z38&RIGHT(AA38,157) -> <br><font color='#43FF98'> 最大攻击+10<br><br><font color='#F2F2F2'>封印强大灵魂能量的红色灵石，可镶入装备的红色插槽中提升装备属性<br><font color='#B2B2B2'> [按下<font color='#FFa500'>I<font color='#B2B2B2'>键打开灵魂镶嵌界面] | AC38: 20 | AD38: StaticMesh Bottle.Dro_Bottle03 | AE38: 0 | AF38: 15 | AG38: 0 | AH38: 0 | AI38: 1 | AL38: 0 | AM38: 0 | AN38: 0 | AO38: 1
A39: 10206 | B39: 迅捷日光灵石7级 | C39: ITEMTYPE_SOUL | D39: ITEMSUBTYPE_SOUL_DEFAULT | E39: 1 | F39: 15 | G39: 0 | H39: 0 | I39: 99999 | J39: 2 | K39: 0 | L39: 2 | M39: 99 | O39: 0 | P39: 0 | R39: None | S39: 200 | T39: 0 | U39: 1 | V39: 1 | W39: 1 | Y39: Texture2D MMO_ItemIcon_Supplies.Item_15 | Z39: 最大攻击+13 | AA39: <br><font color='#43FF98'> 敏捷 67<br><br><font color='#F2F2F2'>封印强大灵魂能量的红色灵石，可镶入装备的红色插槽中提升装备属性<br><font color='#B2B2B2'> [按下<font color='#FFa500'>I<font color='#B2B2B2'>键打开灵魂镶嵌界面] | AB39: =LEFT(AA39,52)&Z39&RIGHT(AA39,157) -> <br><font color='#43FF98'> 最大攻击+13<br><br><font color='#F2F2F2'>封印强大灵魂能量的红色灵石，可镶入装备的红色插槽中提升装备属性<br><font color='#B2B2B2'> [按下<font color='#FFa500'>I<font color='#B2B2B2'>键打开灵魂镶嵌界面] | AC39: 20 | AD39: StaticMesh Bottle.Dro_Bottle03 | AE39: 0 | AF39: 15 | AG39: 0 | AH39: 0 | AI39: 1 | AL39: 0 | AM39: 0 | AN39: 0 | AO39: 1
A40: 10207 | B40: 迅捷日光灵石8级 | C40: ITEMTYPE_SOUL | D40: ITEMSUBTYPE_SOUL_DEFAULT | E40: 1 | F40: 15 | G40: 0 | H40: 0 | I40: 99999 | J40: 3 | K40: 0 | L40: 2 | M40: 99 | O40: 0 | P40: 0 | R40: None | S40: 400 | T40: 0 | U40: 1 | V40: 1 | W40: 1 | Y40: Texture2D MMO_ItemIcon_Supplies.Item_15 | Z40: 最大攻击+17 | AA40: <br><font color='#43FF98'> 敏捷 85<br><br><font color='#F2F2F2'>封印强大灵魂能量的红色灵石，可镶入装备的红色插槽中提升装备属性<br><font color='#B2B2B2'> [按下<font color='#FFa500'>I<font color='#B2B2B2'>键打开灵魂镶嵌界面] | AB40: =LEFT(AA40,52)&Z40&RIGHT(AA40,157) -> <br><font color='#43FF98'> 最大攻击+17<br><br><font color='#F2F2F2'>封印强大灵魂能量的红色灵石，可镶入装备的红色插槽中提升装备属性<br><font color='#B2B2B2'> [按下<font color='#FFa500'>I<font color='#B2B2B2'>键打开灵魂镶嵌界面] | AC40: 20 | AD40: StaticMesh Bottle.Dro_Bottle03 | AE40: 0 | AF40: 15 | AG40: 0 | AH40: 0 | AI40: 1 | AL40: 0 | AM40: 0 | AN40: 0 | AO40: 1
...

Sheet define
A1: 字段名称 | B1: 描述 | C1: 说明
A2: ID | B2: id | C2: 与item_armor表共用，不能重复
A3: Name | C3: 不能重复
A4: Type | B4: 道具类型
A5: SubType | B5: 道具子类型
A6: RequireLevel | B6: 使用等级限制
A7: RequireClass | B7: 使用职业限制 | C7: 4位代表4个职业，15（1111）代表每个职业都能用 | D7: 1战士 | E7: 2法师 | F7: 4刺客 | G7: 8弓手
A8: RequireGender | B8: 使用性别限制 | C8: 0表示无限制
A9: MaxEquip | B9: 最大装备量 | C9: 填0
A10: MaxOwn | B10: 可拥有上限
A11: Color | B11: 道具品质 | C11: 0-白，1-绿，2-蓝，3-紫，4-橙
A12: BindType | B12: 绑定类型 | C12: BINDTYPE_NONE, //不绑定
C13: BINDTYPE_BOU, //使用绑定, bind on use
C14: BINDTYPE_BOE, //装备绑定, bind on equip
C15: BINDTYPE_BOP, //拾取绑定, bind on pick up
C16: BINDTYPE_BOT, //交易绑定, bind on trade
C17: BINDTYPE_BINDED = 10//已绑定
A18: DurType | B18: 耐久类型 | C18: DURTYPE_NONE, //无耐久
C19: DURTYPE_EQUIP, //装备耐久
C20: DURTYPE_STACK, //物品堆叠
C21: DURTYPE_USE, //使用次数
C22: DURTYPE_DEPOSIT //储值
A23: Dur | B23: 耐久对应的值
A24: SpellID | B24: 技能id
A25: SpellLevel | B25: 技能等级
A26: SelfCoolDown | B26: 道具自身cd时间
A27: GroupCoolDown | B27: 道具组cd时间
A28: SubSubType | B28: 子子类型 | C28: 没用到
A29: Price | B29: 卖店绑金价格
A30: UsedStatus | B30: 使用的状态 | C30: ITEMCOMBAT_BOTH, //道具使用不关心战斗状态
C31: ITEMCOMBAT_IN, //道具必须在战斗状态下使用 | F31: SoundActionType
C32: ITEMCOMBAT_OUT //道具必须在非战斗状态下使用 | F32: EIAST_Bag =0,
A33: CanDrop | B33: 可以丢弃 | C33: 1-可以，0-不可 | F33: EIAST_Book =1,
A34: Trade | B34: 可交易 | C34: 1-可以，0-不可 | F34: EIAST_ClothLeather =2,
A35: Storage | B35: 可存入仓库 | C35: 1-可以，0-不可 | F35: EIAST_FoodGeneric =3,
A36: Script | B36: 脚本编号 | F36: EIAST_Gems =4,
A37: DisplayIcon | B37: 道具图标 | F37: EIAST_Herb =5,
A38: Description | B38: tips描述 | F38: EIAST_LargeChain =6,
A39: MaxStackNum | B39: 一堆的数量 | F39: EIAST_SmallChain =7,
A40: DropMesh | B40: 掉落模型 | F40: EIAST_Meat =8,
...

Sheet 价目表
A1: 道具ID | B1: 道具名称 | C1: 标准商店价 | D1: 卖店价
A2: 0 | B2: 绑金 | C2: =D2*2 -> 2 | D2: =item!S4 -> 1
A3: 1 | B3: 金币 | C3: =D3*2 -> 2 | D3: =item!S5 -> 1
A4: 10 | B4: 经验 | C4: =D4*2 -> 2 | D4: =item!S6 -> 1
A5: 20 | B5: 公会贡献 | C5: =D5*2 -> 2 | D5: =item!S9 -> 1
A6: 301 | B6: 金创药(小量) | C6: =D6*2 -> 80 | D6: =item!S10 -> 40
A7: 302 | B7: 金创药(中量) | C7: =D7*2 -> 260 | D7: =item!S11 -> 130
A8: 303 | B8: 强效金创药 | C8: =D8*2 -> 700 | D8: =item!S12 -> 350
A9: 304 | B9: 超强金创药（占位） | C9: =D9*2 -> 2 | D9: =item!S13 -> 1
A10: 305 | B10: 金创药（占位） | C10: =D10*2 -> 2 | D10: =item!S14 -> 1
A11: 311 | B11: 小金创药(绑定) | C11: =D11*2 -> 2 | D11: =item!S18 -> 1
A12: 312 | B12: 中金创药(绑定) | C12: =D12*2 -> 2 | D12: =item!S19 -> 1
A13: 321 | B13: 魔法药(小量) | C13: =D13*2 -> 80 | D13: =item!S20 -> 40
A14: 322 | B14: 魔法药(中量) | C14: =D14*2 -> 260 | D14: =item!S21 -> 130
A15: 323 | B15: 强效魔法药 | C15: =D15*2 -> 700 | D15: =item!S22 -> 350
A16: 324 | B16: 超强魔法药(占位） | C16: =D16*2 -> 2 | D16: =item!S26 -> 1
A17: 331 | B17: 新手药水(绑定) | C17: =D17*2 -> 2 | D17: =item!S27 -> 1
A18: 351 | B18: 太阳水 | C18: =D18*2 -> 1000 | D18: =item!S28 -> 500
A19: 352 | B19: 强效太阳水 | C19: =D19*2 -> 2500 | D19: =item!S29 -> 1250
A20: 353 | B20: 疗伤药 | C20: =D20*2 -> 5000 | D20: =item!S30 -> 2500
A21: 361 | B21: 金创药(小)包 | C21: =D21*2 -> 480 | D21: =item!S36 -> 240
A22: 362 | B22: 金创药(中)包 | C22: =D22*2 -> 1560 | D22: =item!S37 -> 780
A23: 363 | B23: 超级金创药 | C23: =D23*2 -> 4200 | D23: =item!S38 -> 2100
A24: 371 | B24: 魔法药(小)包 | C24: =D24*2 -> 480 | D24: =item!S42 -> 240
A25: 372 | B25: 魔法药(中)包 | C25: =D25*2 -> 1560 | D25: =item!S43 -> 780
A26: 373 | B26: 超级魔法药 | C26: =D26*2 -> 4200 | D26: =item!S44 -> 2100
