Workbook

Sheet Sheet1
A1: QuestID | B1: NpcTemplateID | C1: NpcGroupID | D1: ResetType | E1: Desc | F1: Icon | G1: BaseClass | H1: SubClass | I1: Name1 | J1: KillCount1 | K1: AchievementPts1 | L1: RewardExp1 | M1: AutoTrace1 | N1: MinTraceLevel1 | O1: MaxTraceLevel1 | P1: Hide1 | Q1: Name2 | R1: KillCount2 | S1: AchievementPts2 | T1: RewardExp2 | U1: AutoTrace2 | V1: MinTraceLevel2 | W1: MaxTraceLevel2 | X1: Hide2 | Y1: Name3 | Z1: KillCount3 | AA1: AchievementPts3 | AB1: RewardExp3 | AC1: AutoTrace3 | AD1: MinTraceLevel3 | AE1: MaxTraceLevel3 | AF1: Hide3 | AG1: Name4 | AH1: KillCount4 | AI1: AchievementPts4 | AJ1: RewardExp4 | AK1: AutoTrace4 | AL1: MinTraceLevel4 | AM1: MaxTraceLevel4 | AN1: Hide4 | AO1: Name5 | AP1: KillCount5 | AQ1: AchievementPts5 | AR1: RewardExp5 | AS1: AutoTrace5 | AT1: MinTraceLevel5 | AU1: MaxTraceLevel5 | AV1: Hide5 | AW1: Name6 | AX1: KillCount6 | AY1: AchievementPts6 | AZ1: RewardExp6 | BA1: AutoTrace6 | BB1: MinTraceLevel6 | BC1: MaxTraceLevel6 | BD1: Hide6 | BE1: Name7 | BF1: KillCount7 | BG1: AchievementPts7 | BH1: RewardExp7 | BI1: AutoTrace7 | BJ1: MinTraceLevel7 | BK1: MaxTraceLevel7 | BL1: Hide7 | BM1: Name8 | BN1: KillCount8 | BO1: AchievementPts8 | BP1: RewardExp8 | BQ1: AutoTrace8 | BR1: MinTraceLevel8 | BS1: MaxTraceLevel8 | BT1: Hide8
A2: Both | B2: Both | C2: Both | D2: Server | E2: Client | F2: Client | G2: Client | H2: Client | I2: Both | J2: Both | K2: Both | L2: Both | M2: Client | N2: Client | O2: Client | P2: Client | Q2: Both | R2: Both | S2: Both | T2: Both | U2: Client | V2: Client | W2: Client | X2: Client | Y2: Both | Z2: Both | AA2: Both | AB2: Both | AC2: Client | AD2: Client | AE2: Client | AF2: Client | AG2: Both | AH2: Both | AI2: Both | AJ2: Both | AK2: Client | AL2: Client | AM2: Client | AN2: Client | AO2: Both | AP2: Both | AQ2: Both | AR2: Both | AS2: Client | AT2: Client | AU2: Client | AV2: Client | AW2: Both | AX2: Both | AY2: Both | AZ2: Both | BA2: Client | BB2: Client | BC2: Client | BD2: Client | BE2: Both | BF2: Both | BG2: Both | BH2: Both | BI2: Client | BJ2: Client | BK2: Client | BL2: Client | BM2: Both | BN2: Both | BO2: Both | BP2: Both | BQ2: Client | BR2: Client | BS2: Client | BT2: Client
A3: 0 | B3: 0 | C3: 0 | D3: 0 | E3: 0 | F3: 0 | G3: 0 | H3: 0 | I3: 0 | J3: 0 | K3: 0 | L3: 0 | M3: 0 | N3: 0 | O3: 0 | P3: 0 | Q3: 0 | R3: 0 | S3: 0 | T3: 0 | U3: 0 | V3: 0 | W3: 0 | X3: 0 | Y3: 0 | Z3: 0 | AA3: 0 | AB3: 0 | AC3: 0 | AD3: 0 | AE3: 0 | AF3: 0 | AG3: 0 | AH3: 0 | AI3: 0 | AJ3: 0 | AK3: 0 | AL3: 0 | AM3: 0 | AN3: 0 | AO3: 0 | AP3: 0 | AQ3: 0 | AR3: 0 | AS3: 0 | AT3: 0 | AU3: 0 | AV3: 0 | AW3: 0 | AX3: 0 | AY3: 0 | AZ3: 0 | BA3: 0 | BB3: 0 | BC3: 0 | BD3: 0 | BE3: 0 | BF3: 0 | BG3: 0 | BH3: 0 | BI3: 0 | BJ3: 0 | BK3: 0 | BL3: 0 | BM3: 0 | BN3: 0 | BO3: 0 | BP3: 0 | BQ3: 0 | BR3: 0 | BS3: 0 | BT3: 0
A4: 1 | B4: 0 | C4: 10003 | D4: qttNoReset | E4: 在边界村击败%d个稻草人 | F4: img://UI_Achievement.monster.801 | G4: 3 | H4: 2 | I4: 稻草人杀手 | J4: 10 | K4: 5 | L4: =ROUND(VLOOKUP($A4,索引!$A$2:$L$38,4,FALSE)*30%,-1) -> 50 | M4: 0 | N4: 0 | O4: 0 | P4: 0 | Q4: 稻草人猎手 | R4: 50 | S4: 5 | T4: =ROUND(VLOOKUP($A4,索引!$A$2:$L$38,4,FALSE)*70%,-1) -> 120 | U4: 0 | V4: 0 | W4: 0 | X4: 0 | Y4: 0 | Z4: 0 | AA4: 0 | AB4: 0 | AC4: 0 | AD4: 0 | AE4: 0 | AF4: 0 | AG4: 0 | AH4: 0 | AI4: 0 | AJ4: 0 | AK4: 0 | AL4: 0 | AM4: 0 | AN4: 0 | AO4: 0 | AP4: 0 | AQ4: 0 | AR4: 0 | AS4: 0 | AT4: 0 | AU4: 0 | AV4: 0 | AW4: 0 | AX4: 0 | AY4: 0 | AZ4: 0 | BA4: 0 | BB4: 0 | BC4: 0 | BD4: 0 | BE4: 0 | BF4: 0 | BG4: 0 | BH4: 0 | BI4: 0 | BJ4: 0 | BK4: 0 | BL4: 0 | BM4: 0 | BN4: 0 | BO4: 0 | BP4: 0 | BQ4: 0 | BR4: 0 | BS4: 0 | BT4: 0
A5: 2 | B5: 0 | C5: 10004 | D5: qttNoReset | E5: 在边界村击败%d个钉耙猫 | F5: img://UI_Achievement.monster.802 | G5: 3 | H5: 2 | I5: 钉耙猫杀手 | J5: 10 | K5: 5 | L5: =ROUND(VLOOKUP($A5,索引!$A$2:$L$38,4,FALSE)*30%,-1) -> 80 | M5: 0 | N5: 0 | O5: 0 | P5: 0 | Q5: 钉耙猫猎手 | R5: 50 | S5: 5 | T5: =ROUND(VLOOKUP($A5,索引!$A$2:$L$38,4,FALSE)*70%,-1) -> 190 | U5: 0 | V5: 0 | W5: 0 | X5: 0 | Y5: 0 | Z5: 0 | AA5: 0 | AB5: 0 | AC5: 0 | AD5: 0 | AE5: 0 | AF5: 0 | AG5: 0 | AH5: 0 | AI5: 0 | AJ5: 0 | AK5: 0 | AL5: 0 | AM5: 0 | AN5: 0 | AO5: 0 | AP5: 0 | AQ5: 0 | AR5: 0 | AS5: 0 | AT5: 0 | AU5: 0 | AV5: 0 | AW5: 0 | AX5: 0 | AY5: 0 | AZ5: 0 | BA5: 0 | BB5: 0 | BC5: 0 | BD5: 0 | BE5: 0 | BF5: 0 | BG5: 0 | BH5: 0 | BI5: 0 | BJ5: 0 | BK5: 0 | BL5: 0 | BM5: 0 | BN5: 0 | BO5: 0 | BP5: 0 | BQ5: 0 | BR5: 0 | BS5: 0 | BT5: 0
A6: 3 | B6: 0 | C6: 10025 | D6: qttNoReset | E6: 在比奇省击败%d个僵尸 | F6: img://UI_Achievement.monster.901 | G6: 3 | H6: 3 | I6: 尸魔猎人 | J6: 10 | K6: 10 | L6: =ROUND(VLOOKUP($A6,索引!$A$2:$L$38,4,FALSE)*15%,-1) -> 930 | M6: 0 | N6: 0 | O6: 0 | P6: 0 | Q6: 尸魔猎手 | R6: 50 | S6: 10 | T6: =ROUND(VLOOKUP($A6,索引!$A$2:$L$38,4,FALSE)*35%,-1) -> 2170 | U6: 0 | V6: 0 | W6: 0 | X6: 0 | Y6: 尸魔宿敌 | Z6: 200 | AA6: 10 | AB6: =ROUND(VLOOKUP($A6,索引!$A$2:$L$38,4,FALSE)*50%,-1) -> 3100 | AC6: 0 | AD6: 0 | AE6: 0 | AF6: 0 | AG6: 尸魔克星 | AH6: 1000 | AI6: 30 | AJ6: =ROUND(VLOOKUP($A6,索引!$A$2:$L$38,4,FALSE)*150%,-2) -> 9300 | AK6: 0 | AL6: 0 | AM6: 0 | AN6: 0 | AO6: 0 | AP6: 0 | AQ6: 0 | AR6: 0 | AS6: 0 | AT6: 0 | AU6: 0 | AV6: 0 | AW6: 0 | AX6: 0 | AY6: 0 | AZ6: 0 | BA6: 0 | BB6: 0 | BC6: 0 | BD6: 0 | BE6: 0 | BF6: 0 | BG6: 0 | BH6: 0 | BI6: 0 | BJ6: 0 | BK6: 0 | BL6: 0 | BM6: 0 | BN6: 0 | BO6: 0 | BP6: 0 | BQ6: 0 | BR6: 0 | BS6: 0 | BT6: 0
A7: 4 | B7: 0 | C7: 10024 | D7: qttNoReset | E7: 在比奇省击败%d个半兽人或半兽人战士 | F7: img://UI_Achievement.monster.803 | G7: 3 | H7: 3 | I7: 比奇半兽人驱逐者 | J7: 10 | K7: 10 | L7: =ROUND(VLOOKUP($A7,索引!$A$2:$L$38,4,FALSE)*8%,-1) -> 140 | M7: 0 | N7: 0 | O7: 0 | P7: 0 | Q7: 比奇半兽人抗击者 | R7: 50 | S7: 10 | T7: =ROUND(VLOOKUP($A7,索引!$A$2:$L$38,4,FALSE)*24%,-1) -> 430 | U7: 0 | V7: 0 | W7: 0 | X7: 0 | Y7: 比奇半兽人狙击者 | Z7: 200 | AA7: 10 | AB7: =ROUND(VLOOKUP($A7,索引!$A$2:$L$38,4,FALSE)*68%,-1) -> 1220 | AC7: 0 | AD7: 0 | AE7: 0 | AF7: 0 | AG7: 比奇半兽人灭绝者 | AH7: 1000 | AI7: 30 | AJ7: =ROUND(VLOOKUP($A7,索引!$A$2:$L$38,4,FALSE)*200%,-1) -> 3600 | AK7: 0 | AL7: 0 | AM7: 0 | AN7: 0 | AO7: 0 | AP7: 0 | AQ7: 0 | AR7: 0 | AS7: 0 | AT7: 0 | AU7: 0 | AV7: 0 | AW7: 0 | AX7: 0 | AY7: 0 | AZ7: 0 | BA7: 0 | BB7: 0 | BC7: 0 | BD7: 0 | BE7: 0 | BF7: 0 | BG7: 0 | BH7: 0 | BI7: 0 | BJ7: 0 | BK7: 0 | BL7: 0 | BM7: 0 | BN7: 0 | BO7: 0 | BP7: 0 | BQ7: 0 | BR7: 0 | BS7: 0 | BT7: 0
A8: 5 | B8: 0 | C8: 10010 | D8: qttNoReset | E8: 在沃玛森林击败%d个熊、鹿或狼 | F8: img://UI_Achievement.monster.3131 | G8: 3 | H8: 4 | I8: 动物杀手 | J8: 10 | K8: 10 | L8: =ROUND(VLOOKUP($A8,索引!$A$2:$L$38,4,FALSE)*8%,-1) -> 140 | M8: 0 | N8: 0 | O8: 0 | P8: 0 | Q8: 动物猎手 | R8: 50 | S8: 10 | T8: =ROUND(VLOOKUP($A8,索引!$A$2:$L$38,4,FALSE)*24%,-1) -> 430 | U8: 0 | V8: 0 | W8: 0 | X8: 0 | Y8: 动物宿敌 | Z8: 200 | AA8: 10 | AB8: =ROUND(VLOOKUP($A8,索引!$A$2:$L$38,4,FALSE)*68%,-1) -> 1220 | AC8: 0 | AD8: 0 | AE8: 0 | AF8: 0 | AG8: 动物克星 | AH8: 1000 | AI8: 30 | AJ8: =ROUND(VLOOKUP($A8,索引!$A$2:$L$38,4,FALSE)*200%,-1) -> 3600 | AK8: 0 | AL8: 0 | AM8: 0 | AN8: 0 | AO8: 0 | AP8: 0 | AQ8: 0 | AR8: 0 | AS8: 0 | AT8: 0 | AU8: 0 | AV8: 0 | AW8: 0 | AX8: 0 | AY8: 0 | AZ8: 0 | BA8: 0 | BB8: 0 | BC8: 0 | BD8: 0 | BE8: 0 | BF8: 0 | BG8: 0 | BH8: 0 | BI8: 0 | BJ8: 0 | BK8: 0 | BL8: 0 | BM8: 0 | BN8: 0 | BO8: 0 | BP8: 0 | BQ8: 0 | BR8: 0 | BS8: 0 | BT8: 0
A9: 6 | B9: 0 | C9: 10009 | D9: qttNoReset | E9: 在沃玛森林击败%d个半兽人、半兽人战士或半兽人勇士 | F9: img://UI_Achievement.monster.803 | G9: 3 | H9: 4 | I9: 半兽人杀手 | J9: 10 | K9: 10 | L9: =ROUND(VLOOKUP($A9,索引!$A$2:$L$38,4,FALSE)*8%,-1) -> 140 | M9: 0 | N9: 0 | O9: 0 | P9: 0 | Q9: 半兽人猎手 | R9: 50 | S9: 10 | T9: =ROUND(VLOOKUP($A9,索引!$A$2:$L$38,4,FALSE)*24%,-1) -> 430 | U9: 0 | V9: 0 | W9: 0 | X9: 0 | Y9: 半兽人宿敌 | Z9: 200 | AA9: 10 | AB9: =ROUND(VLOOKUP($A9,索引!$A$2:$L$38,4,FALSE)*68%,-1) -> 1220 | AC9: 0 | AD9: 0 | AE9: 0 | AF9: 0 | AG9: 半兽人克星 | AH9: 1000 | AI9: 30 | AJ9: =ROUND(VLOOKUP($A9,索引!$A$2:$L$38,4,FALSE)*200%,-1) -> 3600 | AK9: 0 | AL9: 0 | AM9: 0 | AN9: 0 | AO9: 0 | AP9: 0 | AQ9: 0 | AR9: 0 | AS9: 0 | AT9: 0 | AU9: 0 | AV9: 0 | AW9: 0 | AX9: 0 | AY9: 0 | AZ9: 0 | BA9: 0 | BB9: 0 | BC9: 0 | BD9: 0 | BE9: 0 | BF9: 0 | BG9: 0 | BH9: 0 | BI9: 0 | BJ9: 0 | BK9: 0 | BL9: 0 | BM9: 0 | BN9: 0 | BO9: 0 | BP9: 0 | BQ9: 0 | BR9: 0 | BS9: 0 | BT9: 0
A10: 7 | B10: 0 | C10: 10042 | D10: qttNoReset | E10: 在沃玛森林击败%d个巨力士：虎勇、火舞者或冰刀 | F10: img://UI_Achievement.monster.803 | G10: 3 | H10: 4 | I10: 巨力士征服者 | J10: 1 | K10: 20 | L10: =ROUND(VLOOKUP($A10,索引!$A$2:$L$38,4,FALSE)*100%,-1) -> 600 | M10: 0 | N10: 0 | O10: 0 | P10: 0 | Q10: 0 | R10: 0 | S10: 0 | T10: 0 | U10: 0 | V10: 0 | W10: 0 | X10: 0 | Y10: 0 | Z10: 0 | AA10: 0 | AB10: 0 | AC10: 0 | AD10: 0 | AE10: 0 | AF10: 0 | AG10: 0 | AH10: 0 | AI10: 0 | AJ10: 0 | AK10: 0 | AL10: 0 | AM10: 0 | AN10: 0 | AO10: 0 | AP10: 0 | AQ10: 0 | AR10: 0 | AS10: 0 | AT10: 0 | AU10: 0 | AV10: 0 | AW10: 0 | AX10: 0 | AY10: 0 | AZ10: 0 | BA10: 0 | BB10: 0 | BC10: 0 | BD10: 0 | BE10: 0 | BF10: 0 | BG10: 0 | BH10: 0 | BI10: 0 | BJ10: 0 | BK10: 0 | BL10: 0 | BM10: 0 | BN10: 0 | BO10: 0 | BP10: 0 | BQ10: 0 | BR10: 0 | BS10: 0 | BT10: 0
A11: 8 | B11: 0 | C11: 10043 | D11: qttNoReset | E11: 在沃玛森林击败%d个蛮战士：怒号、血角或铜须 | F11: img://UI_Achievement.monster.3126 | G11: 3 | H11: 4 | I11: 蛮战士征服者 | J11: 1 | K11: 20 | L11: =ROUND(VLOOKUP($A11,索引!$A$2:$L$38,4,FALSE)*100%,-1) -> 600 | M11: 0 | N11: 0 | O11: 0 | P11: 0 | Q11: 0 | R11: 0 | S11: 0 | T11: 0 | U11: 0 | V11: 0 | W11: 0 | X11: 0 | Y11: 0 | Z11: 0 | AA11: 0 | AB11: 0 | AC11: 0 | AD11: 0 | AE11: 0 | AF11: 0 | AG11: 0 | AH11: 0 | AI11: 0 | AJ11: 0 | AK11: 0 | AL11: 0 | AM11: 0 | AN11: 0 | AO11: 0 | AP11: 0 | AQ11: 0 | AR11: 0 | AS11: 0 | AT11: 0 | AU11: 0 | AV11: 0 | AW11: 0 | AX11: 0 | AY11: 0 | AZ11: 0 | BA11: 0 | BB11: 0 | BC11: 0 | BD11: 0 | BE11: 0 | BF11: 0 | BG11: 0 | BH11: 0 | BI11: 0 | BJ11: 0 | BK11: 0 | BL11: 0 | BM11: 0 | BN11: 0 | BO11: 0 | BP11: 0 | BQ11: 0 | BR11: 0 | BS11: 0 | BT11: 0
A12: 9 | B12: 0 | C12: 10015 | D12: qttNoReset | E12: 在盟重省击败%d个盔甲虫、腐蚀虫、多角虫或巨型多角虫 | F12: img://UI_Achievement.monster.961 | G12: 3 | H12: 5 | I12: 盟重虫族杀手 | J12: 10 | K12: 10 | L12: =ROUND(VLOOKUP($A12,索引!$A$2:$L$38,4,FALSE)*8%,-1) -> 190 | M12: 0 | N12: 0 | O12: 0 | P12: 0 | Q12: 盟重虫族猎手 | R12: 50 | S12: 10 | T12: =ROUND(VLOOKUP($A12,索引!$A$2:$L$38,4,FALSE)*24%,-1) -> 580 | U12: 0 | V12: 0 | W12: 0 | X12: 0 | Y12: 盟重虫族宿敌 | Z12: 200 | AA12: 10 | AB12: =ROUND(VLOOKUP($A12,索引!$A$2:$L$38,4,FALSE)*68%,-1) -> 1630 | AC12: 0 | AD12: 0 | AE12: 0 | AF12: 0 | AG12: 盟重虫族克星 | AH12: 1000 | AI12: 30 | AJ12: =ROUND(VLOOKUP($A12,索引!$A$2:$L$38,4,FALSE)*200%,-1) -> 4800 | AK12: 0 | AL12: 0 | AM12: 0 | AN12: 0 | AO12: 0 | AP12: 0 | AQ12: 0 | AR12: 0 | AS12: 0 | AT12: 0 | AU12: 0 | AV12: 0 | AW12: 0 | AX12: 0 | AY12: 0 | AZ12: 0 | BA12: 0 | BB12: 0 | BC12: 0 | BD12: 0 | BE12: 0 | BF12: 0 | BG12: 0 | BH12: 0 | BI12: 0 | BJ12: 0 | BK12: 0 | BL12: 0 | BM12: 0 | BN12: 0 | BO12: 0 | BP12: 0 | BQ12: 0 | BR12: 0 | BS12: 0 | BT12: 0
A13: 10 | B13: 0 | C13: 10016 | D13: qttNoReset | E13: 在盟重省击败%d个狼 | F13: img://UI_Achievement.monster.3134 | G13: 3 | H13: 5 | I13: 盟重狼杀手 | J13: 10 | K13: 10 | L13: =ROUND(VLOOKUP($A13,索引!$A$2:$L$38,4,FALSE)*8%,-1) -> 170 | M13: 0 | N13: 0 | O13: 0 | P13: 0 | Q13: 盟重狼猎手 | R13: 50 | S13: 10 | T13: =ROUND(VLOOKUP($A13,索引!$A$2:$L$38,4,FALSE)*24%,-1) -> 500 | U13: 0 | V13: 0 | W13: 0 | X13: 0 | Y13: 盟重狼宿敌 | Z13: 200 | AA13: 10 | AB13: =ROUND(VLOOKUP($A13,索引!$A$2:$L$38,4,FALSE)*68%,-1) -> 1430 | AC13: 0 | AD13: 0 | AE13: 0 | AF13: 0 | AG13: 盟重狼克星 | AH13: 1000 | AI13: 30 | AJ13: =ROUND(VLOOKUP($A13,索引!$A$2:$L$38,4,FALSE)*200%,-1) -> 4200 | AK13: 0 | AL13: 0 | AM13: 0 | AN13: 0 | AO13: 0 | AP13: 0 | AQ13: 0 | AR13: 0 | AS13: 0 | AT13: 0 | AU13: 0 | AV13: 0 | AW13: 0 | AX13: 0 | AY13: 0 | AZ13: 0 | BA13: 0 | BB13: 0 | BC13: 0 | BD13: 0 | BE13: 0 | BF13: 0 | BG13: 0 | BH13: 0 | BI13: 0 | BJ13: 0 | BK13: 0 | BL13: 0 | BM13: 0 | BN13: 0 | BO13: 0 | BP13: 0 | BQ13: 0 | BR13: 0 | BS13: 0 | BT13: 0
A14: 11 | B14: 0 | C14: 10048 | D14: qttNoReset | E14: 在盟重省击败%d个废墟魔狼：丑面、尖耳或疾电 | F14: img://UI_Achievement.monster.3134 | G14: 3 | H14: 5 | I14: 废墟魔狼征服者 | J14: 1 | K14: 20 | L14: =ROUND(VLOOKUP($A14,索引!$A$2:$L$38,4,FALSE)*100%,-1) -> 800 | M14: 0 | N14: 0 | O14: 0 | P14: 0 | Q14: 0 | R14: 0 | S14: 0 | T14: 0 | U14: 0 | V14: 0 | W14: 0 | X14: 0 | Y14: 0 | Z14: 0 | AA14: 0 | AB14: 0 | AC14: 0 | AD14: 0 | AE14: 0 | AF14: 0 | AG14: 0 | AH14: 0 | AI14: 0 | AJ14: 0 | AK14: 0 | AL14: 0 | AM14: 0 | AN14: 0 | AO14: 0 | AP14: 0 | AQ14: 0 | AR14: 0 | AS14: 0 | AT14: 0 | AU14: 0 | AV14: 0 | AW14: 0 | AX14: 0 | AY14: 0 | AZ14: 0 | BA14: 0 | BB14: 0 | BC14: 0 | BD14: 0 | BE14: 0 | BF14: 0 | BG14: 0 | BH14: 0 | BI14: 0 | BJ14: 0 | BK14: 0 | BL14: 0 | BM14: 0 | BN14: 0 | BO14: 0 | BP14: 0 | BQ14: 0 | BR14: 0 | BS14: 0 | BT14: 0
A15: 12 | B15: 0 | C15: 10049 | D15: qttNoReset | E15: 在盟重省击败%d个铁腹角虫：六足、尖角或斑纹 | F15: img://UI_Achievement.monster.963 | G15: 3 | H15: 5 | I15: 铁腹角虫征服者 | J15: 1 | K15: 20 | L15: =ROUND(VLOOKUP($A15,索引!$A$2:$L$38,4,FALSE)*100%,-1) -> 800 | M15: 0 | N15: 0 | O15: 0 | P15: 0 | Q15: 0 | R15: 0 | S15: 0 | T15: 0 | U15: 0 | V15: 0 | W15: 0 | X15: 0 | Y15: 0 | Z15: 0 | AA15: 0 | AB15: 0 | AC15: 0 | AD15: 0 | AE15: 0 | AF15: 0 | AG15: 0 | AH15: 0 | AI15: 0 | AJ15: 0 | AK15: 0 | AL15: 0 | AM15: 0 | AN15: 0 | AO15: 0 | AP15: 0 | AQ15: 0 | AR15: 0 | AS15: 0 | AT15: 0 | AU15: 0 | AV15: 0 | AW15: 0 | AX15: 0 | AY15: 0 | AZ15: 0 | BA15: 0 | BB15: 0 | BC15: 0 | BD15: 0 | BE15: 0 | BF15: 0 | BG15: 0 | BH15: 0 | BI15: 0 | BJ15: 0 | BK15: 0 | BL15: 0 | BM15: 0 | BN15: 0 | BO15: 0 | BP15: 0 | BQ15: 0 | BR15: 0 | BS15: 0 | BT15: 0
A16: 13 | B16: 2113 | C16: 0 | D16: qttWeek | E16: 杀死%d个分布在幽冥海四层的毒魔 | F16: img://UI_Achievement.monster.2113 | G16: 4 | H16: 1 | I16: 降魔斗士 | J16: 20 | K16: 0 | L16: =索引!D40 -> 30000 | M16: 0 | N16: 0 | O16: 0 | P16: 0 | Q16: 0 | R16: 0 | S16: 0 | T16: 0 | U16: 0 | V16: 0 | W16: 0 | X16: 0 | Y16: 0 | Z16: 0 | AA16: 0 | AB16: 0 | AC16: 0 | AD16: 0 | AE16: 0 | AF16: 0 | AG16: 0 | AH16: 0 | AI16: 0 | AJ16: 0 | AK16: 0 | AL16: 0 | AM16: 0 | AN16: 0 | AO16: 0 | AP16: 0 | AQ16: 0 | AR16: 0 | AS16: 0 | AT16: 0 | AU16: 0 | AV16: 0 | AW16: 0 | AX16: 0 | AY16: 0 | AZ16: 0 | BA16: 0 | BB16: 0 | BC16: 0 | BD16: 0 | BE16: 0 | BF16: 0 | BG16: 0 | BH16: 0 | BI16: 0 | BJ16: 0 | BK16: 0 | BL16: 0 | BM16: 0 | BN16: 0 | BO16: 0 | BP16: 0 | BQ16: 0 | BR16: 0 | BS16: 0 | BT16: 0
A17: 14 | B17: 0 | C17: 10006 | D17: qttNoReset | E17: 在比奇矿区击败%d个僵尸 | F17: img://UI_Achievement.monster.901 | G17: 3 | H17: 6 | I17: 僵尸杀手 | J17: 20 | K17: 10 | L17: =ROUND(VLOOKUP($A17,索引!$A$2:$L$38,4,FALSE)*3%,-2) -> 1900 | M17: 0 | N17: 0 | O17: 0 | P17: 0 | Q17: 僵尸猎手 | R17: 100 | S17: 10 | T17: =ROUND(VLOOKUP($A17,索引!$A$2:$L$38,4,FALSE)*9%,-2) -> 5600 | U17: 0 | V17: 0 | W17: 0 | X17: 0 | Y17: 僵尸宿敌 | Z17: 500 | AA17: 10 | AB17: =ROUND(VLOOKUP($A17,索引!$A$2:$L$38,4,FALSE)*27%,-2) -> 16700 | AC17: 0 | AD17: 0 | AE17: 0 | AF17: 0 | AG17: 僵尸克星 | AH17: 2000 | AI17: 30 | AJ17: =ROUND(VLOOKUP($A17,索引!$A$2:$L$38,4,FALSE)*61%,-2) -> 37800 | AK17: 0 | AL17: 0 | AM17: 0 | AN17: 0 | AO17: 0 | AP17: 0 | AQ17: 0 | AR17: 0 | AS17: 0 | AT17: 0 | AU17: 0 | AV17: 0 | AW17: 0 | AX17: 0 | AY17: 0 | AZ17: 0 | BA17: 0 | BB17: 0 | BC17: 0 | BD17: 0 | BE17: 0 | BF17: 0 | BG17: 0 | BH17: 0 | BI17: 0 | BJ17: 0 | BK17: 0 | BL17: 0 | BM17: 0 | BN17: 0 | BO17: 0 | BP17: 0 | BQ17: 0 | BR17: 0 | BS17: 0 | BT17: 0
A18: 15 | B18: 0 | C18: 10038 | D18: qttNoReset | E18: 在比奇矿区击败%d个僵尸护卫：杜杀、黑子或黑鹰 | F18: img://UI_Achievement.monster.3097 | G18: 3 | H18: 6 | I18: 僵尸护卫征服者 | J18: 1 | K18: 20 | L18: =ROUND(VLOOKUP($A18,索引!$A$2:$L$38,4,FALSE)*100%,-2) -> 2500 | M18: 0 | N18: 0 | O18: 0 | P18: 0 | Q18: 0 | R18: 0 | S18: 0 | T18: 0 | U18: 0 | V18: 0 | W18: 0 | X18: 0 | Y18: 0 | Z18: 0 | AA18: 0 | AB18: 0 | AC18: 0 | AD18: 0 | AE18: 0 | AF18: 0 | AG18: 0 | AH18: 0 | AI18: 0 | AJ18: 0 | AK18: 0 | AL18: 0 | AM18: 0 | AN18: 0 | AO18: 0 | AP18: 0 | AQ18: 0 | AR18: 0 | AS18: 0 | AT18: 0 | AU18: 0 | AV18: 0 | AW18: 0 | AX18: 0 | AY18: 0 | AZ18: 0 | BA18: 0 | BB18: 0 | BC18: 0 | BD18: 0 | BE18: 0 | BF18: 0 | BG18: 0 | BH18: 0 | BI18: 0 | BJ18: 0 | BK18: 0 | BL18: 0 | BM18: 0 | BN18: 0 | BO18: 0 | BP18: 0 | BQ18: 0 | BR18: 0 | BS18: 0 | BT18: 0
A19: 16 | B19: 0 | C19: 10039 | D19: qttNoReset | E19: 在比奇矿区击败%d个僵尸强盗：黑山、金豹或杜冷 | F19: img://UI_Achievement.monster.3100 | G19: 3 | H19: 6 | I19: 僵尸强盗征服者 | J19: 1 | K19: 20 | L19: =ROUND(VLOOKUP($A19,索引!$A$2:$L$38,4,FALSE)*100%,-2) -> 2500 | M19: 0 | N19: 0 | O19: 0 | P19: 0 | Q19: 0 | R19: 0 | S19: 0 | T19: 0 | U19: 0 | V19: 0 | W19: 0 | X19: 0 | Y19: 0 | Z19: 0 | AA19: 0 | AB19: 0 | AC19: 0 | AD19: 0 | AE19: 0 | AF19: 0 | AG19: 0 | AH19: 0 | AI19: 0 | AJ19: 0 | AK19: 0 | AL19: 0 | AM19: 0 | AN19: 0 | AO19: 0 | AP19: 0 | AQ19: 0 | AR19: 0 | AS19: 0 | AT19: 0 | AU19: 0 | AV19: 0 | AW19: 0 | AX19: 0 | AY19: 0 | AZ19: 0 | BA19: 0 | BB19: 0 | BC19: 0 | BD19: 0 | BE19: 0 | BF19: 0 | BG19: 0 | BH19: 0 | BI19: 0 | BJ19: 0 | BK19: 0 | BL19: 0 | BM19: 0 | BN19: 0 | BO19: 0 | BP19: 0 | BQ19: 0 | BR19: 0 | BS19: 0 | BT19: 0
A20: 17 | B20: 2189 | C20: 0 | D20: qttWeek | E20: 在皇室宝库里杀死%d个宝库大盗 | F20: img://UI_Achievement.monster.3135 | G20: 4 | H20: 1 | I20: 人生赢家 | J20: 2 | K20: 0 | L20: 20000 | M20: 0 | N20: 0 | O20: 0 | P20: 0 | Q20: 0 | R20: 0 | S20: 0 | T20: 0 | U20: 0 | V20: 0 | W20: 0 | X20: 0 | Y20: 0 | Z20: 0 | AA20: 0 | AB20: 0 | AC20: 0 | AD20: 0 | AE20: 0 | AF20: 0 | AG20: 0 | AH20: 0 | AI20: 0 | AJ20: 0 | AK20: 0 | AL20: 0 | AM20: 0 | AN20: 0 | AO20: 0 | AP20: 0 | AQ20: 0 | AR20: 0 | AS20: 0 | AT20: 0 | AU20: 0 | AV20: 0 | AW20: 0 | AX20: 0 | AY20: 0 | AZ20: 0 | BA20: 0 | BB20: 0 | BC20: 0 | BD20: 0 | BE20: 0 | BF20: 0 | BG20: 0 | BH20: 0 | BI20: 0 | BJ20: 0 | BK20: 0 | BL20: 0 | BM20: 0 | BN20: 0 | BO20: 0 | BP20: 0 | BQ20: 0 | BR20: 0 | BS20: 0 | BT20: 0
A21: 18 | B21: 3248 | C21: 0 | D21: qttWeek | E21: 杀死%d个虹魔教主身边的白野猪暴徒 | F21: img://UI_Achievement.monster.1034 | G21: 4 | H21: 1 | I21: 铲除帮凶 | J21: 10 | K21: 0 | L21: 20000 | M21: 0 | N21: 0 | O21: 0 | P21: 0 | Q21: 0 | R21: 0 | S21: 0 | T21: 0 | U21: 0 | V21: 0 | W21: 0 | X21: 0 | Y21: 0 | Z21: 0 | AA21: 0 | AB21: 0 | AC21: 0 | AD21: 0 | AE21: 0 | AF21: 0 | AG21: 0 | AH21: 0 | AI21: 0 | AJ21: 0 | AK21: 0 | AL21: 0 | AM21: 0 | AN21: 0 | AO21: 0 | AP21: 0 | AQ21: 0 | AR21: 0 | AS21: 0 | AT21: 0 | AU21: 0 | AV21: 0 | AW21: 0 | AX21: 0 | AY21: 0 | AZ21: 0 | BA21: 0 | BB21: 0 | BC21: 0 | BD21: 0 | BE21: 0 | BF21: 0 | BG21: 0 | BH21: 0 | BI21: 0 | BJ21: 0 | BK21: 0 | BL21: 0 | BM21: 0 | BN21: 0 | BO21: 0 | BP21: 0 | BQ21: 0 | BR21: 0 | BS21: 0 | BT21: 0
A22: 19 | B22: 5268 | C22: 0 | D22: qttNoReset | E22: 在尸王殿击败%d个尸王 | F22: img://UI_Achievement.monster.5268 | G22: 3 | H22: 6 | I22: 首杀：尸王 | J22: 1 | K22: 50 | L22: =索引!D50 -> 20000 | M22: 0 | N22: 0 | O22: 0 | P22: 0 | Q22: 0 | R22: 0 | S22: 0 | T22: 0 | U22: 0 | V22: 0 | W22: 0 | X22: 0 | Y22: 0 | Z22: 0 | AA22: 0 | AB22: 0 | AC22: 0 | AD22: 0 | AE22: 0 | AF22: 0 | AG22: 0 | AH22: 0 | AI22: 0 | AJ22: 0 | AK22: 0 | AL22: 0 | AM22: 0 | AN22: 0 | AO22: 0 | AP22: 0 | AQ22: 0 | AR22: 0 | AS22: 0 | AT22: 0 | AU22: 0 | AV22: 0 | AW22: 0 | AX22: 0 | AY22: 0 | AZ22: 0 | BA22: 0 | BB22: 0 | BC22: 0 | BD22: 0 | BE22: 0 | BF22: 0 | BG22: 0 | BH22: 0 | BI22: 0 | BJ22: 0 | BK22: 0 | BL22: 0 | BM22: 0 | BN22: 0 | BO22: 0 | BP22: 0 | BQ22: 0 | BR22: 0 | BS22: 0 | BT22: 0
A23: 20 | B23: 0 | C23: 10014 | D23: qttNoReset | E23: 在沃玛寺庙击败%d个山洞蝙蝠或黑色恶蛆 | F23: img://UI_Achievement.monster.3110 | G23: 3 | H23: 7 | I23: 黑暗生物杀手 | J23: 50 | K23: 10 | L23: =ROUND(VLOOKUP($A23,索引!$A$2:$L$38,4,FALSE)*2%,-2) -> 5100 | M23: 0 | N23: 0 | O23: 0 | P23: 0 | Q23: 黑暗生物猎手 | R23: 200 | S23: 10 | T23: =ROUND(VLOOKUP($A23,索引!$A$2:$L$38,4,FALSE)*5%,-2) -> 12800 | U23: 0 | V23: 0 | W23: 0 | X23: 0 | Y23: 黑暗生物宿敌 | Z23: 1000 | AA23: 10 | AB23: =ROUND(VLOOKUP($A23,索引!$A$2:$L$38,4,FALSE)*12%,-2) -> 30600 | AC23: 0 | AD23: 0 | AE23: 0 | AF23: 0 | AG23: 黑暗生物克星 | AH23: 3000 | AI23: 30 | AJ23: =ROUND(VLOOKUP($A23,索引!$A$2:$L$38,4,FALSE)*25%,-2) -> 63800 | AK23: 0 | AL23: 0 | AM23: 0 | AN23: 0 | AO23: 黑暗生物的噩梦 | AP23: 10000 | AQ23: 50 | AR23: =ROUND(VLOOKUP($A23,索引!$A$2:$L$38,4,FALSE)*56%,-3) -> 143000 | AS23: 0 | AT23: 0 | AU23: 0 | AV23: 0 | AW23: 0 | AX23: 0 | AY23: 0 | AZ23: 0 | BA23: 0 | BB23: 0 | BC23: 0 | BD23: 0 | BE23: 0 | BF23: 0 | BG23: 0 | BH23: 0 | BI23: 0 | BJ23: 0 | BK23: 0 | BL23: 0 | BM23: 0 | BN23: 0 | BO23: 0 | BP23: 0 | BQ23: 0 | BR23: 0 | BS23: 0 | BT23: 0
A24: 21 | B24: 0 | C24: 10013 | D24: qttNoReset | E24: 击败%d个沃玛战士/卫兵/斥候/勇士/战将/火焰沃玛 | F24: img://UI_Achievement.monster.942 | G24: 3 | H24: 7 | I24: 沃玛生物杀手 | J24: 50 | K24: 10 | L24: =ROUND(VLOOKUP($A24,索引!$A$2:$L$38,4,FALSE)*2%,-2) -> 6600 | M24: 0 | N24: 0 | O24: 0 | P24: 0 | Q24: 沃玛生物猎手 | R24: 200 | S24: 10 | T24: =ROUND(VLOOKUP($A24,索引!$A$2:$L$38,4,FALSE)*5%,-2) -> 16500 | U24: 0 | V24: 0 | W24: 0 | X24: 0 | Y24: 沃玛生物宿敌 | Z24: 1000 | AA24: 10 | AB24: =ROUND(VLOOKUP($A24,索引!$A$2:$L$38,4,FALSE)*12%,-2) -> 39600 | AC24: 0 | AD24: 0 | AE24: 0 | AF24: 0 | AG24: 沃玛生物克星 | AH24: 3000 | AI24: 30 | AJ24: =ROUND(VLOOKUP($A24,索引!$A$2:$L$38,4,FALSE)*25%,-2) -> 82500 | AK24: 0 | AL24: 0 | AM24: 0 | AN24: 0 | AO24: 沃玛生物的噩梦 | AP24: 10000 | AQ24: 50 | AR24: =ROUND(VLOOKUP($A24,索引!$A$2:$L$38,4,FALSE)*56%,-3) -> 185000 | AS24: 0 | AT24: 0 | AU24: 0 | AV24: 0 | AW24: 0 | AX24: 0 | AY24: 0 | AZ24: 0 | BA24: 0 | BB24: 0 | BC24: 0 | BD24: 0 | BE24: 0 | BF24: 0 | BG24: 0 | BH24: 0 | BI24: 0 | BJ24: 0 | BK24: 0 | BL24: 0 | BM24: 0 | BN24: 0 | BO24: 0 | BP24: 0 | BQ24: 0 | BR24: 0 | BS24: 0 | BT24: 0
A25: 22 | B25: 0 | C25: 10044 | D25: qttNoReset | E25: 在沃玛寺庙击败%d个疯魔卫：无畏、铁蹄或钢角 | F25: img://UI_Achievement.monster.943 | G25: 3 | H25: 7 | I25: 疯魔卫征服者 | J25: 1 | K25: 20 | L25: =ROUND(VLOOKUP($A25,索引!$A$2:$L$38,4,FALSE)*100%,-2) -> 4000 | M25: 0 | N25: 0 | O25: 0 | P25: 0 | Q25: 0 | R25: 0 | S25: 0 | T25: 0 | U25: 0 | V25: 0 | W25: 0 | X25: 0 | Y25: 0 | Z25: 0 | AA25: 0 | AB25: 0 | AC25: 0 | AD25: 0 | AE25: 0 | AF25: 0 | AG25: 0 | AH25: 0 | AI25: 0 | AJ25: 0 | AK25: 0 | AL25: 0 | AM25: 0 | AN25: 0 | AO25: 0 | AP25: 0 | AQ25: 0 | AR25: 0 | AS25: 0 | AT25: 0 | AU25: 0 | AV25: 0 | AW25: 0 | AX25: 0 | AY25: 0 | AZ25: 0 | BA25: 0 | BB25: 0 | BC25: 0 | BD25: 0 | BE25: 0 | BF25: 0 | BG25: 0 | BH25: 0 | BI25: 0 | BJ25: 0 | BK25: 0 | BL25: 0 | BM25: 0 | BN25: 0 | BO25: 0 | BP25: 0 | BQ25: 0 | BR25: 0 | BS25: 0 | BT25: 0
A26: 23 | B26: 0 | C26: 10045 | D26: qttNoReset | E26: 在沃玛寺庙击败%d个鬼域守卫：鬼面、羊钉或怒锤 | F26: img://UI_Achievement.monster.944 | G26: 3 | H26: 7 | I26: 鬼域守卫征服者 | J26: 1 | K26: 20 | L26: =ROUND(VLOOKUP($A26,索引!$A$2:$L$38,4,FALSE)*100%,-2) -> 4000 | M26: 0 | N26: 0 | O26: 0 | P26: 0 | Q26: 0 | R26: 0 | S26: 0 | T26: 0 | U26: 0 | V26: 0 | W26: 0 | X26: 0 | Y26: 0 | Z26: 0 | AA26: 0 | AB26: 0 | AC26: 0 | AD26: 0 | AE26: 0 | AF26: 0 | AG26: 0 | AH26: 0 | AI26: 0 | AJ26: 0 | AK26: 0 | AL26: 0 | AM26: 0 | AN26: 0 | AO26: 0 | AP26: 0 | AQ26: 0 | AR26: 0 | AS26: 0 | AT26: 0 | AU26: 0 | AV26: 0 | AW26: 0 | AX26: 0 | AY26: 0 | AZ26: 0 | BA26: 0 | BB26: 0 | BC26: 0 | BD26: 0 | BE26: 0 | BF26: 0 | BG26: 0 | BH26: 0 | BI26: 0 | BJ26: 0 | BK26: 0 | BL26: 0 | BM26: 0 | BN26: 0 | BO26: 0 | BP26: 0 | BQ26: 0 | BR26: 0 | BS26: 0 | BT26: 0
A27: 24 | B27: 1078 | C27: 0 | D27: qttWeek | E27: 杀死%d个祖玛教主身边的邪箭弓手 | F27: img://UI_Achievement.monster.942 | G27: 4 | H27: 1 | I27: 铲除鹰犬 | J27: 10 | K27: 0 | L27: 25000 | M27: 0 | N27: 0 | O27: 0 | P27: 0 | Q27: 0 | R27: 0 | S27: 0 | T27: 0 | U27: 0 | V27: 0 | W27: 0 | X27: 0 | Y27: 0 | Z27: 0 | AA27: 0 | AB27: 0 | AC27: 0 | AD27: 0 | AE27: 0 | AF27: 0 | AG27: 0 | AH27: 0 | AI27: 0 | AJ27: 0 | AK27: 0 | AL27: 0 | AM27: 0 | AN27: 0 | AO27: 0 | AP27: 0 | AQ27: 0 | AR27: 0 | AS27: 0 | AT27: 0 | AU27: 0 | AV27: 0 | AW27: 0 | AX27: 0 | AY27: 0 | AZ27: 0 | BA27: 0 | BB27: 0 | BC27: 0 | BD27: 0 | BE27: 0 | BF27: 0 | BG27: 0 | BH27: 0 | BI27: 0 | BJ27: 0 | BK27: 0 | BL27: 0 | BM27: 0 | BN27: 0 | BO27: 0 | BP27: 0 | BQ27: 0 | BR27: 0 | BS27: 0 | BT27: 0
A28: 26 | B28: 5278 | C28: 0 | D28: qttNoReset | E28: 在沃玛寺庙三层击败%d个沃玛教主 | F28: img://UI_Achievement.monster.5278 | G28: 3 | H28: 7 | I28: 首杀：沃玛教主 | J28: 1 | K28: 50 | L28: =索引!D51 -> 35000 | M28: 0 | N28: 0 | O28: 0 | P28: 0 | Q28: 0 | R28: 0 | S28: 0 | T28: 0 | U28: 0 | V28: 0 | W28: 0 | X28: 0 | Y28: 0 | Z28: 0 | AA28: 0 | AB28: 0 | AC28: 0 | AD28: 0 | AE28: 0 | AF28: 0 | AG28: 0 | AH28: 0 | AI28: 0 | AJ28: 0 | AK28: 0 | AL28: 0 | AM28: 0 | AN28: 0 | AO28: 0 | AP28: 0 | AQ28: 0 | AR28: 0 | AS28: 0 | AT28: 0 | AU28: 0 | AV28: 0 | AW28: 0 | AX28: 0 | AY28: 0 | AZ28: 0 | BA28: 0 | BB28: 0 | BC28: 0 | BD28: 0 | BE28: 0 | BF28: 0 | BG28: 0 | BH28: 0 | BI28: 0 | BJ28: 0 | BK28: 0 | BL28: 0 | BM28: 0 | BN28: 0 | BO28: 0 | BP28: 0 | BQ28: 0 | BR28: 0 | BS28: 0 | BT28: 0
A29: 27 | B29: 0 | C29: 10018 | D29: qttNoReset | E29: 在死亡峡谷击败%d个蜈蚣、巨型蠕虫、钳虫或跳跳蜂 | F29: img://UI_Achievement.monster.1011 | G29: 3 | H29: 8 | I29: 虫族杀手 | J29: 50 | K29: 10 | L29: =ROUND(VLOOKUP($A29,索引!$A$2:$L$38,4,FALSE)*2%,-2) -> 6900 | M29: 0 | N29: 0 | O29: 0 | P29: 0 | Q29: 虫族猎手 | R29: 200 | S29: 10 | T29: =ROUND(VLOOKUP($A29,索引!$A$2:$L$38,4,FALSE)*5%,-2) -> 17300 | U29: 0 | V29: 0 | W29: 0 | X29: 0 | Y29: 虫族宿敌 | Z29: 1000 | AA29: 10 | AB29: =ROUND(VLOOKUP($A29,索引!$A$2:$L$38,4,FALSE)*12%,-2) -> 41400 | AC29: 0 | AD29: 0 | AE29: 0 | AF29: 0 | AG29: 虫族克星 | AH29: 3000 | AI29: 30 | AJ29: =ROUND(VLOOKUP($A29,索引!$A$2:$L$38,4,FALSE)*25%,-2) -> 86300 | AK29: 0 | AL29: 0 | AM29: 0 | AN29: 0 | AO29: 虫族的噩梦 | AP29: 10000 | AQ29: 50 | AR29: =ROUND(VLOOKUP($A29,索引!$A$2:$L$38,4,FALSE)*56%,-3) -> 193000 | AS29: 0 | AT29: 0 | AU29: 0 | AV29: 0 | AW29: 0 | AX29: 0 | AY29: 0 | AZ29: 0 | BA29: 0 | BB29: 0 | BC29: 0 | BD29: 0 | BE29: 0 | BF29: 0 | BG29: 0 | BH29: 0 | BI29: 0 | BJ29: 0 | BK29: 0 | BL29: 0 | BM29: 0 | BN29: 0 | BO29: 0 | BP29: 0 | BQ29: 0 | BR29: 0 | BS29: 0 | BT29: 0
A30: 28 | B30: 0 | C30: 10052 | D30: qttNoReset | E30: 在死亡峡谷击败%d个钳虫：战不死/锯骨狂/凶目魔或邪恶钳虫 | F30: img://UI_Achievement.monster.1013 | G30: 3 | H30: 8 | I30: 钳虫征服者 | J30: 1 | K30: 20 | L30: =ROUND(VLOOKUP($A30,索引!$A$2:$L$38,4,FALSE)*100%,-2) -> 4500 | M30: 0 | N30: 0 | O30: 0 | P30: 0 | Q30: 0 | R30: 0 | S30: 0 | T30: 0 | U30: 0 | V30: 0 | W30: 0 | X30: 0 | Y30: 0 | Z30: 0 | AA30: 0 | AB30: 0 | AC30: 0 | AD30: 0 | AE30: 0 | AF30: 0 | AG30: 0 | AH30: 0 | AI30: 0 | AJ30: 0 | AK30: 0 | AL30: 0 | AM30: 0 | AN30: 0 | AO30: 0 | AP30: 0 | AQ30: 0 | AR30: 0 | AS30: 0 | AT30: 0 | AU30: 0 | AV30: 0 | AW30: 0 | AX30: 0 | AY30: 0 | AZ30: 0 | BA30: 0 | BB30: 0 | BC30: 0 | BD30: 0 | BE30: 0 | BF30: 0 | BG30: 0 | BH30: 0 | BI30: 0 | BJ30: 0 | BK30: 0 | BL30: 0 | BM30: 0 | BN30: 0 | BO30: 0 | BP30: 0 | BQ30: 0 | BR30: 0 | BS30: 0 | BT30: 0
A31: 29 | B31: 0 | C31: 10053 | D31: qttNoReset | E31: 在死亡峡谷击败%d个杀人蜂：铁翼、鬼影、妖刀或暗夜舞者 | F31: img://UI_Achievement.monster.3219 | G31: 3 | H31: 8 | I31: 杀人蜂征服者 | J31: 1 | K31: 20 | L31: =ROUND(VLOOKUP($A31,索引!$A$2:$L$38,4,FALSE)*100%,-2) -> 4500 | M31: 0 | N31: 0 | O31: 0 | P31: 0 | Q31: 0 | R31: 0 | S31: 0 | T31: 0 | U31: 0 | V31: 0 | W31: 0 | X31: 0 | Y31: 0 | Z31: 0 | AA31: 0 | AB31: 0 | AC31: 0 | AD31: 0 | AE31: 0 | AF31: 0 | AG31: 0 | AH31: 0 | AI31: 0 | AJ31: 0 | AK31: 0 | AL31: 0 | AM31: 0 | AN31: 0 | AO31: 0 | AP31: 0 | AQ31: 0 | AR31: 0 | AS31: 0 | AT31: 0 | AU31: 0 | AV31: 0 | AW31: 0 | AX31: 0 | AY31: 0 | AZ31: 0 | BA31: 0 | BB31: 0 | BC31: 0 | BD31: 0 | BE31: 0 | BF31: 0 | BG31: 0 | BH31: 0 | BI31: 0 | BJ31: 0 | BK31: 0 | BL31: 0 | BM31: 0 | BN31: 0 | BO31: 0 | BP31: 0 | BQ31: 0 | BR31: 0 | BS31: 0 | BT31: 0
A32: 31 | B32: 5287 | C32: 0 | D32: qttNoReset | E32: 在死亡峡谷六层击败%d个触龙神 | F32: img://UI_Achievement.monster.5287 | G32: 3 | H32: 8 | I32: 首杀：触龙神 | J32: 1 | K32: 50 | L32: =索引!D52 -> 36000 | M32: 0 | N32: 0 | O32: 0 | P32: 0 | Q32: 0 | R32: 0 | S32: 0 | T32: 0 | U32: 0 | V32: 0 | W32: 0 | X32: 0 | Y32: 0 | Z32: 0 | AA32: 0 | AB32: 0 | AC32: 0 | AD32: 0 | AE32: 0 | AF32: 0 | AG32: 0 | AH32: 0 | AI32: 0 | AJ32: 0 | AK32: 0 | AL32: 0 | AM32: 0 | AN32: 0 | AO32: 0 | AP32: 0 | AQ32: 0 | AR32: 0 | AS32: 0 | AT32: 0 | AU32: 0 | AV32: 0 | AW32: 0 | AX32: 0 | AY32: 0 | AZ32: 0 | BA32: 0 | BB32: 0 | BC32: 0 | BD32: 0 | BE32: 0 | BF32: 0 | BG32: 0 | BH32: 0 | BI32: 0 | BJ32: 0 | BK32: 0 | BL32: 0 | BM32: 0 | BN32: 0 | BO32: 0 | BP32: 0 | BQ32: 0 | BR32: 0 | BS32: 0 | BT32: 0
A33: 32 | B33: 0 | C33: 10022 | D33: qttNoReset | E33: 在石墓击败%d个黑色恶蛆 | F33: img://UI_Achievement.monster.949 | G33: 3 | H33: 9 | I33: 恶蛆杀手 | J33: 50 | K33: 10 | L33: =ROUND(VLOOKUP($A33,索引!$A$2:$L$38,4,FALSE)*2%,-2) -> 5100 | M33: 0 | N33: 0 | O33: 0 | P33: 0 | Q33: 恶蛆猎手 | R33: 200 | S33: 10 | T33: =ROUND(VLOOKUP($A33,索引!$A$2:$L$38,4,FALSE)*5%,-2) -> 12800 | U33: 0 | V33: 0 | W33: 0 | X33: 0 | Y33: 恶蛆宿敌 | Z33: 1000 | AA33: 10 | AB33: =ROUND(VLOOKUP($A33,索引!$A$2:$L$38,4,FALSE)*12%,-2) -> 30600 | AC33: 0 | AD33: 0 | AE33: 0 | AF33: 0 | AG33: 恶蛆克星 | AH33: 3000 | AI33: 30 | AJ33: =ROUND(VLOOKUP($A33,索引!$A$2:$L$38,4,FALSE)*25%,-2) -> 63800 | AK33: 0 | AL33: 0 | AM33: 0 | AN33: 0 | AO33: 恶蛆的噩梦 | AP33: 10000 | AQ33: 50 | AR33: =ROUND(VLOOKUP($A33,索引!$A$2:$L$38,4,FALSE)*56%,-3) -> 143000 | AS33: 0 | AT33: 0 | AU33: 0 | AV33: 0 | AW33: 0 | AX33: 0 | AY33: 0 | AZ33: 0 | BA33: 0 | BB33: 0 | BC33: 0 | BD33: 0 | BE33: 0 | BF33: 0 | BG33: 0 | BH33: 0 | BI33: 0 | BJ33: 0 | BK33: 0 | BL33: 0 | BM33: 0 | BN33: 0 | BO33: 0 | BP33: 0 | BQ33: 0 | BR33: 0 | BS33: 0 | BT33: 0
A34: 33 | B34: 0 | C34: 10021 | D34: qttNoReset | E34: 在石墓击败%d个红野猪、黑野猪或白野猪 | F34: img://UI_Achievement.monster.1032 | G34: 3 | H34: 9 | I34: 野猪杀手 | J34: 50 | K34: 10 | L34: =ROUND(VLOOKUP($A34,索引!$A$2:$L$38,4,FALSE)*2%,-2) -> 8600 | M34: 0 | N34: 0 | O34: 0 | P34: 0 | Q34: 野猪猎手 | R34: 200 | S34: 10 | T34: =ROUND(VLOOKUP($A34,索引!$A$2:$L$38,4,FALSE)*5%,-2) -> 21500 | U34: 0 | V34: 0 | W34: 0 | X34: 0 | Y34: 野猪宿敌 | Z34: 1000 | AA34: 10 | AB34: =ROUND(VLOOKUP($A34,索引!$A$2:$L$38,4,FALSE)*12%,-2) -> 51500 | AC34: 0 | AD34: 0 | AE34: 0 | AF34: 0 | AG34: 野猪克星 | AH34: 3000 | AI34: 30 | AJ34: =ROUND(VLOOKUP($A34,索引!$A$2:$L$38,4,FALSE)*25%,-2) -> 107300 | AK34: 0 | AL34: 0 | AM34: 0 | AN34: 0 | AO34: 野猪的噩梦 | AP34: 10000 | AQ34: 50 | AR34: =ROUND(VLOOKUP($A34,索引!$A$2:$L$38,4,FALSE)*56%,-3) -> 240000 | AS34: 0 | AT34: 0 | AU34: 0 | AV34: 0 | AW34: 0 | AX34: 0 | AY34: 0 | AZ34: 0 | BA34: 0 | BB34: 0 | BC34: 0 | BD34: 0 | BE34: 0 | BF34: 0 | BG34: 0 | BH34: 0 | BI34: 0 | BJ34: 0 | BK34: 0 | BL34: 0 | BM34: 0 | BN34: 0 | BO34: 0 | BP34: 0 | BQ34: 0 | BR34: 0 | BS34: 0 | BT34: 0
A35: 34 | B35: 0 | C35: 10054 | D35: qttNoReset | E35: 在石墓击败%d个咆哮战士：钢鬃、黑风或腐牙 | F35: img://UI_Achievement.monster.1033 | G35: 3 | H35: 9 | I35: 咆哮战士征服者 | J35: 1 | K35: 20 | L35: =ROUND(VLOOKUP($A35,索引!$A$2:$L$38,4,FALSE)*100%,-2) -> 6000 | M35: 0 | N35: 0 | O35: 0 | P35: 0 | Q35: 0 | R35: 0 | S35: 0 | T35: 0 | U35: 0 | V35: 0 | W35: 0 | X35: 0 | Y35: 0 | Z35: 0 | AA35: 0 | AB35: 0 | AC35: 0 | AD35: 0 | AE35: 0 | AF35: 0 | AG35: 0 | AH35: 0 | AI35: 0 | AJ35: 0 | AK35: 0 | AL35: 0 | AM35: 0 | AN35: 0 | AO35: 0 | AP35: 0 | AQ35: 0 | AR35: 0 | AS35: 0 | AT35: 0 | AU35: 0 | AV35: 0 | AW35: 0 | AX35: 0 | AY35: 0 | AZ35: 0 | BA35: 0 | BB35: 0 | BC35: 0 | BD35: 0 | BE35: 0 | BF35: 0 | BG35: 0 | BH35: 0 | BI35: 0 | BJ35: 0 | BK35: 0 | BL35: 0 | BM35: 0 | BN35: 0 | BO35: 0 | BP35: 0 | BQ35: 0 | BR35: 0 | BS35: 0 | BT35: 0
A36: 35 | B36: 0 | C36: 10055 | D36: qttNoReset | E36: 在石墓击败%d个邪血卫士：狂徒、锐爪或猛鬼 | F36: img://UI_Achievement.monster.1034 | G36: 3 | H36: 9 | I36: 邪血卫士征服者 | J36: 1 | K36: 20 | L36: =ROUND(VLOOKUP($A36,索引!$A$2:$L$38,4,FALSE)*100%,-2) -> 6000 | M36: 0 | N36: 0 | O36: 0 | P36: 0 | Q36: 0 | R36: 0 | S36: 0 | T36: 0 | U36: 0 | V36: 0 | W36: 0 | X36: 0 | Y36: 0 | Z36: 0 | AA36: 0 | AB36: 0 | AC36: 0 | AD36: 0 | AE36: 0 | AF36: 0 | AG36: 0 | AH36: 0 | AI36: 0 | AJ36: 0 | AK36: 0 | AL36: 0 | AM36: 0 | AN36: 0 | AO36: 0 | AP36: 0 | AQ36: 0 | AR36: 0 | AS36: 0 | AT36: 0 | AU36: 0 | AV36: 0 | AW36: 0 | AX36: 0 | AY36: 0 | AZ36: 0 | BA36: 0 | BB36: 0 | BC36: 0 | BD36: 0 | BE36: 0 | BF36: 0 | BG36: 0 | BH36: 0 | BI36: 0 | BJ36: 0 | BK36: 0 | BL36: 0 | BM36: 0 | BN36: 0 | BO36: 0 | BP36: 0 | BQ36: 0 | BR36: 0 | BS36: 0 | BT36: 0
A37: 38 | B37: 0 | C37: 10069 | D37: qttNoReset | E37: 在虹魔教坛击败%d个虹魔教主 | F37: img://UI_Achievement.monster.5297 | G37: 3 | H37: 9 | I37: 首杀：虹魔教主 | J37: 1 | K37: 50 | L37: =索引!D53 -> 50000 | M37: 0 | N37: 0 | O37: 0 | P37: 0 | Q37: 0 | R37: 0 | S37: 0 | T37: 0 | U37: 0 | V37: 0 | W37: 0 | X37: 0 | Y37: 0 | Z37: 0 | AA37: 0 | AB37: 0 | AC37: 0 | AD37: 0 | AE37: 0 | AF37: 0 | AG37: 0 | AH37: 0 | AI37: 0 | AJ37: 0 | AK37: 0 | AL37: 0 | AM37: 0 | AN37: 0 | AO37: 0 | AP37: 0 | AQ37: 0 | AR37: 0 | AS37: 0 | AT37: 0 | AU37: 0 | AV37: 0 | AW37: 0 | AX37: 0 | AY37: 0 | AZ37: 0 | BA37: 0 | BB37: 0 | BC37: 0 | BD37: 0 | BE37: 0 | BF37: 0 | BG37: 0 | BH37: 0 | BI37: 0 | BJ37: 0 | BK37: 0 | BL37: 0 | BM37: 0 | BN37: 0 | BO37: 0 | BP37: 0 | BQ37: 0 | BR37: 0 | BS37: 0 | BT37: 0
A38: 39 | B38: 0 | C38: 10059 | D38: qttNoReset | E38: 在祖玛寺庙击败%d个祖玛老鼠、角蝇或楔蛾 | F38: img://UI_Achievement.monster.1071 | G38: 3 | H38: 10 | I38: 祖玛动物杀手 | J38: 50 | K38: 10 | L38: =ROUND(VLOOKUP($A38,索引!$A$2:$L$38,4,FALSE)*2%,-2) -> 8600 | M38: 0 | N38: 0 | O38: 0 | P38: 0 | Q38: 祖玛动物猎手 | R38: 200 | S38: 10 | T38: =ROUND(VLOOKUP($A38,索引!$A$2:$L$38,4,FALSE)*5%,-2) -> 21600 | U38: 0 | V38: 0 | W38: 0 | X38: 0 | Y38: 祖玛动物宿敌 | Z38: 1000 | AA38: 10 | AB38: =ROUND(VLOOKUP($A38,索引!$A$2:$L$38,4,FALSE)*12%,-2) -> 51800 | AC38: 0 | AD38: 0 | AE38: 0 | AF38: 0 | AG38: 祖玛动物克星 | AH38: 3000 | AI38: 30 | AJ38: =ROUND(VLOOKUP($A38,索引!$A$2:$L$38,4,FALSE)*25%,-2) -> 108000 | AK38: 0 | AL38: 0 | AM38: 0 | AN38: 0 | AO38: 祖玛动物的噩梦 | AP38: 10000 | AQ38: 50 | AR38: =ROUND(VLOOKUP($A38,索引!$A$2:$L$38,4,FALSE)*56%,-3) -> 242000 | AS38: 0 | AT38: 0 | AU38: 0 | AV38: 0 | AW38: 0 | AX38: 0 | AY38: 0 | AZ38: 0 | BA38: 0 | BB38: 0 | BC38: 0 | BD38: 0 | BE38: 0 | BF38: 0 | BG38: 0 | BH38: 0 | BI38: 0 | BJ38: 0 | BK38: 0 | BL38: 0 | BM38: 0 | BN38: 0 | BO38: 0 | BP38: 0 | BQ38: 0 | BR38: 0 | BS38: 0 | BT38: 0
A39: 40 | B39: 0 | C39: 10060 | D39: qttNoReset | E39: 在祖玛寺庙击败%d个祖玛卫士、祖玛雕像或祖玛弓手 | F39: img://UI_Achievement.monster.1072 | G39: 3 | H39: 10 | I39: 祖玛守卫杀手 | J39: 50 | K39: 10 | L39: =ROUND(VLOOKUP($A39,索引!$A$2:$L$38,4,FALSE)*2%,-2) -> 10800 | M39: 0 | N39: 0 | O39: 0 | P39: 0 | Q39: 祖玛生物猎手 | R39: 200 | S39: 10 | T39: =ROUND(VLOOKUP($A39,索引!$A$2:$L$38,4,FALSE)*5%,-2) -> 27000 | U39: 0 | V39: 0 | W39: 0 | X39: 0 | Y39: 祖玛生物宿敌 | Z39: 1000 | AA39: 10 | AB39: =ROUND(VLOOKUP($A39,索引!$A$2:$L$38,4,FALSE)*12%,-2) -> 64800 | AC39: 0 | AD39: 0 | AE39: 0 | AF39: 0 | AG39: 祖玛生物克星 | AH39: 3000 | AI39: 30 | AJ39: =ROUND(VLOOKUP($A39,索引!$A$2:$L$38,4,FALSE)*25%,-2) -> 135000 | AK39: 0 | AL39: 0 | AM39: 0 | AN39: 0 | AO39: 祖玛生物的噩梦 | AP39: 10000 | AQ39: 50 | AR39: =ROUND(VLOOKUP($A39,索引!$A$2:$L$38,4,FALSE)*56%,-3) -> 302000 | AS39: 0 | AT39: 0 | AU39: 0 | AV39: 0 | AW39: 0 | AX39: 0 | AY39: 0 | AZ39: 0 | BA39: 0 | BB39: 0 | BC39: 0 | BD39: 0 | BE39: 0 | BF39: 0 | BG39: 0 | BH39: 0 | BI39: 0 | BJ39: 0 | BK39: 0 | BL39: 0 | BM39: 0 | BN39: 0 | BO39: 0 | BP39: 0 | BQ39: 0 | BR39: 0 | BS39: 0 | BT39: 0
A40: 41 | B40: 0 | C40: 10061 | D40: qttNoReset | E40: 在祖玛寺庙击败%d个祖玛鼠卫:妖风、长牙或灵爪 | F40: img://UI_Achievement.monster.1086 | G40: 3 | H40: 10 | I40: 祖玛鼠卫征服者 | J40: 1 | K40: 20 | L40: =ROUND(VLOOKUP($A40,索引!$A$2:$L$38,4,FALSE)*100%,-2) -> 8500 | M40: 0 | N40: 0 | O40: 0 | P40: 0 | Q40: 0 | R40: 0 | S40: 0 | T40: 0 | U40: 0 | V40: 0 | W40: 0 | X40: 0 | Y40: 0 | Z40: 0 | AA40: 0 | AB40: 0 | AC40: 0 | AD40: 0 | AE40: 0 | AF40: 0 | AG40: 0 | AH40: 0 | AI40: 0 | AJ40: 0 | AK40: 0 | AL40: 0 | AM40: 0 | AN40: 0 | AO40: 0 | AP40: 0 | AQ40: 0 | AR40: 0 | AS40: 0 | AT40: 0 | AU40: 0 | AV40: 0 | AW40: 0 | AX40: 0 | AY40: 0 | AZ40: 0 | BA40: 0 | BB40: 0 | BC40: 0 | BD40: 0 | BE40: 0 | BF40: 0 | BG40: 0 | BH40: 0 | BI40: 0 | BJ40: 0 | BK40: 0 | BL40: 0 | BM40: 0 | BN40: 0 | BO40: 0 | BP40: 0 | BQ40: 0 | BR40: 0 | BS40: 0 | BT40: 0
...

Sheet 字段说明
A1: QuestID | B1: 任务id
A2: NpcTemplateID | B2: npcid
A3: NpcGroupID | B3: npc组id
A4: ResetType | B4: 重复类型 | C4: qttNoReset | D4: 不重复
C5: qttDay | D5: 日常
C6: qttWeek | D6: 周常
A7: Name1 | B7: 中文名
A8: KillCount1 | B8: 击杀数量
A9: AchievementPts1 | B9: 奖励成就点
A10: RewardExp1 | B10: 奖励经验

Sheet 索引
A2: 1 | B2: qttNoReset | C2: 在边界村击败%d个稻草人 | D2: =E2*F2*G2 -> 175 | E2: 10 | F2: 50 | G2: 0.35 | H2: =SUM(D2:D3) -> 445
A3: 2 | B3: qttNoReset | C3: 在边界村击败%d个钉耙猫 | D3: =E3*F3*G3 -> 270 | E3: 18 | F3: 50 | G3: 0.3
A4: 4 | B4: qttNoReset | C4: 在比奇省击败%d个半兽人或半兽人战士 | D4: =E4*F4*G4 -> 1800 | E4: 30 | F4: 200 | G4: 0.3 | H4: =SUM(D4:D12) -> 12700
A5: 5 | B5: qttNoReset | C5: 在沃玛森林击败%d个熊、鹿或狼 | D5: =E5*F5*G5 -> 1800 | E5: 30 | F5: 200 | G5: 0.3
A6: 6 | B6: qttNoReset | C6: 在沃玛森林击败%d个半兽人、半兽人战士或半兽人勇士 | D6: =E6*F6*G6 -> 1800 | E6: 30 | F6: 200 | G6: 0.3
A7: 7 | B7: qttNoReset | C7: 在沃玛森林击败%d个巨力士：虎勇、火舞者或冰刀 | D7: =E7*F7*G7 -> 600 | E7: 600 | F7: 1 | G7: 1
A8: 8 | B8: qttNoReset | C8: 在沃玛森林击败%d个蛮战士：怒号、血角或铜须 | D8: =E8*F8*G8 -> 600 | E8: 600 | F8: 1 | G8: 1
A9: 9 | B9: qttNoReset | C9: 在盟重省击败%d个盔甲虫、腐蚀虫、多角虫或巨型多角虫 | D9: =E9*F9*G9 -> 2400 | E9: 40 | F9: 200 | G9: 0.3
A10: 10 | B10: qttNoReset | C10: 在盟重省击败%d个狼 | D10: =E10*F10*G10 -> 2100 | E10: 35 | F10: 200 | G10: 0.3
A11: 11 | B11: qttNoReset | C11: 在盟重省击败%d个废墟魔狼：丑面、尖耳或疾电 | D11: =E11*F11*G11 -> 800 | E11: 800 | F11: 1 | G11: 1
A12: 12 | B12: qttNoReset | C12: 在盟重省击败%d个铁腹角虫：六足、尖角或斑纹 | D12: =E12*F12*G12 -> 800 | E12: 800 | F12: 1 | G12: 1
A13: 3 | B13: qttNoReset | C13: 在比奇省击败%d个僵尸 | D13: =E13*F13*G13 -> 6200 | E13: 155 | F13: 200 | G13: 0.2 | H13: =SUM(D13:D16) -> 73200
A14: 14 | B14: qttNoReset | C14: 在比奇矿区击败%d个僵尸 | D14: =E14*F14*G14 -> 62000 | E14: 155 | F14: 2000 | G14: 0.2
A15: 15 | B15: qttNoReset | C15: 在比奇矿区击败%d个僵尸护卫：杜杀、黑子或黑鹰 | D15: =E15*F15*G15 -> 2500 | E15: 2500 | F15: 1 | G15: 1
A16: 16 | B16: qttNoReset | C16: 在比奇矿区击败%d个僵尸强盗：黑山、金豹或杜冷 | D16: =E16*F16*G16 -> 2500 | E16: 2500 | F16: 1 | G16: 1
A17: 20 | B17: qttNoReset | C17: 在沃玛寺庙击败%d个山洞蝙蝠或黑色恶蛆 | D17: =E17*F17*G17 -> 255000 | E17: 170 | F17: 10000 | G17: 0.15 | H17: =SUM(D17:D20) -> 593000
A18: 21 | B18: qttNoReset | C18: 击败%d个沃玛战士、卫士、勇士、战将或火焰沃玛 | D18: =E18*F18*G18 -> 330000 | E18: 220 | F18: 10000 | G18: 0.15
A19: 22 | B19: qttNoReset | C19: 在沃玛寺庙击败%d个疯魔卫：无畏、铁蹄或钢角 | D19: =E19*F19*G19 -> 4000 | E19: 4000 | F19: 1 | G19: 1
A20: 23 | B20: qttNoReset | C20: 在沃玛寺庙击败%d个鬼域守卫：鬼面、羊钉或怒锤 | D20: =E20*F20*G20 -> 4000 | E20: 4000 | F20: 1 | G20: 1
A21: 27 | B21: qttNoReset | C21: 在死亡峡谷击败%d个蜈蚣、巨型蠕虫、钳虫或跳跳蜂 | D21: =E21*F21*G21 -> 345000 | E21: 230 | F21: 10000 | G21: 0.15 | H21: =SUM(D21:D23) -> 354000
A22: 28 | B22: qttNoReset | C22: 在死亡峡谷击败%d个钳虫：战不死、锯骨狂或凶目魔 | D22: =E22*F22*G22 -> 4500 | E22: 4500 | F22: 1 | G22: 1
A23: 29 | B23: qttNoReset | C23: 在死亡峡谷击败%d个杀人蜂：铁翼、鬼影或妖刀 | D23: =E23*F23*G23 -> 4500 | E23: 4500 | F23: 1 | G23: 1
A24: 32 | B24: qttNoReset | C24: 在石墓击败%d个黑色恶蛆 | D24: =E24*F24*G24 -> 255000 | E24: 170 | F24: 10000 | G24: 0.15 | H24: =SUM(D24:D27) -> 696000
A25: 33 | B25: qttNoReset | C25: 在石墓击败%d个红野猪、黑野猪或白野猪 | D25: =E25*F25*G25 -> 429000 | E25: 330 | F25: 10000 | G25: 0.13
A26: 34 | B26: qttNoReset | C26: 在石墓击败%d个咆哮战士：钢鬃、黑风或腐牙 | D26: =E26*F26*G26 -> 6000 | E26: 6000 | F26: 1 | G26: 1
A27: 35 | B27: qttNoReset | C27: 在石墓击败%d个邪血卫士：狂徒、锐爪或猛鬼 | D27: =E27*F27*G27 -> 6000 | E27: 6000 | F27: 1 | G27: 1
A28: 39 | B28: qttNoReset | C28: 在祖玛寺庙击败%d个祖玛老鼠、角蝇或楔蛾 | D28: =E28*F28*G28 -> 432000 | E28: 360 | F28: 10000 | G28: 0.12 | H28: =SUM(D28:D31) -> 989000
A29: 40 | B29: qttNoReset | C29: 在祖玛寺庙击败%d个祖玛怪物 | D29: =E29*F29*G29 -> 540000 | E29: 450 | F29: 10000 | G29: 0.12
A30: 41 | B30: qttNoReset | C30: 在祖玛寺庙击败%d个祖玛鼠卫:妖风、长牙或灵爪 | D30: =E30*F30*G30 -> 8500 | E30: 8500 | F30: 1 | G30: 1
A31: 42 | B31: qttNoReset | C31: 在祖玛寺庙击败%d个石像守卫：劈颅、灾狱或夜冥 | D31: =E31*F31*G31 -> 8500 | E31: 8500 | F31: 1 | G31: 1
A32: 53 | B32: qttNoReset | C32: 在赤月岛击败%d个蜘蛛怪物 | D32: =E32*F32*G32 -> 600000 | E32: 600 | F32: 10000 | G32: 0.1 | H32: =SUM(D32:D35) -> 1433600
A33: 54 | B33: qttNoReset | C33: 在赤月岛击败%d个血巨人或血僵尸 | D33: =E33*F33*G33 -> 810000 | E33: 900 | F33: 10000 | G33: 0.09
A34: 55 | B34: qttNoReset | C34: 在赤月岛击败%d个恶魔帮凶：幻花、疯刺或残夜 | D34: =E34*F34*G34 -> 11800 | E34: 11800 | F34: 1 | G34: 1
A35: 56 | B35: qttNoReset | C35: 在赤月岛击败%d个恶魔爪牙：蛇牙、幽灵或黑寡妇 | D35: =E35*F35*G35 -> 11800 | E35: 11800 | F35: 1 | G35: 1
A40: 13 | B40: qttWeek | C40: =Sheet1!E16 -> 杀死%d个分布在幽冥海四层的毒魔 | D40: 30000
A41: 17 | B41: qttWeek | C41: =Sheet1!E20 -> 在皇室宝库里杀死%d个宝库大盗 | D41: 30000
A42: 18 | B42: qttWeek | C42: =Sheet1!E21 -> 杀死%d个虹魔教主身边的白野猪暴徒 | D42: 40000
A43: 24 | B43: qttWeek | C43: =Sheet1!E27 -> 杀死%d个祖玛教主身边的邪箭弓手 | D43: 50000
A44: 25 | B44: qttWeek | C44: 在沃玛寺庙击败%d个裂地巨魔：折锐、风吼或断空 | D44: =D19*4 -> 16000
A45: 30 | B45: qttWeek | C45: 在死亡峡谷击败%d个巨蠕虫：死亡漩涡、远古虫王或尖脊鬼魅 | D45: =D22*4 -> 18000
...

Sheet Sheet3
A1: 1 | B1: 801 | C1: 0 | D1: 0 | E1: 前往边界村击败%d个稻草人 | F1: img://UI_Achievement.monster.801 | G1: 0 | H1: 3 | I1: 2 | J1: 稻草人杀手 | K1: 10 | L1: 10 | M1: 10 | N1: 稻草人猎手 | O1: 50 | Q1: 20 | R1: 稻草人宿敌 | S1: 100 | T1: 0 | U1: 30 | V1: 稻草人克星 | W1: 500 | X1: 0 | Y1: 40 | Z1: 稻草人的噩梦 | AA1: 1000 | AB1: 0 | AC1: 50 | AD1: 稻草人惨剧制造者 | AE1: 2000 | AF1: 0 | AG1: 0 | AH1: 稻草人眼中的大魔王 | AI1: 5000 | AJ1: 0 | AK1: 0 | AL1: 0 | AM1: 0 | AN1: 0 | AO1: 0
A2: 2 | B2: 802 | C2: 0 | D2: 0 | E2: 前往边界村击败%d个钉耙猫 | F2: img://UI_Achievement.monster.802 | G2: 0 | H2: 3 | I2: 2 | J2: 钉耙猫杀手 | K2: 10 | L2: 10 | M2: 10 | N2: 钉耙猫猎手 | O2: 50 | Q2: 20 | R2: 钉耙猫宿敌 | S2: 100 | T2: 0 | U2: 30 | V2: 钉耙猫克星 | W2: 500 | X2: 0 | Y2: 40 | Z2: 钉耙猫的噩梦 | AA2: 1000 | AB2: 0 | AC2: 50 | AD2: 钉耙猫惨剧制造者 | AE2: 2000 | AF2: 0 | AG2: 0 | AH2: 钉耙猫眼中的大魔王 | AI2: 5000 | AJ2: 0 | AK2: 0 | AL2: 0 | AM2: 0 | AN2: 0 | AO2: 0
A3: 3 | B3: 823 | C3: 0 | D3: 0 | E3: 前往边界村击败%d个鹿 | F3: img://UI_Achievement.monster.823 | G3: 0 | H3: 3 | I3: 2 | J3: 鹿杀手 | K3: 10 | L3: 10 | M3: 10 | N3: 鹿猎手 | O3: 50 | Q3: 20 | R3: 鹿宿敌 | S3: 100 | T3: 0 | U3: 30 | V3: 鹿克星 | W3: 500 | X3: 0 | Y3: 40 | Z3: 鹿的噩梦 | AA3: 1000 | AB3: 0 | AC3: 50 | AD3: 鹿惨剧制造者 | AE3: 2000 | AF3: 0 | AG3: 0 | AH3: 鹿眼中的大魔王 | AI3: 5000 | AJ3: 0 | AK3: 0 | AL3: 0 | AM3: 0 | AN3: 0 | AO3: 0
A4: 4 | B4: 803 | C4: 0 | D4: 0 | E4: 前往边界村击败%d个半兽人 | F4: img://UI_Achievement.monster.803 | G4: 0 | H4: 3 | I4: 2 | J4: 半兽人杀手 | K4: 10 | L4: 10 | M4: 10 | N4: 半兽人猎手 | O4: 50 | Q4: 20 | R4: 半兽人宿敌 | S4: 100 | T4: 0 | U4: 30 | V4: 半兽人克星 | W4: 500 | X4: 0 | Y4: 40 | Z4: 半兽人的噩梦 | AA4: 1000 | AB4: 0 | AC4: 50 | AD4: 半兽人惨剧制造者 | AE4: 2000 | AF4: 0 | AG4: 0 | AH4: 半兽人眼中的大魔王 | AI4: 5000 | AJ4: 0 | AK4: 0 | AL4: 0 | AM4: 0 | AN4: 0 | AO4: 0
A5: 5 | B5: 804 | C5: 0 | D5: 0 | E5: 前往边界村击败%d个半兽人战士 | F5: img://UI_Achievement.monster.804 | G5: 0 | H5: 3 | I5: 2 | J5: 半兽人战士杀手 | K5: 10 | L5: 10 | M5: 10 | N5: 半兽人战士猎手 | O5: 50 | Q5: 20 | R5: 半兽人战士宿敌 | S5: 100 | T5: 0 | U5: 30 | V5: 半兽人战士克星 | W5: 500 | X5: 0 | Y5: 40 | Z5: 半兽人战士的噩梦 | AA5: 1000 | AB5: 0 | AC5: 50 | AD5: 半兽人战士惨剧制造者 | AE5: 2000 | AF5: 0 | AG5: 0 | AH5: 半兽人战士眼中的大魔王 | AI5: 5000 | AJ5: 0 | AK5: 0 | AL5: 0 | AM5: 0 | AN5: 0 | AO5: 0
A6: 6 | B6: 821 | C6: 0 | D6: 0 | E6: 前往边界村击败%d个海蟹 | F6: img://UI_Achievement.monster.821 | G6: 0 | H6: 3 | I6: 2 | J6: 海蟹杀手 | K6: 10 | L6: 10 | M6: 10 | N6: 海蟹猎手 | O6: 50 | Q6: 20 | R6: 海蟹宿敌 | S6: 100 | T6: 0 | U6: 30 | V6: 海蟹克星 | W6: 500 | X6: 0 | Y6: 40 | Z6: 海蟹的噩梦 | AA6: 1000 | AB6: 0 | AC6: 50 | AD6: 海蟹惨剧制造者 | AE6: 2000 | AF6: 0 | AG6: 0 | AH6: 海蟹眼中的大魔王 | AI6: 5000 | AJ6: 0 | AK6: 0 | AL6: 0 | AM6: 0 | AN6: 0 | AO6: 0
A7: 7 | B7: 855 | C7: 0 | D7: 0 | E7: 前往比奇省击败%d个稻草人 | F7: img://UI_Achievement.monster.801 | G7: 0 | H7: 3 | I7: 3 | J7: 稻草人杀手 | K7: 10 | L7: 10 | M7: 10 | N7: 稻草人猎手 | O7: 50 | Q7: 20 | R7: 稻草人宿敌 | S7: 100 | T7: 0 | U7: 30 | V7: 稻草人克星 | W7: 500 | X7: 0 | Y7: 40 | Z7: 稻草人的噩梦 | AA7: 1000 | AB7: 0 | AC7: 50 | AD7: 稻草人惨剧制造者 | AE7: 2000 | AF7: 0 | AG7: 0 | AH7: 稻草人眼中的大魔王 | AI7: 5000 | AJ7: 0 | AK7: 0 | AL7: 0 | AM7: 0 | AN7: 0 | AO7: 0
A8: 8 | B8: 856 | C8: 0 | D8: 0 | E8: 前往比奇省击败%d个钉耙猫 | F8: img://UI_Achievement.monster.802 | G8: 0 | H8: 3 | I8: 3 | J8: 钉耙猫杀手 | K8: 10 | L8: 10 | M8: 10 | N8: 钉耙猫猎手 | O8: 50 | Q8: 20 | R8: 钉耙猫宿敌 | S8: 100 | T8: 0 | U8: 30 | V8: 钉耙猫克星 | W8: 500 | X8: 0 | Y8: 40 | Z8: 钉耙猫的噩梦 | AA8: 1000 | AB8: 0 | AC8: 50 | AD8: 钉耙猫惨剧制造者 | AE8: 2000 | AF8: 0 | AG8: 0 | AH8: 钉耙猫眼中的大魔王 | AI8: 5000 | AJ8: 0 | AK8: 0 | AL8: 0 | AM8: 0 | AN8: 0 | AO8: 0
A9: 9 | B9: 873 | C9: 0 | D9: 0 | E9: 前往比奇省击败%d个鹿 | F9: img://UI_Achievement.monster.823 | G9: 0 | H9: 3 | I9: 3 | J9: 鹿杀手 | K9: 10 | L9: 10 | M9: 10 | N9: 鹿猎手 | O9: 50 | Q9: 20 | R9: 鹿宿敌 | S9: 100 | T9: 0 | U9: 30 | V9: 鹿克星 | W9: 500 | X9: 0 | Y9: 40 | Z9: 鹿的噩梦 | AA9: 1000 | AB9: 0 | AC9: 50 | AD9: 鹿惨剧制造者 | AE9: 2000 | AF9: 0 | AG9: 0 | AH9: 鹿眼中的大魔王 | AI9: 5000 | AJ9: 0 | AK9: 0 | AL9: 0 | AM9: 0 | AN9: 0 | AO9: 0
A10: 10 | B10: 857 | C10: 0 | D10: 0 | E10: 前往比奇省击败%d个半兽人 | F10: img://UI_Achievement.monster.803 | G10: 0 | H10: 3 | I10: 3 | J10: 半兽人杀手 | K10: 10 | L10: 10 | M10: 10 | N10: 半兽人猎手 | O10: 50 | Q10: 20 | R10: 半兽人宿敌 | S10: 100 | T10: 0 | U10: 30 | V10: 半兽人克星 | W10: 500 | X10: 0 | Y10: 40 | Z10: 半兽人的噩梦 | AA10: 1000 | AB10: 0 | AC10: 50 | AD10: 半兽人惨剧制造者 | AE10: 2000 | AF10: 0 | AG10: 0 | AH10: 半兽人眼中的大魔王 | AI10: 5000 | AJ10: 0 | AK10: 0 | AL10: 0 | AM10: 0 | AN10: 0 | AO10: 0
A11: 11 | B11: 858 | C11: 0 | D11: 0 | E11: 前往比奇省击败%d个半兽人战士 | F11: img://UI_Achievement.monster.804 | G11: 0 | H11: 3 | I11: 3 | J11: 半兽人战士杀手 | K11: 10 | L11: 10 | M11: 10 | N11: 半兽人战士猎手 | O11: 50 | Q11: 20 | R11: 半兽人战士宿敌 | S11: 100 | T11: 0 | U11: 30 | V11: 半兽人战士克星 | W11: 500 | X11: 0 | Y11: 40 | Z11: 半兽人战士的噩梦 | AA11: 1000 | AB11: 0 | AC11: 50 | AD11: 半兽人战士惨剧制造者 | AE11: 2000 | AF11: 0 | AG11: 0 | AH11: 半兽人战士眼中的大魔王 | AI11: 5000 | AJ11: 0 | AK11: 0 | AL11: 0 | AM11: 0 | AN11: 0 | AO11: 0
A12: 12 | B12: 3131 | C12: 0 | D12: 0 | E12: 前往沃玛森林击败%d个熊 | F12: img://UI_Achievement.monster.3131 | G12: 0 | H12: 3 | I12: 4 | J12: 熊杀手 | K12: 10 | L12: 10 | M12: 10 | N12: 熊猎手 | O12: 50 | Q12: 20 | R12: 熊宿敌 | S12: 100 | T12: 0 | U12: 30 | V12: 熊克星 | W12: 500 | X12: 0 | Y12: 40 | Z12: 熊的噩梦 | AA12: 1000 | AB12: 0 | AC12: 50 | AD12: 熊惨剧制造者 | AE12: 2000 | AF12: 0 | AG12: 0 | AH12: 熊眼中的大魔王 | AI12: 5000 | AJ12: 0 | AK12: 0 | AL12: 0 | AM12: 0 | AN12: 0 | AO12: 0
... A44: 44 | B44: 5297 | C44: 0 | D44: 0 | E44: 前往虹魔教坛击败%d个虹魔教主 | F44: img://UI_Achievement.monster.5297 | G44: 0 | H44: 3 | I44: 10 | J44: 首杀：虹魔教主 | K44: 1 | L44: 10 | M44: 10 | N44: 连斩：虹魔教主 | O44: 5 | Q44: 20 | R44: 十连斩：虹魔教主 | S44: 10 | T44: 0 | U44: 30 | V44: 屠魔：虹魔教主 | W44: 20 | X44: 0 | Y44: 40 | Z44: 天罚：虹魔教主 | AA44: 50 | AB44: 0 | AC44: 50 | AD44: 龙之怒斩：虹魔教主 | AE44: 100 | AF44: 0 | AG44: 0 | AH44: 夺命神皇：虹魔教主 | AI44: 500 | AJ44: 0 | AK44: 0 | AL44: 0 | AM44: 0 | AN44: 0 | AO44: 0
