Workbook

Sheet npc_pattern
A1: Index | B1: PackageFolder | C1: TemplateID | D1: PatternID | E1: ScriptName | F1: PatternName | G1: Description | H1: Map | I1: Exp | J1: Soul | K1: catPhyAtk | L1: catMaxPhyAtk | M1: catMagAtk | N1: catMaxMagAtk | O1: catTaoAtk | P1: catMaxTaoAtk | Q1: catPhyDef | R1: catMaxPhyDef | S1: catMagDef | T1: catMaxMagDef | U1: catMaxHp | V1: catMaxMp | W1: catAccurate | X1: catAgility | Y1: catHpRecovery | Z1: catHpRecoveryTap | AA1: catTapIncrease | AB1: catRepelResist
A2: 0 | B2: 0 | C2: Both | D2: Both | E2: Both | F2: Both | G2: Both | H2: Both | I2: Server | J2: Server | K2: Both | L2: Both | M2: Both | N2: Both | O2: Both | P2: Both | Q2: Both | R2: Both | S2: Both | T2: Both | U2: Both | V2: Both | W2: Both | X2: Both | Y2: Both | Z2: Both | AA2: Both | AB2: Both
A3: 0 | B3: 0 | G3: 默认数据行 | H3: 所在地图 | I3: 0 | J3: 0 | K3: 0 | L3: 0 | M3: 0 | N3: 0 | O3: 0 | P3: 0 | Q3: 0 | R3: 0 | S3: 0 | T3: 0 | U3: 0 | V3: 0 | W3: 0 | X3: 0 | Y3: 0 | Z3: 0 | AA3: 0 | AB3: 0
A4: PhyType.StandardPhyType | B4: NPC_Pattern | C4: 11 | D4: 11 | E4: StandardPhyType_func | F4: StandardPhyType_func.lua | G4: 标准物理型 | K4: 5 | L4: 15 | M4: 5 | N4: 15 | O4: 0 | P4: 0 | Q4: 3 | R4: 3 | S4: 1 | T4: 1 | U4: 50 | V4: 1 | W4: 10 | X4: 15 | Y4: 75 | Z4: 300 | AA4: 50
A5: DefaultNPCPattern.Sample | B5: NPC_Pattern | C5: 1 | D5: 1 | E5: sample_func | F5: main.lua | G5: 战士模板 | V5: 1
A6: PhyType.NewNpcType | B6: NPC_Pattern | C6: 100 | D6: 100 | G6: 标准NPC | K6: 0 | L6: 0 | M6: 0 | N6: 0 | O6: 0 | P6: 0 | Q6: 0 | R6: 0 | S6: 0 | T6: 0 | U6: 9999 | V6: 1 | W6: 5 | X6: 5 | Y6: 75 | Z6: 300 | AA6: 50
A7: SceneObjectPattern.SceneObject01 | B7: NPC_Pattern | C7: 6 | D7: 6 | E7: ScnObj | F7: ScnObj.lua | G7: 物件模板 | K7: 2 | L7: 4 | M7: 1 | N7: 1 | O7: 1 | P7: 1 | Q7: 1 | R7: 1 | S7: 1 | T7: 1 | U7: 50 | V7: 1 | W7: 5 | X7: 10 | Y7: 75 | Z7: 300 | AA7: 50
A8: ="PhyType.NewNpcType_"&D8 -> PhyType.NewNpcType_101 | B8: NPC_Pattern | C8: 101 | D8: 101 | G8: 稻草人 | H8: 边界村 | I8: 9 | K8: =原始值!D8+VLOOKUP($H8,怪物强度修正!$A$2:$R$17,COLUMN(K8)-9,FALSE) -> 1 | L8: =原始值!E8+VLOOKUP($H8,怪物强度修正!$A$2:$R$17,COLUMN(L8)-9,FALSE) -> 2 | M8: =K8 -> 1 | N8: =L8 -> 2 | O8: =原始值!H8+VLOOKUP($H8,怪物强度修正!$A$2:$R$17,COLUMN(O8)-9,FALSE) -> 0 | P8: =原始值!I8+VLOOKUP($H8,怪物强度修正!$A$2:$R$17,COLUMN(P8)-9,FALSE) -> 0 | Q8: =原始值!J8+VLOOKUP($H8,怪物强度修正!$A$2:$R$17,COLUMN(Q8)-9,FALSE) -> 0 | R8: =原始值!K8+VLOOKUP($H8,怪物强度修正!$A$2:$R$17,COLUMN(R8)-9,FALSE) -> 0 | S8: =原始值!L8+VLOOKUP($H8,怪物强度修正!$A$2:$R$17,COLUMN(S8)-9,FALSE) -> 0 | T8: =原始值!M8+VLOOKUP($H8,怪物强度修正!$A$2:$R$17,COLUMN(T8)-9,FALSE) -> 0 | U8: =原始值!N8+VLOOKUP($H8,怪物强度修正!$A$2:$R$17,COLUMN(U8)-9,FALSE) -> 15 | V8: 1 | W8: =原始值!P8+VLOOKUP($H8,怪物强度修正!$A$2:$R$17,COLUMN(W8)-9,FALSE) -> 5 | X8: =原始值!Q8+VLOOKUP($H8,怪物强度修正!$A$2:$R$17,COLUMN(X8)-9,FALSE) -> 7 | Y8: =原始值!R8+VLOOKUP($H8,怪物强度修正!$A$2:$R$17,COLUMN(Y8)-9,FALSE) -> 75 | Z8: =原始值!S8+VLOOKUP($H8,怪物强度修正!$A$2:$R$17,COLUMN(Z8)-9,FALSE) -> 300 | AA8: =原始值!T8+VLOOKUP($H8,怪物强度修正!$A$2:$R$17,COLUMN(AA8)-9,FALSE) -> 50
A9: ="PhyType.NewNpcType_"&D9 -> PhyType.NewNpcType_102 | B9: NPC_Pattern | C9: 102 | D9: 102 | G9: 钉耙猫 | H9: 边界村 | I9: 17 | K9: =原始值!D9+VLOOKUP($H9,怪物强度修正!$A$2:$R$17,COLUMN(K9)-9,FALSE) -> 2 | L9: =原始值!E9+VLOOKUP($H9,怪物强度修正!$A$2:$R$17,COLUMN(L9)-9,FALSE) -> 4 | M9: =K9 -> 2 | N9: =L9 -> 4 | O9: =原始值!H9+VLOOKUP($H9,怪物强度修正!$A$2:$R$17,COLUMN(O9)-9,FALSE) -> 0 | P9: =原始值!I9+VLOOKUP($H9,怪物强度修正!$A$2:$R$17,COLUMN(P9)-9,FALSE) -> 0 | Q9: =原始值!J9+VLOOKUP($H9,怪物强度修正!$A$2:$R$17,COLUMN(Q9)-9,FALSE) -> 0 | R9: =原始值!K9+VLOOKUP($H9,怪物强度修正!$A$2:$R$17,COLUMN(R9)-9,FALSE) -> 0 | S9: =原始值!L9+VLOOKUP($H9,怪物强度修正!$A$2:$R$17,COLUMN(S9)-9,FALSE) -> 0 | T9: =原始值!M9+VLOOKUP($H9,怪物强度修正!$A$2:$R$17,COLUMN(T9)-9,FALSE) -> 0 | U9: =原始值!N9+VLOOKUP($H9,怪物强度修正!$A$2:$R$17,COLUMN(U9)-9,FALSE) -> 23 | V9: 1 | W9: =原始值!P9+VLOOKUP($H9,怪物强度修正!$A$2:$R$17,COLUMN(W9)-9,FALSE) -> 5 | X9: =原始值!Q9+VLOOKUP($H9,怪物强度修正!$A$2:$R$17,COLUMN(X9)-9,FALSE) -> 7 | Y9: =原始值!R9+VLOOKUP($H9,怪物强度修正!$A$2:$R$17,COLUMN(Y9)-9,FALSE) -> 75 | Z9: =原始值!S9+VLOOKUP($H9,怪物强度修正!$A$2:$R$17,COLUMN(Z9)-9,FALSE) -> 300 | AA9: =原始值!T9+VLOOKUP($H9,怪物强度修正!$A$2:$R$17,COLUMN(AA9)-9,FALSE) -> 50
A10: ="PhyType.NewNpcType_"&D10 -> PhyType.NewNpcType_103 | B10: NPC_Pattern | C10: 103 | D10: 103 | G10: 半兽人 | H10: 边界村 | I10: 24 | K10: =原始值!D10+VLOOKUP($H10,怪物强度修正!$A$2:$R$17,COLUMN(K10)-9,FALSE) -> 3 | L10: =原始值!E10+VLOOKUP($H10,怪物强度修正!$A$2:$R$17,COLUMN(L10)-9,FALSE) -> 7 | M10: =K10 -> 3 | N10: =L10 -> 7 | O10: =原始值!H10+VLOOKUP($H10,怪物强度修正!$A$2:$R$17,COLUMN(O10)-9,FALSE) -> 0 | P10: =原始值!I10+VLOOKUP($H10,怪物强度修正!$A$2:$R$17,COLUMN(P10)-9,FALSE) -> 0 | Q10: =原始值!J10+VLOOKUP($H10,怪物强度修正!$A$2:$R$17,COLUMN(Q10)-9,FALSE) -> 1 | R10: =原始值!K10+VLOOKUP($H10,怪物强度修正!$A$2:$R$17,COLUMN(R10)-9,FALSE) -> 1 | S10: =原始值!L10+VLOOKUP($H10,怪物强度修正!$A$2:$R$17,COLUMN(S10)-9,FALSE) -> 0 | T10: =原始值!M10+VLOOKUP($H10,怪物强度修正!$A$2:$R$17,COLUMN(T10)-9,FALSE) -> 0 | U10: =原始值!N10+VLOOKUP($H10,怪物强度修正!$A$2:$R$17,COLUMN(U10)-9,FALSE) -> 30 | V10: 1 | W10: =原始值!P10+VLOOKUP($H10,怪物强度修正!$A$2:$R$17,COLUMN(W10)-9,FALSE) -> 6 | X10: =原始值!Q10+VLOOKUP($H10,怪物强度修正!$A$2:$R$17,COLUMN(X10)-9,FALSE) -> 8 | Y10: =原始值!R10+VLOOKUP($H10,怪物强度修正!$A$2:$R$17,COLUMN(Y10)-9,FALSE) -> 75 | Z10: =原始值!S10+VLOOKUP($H10,怪物强度修正!$A$2:$R$17,COLUMN(Z10)-9,FALSE) -> 300 | AA10: =原始值!T10+VLOOKUP($H10,怪物强度修正!$A$2:$R$17,COLUMN(AA10)-9,FALSE) -> 50
A11: ="PhyType.NewNpcType_"&D11 -> PhyType.NewNpcType_104 | B11: NPC_Pattern | C11: 104 | D11: 104 | G11: 半兽人战士 | H11: 比奇省 | I11: 89 | K11: =原始值!D11+VLOOKUP($H11,怪物强度修正!$A$2:$R$17,COLUMN(K11)-9,FALSE) -> 5 | L11: =原始值!E11+VLOOKUP($H11,怪物强度修正!$A$2:$R$17,COLUMN(L11)-9,FALSE) -> 12 | M11: =K11 -> 5 | N11: =L11 -> 12 | O11: =原始值!H11+VLOOKUP($H11,怪物强度修正!$A$2:$R$17,COLUMN(O11)-9,FALSE) -> 0 | P11: =原始值!I11+VLOOKUP($H11,怪物强度修正!$A$2:$R$17,COLUMN(P11)-9,FALSE) -> 0 | Q11: =原始值!J11+VLOOKUP($H11,怪物强度修正!$A$2:$R$17,COLUMN(Q11)-9,FALSE) -> 3 | R11: =原始值!K11+VLOOKUP($H11,怪物强度修正!$A$2:$R$17,COLUMN(R11)-9,FALSE) -> 3 | S11: =原始值!L11+VLOOKUP($H11,怪物强度修正!$A$2:$R$17,COLUMN(S11)-9,FALSE) -> 1 | T11: =原始值!M11+VLOOKUP($H11,怪物强度修正!$A$2:$R$17,COLUMN(T11)-9,FALSE) -> 1 | U11: =原始值!N11+VLOOKUP($H11,怪物强度修正!$A$2:$R$17,COLUMN(U11)-9,FALSE) -> 100 | V11: 1 | W11: =原始值!P11+VLOOKUP($H11,怪物强度修正!$A$2:$R$17,COLUMN(W11)-9,FALSE) -> 10 | X11: =原始值!Q11+VLOOKUP($H11,怪物强度修正!$A$2:$R$17,COLUMN(X11)-9,FALSE) -> 13 | Y11: =原始值!R11+VLOOKUP($H11,怪物强度修正!$A$2:$R$17,COLUMN(Y11)-9,FALSE) -> 75 | Z11: =原始值!S11+VLOOKUP($H11,怪物强度修正!$A$2:$R$17,COLUMN(Z11)-9,FALSE) -> 300 | AA11: =原始值!T11+VLOOKUP($H11,怪物强度修正!$A$2:$R$17,COLUMN(AA11)-9,FALSE) -> 50
A12: ="PhyType.NewNpcType_"&D12 -> PhyType.NewNpcType_1041 | B12: NPC_Pattern | C12: 1041 | D12: 1041 | G12: 半兽人战士_BJC | H12: 边界村 | I12: 32 | K12: =原始值!D12+VLOOKUP($H12,怪物强度修正!$A$2:$R$17,COLUMN(K12)-9,FALSE) -> 4 | L12: =原始值!E12+VLOOKUP($H12,怪物强度修正!$A$2:$R$17,COLUMN(L12)-9,FALSE) -> 9 | M12: =K12 -> 4 | N12: =L12 -> 9 | O12: =原始值!H12+VLOOKUP($H12,怪物强度修正!$A$2:$R$17,COLUMN(O12)-9,FALSE) -> 0 | P12: =原始值!I12+VLOOKUP($H12,怪物强度修正!$A$2:$R$17,COLUMN(P12)-9,FALSE) -> 0 | Q12: =原始值!J12+VLOOKUP($H12,怪物强度修正!$A$2:$R$17,COLUMN(Q12)-9,FALSE) -> 1 | R12: =原始值!K12+VLOOKUP($H12,怪物强度修正!$A$2:$R$17,COLUMN(R12)-9,FALSE) -> 1 | S12: =原始值!L12+VLOOKUP($H12,怪物强度修正!$A$2:$R$17,COLUMN(S12)-9,FALSE) -> 0 | T12: =原始值!M12+VLOOKUP($H12,怪物强度修正!$A$2:$R$17,COLUMN(T12)-9,FALSE) -> 0 | U12: =原始值!N12+VLOOKUP($H12,怪物强度修正!$A$2:$R$17,COLUMN(U12)-9,FALSE) -> 35 | V12: 1 | W12: =原始值!P12+VLOOKUP($H12,怪物强度修正!$A$2:$R$17,COLUMN(W12)-9,FALSE) -> 10 | X12: =原始值!Q12+VLOOKUP($H12,怪物强度修正!$A$2:$R$17,COLUMN(X12)-9,FALSE) -> 9 | Y12: =原始值!R12+VLOOKUP($H12,怪物强度修正!$A$2:$R$17,COLUMN(Y12)-9,FALSE) -> 75 | Z12: =原始值!S12+VLOOKUP($H12,怪物强度修正!$A$2:$R$17,COLUMN(Z12)-9,FALSE) -> 300 | AA12: =原始值!T12+VLOOKUP($H12,怪物强度修正!$A$2:$R$17,COLUMN(AA12)-9,FALSE) -> 50
A13: ="PhyType.NewNpcType_"&D13 -> PhyType.NewNpcType_1042 | B13: NPC_Pattern | C13: 1042 | D13: 1042 | G13: 半兽人战士_BQS | H13: 比奇省 | I13: 39 | K13: =原始值!D13+VLOOKUP($H13,怪物强度修正!$A$2:$R$17,COLUMN(K13)-9,FALSE) -> 5 | L13: =原始值!E13+VLOOKUP($H13,怪物强度修正!$A$2:$R$17,COLUMN(L13)-9,FALSE) -> 11 | M13: =K13 -> 5 | N13: =L13 -> 11 | O13: =原始值!H13+VLOOKUP($H13,怪物强度修正!$A$2:$R$17,COLUMN(O13)-9,FALSE) -> 0 | P13: =原始值!I13+VLOOKUP($H13,怪物强度修正!$A$2:$R$17,COLUMN(P13)-9,FALSE) -> 0 | Q13: =原始值!J13+VLOOKUP($H13,怪物强度修正!$A$2:$R$17,COLUMN(Q13)-9,FALSE) -> 1 | R13: =原始值!K13+VLOOKUP($H13,怪物强度修正!$A$2:$R$17,COLUMN(R13)-9,FALSE) -> 1 | S13: =原始值!L13+VLOOKUP($H13,怪物强度修正!$A$2:$R$17,COLUMN(S13)-9,FALSE) -> 0 | T13: =原始值!M13+VLOOKUP($H13,怪物强度修正!$A$2:$R$17,COLUMN(T13)-9,FALSE) -> 0 | U13: =原始值!N13+VLOOKUP($H13,怪物强度修正!$A$2:$R$17,COLUMN(U13)-9,FALSE) -> 45 | V13: 1 | W13: =原始值!P13+VLOOKUP($H13,怪物强度修正!$A$2:$R$17,COLUMN(W13)-9,FALSE) -> 10 | X13: =原始值!Q13+VLOOKUP($H13,怪物强度修正!$A$2:$R$17,COLUMN(X13)-9,FALSE) -> 10 | Y13: =原始值!R13+VLOOKUP($H13,怪物强度修正!$A$2:$R$17,COLUMN(Y13)-9,FALSE) -> 75 | Z13: =原始值!S13+VLOOKUP($H13,怪物强度修正!$A$2:$R$17,COLUMN(Z13)-9,FALSE) -> 300 | AA13: =原始值!T13+VLOOKUP($H13,怪物强度修正!$A$2:$R$17,COLUMN(AA13)-9,FALSE) -> 50
A14: ="PhyType.NewNpcType_"&D14 -> PhyType.NewNpcType_105 | B14: NPC_Pattern | C14: 105 | D14: 105 | G14: 半兽人勇士 | H14: 比奇省 | I14: 299 | K14: =原始值!D14+VLOOKUP($H14,怪物强度修正!$A$2:$R$17,COLUMN(K14)-9,FALSE) -> 15 | L14: =原始值!E14+VLOOKUP($H14,怪物强度修正!$A$2:$R$17,COLUMN(L14)-9,FALSE) -> 32 | M14: =K14 -> 15 | N14: =L14 -> 32 | O14: =原始值!H14+VLOOKUP($H14,怪物强度修正!$A$2:$R$17,COLUMN(O14)-9,FALSE) -> 0 | P14: =原始值!I14+VLOOKUP($H14,怪物强度修正!$A$2:$R$17,COLUMN(P14)-9,FALSE) -> 0 | Q14: =原始值!J14+VLOOKUP($H14,怪物强度修正!$A$2:$R$17,COLUMN(Q14)-9,FALSE) -> 0 | R14: =原始值!K14+VLOOKUP($H14,怪物强度修正!$A$2:$R$17,COLUMN(R14)-9,FALSE) -> 0 | S14: =原始值!L14+VLOOKUP($H14,怪物强度修正!$A$2:$R$17,COLUMN(S14)-9,FALSE) -> 0 | T14: =原始值!M14+VLOOKUP($H14,怪物强度修正!$A$2:$R$17,COLUMN(T14)-9,FALSE) -> 0 | U14: =原始值!N14+VLOOKUP($H14,怪物强度修正!$A$2:$R$17,COLUMN(U14)-9,FALSE) -> 300 | V14: 1 | W14: =原始值!P14+VLOOKUP($H14,怪物强度修正!$A$2:$R$17,COLUMN(W14)-9,FALSE) -> 13 | X14: =原始值!Q14+VLOOKUP($H14,怪物强度修正!$A$2:$R$17,COLUMN(X14)-9,FALSE) -> 13 | Y14: =原始值!R14+VLOOKUP($H14,怪物强度修正!$A$2:$R$17,COLUMN(Y14)-9,FALSE) -> 75 | Z14: =原始值!S14+VLOOKUP($H14,怪物强度修正!$A$2:$R$17,COLUMN(Z14)-9,FALSE) -> 300 | AA14: =原始值!T14+VLOOKUP($H14,怪物强度修正!$A$2:$R$17,COLUMN(AA14)-9,FALSE) -> 50
A15: ="PhyType.NewNpcType_"&D15 -> PhyType.NewNpcType_1051 | B15: NPC_Pattern | C15: 1051 | D15: 1051 | G15: 半兽人勇士_BJC | H15: 边界村 | I15: 59 | K15: =原始值!D15+VLOOKUP($H15,怪物强度修正!$A$2:$R$17,COLUMN(K15)-9,FALSE) -> 6 | L15: =原始值!E15+VLOOKUP($H15,怪物强度修正!$A$2:$R$17,COLUMN(L15)-9,FALSE) -> 13 | M15: =K15 -> 6 | N15: =L15 -> 13 | O15: =原始值!H15+VLOOKUP($H15,怪物强度修正!$A$2:$R$17,COLUMN(O15)-9,FALSE) -> 0 | P15: =原始值!I15+VLOOKUP($H15,怪物强度修正!$A$2:$R$17,COLUMN(P15)-9,FALSE) -> 0 | Q15: =原始值!J15+VLOOKUP($H15,怪物强度修正!$A$2:$R$17,COLUMN(Q15)-9,FALSE) -> 2 | R15: =原始值!K15+VLOOKUP($H15,怪物强度修正!$A$2:$R$17,COLUMN(R15)-9,FALSE) -> 2 | S15: =原始值!L15+VLOOKUP($H15,怪物强度修正!$A$2:$R$17,COLUMN(S15)-9,FALSE) -> 1 | T15: =原始值!M15+VLOOKUP($H15,怪物强度修正!$A$2:$R$17,COLUMN(T15)-9,FALSE) -> 1 | U15: =原始值!N15+VLOOKUP($H15,怪物强度修正!$A$2:$R$17,COLUMN(U15)-9,FALSE) -> 65 | V15: 1 | W15: =原始值!P15+VLOOKUP($H15,怪物强度修正!$A$2:$R$17,COLUMN(W15)-9,FALSE) -> 13 | X15: =原始值!Q15+VLOOKUP($H15,怪物强度修正!$A$2:$R$17,COLUMN(X15)-9,FALSE) -> 10 | Y15: =原始值!R15+VLOOKUP($H15,怪物强度修正!$A$2:$R$17,COLUMN(Y15)-9,FALSE) -> 75 | Z15: =原始值!S15+VLOOKUP($H15,怪物强度修正!$A$2:$R$17,COLUMN(Z15)-9,FALSE) -> 300 | AA15: =原始值!T15+VLOOKUP($H15,怪物强度修正!$A$2:$R$17,COLUMN(AA15)-9,FALSE) -> 50
A16: ="PhyType.NewNpcType_"&D16 -> PhyType.NewNpcType_1052 | B16: NPC_Pattern | C16: 1052 | D16: 1052 | G16: 半兽人勇士_BQS | H16: 比奇省 | I16: 59 | K16: =原始值!D16+VLOOKUP($H16,怪物强度修正!$A$2:$R$17,COLUMN(K16)-9,FALSE) -> 6 | L16: =原始值!E16+VLOOKUP($H16,怪物强度修正!$A$2:$R$17,COLUMN(L16)-9,FALSE) -> 13 | M16: =K16 -> 6 | N16: =L16 -> 13 | O16: =原始值!H16+VLOOKUP($H16,怪物强度修正!$A$2:$R$17,COLUMN(O16)-9,FALSE) -> 0 | P16: =原始值!I16+VLOOKUP($H16,怪物强度修正!$A$2:$R$17,COLUMN(P16)-9,FALSE) -> 0 | Q16: =原始值!J16+VLOOKUP($H16,怪物强度修正!$A$2:$R$17,COLUMN(Q16)-9,FALSE) -> 2 | R16: =原始值!K16+VLOOKUP($H16,怪物强度修正!$A$2:$R$17,COLUMN(R16)-9,FALSE) -> 2 | S16: =原始值!L16+VLOOKUP($H16,怪物强度修正!$A$2:$R$17,COLUMN(S16)-9,FALSE) -> 1 | T16: =原始值!M16+VLOOKUP($H16,怪物强度修正!$A$2:$R$17,COLUMN(T16)-9,FALSE) -> 1 | U16: =原始值!N16+VLOOKUP($H16,怪物强度修正!$A$2:$R$17,COLUMN(U16)-9,FALSE) -> 65 | V16: 1 | W16: =原始值!P16+VLOOKUP($H16,怪物强度修正!$A$2:$R$17,COLUMN(W16)-9,FALSE) -> 13 | X16: =原始值!Q16+VLOOKUP($H16,怪物强度修正!$A$2:$R$17,COLUMN(X16)-9,FALSE) -> 11 | Y16: =原始值!R16+VLOOKUP($H16,怪物强度修正!$A$2:$R$17,COLUMN(Y16)-9,FALSE) -> 75 | Z16: =原始值!S16+VLOOKUP($H16,怪物强度修正!$A$2:$R$17,COLUMN(Z16)-9,FALSE) -> 300 | AA16: =原始值!T16+VLOOKUP($H16,怪物强度修正!$A$2:$R$17,COLUMN(AA16)-9,FALSE) -> 50
A17: ="PhyType.NewNpcType_"&D17 -> PhyType.NewNpcType_106 | B17: NPC_Pattern | C17: 106 | D17: 106 | G17: 鹿 | H17: 边界村 | I17: 14 | K17: =原始值!D17+VLOOKUP($H17,怪物强度修正!$A$2:$R$17,COLUMN(K17)-9,FALSE) -> 2 | L17: =原始值!E17+VLOOKUP($H17,怪物强度修正!$A$2:$R$17,COLUMN(L17)-9,FALSE) -> 4 | M17: =K17 -> 2 | N17: =L17 -> 4 | O17: =原始值!H17+VLOOKUP($H17,怪物强度修正!$A$2:$R$17,COLUMN(O17)-9,FALSE) -> 0 | P17: =原始值!I17+VLOOKUP($H17,怪物强度修正!$A$2:$R$17,COLUMN(P17)-9,FALSE) -> 0 | Q17: =原始值!J17+VLOOKUP($H17,怪物强度修正!$A$2:$R$17,COLUMN(Q17)-9,FALSE) -> 0 | R17: =原始值!K17+VLOOKUP($H17,怪物强度修正!$A$2:$R$17,COLUMN(R17)-9,FALSE) -> 0 | S17: =原始值!L17+VLOOKUP($H17,怪物强度修正!$A$2:$R$17,COLUMN(S17)-9,FALSE) -> 0 | T17: =原始值!M17+VLOOKUP($H17,怪物强度修正!$A$2:$R$17,COLUMN(T17)-9,FALSE) -> 0 | U17: =原始值!N17+VLOOKUP($H17,怪物强度修正!$A$2:$R$17,COLUMN(U17)-9,FALSE) -> 15 | V17: 1 | W17: =原始值!P17+VLOOKUP($H17,怪物强度修正!$A$2:$R$17,COLUMN(W17)-9,FALSE) -> 12 | X17: =原始值!Q17+VLOOKUP($H17,怪物强度修正!$A$2:$R$17,COLUMN(X17)-9,FALSE) -> 1 | Y17: =原始值!R17+VLOOKUP($H17,怪物强度修正!$A$2:$R$17,COLUMN(Y17)-9,FALSE) -> 75 | Z17: =原始值!S17+VLOOKUP($H17,怪物强度修正!$A$2:$R$17,COLUMN(Z17)-9,FALSE) -> 300 | AA17: =原始值!T17+VLOOKUP($H17,怪物强度修正!$A$2:$R$17,COLUMN(AA17)-9,FALSE) -> 50
A18: ="PhyType.NewNpcType_"&D18 -> PhyType.NewNpcType_107 | B18: NPC_Pattern | C18: 107 | D18: 107 | G18: 残肢僵尸 | H18: 比奇矿区 | I18: 139 | K18: =原始值!D18+VLOOKUP($H18,怪物强度修正!$A$2:$R$17,COLUMN(K18)-9,FALSE) -> 5 | L18: =原始值!E18+VLOOKUP($H18,怪物强度修正!$A$2:$R$17,COLUMN(L18)-9,FALSE) -> 12 | M18: =K18 -> 5 | N18: =L18 -> 12 | O18: =原始值!H18+VLOOKUP($H18,怪物强度修正!$A$2:$R$17,COLUMN(O18)-9,FALSE) -> 0 | P18: =原始值!I18+VLOOKUP($H18,怪物强度修正!$A$2:$R$17,COLUMN(P18)-9,FALSE) -> 0 | Q18: =原始值!J18+VLOOKUP($H18,怪物强度修正!$A$2:$R$17,COLUMN(Q18)-9,FALSE) -> 2 | R18: =原始值!K18+VLOOKUP($H18,怪物强度修正!$A$2:$R$17,COLUMN(R18)-9,FALSE) -> 2 | S18: =原始值!L18+VLOOKUP($H18,怪物强度修正!$A$2:$R$17,COLUMN(S18)-9,FALSE) -> 1 | T18: =原始值!M18+VLOOKUP($H18,怪物强度修正!$A$2:$R$17,COLUMN(T18)-9,FALSE) -> 1 | U18: =原始值!N18+VLOOKUP($H18,怪物强度修正!$A$2:$R$17,COLUMN(U18)-9,FALSE) -> 155 | V18: 1 | W18: =原始值!P18+VLOOKUP($H18,怪物强度修正!$A$2:$R$17,COLUMN(W18)-9,FALSE) -> 12 | X18: =原始值!Q18+VLOOKUP($H18,怪物强度修正!$A$2:$R$17,COLUMN(X18)-9,FALSE) -> 15 | Y18: =原始值!R18+VLOOKUP($H18,怪物强度修正!$A$2:$R$17,COLUMN(Y18)-9,FALSE) -> 75 | Z18: =原始值!S18+VLOOKUP($H18,怪物强度修正!$A$2:$R$17,COLUMN(Z18)-9,FALSE) -> 300 | AA18: =原始值!T18+VLOOKUP($H18,怪物强度修正!$A$2:$R$17,COLUMN(AA18)-9,FALSE) -> 50
A19: ="PhyType.NewNpcType_"&D19 -> PhyType.NewNpcType_108 | B19: NPC_Pattern | C19: 108 | D19: 108 | G19: 直立僵尸 | H19: 比奇矿区 | I19: 149 | K19: =原始值!D19+VLOOKUP($H19,怪物强度修正!$A$2:$R$17,COLUMN(K19)-9,FALSE) -> 5 | L19: =原始值!E19+VLOOKUP($H19,怪物强度修正!$A$2:$R$17,COLUMN(L19)-9,FALSE) -> 15 | M19: =K19 -> 5 | N19: =L19 -> 15 | O19: =原始值!H19+VLOOKUP($H19,怪物强度修正!$A$2:$R$17,COLUMN(O19)-9,FALSE) -> 0 | P19: =原始值!I19+VLOOKUP($H19,怪物强度修正!$A$2:$R$17,COLUMN(P19)-9,FALSE) -> 0 | Q19: =原始值!J19+VLOOKUP($H19,怪物强度修正!$A$2:$R$17,COLUMN(Q19)-9,FALSE) -> 2 | R19: =原始值!K19+VLOOKUP($H19,怪物强度修正!$A$2:$R$17,COLUMN(R19)-9,FALSE) -> 2 | S19: =原始值!L19+VLOOKUP($H19,怪物强度修正!$A$2:$R$17,COLUMN(S19)-9,FALSE) -> 1 | T19: =原始值!M19+VLOOKUP($H19,怪物强度修正!$A$2:$R$17,COLUMN(T19)-9,FALSE) -> 1 | U19: =原始值!N19+VLOOKUP($H19,怪物强度修正!$A$2:$R$17,COLUMN(U19)-9,FALSE) -> 155 | V19: 1 | W19: =原始值!P19+VLOOKUP($H19,怪物强度修正!$A$2:$R$17,COLUMN(W19)-9,FALSE) -> 12 | X19: =原始值!Q19+VLOOKUP($H19,怪物强度修正!$A$2:$R$17,COLUMN(X19)-9,FALSE) -> 15 | Y19: =原始值!R19+VLOOKUP($H19,怪物强度修正!$A$2:$R$17,COLUMN(Y19)-9,FALSE) -> 75 | Z19: =原始值!S19+VLOOKUP($H19,怪物强度修正!$A$2:$R$17,COLUMN(Z19)-9,FALSE) -> 300 | AA19: =原始值!T19+VLOOKUP($H19,怪物强度修正!$A$2:$R$17,COLUMN(AA19)-9,FALSE) -> 50
... A63: ="PhyType.NewNpcType_"&D63 -> PhyType.NewNpcType_152 | B63: NPC_Pattern | C63: 152 | D63: 152 | G63: 暴牙蜘蛛 | H63: 赤月峡谷 | I63: 399 | K63: =原始值!D63+VLOOKUP($H63,怪物强度修正!$A$2:$R$17,COLUMN(K63)-9,FALSE) -> 27 | L63: =原始值!E63+VLOOKUP($H63,怪物强度修正!$A$2:$R$17,COLUMN(L63)-9,FALSE) -> 39 | M63: =K63 -> 27 | N63: =L63 -> 39 | O63: =原始值!H63+VLOOKUP($H63,怪物强度修正!$A$2:$R$17,COLUMN(O63)-9,FALSE) -> 0 | P63: =原始值!I63+VLOOKUP($H63,怪物强度修正!$A$2:$R$17,COLUMN(P63)-9,FALSE) -> 0 | Q63: =原始值!J63+VLOOKUP($H63,怪物强度修正!$A$2:$R$17,COLUMN(Q63)-9,FALSE) -> 13 | R63: =原始值!K63+VLOOKUP($H63,怪物强度修正!$A$2:$R$17,COLUMN(R63)-9,FALSE) -> 13 | S63: =原始值!L63+VLOOKUP($H63,怪物强度修正!$A$2:$R$17,COLUMN(S63)-9,FALSE) -> 32 | T63: =原始值!M63+VLOOKUP($H63,怪物强度修正!$A$2:$R$17,COLUMN(T63)-9,FALSE) -> 32 | U63: =原始值!N63+VLOOKUP($H63,怪物强度修正!$A$2:$R$17,COLUMN(U63)-9,FALSE) -> 500 | V63: 12 | W63: =原始值!P63+VLOOKUP($H63,怪物强度修正!$A$2:$R$17,COLUMN(W63)-9,FALSE) -> 17 | X63: =原始值!Q63+VLOOKUP($H63,怪物强度修正!$A$2:$R$17,COLUMN(X63)-9,FALSE) -> 17 | Y63: =原始值!R63+VLOOKUP($H63,怪物强度修正!$A$2:$R$17,COLUMN(Y63)-9,FALSE) -> 75 | Z63: =原始值!S63+VLOOKUP($H63,怪物强度修正!$A$2:$R$17,COLUMN(Z63)-9,FALSE) -> 300 | AA63: =原始值!T63+VLOOKUP($H63,怪物强度修正!$A$2:$R$17,COLUMN(AA63)-9,FALSE) -> 50
A64: ="PhyType.NewNpcType_"&D64 -> PhyType.NewNpcType_201 | B64: NPC_Pattern | C64: 201 | D64: 201 | G64: =G8&"微型" -> 稻草人微型 | H64: =H8 -> 边界村 | I64: =INT((I8+1)*0.6-1) -> 5 | K64: =原始值!D64+VLOOKUP($H64,怪物强度修正!$A$2:$R$17,COLUMN(K64)-9,FALSE) -> 1 | L64: =原始值!E64+VLOOKUP($H64,怪物强度修正!$A$2:$R$17,COLUMN(L64)-9,FALSE) -> 2 | M64: =K64 -> 1 | N64: =L64 -> 2 | O64: =原始值!H64+VLOOKUP($H64,怪物强度修正!$A$2:$R$17,COLUMN(O64)-9,FALSE) -> 0 | P64: =原始值!I64+VLOOKUP($H64,怪物强度修正!$A$2:$R$17,COLUMN(P64)-9,FALSE) -> 0 | Q64: =原始值!J64+VLOOKUP($H64,怪物强度修正!$A$2:$R$17,COLUMN(Q64)-9,FALSE) -> 0 | R64: =原始值!K64+VLOOKUP($H64,怪物强度修正!$A$2:$R$17,COLUMN(R64)-9,FALSE) -> 0 | S64: =原始值!L64+VLOOKUP($H64,怪物强度修正!$A$2:$R$17,COLUMN(S64)-9,FALSE) -> 0 | T64: =原始值!M64+VLOOKUP($H64,怪物强度修正!$A$2:$R$17,COLUMN(T64)-9,FALSE) -> 0 | U64: =原始值!N64+VLOOKUP($H64,怪物强度修正!$A$2:$R$17,COLUMN(U64)-9,FALSE) -> 11 | V64: 1 | W64: =原始值!P64+VLOOKUP($H64,怪物强度修正!$A$2:$R$17,COLUMN(W64)-9,FALSE) -> 5 | X64: =原始值!Q64+VLOOKUP($H64,怪物强度修正!$A$2:$R$17,COLUMN(X64)-9,FALSE) -> 7 | Y64: =原始值!R64+VLOOKUP($H64,怪物强度修正!$A$2:$R$17,COLUMN(Y64)-9,FALSE) -> 75 | Z64: =原始值!S64+VLOOKUP($H64,怪物强度修正!$A$2:$R$17,COLUMN(Z64)-9,FALSE) -> 300 | AA64: =原始值!T64+VLOOKUP($H64,怪物强度修正!$A$2:$R$17,COLUMN(AA64)-9,FALSE) -> 50
A65: ="PhyType.NewNpcType_"&D65 -> PhyType.NewNpcType_202 | B65: NPC_Pattern | C65: 202 | D65: 202 | G65: =G9&"微型" -> 钉耙猫微型 | H65: =H9 -> 边界村 | I65: =INT((I9+1)*0.6-1) -> 9 | K65: =原始值!D65+VLOOKUP($H65,怪物强度修正!$A$2:$R$17,COLUMN(K65)-9,FALSE) -> 2 | L65: =原始值!E65+VLOOKUP($H65,怪物强度修正!$A$2:$R$17,COLUMN(L65)-9,FALSE) -> 3 | M65: =K65 -> 2 | N65: =L65 -> 3 | O65: =原始值!H65+VLOOKUP($H65,怪物强度修正!$A$2:$R$17,COLUMN(O65)-9,FALSE) -> 0 | P65: =原始值!I65+VLOOKUP($H65,怪物强度修正!$A$2:$R$17,COLUMN(P65)-9,FALSE) -> 0 | Q65: =原始值!J65+VLOOKUP($H65,怪物强度修正!$A$2:$R$17,COLUMN(Q65)-9,FALSE) -> 0 | R65: =原始值!K65+VLOOKUP($H65,怪物强度修正!$A$2:$R$17,COLUMN(R65)-9,FALSE) -> 0 | S65: =原始值!L65+VLOOKUP($H65,怪物强度修正!$A$2:$R$17,COLUMN(S65)-9,FALSE) -> 0 | T65: =原始值!M65+VLOOKUP($H65,怪物强度修正!$A$2:$R$17,COLUMN(T65)-9,FALSE) -> 0 | U65: =原始值!N65+VLOOKUP($H65,怪物强度修正!$A$2:$R$17,COLUMN(U65)-9,FALSE) -> 16 | V65: 1 | W65: =原始值!P65+VLOOKUP($H65,怪物强度修正!$A$2:$R$17,COLUMN(W65)-9,FALSE) -> 5 | X65: =原始值!Q65+VLOOKUP($H65,怪物强度修正!$A$2:$R$17,COLUMN(X65)-9,FALSE) -> 7 | Y65: =原始值!R65+VLOOKUP($H65,怪物强度修正!$A$2:$R$17,COLUMN(Y65)-9,FALSE) -> 75 | Z65: =原始值!S65+VLOOKUP($H65,怪物强度修正!$A$2:$R$17,COLUMN(Z65)-9,FALSE) -> 300 | AA65: =原始值!T65+VLOOKUP($H65,怪物强度修正!$A$2:$R$17,COLUMN(AA65)-9,FALSE) -> 50
A66: ="PhyType.NewNpcType_"&D66 -> PhyType.NewNpcType_203 | B66: NPC_Pattern | C66: 203 | D66: 203 | G66: =G10&"微型" -> 半兽人微型 | H66: =H10 -> 边界村 | I66: =INT((I10+1)*0.6-1) -> 14 | K66: =原始值!D66+VLOOKUP($H66,怪物强度修正!$A$2:$R$17,COLUMN(K66)-9,FALSE) -> 2 | L66: =原始值!E66+VLOOKUP($H66,怪物强度修正!$A$2:$R$17,COLUMN(L66)-9,FALSE) -> 6 | M66: =K66 -> 2 | N66: =L66 -> 6 | O66: =原始值!H66+VLOOKUP($H66,怪物强度修正!$A$2:$R$17,COLUMN(O66)-9,FALSE) -> 0 | P66: =原始值!I66+VLOOKUP($H66,怪物强度修正!$A$2:$R$17,COLUMN(P66)-9,FALSE) -> 0 | Q66: =原始值!J66+VLOOKUP($H66,怪物强度修正!$A$2:$R$17,COLUMN(Q66)-9,FALSE) -> 1 | R66: =原始值!K66+VLOOKUP($H66,怪物强度修正!$A$2:$R$17,COLUMN(R66)-9,FALSE) -> 1 | S66: =原始值!L66+VLOOKUP($H66,怪物强度修正!$A$2:$R$17,COLUMN(S66)-9,FALSE) -> 0 | T66: =原始值!M66+VLOOKUP($H66,怪物强度修正!$A$2:$R$17,COLUMN(T66)-9,FALSE) -> 0 | U66: =原始值!N66+VLOOKUP($H66,怪物强度修正!$A$2:$R$17,COLUMN(U66)-9,FALSE) -> 21 | V66: 1 | W66: =原始值!P66+VLOOKUP($H66,怪物强度修正!$A$2:$R$17,COLUMN(W66)-9,FALSE) -> 6 | X66: =原始值!Q66+VLOOKUP($H66,怪物强度修正!$A$2:$R$17,COLUMN(X66)-9,FALSE) -> 8 | Y66: =原始值!R66+VLOOKUP($H66,怪物强度修正!$A$2:$R$17,COLUMN(Y66)-9,FALSE) -> 75 | Z66: =原始值!S66+VLOOKUP($H66,怪物强度修正!$A$2:$R$17,COLUMN(Z66)-9,FALSE) -> 300 | AA66: =原始值!T66+VLOOKUP($H66,怪物强度修正!$A$2:$R$17,COLUMN(AA66)-9,FALSE) -> 50
A67: ="PhyType.NewNpcType_"&D67 -> PhyType.NewNpcType_204 | B67: NPC_Pattern | C67: 204 | D67: 204 | G67: =G11&"微型" -> 半兽人战士微型 | H67: =H11 -> 比奇省 | I67: =INT((I11+1)*0.6-1) -> 53 | K67: =原始值!D67+VLOOKUP($H67,怪物强度修正!$A$2:$R$17,COLUMN(K67)-9,FALSE) -> 4 | L67: =原始值!E67+VLOOKUP($H67,怪物强度修正!$A$2:$R$17,COLUMN(L67)-9,FALSE) -> 10 | M67: =K67 -> 4 | N67: =L67 -> 10 | O67: =原始值!H67+VLOOKUP($H67,怪物强度修正!$A$2:$R$17,COLUMN(O67)-9,FALSE) -> 0 | P67: =原始值!I67+VLOOKUP($H67,怪物强度修正!$A$2:$R$17,COLUMN(P67)-9,FALSE) -> 0 | Q67: =原始值!J67+VLOOKUP($H67,怪物强度修正!$A$2:$R$17,COLUMN(Q67)-9,FALSE) -> 3 | R67: =原始值!K67+VLOOKUP($H67,怪物强度修正!$A$2:$R$17,COLUMN(R67)-9,FALSE) -> 3 | S67: =原始值!L67+VLOOKUP($H67,怪物强度修正!$A$2:$R$17,COLUMN(S67)-9,FALSE) -> 1 | T67: =原始值!M67+VLOOKUP($H67,怪物强度修正!$A$2:$R$17,COLUMN(T67)-9,FALSE) -> 1 | U67: =原始值!N67+VLOOKUP($H67,怪物强度修正!$A$2:$R$17,COLUMN(U67)-9,FALSE) -> 70 | V67: 1 | W67: =原始值!P67+VLOOKUP($H67,怪物强度修正!$A$2:$R$17,COLUMN(W67)-9,FALSE) -> 10 | X67: =原始值!Q67+VLOOKUP($H67,怪物强度修正!$A$2:$R$17,COLUMN(X67)-9,FALSE) -> 13 | Y67: =原始值!R67+VLOOKUP($H67,怪物强度修正!$A$2:$R$17,COLUMN(Y67)-9,FALSE) -> 75 | Z67: =原始值!S67+VLOOKUP($H67,怪物强度修正!$A$2:$R$17,COLUMN(Z67)-9,FALSE) -> 300 | AA67: =原始值!T67+VLOOKUP($H67,怪物强度修正!$A$2:$R$17,COLUMN(AA67)-9,FALSE) -> 50
A68: ="PhyType.NewNpcType_"&D68 -> PhyType.NewNpcType_2041 | B68: NPC_Pattern | C68: 2041 | D68: 2041 | G68: =G12&"微型" -> 半兽人战士_BJC微型 | H68: =H12 -> 边界村 | I68: =INT((I12+1)*0.6-1) -> 18 | K68: =原始值!D68+VLOOKUP($H68,怪物强度修正!$A$2:$R$17,COLUMN(K68)-9,FALSE) -> 3 | L68: =原始值!E68+VLOOKUP($H68,怪物强度修正!$A$2:$R$17,COLUMN(L68)-9,FALSE) -> 7 | M68: =K68 -> 3 | N68: =L68 -> 7 | O68: =原始值!H68+VLOOKUP($H68,怪物强度修正!$A$2:$R$17,COLUMN(O68)-9,FALSE) -> 0 | P68: =原始值!I68+VLOOKUP($H68,怪物强度修正!$A$2:$R$17,COLUMN(P68)-9,FALSE) -> 0 | Q68: =原始值!J68+VLOOKUP($H68,怪物强度修正!$A$2:$R$17,COLUMN(Q68)-9,FALSE) -> 1 | R68: =原始值!K68+VLOOKUP($H68,怪物强度修正!$A$2:$R$17,COLUMN(R68)-9,FALSE) -> 1 | S68: =原始值!L68+VLOOKUP($H68,怪物强度修正!$A$2:$R$17,COLUMN(S68)-9,FALSE) -> 0 | T68: =原始值!M68+VLOOKUP($H68,怪物强度修正!$A$2:$R$17,COLUMN(T68)-9,FALSE) -> 0 | U68: =原始值!N68+VLOOKUP($H68,怪物强度修正!$A$2:$R$17,COLUMN(U68)-9,FALSE) -> 25 | V68: 1 | W68: =原始值!P68+VLOOKUP($H68,怪物强度修正!$A$2:$R$17,COLUMN(W68)-9,FALSE) -> 10 | X68: =原始值!Q68+VLOOKUP($H68,怪物强度修正!$A$2:$R$17,COLUMN(X68)-9,FALSE) -> 9 | Y68: =原始值!R68+VLOOKUP($H68,怪物强度修正!$A$2:$R$17,COLUMN(Y68)-9,FALSE) -> 75 | Z68: =原始值!S68+VLOOKUP($H68,怪物强度修正!$A$2:$R$17,COLUMN(Z68)-9,FALSE) -> 300 | AA68: =原始值!T68+VLOOKUP($H68,怪物强度修正!$A$2:$R$17,COLUMN(AA68)-9,FALSE) -> 50
A69: ="PhyType.NewNpcType_"&D69 -> PhyType.NewNpcType_2042 | B69: NPC_Pattern | C69: 2042 | D69: 2042 | G69: =G13&"微型" -> 半兽人战士_BQS微型 | H69: =H13 -> 比奇省 | I69: =INT((I13+1)*0.6-1) -> 23 | K69: =原始值!D69+VLOOKUP($H69,怪物强度修正!$A$2:$R$17,COLUMN(K69)-9,FALSE) -> 4 | L69: =原始值!E69+VLOOKUP($H69,怪物强度修正!$A$2:$R$17,COLUMN(L69)-9,FALSE) -> 9 | M69: =K69 -> 4 | N69: =L69 -> 9 | O69: =原始值!H69+VLOOKUP($H69,怪物强度修正!$A$2:$R$17,COLUMN(O69)-9,FALSE) -> 0 | P69: =原始值!I69+VLOOKUP($H69,怪物强度修正!$A$2:$R$17,COLUMN(P69)-9,FALSE) -> 0 | Q69: =原始值!J69+VLOOKUP($H69,怪物强度修正!$A$2:$R$17,COLUMN(Q69)-9,FALSE) -> 1 | R69: =原始值!K69+VLOOKUP($H69,怪物强度修正!$A$2:$R$17,COLUMN(R69)-9,FALSE) -> 1 | S69: =原始值!L69+VLOOKUP($H69,怪物强度修正!$A$2:$R$17,COLUMN(S69)-9,FALSE) -> 0 | T69: =原始值!M69+VLOOKUP($H69,怪物强度修正!$A$2:$R$17,COLUMN(T69)-9,FALSE) -> 0 | U69: =原始值!N69+VLOOKUP($H69,怪物强度修正!$A$2:$R$17,COLUMN(U69)-9,FALSE) -> 32 | V69: 1 | W69: =原始值!P69+VLOOKUP($H69,怪物强度修正!$A$2:$R$17,COLUMN(W69)-9,FALSE) -> 10 | X69: =原始值!Q69+VLOOKUP($H69,怪物强度修正!$A$2:$R$17,COLUMN(X69)-9,FALSE) -> 10 | Y69: =原始值!R69+VLOOKUP($H69,怪物强度修正!$A$2:$R$17,COLUMN(Y69)-9,FALSE) -> 75 | Z69: =原始值!S69+VLOOKUP($H69,怪物强度修正!$A$2:$R$17,COLUMN(Z69)-9,FALSE) -> 300 | AA69: =原始值!T69+VLOOKUP($H69,怪物强度修正!$A$2:$R$17,COLUMN(AA69)-9,FALSE) -> 50
A70: ="PhyType.NewNpcType_"&D70 -> PhyType.NewNpcType_205 | B70: NPC_Pattern | C70: 205 | D70: 205 | G70: =G14&"微型" -> 半兽人勇士微型 | H70: =H14 -> 比奇省 | I70: =INT((I14+1)*0.6-1) -> 179 | K70: =原始值!D70+VLOOKUP($H70,怪物强度修正!$A$2:$R$17,COLUMN(K70)-9,FALSE) -> 12 | L70: =原始值!E70+VLOOKUP($H70,怪物强度修正!$A$2:$R$17,COLUMN(L70)-9,FALSE) -> 26 | M70: =K70 -> 12 | N70: =L70 -> 26 | O70: =原始值!H70+VLOOKUP($H70,怪物强度修正!$A$2:$R$17,COLUMN(O70)-9,FALSE) -> 0 | P70: =原始值!I70+VLOOKUP($H70,怪物强度修正!$A$2:$R$17,COLUMN(P70)-9,FALSE) -> 0 | Q70: =原始值!J70+VLOOKUP($H70,怪物强度修正!$A$2:$R$17,COLUMN(Q70)-9,FALSE) -> 0 | R70: =原始值!K70+VLOOKUP($H70,怪物强度修正!$A$2:$R$17,COLUMN(R70)-9,FALSE) -> 0 | S70: =原始值!L70+VLOOKUP($H70,怪物强度修正!$A$2:$R$17,COLUMN(S70)-9,FALSE) -> 0 | T70: =原始值!M70+VLOOKUP($H70,怪物强度修正!$A$2:$R$17,COLUMN(T70)-9,FALSE) -> 0 | U70: =原始值!N70+VLOOKUP($H70,怪物强度修正!$A$2:$R$17,COLUMN(U70)-9,FALSE) -> 210 | V70: 1 | W70: =原始值!P70+VLOOKUP($H70,怪物强度修正!$A$2:$R$17,COLUMN(W70)-9,FALSE) -> 13 | X70: =原始值!Q70+VLOOKUP($H70,怪物强度修正!$A$2:$R$17,COLUMN(X70)-9,FALSE) -> 13 | Y70: =原始值!R70+VLOOKUP($H70,怪物强度修正!$A$2:$R$17,COLUMN(Y70)-9,FALSE) -> 75 | Z70: =原始值!S70+VLOOKUP($H70,怪物强度修正!$A$2:$R$17,COLUMN(Z70)-9,FALSE) -> 300 | AA70: =原始值!T70+VLOOKUP($H70,怪物强度修正!$A$2:$R$17,COLUMN(AA70)-9,FALSE) -> 50
A71: ="PhyType.NewNpcType_"&D71 -> PhyType.NewNpcType_2051 | B71: NPC_Pattern | C71: 2051 | D71: 2051 | G71: =G15&"微型" -> 半兽人勇士_BJC微型 | H71: =H15 -> 边界村 | I71: =INT((I15+1)*0.6-1) -> 35 | K71: =原始值!D71+VLOOKUP($H71,怪物强度修正!$A$2:$R$17,COLUMN(K71)-9,FALSE) -> 5 | L71: =原始值!E71+VLOOKUP($H71,怪物强度修正!$A$2:$R$17,COLUMN(L71)-9,FALSE) -> 10 | M71: =K71 -> 5 | N71: =L71 -> 10 | O71: =原始值!H71+VLOOKUP($H71,怪物强度修正!$A$2:$R$17,COLUMN(O71)-9,FALSE) -> 0 | P71: =原始值!I71+VLOOKUP($H71,怪物强度修正!$A$2:$R$17,COLUMN(P71)-9,FALSE) -> 0 | Q71: =原始值!J71+VLOOKUP($H71,怪物强度修正!$A$2:$R$17,COLUMN(Q71)-9,FALSE) -> 2 | R71: =原始值!K71+VLOOKUP($H71,怪物强度修正!$A$2:$R$17,COLUMN(R71)-9,FALSE) -> 2 | S71: =原始值!L71+VLOOKUP($H71,怪物强度修正!$A$2:$R$17,COLUMN(S71)-9,FALSE) -> 1 | T71: =原始值!M71+VLOOKUP($H71,怪物强度修正!$A$2:$R$17,COLUMN(T71)-9,FALSE) -> 1 | U71: =原始值!N71+VLOOKUP($H71,怪物强度修正!$A$2:$R$17,COLUMN(U71)-9,FALSE) -> 46 | V71: 1 | W71: =原始值!P71+VLOOKUP($H71,怪物强度修正!$A$2:$R$17,COLUMN(W71)-9,FALSE) -> 13 | X71: =原始值!Q71+VLOOKUP($H71,怪物强度修正!$A$2:$R$17,COLUMN(X71)-9,FALSE) -> 10 | Y71: =原始值!R71+VLOOKUP($H71,怪物强度修正!$A$2:$R$17,COLUMN(Y71)-9,FALSE) -> 75 | Z71: =原始值!S71+VLOOKUP($H71,怪物强度修正!$A$2:$R$17,COLUMN(Z71)-9,FALSE) -> 300 | AA71: =原始值!T71+VLOOKUP($H71,怪物强度修正!$A$2:$R$17,COLUMN(AA71)-9,FALSE) -> 50
A72: ="PhyType.NewNpcType_"&D72 -> PhyType.NewNpcType_2052 | B72: NPC_Pattern | C72: 2052 | D72: 2052 | G72: =G16&"微型" -> 半兽人勇士_BQS微型 | H72: =H16 -> 比奇省 | I72: =INT((I16+1)*0.6-1) -> 35 | K72: =原始值!D72+VLOOKUP($H72,怪物强度修正!$A$2:$R$17,COLUMN(K72)-9,FALSE) -> 5 | L72: =原始值!E72+VLOOKUP($H72,怪物强度修正!$A$2:$R$17,COLUMN(L72)-9,FALSE) -> 10 | M72: =K72 -> 5 | N72: =L72 -> 10 | O72: =原始值!H72+VLOOKUP($H72,怪物强度修正!$A$2:$R$17,COLUMN(O72)-9,FALSE) -> 0 | P72: =原始值!I72+VLOOKUP($H72,怪物强度修正!$A$2:$R$17,COLUMN(P72)-9,FALSE) -> 0 | Q72: =原始值!J72+VLOOKUP($H72,怪物强度修正!$A$2:$R$17,COLUMN(Q72)-9,FALSE) -> 2 | R72: =原始值!K72+VLOOKUP($H72,怪物强度修正!$A$2:$R$17,COLUMN(R72)-9,FALSE) -> 2 | S72: =原始值!L72+VLOOKUP($H72,怪物强度修正!$A$2:$R$17,COLUMN(S72)-9,FALSE) -> 1 | T72: =原始值!M72+VLOOKUP($H72,怪物强度修正!$A$2:$R$17,COLUMN(T72)-9,FALSE) -> 1 | U72: =原始值!N72+VLOOKUP($H72,怪物强度修正!$A$2:$R$17,COLUMN(U72)-9,FALSE) -> 46 | V72: 1 | W72: =原始值!P72+VLOOKUP($H72,怪物强度修正!$A$2:$R$17,COLUMN(W72)-9,FALSE) -> 13 | X72: =原始值!Q72+VLOOKUP($H72,怪物强度修正!$A$2:$R$17,COLUMN(X72)-9,FALSE) -> 11 | Y72: =原始值!R72+VLOOKUP($H72,怪物强度修正!$A$2:$R$17,COLUMN(Y72)-9,FALSE) -> 75 | Z72: =原始值!S72+VLOOKUP($H72,怪物强度修正!$A$2:$R$17,COLUMN(Z72)-9,FALSE) -> 300 | AA72: =原始值!T72+VLOOKUP($H72,怪物强度修正!$A$2:$R$17,COLUMN(AA72)-9,FALSE) -> 50
A73: ="PhyType.NewNpcType_"&D73 -> PhyType.NewNpcType_206 | B73: NPC_Pattern | C73: 206 | D73: 206 | G73: =G17&"微型" -> 鹿微型 | H73: =H17 -> 边界村 | I73: =INT((I17+1)*0.6-1) -> 8 | K73: =原始值!D73+VLOOKUP($H73,怪物强度修正!$A$2:$R$17,COLUMN(K73)-9,FALSE) -> 2 | L73: =原始值!E73+VLOOKUP($H73,怪物强度修正!$A$2:$R$17,COLUMN(L73)-9,FALSE) -> 3 | M73: =K73 -> 2 | N73: =L73 -> 3 | O73: =原始值!H73+VLOOKUP($H73,怪物强度修正!$A$2:$R$17,COLUMN(O73)-9,FALSE) -> 0 | P73: =原始值!I73+VLOOKUP($H73,怪物强度修正!$A$2:$R$17,COLUMN(P73)-9,FALSE) -> 0 | Q73: =原始值!J73+VLOOKUP($H73,怪物强度修正!$A$2:$R$17,COLUMN(Q73)-9,FALSE) -> 0 | R73: =原始值!K73+VLOOKUP($H73,怪物强度修正!$A$2:$R$17,COLUMN(R73)-9,FALSE) -> 0 | S73: =原始值!L73+VLOOKUP($H73,怪物强度修正!$A$2:$R$17,COLUMN(S73)-9,FALSE) -> 0 | T73: =原始值!M73+VLOOKUP($H73,怪物强度修正!$A$2:$R$17,COLUMN(T73)-9,FALSE) -> 0 | U73: =原始值!N73+VLOOKUP($H73,怪物强度修正!$A$2:$R$17,COLUMN(U73)-9,FALSE) -> 11 | V73: 1 | W73: =原始值!P73+VLOOKUP($H73,怪物强度修正!$A$2:$R$17,COLUMN(W73)-9,FALSE) -> 12 | X73: =原始值!Q73+VLOOKUP($H73,怪物强度修正!$A$2:$R$17,COLUMN(X73)-9,FALSE) -> 1 | Y73: =原始值!R73+VLOOKUP($H73,怪物强度修正!$A$2:$R$17,COLUMN(Y73)-9,FALSE) -> 75 | Z73: =原始值!S73+VLOOKUP($H73,怪物强度修正!$A$2:$R$17,COLUMN(Z73)-9,FALSE) -> 300 | AA73: =原始值!T73+VLOOKUP($H73,怪物强度修正!$A$2:$R$17,COLUMN(AA73)-9,FALSE) -> 50
A74: ="PhyType.NewNpcType_"&D74 -> PhyType.NewNpcType_207 | B74: NPC_Pattern | C74: 207 | D74: 207 | G74: =G18&"微型" -> 残肢僵尸微型 | H74: =H18 -> 比奇矿区 | I74: =INT((I18+1)*0.6-1) -> 83 | K74: =原始值!D74+VLOOKUP($H74,怪物强度修正!$A$2:$R$17,COLUMN(K74)-9,FALSE) -> 4 | L74: =原始值!E74+VLOOKUP($H74,怪物强度修正!$A$2:$R$17,COLUMN(L74)-9,FALSE) -> 10 | M74: =K74 -> 4 | N74: =L74 -> 10 | O74: =原始值!H74+VLOOKUP($H74,怪物强度修正!$A$2:$R$17,COLUMN(O74)-9,FALSE) -> 0 | P74: =原始值!I74+VLOOKUP($H74,怪物强度修正!$A$2:$R$17,COLUMN(P74)-9,FALSE) -> 0 | Q74: =原始值!J74+VLOOKUP($H74,怪物强度修正!$A$2:$R$17,COLUMN(Q74)-9,FALSE) -> 2 | R74: =原始值!K74+VLOOKUP($H74,怪物强度修正!$A$2:$R$17,COLUMN(R74)-9,FALSE) -> 2 | S74: =原始值!L74+VLOOKUP($H74,怪物强度修正!$A$2:$R$17,COLUMN(S74)-9,FALSE) -> 1 | T74: =原始值!M74+VLOOKUP($H74,怪物强度修正!$A$2:$R$17,COLUMN(T74)-9,FALSE) -> 1 | U74: =原始值!N74+VLOOKUP($H74,怪物强度修正!$A$2:$R$17,COLUMN(U74)-9,FALSE) -> 109 | V74: 1 | W74: =原始值!P74+VLOOKUP($H74,怪物强度修正!$A$2:$R$17,COLUMN(W74)-9,FALSE) -> 12 | X74: =原始值!Q74+VLOOKUP($H74,怪物强度修正!$A$2:$R$17,COLUMN(X74)-9,FALSE) -> 15 | Y74: =原始值!R74+VLOOKUP($H74,怪物强度修正!$A$2:$R$17,COLUMN(Y74)-9,FALSE) -> 75 | Z74: =原始值!S74+VLOOKUP($H74,怪物强度修正!$A$2:$R$17,COLUMN(Z74)-9,FALSE) -> 300 | AA74: =原始值!T74+VLOOKUP($H74,怪物强度修正!$A$2:$R$17,COLUMN(AA74)-9,FALSE) -> 50
A75: ="PhyType.NewNpcType_"&D75 -> PhyType.NewNpcType_208 | B75: NPC_Pattern | C75: 208 | D75: 208 | G75: =G19&"微型" -> 直立僵尸微型 | H75: =H19 -> 比奇矿区 | I75: =INT((I19+1)*0.6-1) -> 89 | K75: =原始值!D75+VLOOKUP($H75,怪物强度修正!$A$2:$R$17,COLUMN(K75)-9,FALSE) -> 4 | L75: =原始值!E75+VLOOKUP($H75,怪物强度修正!$A$2:$R$17,COLUMN(L75)-9,FALSE) -> 12 | M75: =K75 -> 4 | N75: =L75 -> 12 | O75: =原始值!H75+VLOOKUP($H75,怪物强度修正!$A$2:$R$17,COLUMN(O75)-9,FALSE) -> 0 | P75: =原始值!I75+VLOOKUP($H75,怪物强度修正!$A$2:$R$17,COLUMN(P75)-9,FALSE) -> 0 | Q75: =原始值!J75+VLOOKUP($H75,怪物强度修正!$A$2:$R$17,COLUMN(Q75)-9,FALSE) -> 2 | R75: =原始值!K75+VLOOKUP($H75,怪物强度修正!$A$2:$R$17,COLUMN(R75)-9,FALSE) -> 2 | S75: =原始值!L75+VLOOKUP($H75,怪物强度修正!$A$2:$R$17,COLUMN(S75)-9,FALSE) -> 1 | T75: =原始值!M75+VLOOKUP($H75,怪物强度修正!$A$2:$R$17,COLUMN(T75)-9,FALSE) -> 1 | U75: =原始值!N75+VLOOKUP($H75,怪物强度修正!$A$2:$R$17,COLUMN(U75)-9,FALSE) -> 109 | V75: 1 | W75: =原始值!P75+VLOOKUP($H75,怪物强度修正!$A$2:$R$17,COLUMN(W75)-9,FALSE) -> 12 | X75: =原始值!Q75+VLOOKUP($H75,怪物强度修正!$A$2:$R$17,COLUMN(X75)-9,FALSE) -> 15 | Y75: =原始值!R75+VLOOKUP($H75,怪物强度修正!$A$2:$R$17,COLUMN(Y75)-9,FALSE) -> 75 | Z75: =原始值!S75+VLOOKUP($H75,怪物强度修正!$A$2:$R$17,COLUMN(Z75)-9,FALSE) -> 300 | AA75: =原始值!T75+VLOOKUP($H75,怪物强度修正!$A$2:$R$17,COLUMN(AA75)-9,FALSE) -> 50
... A119: ="PhyType.NewNpcType_"&D119 -> PhyType.NewNpcType_252 | B119: NPC_Pattern | C119: 252 | D119: 252 | G119: =G63&"微型" -> 暴牙蜘蛛微型 | H119: =H63 -> 赤月峡谷 | I119: =INT((I63+1)*0.6-1) -> 239 | K119: =原始值!D119+VLOOKUP($H119,怪物强度修正!$A$2:$R$17,COLUMN(K119)-9,FALSE) -> 23 | L119: =原始值!E119+VLOOKUP($H119,怪物强度修正!$A$2:$R$17,COLUMN(L119)-9,FALSE) -> 32 | M119: =K119 -> 23 | N119: =L119 -> 32 | O119: =原始值!H119+VLOOKUP($H119,怪物强度修正!$A$2:$R$17,COLUMN(O119)-9,FALSE) -> 0 | P119: =原始值!I119+VLOOKUP($H119,怪物强度修正!$A$2:$R$17,COLUMN(P119)-9,FALSE) -> 0 | Q119: =原始值!J119+VLOOKUP($H119,怪物强度修正!$A$2:$R$17,COLUMN(Q119)-9,FALSE) -> 13 | R119: =原始值!K119+VLOOKUP($H119,怪物强度修正!$A$2:$R$17,COLUMN(R119)-9,FALSE) -> 13 | S119: =原始值!L119+VLOOKUP($H119,怪物强度修正!$A$2:$R$17,COLUMN(S119)-9,FALSE) -> 32 | T119: =原始值!M119+VLOOKUP($H119,怪物强度修正!$A$2:$R$17,COLUMN(T119)-9,FALSE) -> 32 | U119: =原始值!N119+VLOOKUP($H119,怪物强度修正!$A$2:$R$17,COLUMN(U119)-9,FALSE) -> 350 | V119: 12 | W119: =原始值!P119+VLOOKUP($H119,怪物强度修正!$A$2:$R$17,COLUMN(W119)-9,FALSE) -> 17 | X119: =原始值!Q119+VLOOKUP($H119,怪物强度修正!$A$2:$R$17,COLUMN(X119)-9,FALSE) -> 17 | Y119: =原始值!R119+VLOOKUP($H119,怪物强度修正!$A$2:$R$17,COLUMN(Y119)-9,FALSE) -> 75 | Z119: =原始值!S119+VLOOKUP($H119,怪物强度修正!$A$2:$R$17,COLUMN(Z119)-9,FALSE) -> 300 | AA119: =原始值!T119+VLOOKUP($H119,怪物强度修正!$A$2:$R$17,COLUMN(AA119)-9,FALSE) -> 50
A120: ="PhyType.NewNpcType_"&D120 -> PhyType.NewNpcType_301 | B120: NPC_Pattern | C120: 301 | D120: 301 | G120: =G8&"头目" -> 稻草人头目 | H120: =H8 -> 边界村 | I120: =INT((I8+1)*1.7-1) -> 16 | K120: =原始值!D120+VLOOKUP($H120,怪物强度修正!$A$2:$R$17,COLUMN(K120)-9,FALSE) -> 1 | L120: =原始值!E120+VLOOKUP($H120,怪物强度修正!$A$2:$R$17,COLUMN(L120)-9,FALSE) -> 2 | M120: =K120 -> 1 | N120: =L120 -> 2 | O120: =原始值!H120+VLOOKUP($H120,怪物强度修正!$A$2:$R$17,COLUMN(O120)-9,FALSE) -> 0 | P120: =原始值!I120+VLOOKUP($H120,怪物强度修正!$A$2:$R$17,COLUMN(P120)-9,FALSE) -> 0 | Q120: =原始值!J120+VLOOKUP($H120,怪物强度修正!$A$2:$R$17,COLUMN(Q120)-9,FALSE) -> 0 | R120: =原始值!K120+VLOOKUP($H120,怪物强度修正!$A$2:$R$17,COLUMN(R120)-9,FALSE) -> 0 | S120: =原始值!L120+VLOOKUP($H120,怪物强度修正!$A$2:$R$17,COLUMN(S120)-9,FALSE) -> 0 | T120: =原始值!M120+VLOOKUP($H120,怪物强度修正!$A$2:$R$17,COLUMN(T120)-9,FALSE) -> 0 | U120: =原始值!N120+VLOOKUP($H120,怪物强度修正!$A$2:$R$17,COLUMN(U120)-9,FALSE) -> 24 | V120: 1 | W120: =原始值!P120+VLOOKUP($H120,怪物强度修正!$A$2:$R$17,COLUMN(W120)-9,FALSE) -> 5 | X120: =原始值!Q120+VLOOKUP($H120,怪物强度修正!$A$2:$R$17,COLUMN(X120)-9,FALSE) -> 7 | Y120: =原始值!R120+VLOOKUP($H120,怪物强度修正!$A$2:$R$17,COLUMN(Y120)-9,FALSE) -> 75 | Z120: =原始值!S120+VLOOKUP($H120,怪物强度修正!$A$2:$R$17,COLUMN(Z120)-9,FALSE) -> 300 | AA120: =原始值!T120+VLOOKUP($H120,怪物强度修正!$A$2:$R$17,COLUMN(AA120)-9,FALSE) -> 50
A121: ="PhyType.NewNpcType_"&D121 -> PhyType.NewNpcType_302 | B121: NPC_Pattern | C121: 302 | D121: 302 | G121: =G9&"头目" -> 钉耙猫头目 | H121: =H9 -> 边界村 | I121: =INT((I9+1)*1.7-1) -> 29 | K121: =原始值!D121+VLOOKUP($H121,怪物强度修正!$A$2:$R$17,COLUMN(K121)-9,FALSE) -> 2 | L121: =原始值!E121+VLOOKUP($H121,怪物强度修正!$A$2:$R$17,COLUMN(L121)-9,FALSE) -> 5 | M121: =K121 -> 2 | N121: =L121 -> 5 | O121: =原始值!H121+VLOOKUP($H121,怪物强度修正!$A$2:$R$17,COLUMN(O121)-9,FALSE) -> 0 | P121: =原始值!I121+VLOOKUP($H121,怪物强度修正!$A$2:$R$17,COLUMN(P121)-9,FALSE) -> 0 | Q121: =原始值!J121+VLOOKUP($H121,怪物强度修正!$A$2:$R$17,COLUMN(Q121)-9,FALSE) -> 0 | R121: =原始值!K121+VLOOKUP($H121,怪物强度修正!$A$2:$R$17,COLUMN(R121)-9,FALSE) -> 0 | S121: =原始值!L121+VLOOKUP($H121,怪物强度修正!$A$2:$R$17,COLUMN(S121)-9,FALSE) -> 0 | T121: =原始值!M121+VLOOKUP($H121,怪物强度修正!$A$2:$R$17,COLUMN(T121)-9,FALSE) -> 0 | U121: =原始值!N121+VLOOKUP($H121,怪物强度修正!$A$2:$R$17,COLUMN(U121)-9,FALSE) -> 37 | V121: 1 | W121: =原始值!P121+VLOOKUP($H121,怪物强度修正!$A$2:$R$17,COLUMN(W121)-9,FALSE) -> 5 | X121: =原始值!Q121+VLOOKUP($H121,怪物强度修正!$A$2:$R$17,COLUMN(X121)-9,FALSE) -> 7 | Y121: =原始值!R121+VLOOKUP($H121,怪物强度修正!$A$2:$R$17,COLUMN(Y121)-9,FALSE) -> 75 | Z121: =原始值!S121+VLOOKUP($H121,怪物强度修正!$A$2:$R$17,COLUMN(Z121)-9,FALSE) -> 300 | AA121: =原始值!T121+VLOOKUP($H121,怪物强度修正!$A$2:$R$17,COLUMN(AA121)-9,FALSE) -> 50
A122: ="PhyType.NewNpcType_"&D122 -> PhyType.NewNpcType_303 | B122: NPC_Pattern | C122: 303 | D122: 303 | G122: =G10&"头目" -> 半兽人头目 | H122: =H10 -> 边界村 | I122: =INT((I10+1)*1.7-1) -> 41 | K122: =原始值!D122+VLOOKUP($H122,怪物强度修正!$A$2:$R$17,COLUMN(K122)-9,FALSE) -> 4 | L122: =原始值!E122+VLOOKUP($H122,怪物强度修正!$A$2:$R$17,COLUMN(L122)-9,FALSE) -> 8 | M122: =K122 -> 4 | N122: =L122 -> 8 | O122: =原始值!H122+VLOOKUP($H122,怪物强度修正!$A$2:$R$17,COLUMN(O122)-9,FALSE) -> 0 | P122: =原始值!I122+VLOOKUP($H122,怪物强度修正!$A$2:$R$17,COLUMN(P122)-9,FALSE) -> 0 | Q122: =原始值!J122+VLOOKUP($H122,怪物强度修正!$A$2:$R$17,COLUMN(Q122)-9,FALSE) -> 1 | R122: =原始值!K122+VLOOKUP($H122,怪物强度修正!$A$2:$R$17,COLUMN(R122)-9,FALSE) -> 1 | S122: =原始值!L122+VLOOKUP($H122,怪物强度修正!$A$2:$R$17,COLUMN(S122)-9,FALSE) -> 0 | T122: =原始值!M122+VLOOKUP($H122,怪物强度修正!$A$2:$R$17,COLUMN(T122)-9,FALSE) -> 0 | U122: =原始值!N122+VLOOKUP($H122,怪物强度修正!$A$2:$R$17,COLUMN(U122)-9,FALSE) -> 48 | V122: 1 | W122: =原始值!P122+VLOOKUP($H122,怪物强度修正!$A$2:$R$17,COLUMN(W122)-9,FALSE) -> 6 | X122: =原始值!Q122+VLOOKUP($H122,怪物强度修正!$A$2:$R$17,COLUMN(X122)-9,FALSE) -> 8 | Y122: =原始值!R122+VLOOKUP($H122,怪物强度修正!$A$2:$R$17,COLUMN(Y122)-9,FALSE) -> 75 | Z122: =原始值!S122+VLOOKUP($H122,怪物强度修正!$A$2:$R$17,COLUMN(Z122)-9,FALSE) -> 300 | AA122: =原始值!T122+VLOOKUP($H122,怪物强度修正!$A$2:$R$17,COLUMN(AA122)-9,FALSE) -> 50
A123: ="PhyType.NewNpcType_"&D123 -> PhyType.NewNpcType_304 | B123: NPC_Pattern | C123: 304 | D123: 304 | G123: =G11&"头目" -> 半兽人战士头目 | H123: =H11 -> 比奇省 | I123: =INT((I11+1)*1.7-1) -> 152 | K123: =原始值!D123+VLOOKUP($H123,怪物强度修正!$A$2:$R$17,COLUMN(K123)-9,FALSE) -> 6 | L123: =原始值!E123+VLOOKUP($H123,怪物强度修正!$A$2:$R$17,COLUMN(L123)-9,FALSE) -> 14 | M123: =K123 -> 6 | N123: =L123 -> 14 | O123: =原始值!H123+VLOOKUP($H123,怪物强度修正!$A$2:$R$17,COLUMN(O123)-9,FALSE) -> 0 | P123: =原始值!I123+VLOOKUP($H123,怪物强度修正!$A$2:$R$17,COLUMN(P123)-9,FALSE) -> 0 | Q123: =原始值!J123+VLOOKUP($H123,怪物强度修正!$A$2:$R$17,COLUMN(Q123)-9,FALSE) -> 3 | R123: =原始值!K123+VLOOKUP($H123,怪物强度修正!$A$2:$R$17,COLUMN(R123)-9,FALSE) -> 3 | S123: =原始值!L123+VLOOKUP($H123,怪物强度修正!$A$2:$R$17,COLUMN(S123)-9,FALSE) -> 1 | T123: =原始值!M123+VLOOKUP($H123,怪物强度修正!$A$2:$R$17,COLUMN(T123)-9,FALSE) -> 1 | U123: =原始值!N123+VLOOKUP($H123,怪物强度修正!$A$2:$R$17,COLUMN(U123)-9,FALSE) -> 160 | V123: 1 | W123: =原始值!P123+VLOOKUP($H123,怪物强度修正!$A$2:$R$17,COLUMN(W123)-9,FALSE) -> 10 | X123: =原始值!Q123+VLOOKUP($H123,怪物强度修正!$A$2:$R$17,COLUMN(X123)-9,FALSE) -> 13 | Y123: =原始值!R123+VLOOKUP($H123,怪物强度修正!$A$2:$R$17,COLUMN(Y123)-9,FALSE) -> 75 | Z123: =原始值!S123+VLOOKUP($H123,怪物强度修正!$A$2:$R$17,COLUMN(Z123)-9,FALSE) -> 300 | AA123: =原始值!T123+VLOOKUP($H123,怪物强度修正!$A$2:$R$17,COLUMN(AA123)-9,FALSE) -> 50
A124: ="PhyType.NewNpcType_"&D124 -> PhyType.NewNpcType_3041 | B124: NPC_Pattern | C124: 3041 | D124: 3041 | G124: =G12&"头目" -> 半兽人战士_BJC头目 | H124: =H12 -> 边界村 | I124: =INT((I12+1)*1.7-1) -> 55 | K124: =原始值!D124+VLOOKUP($H124,怪物强度修正!$A$2:$R$17,COLUMN(K124)-9,FALSE) -> 5 | L124: =原始值!E124+VLOOKUP($H124,怪物强度修正!$A$2:$R$17,COLUMN(L124)-9,FALSE) -> 11 | M124: =K124 -> 5 | N124: =L124 -> 11 | O124: =原始值!H124+VLOOKUP($H124,怪物强度修正!$A$2:$R$17,COLUMN(O124)-9,FALSE) -> 0 | P124: =原始值!I124+VLOOKUP($H124,怪物强度修正!$A$2:$R$17,COLUMN(P124)-9,FALSE) -> 0 | Q124: =原始值!J124+VLOOKUP($H124,怪物强度修正!$A$2:$R$17,COLUMN(Q124)-9,FALSE) -> 1 | R124: =原始值!K124+VLOOKUP($H124,怪物强度修正!$A$2:$R$17,COLUMN(R124)-9,FALSE) -> 1 | S124: =原始值!L124+VLOOKUP($H124,怪物强度修正!$A$2:$R$17,COLUMN(S124)-9,FALSE) -> 0 | T124: =原始值!M124+VLOOKUP($H124,怪物强度修正!$A$2:$R$17,COLUMN(T124)-9,FALSE) -> 0 | U124: =原始值!N124+VLOOKUP($H124,怪物强度修正!$A$2:$R$17,COLUMN(U124)-9,FALSE) -> 56 | V124: 1 | W124: =原始值!P124+VLOOKUP($H124,怪物强度修正!$A$2:$R$17,COLUMN(W124)-9,FALSE) -> 10 | X124: =原始值!Q124+VLOOKUP($H124,怪物强度修正!$A$2:$R$17,COLUMN(X124)-9,FALSE) -> 9 | Y124: =原始值!R124+VLOOKUP($H124,怪物强度修正!$A$2:$R$17,COLUMN(Y124)-9,FALSE) -> 75 | Z124: =原始值!S124+VLOOKUP($H124,怪物强度修正!$A$2:$R$17,COLUMN(Z124)-9,FALSE) -> 300 | AA124: =原始值!T124+VLOOKUP($H124,怪物强度修正!$A$2:$R$17,COLUMN(AA124)-9,FALSE) -> 50
A125: ="PhyType.NewNpcType_"&D125 -> PhyType.NewNpcType_3042 | B125: NPC_Pattern | C125: 3042 | D125: 3042 | G125: =G13&"头目" -> 半兽人战士_BQS头目 | H125: =H13 -> 比奇省 | I125: =INT((I13+1)*1.7-1) -> 67 | K125: =原始值!D125+VLOOKUP($H125,怪物强度修正!$A$2:$R$17,COLUMN(K125)-9,FALSE) -> 6 | L125: =原始值!E125+VLOOKUP($H125,怪物强度修正!$A$2:$R$17,COLUMN(L125)-9,FALSE) -> 13 | M125: =K125 -> 6 | N125: =L125 -> 13 | O125: =原始值!H125+VLOOKUP($H125,怪物强度修正!$A$2:$R$17,COLUMN(O125)-9,FALSE) -> 0 | P125: =原始值!I125+VLOOKUP($H125,怪物强度修正!$A$2:$R$17,COLUMN(P125)-9,FALSE) -> 0 | Q125: =原始值!J125+VLOOKUP($H125,怪物强度修正!$A$2:$R$17,COLUMN(Q125)-9,FALSE) -> 1 | R125: =原始值!K125+VLOOKUP($H125,怪物强度修正!$A$2:$R$17,COLUMN(R125)-9,FALSE) -> 1 | S125: =原始值!L125+VLOOKUP($H125,怪物强度修正!$A$2:$R$17,COLUMN(S125)-9,FALSE) -> 0 | T125: =原始值!M125+VLOOKUP($H125,怪物强度修正!$A$2:$R$17,COLUMN(T125)-9,FALSE) -> 0 | U125: =原始值!N125+VLOOKUP($H125,怪物强度修正!$A$2:$R$17,COLUMN(U125)-9,FALSE) -> 72 | V125: 1 | W125: =原始值!P125+VLOOKUP($H125,怪物强度修正!$A$2:$R$17,COLUMN(W125)-9,FALSE) -> 10 | X125: =原始值!Q125+VLOOKUP($H125,怪物强度修正!$A$2:$R$17,COLUMN(X125)-9,FALSE) -> 10 | Y125: =原始值!R125+VLOOKUP($H125,怪物强度修正!$A$2:$R$17,COLUMN(Y125)-9,FALSE) -> 75 | Z125: =原始值!S125+VLOOKUP($H125,怪物强度修正!$A$2:$R$17,COLUMN(Z125)-9,FALSE) -> 300 | AA125: =原始值!T125+VLOOKUP($H125,怪物强度修正!$A$2:$R$17,COLUMN(AA125)-9,FALSE) -> 50
A126: ="PhyType.NewNpcType_"&D126 -> PhyType.NewNpcType_305 | B126: NPC_Pattern | C126: 305 | D126: 305 | G126: =G14&"头目" -> 半兽人勇士头目 | H126: =H14 -> 比奇省 | I126: =INT((I14+1)*1.7-1) -> 509 | K126: =原始值!D126+VLOOKUP($H126,怪物强度修正!$A$2:$R$17,COLUMN(K126)-9,FALSE) -> 18 | L126: =原始值!E126+VLOOKUP($H126,怪物强度修正!$A$2:$R$17,COLUMN(L126)-9,FALSE) -> 38 | M126: =K126 -> 18 | N126: =L126 -> 38 | O126: =原始值!H126+VLOOKUP($H126,怪物强度修正!$A$2:$R$17,COLUMN(O126)-9,FALSE) -> 0 | P126: =原始值!I126+VLOOKUP($H126,怪物强度修正!$A$2:$R$17,COLUMN(P126)-9,FALSE) -> 0 | Q126: =原始值!J126+VLOOKUP($H126,怪物强度修正!$A$2:$R$17,COLUMN(Q126)-9,FALSE) -> 0 | R126: =原始值!K126+VLOOKUP($H126,怪物强度修正!$A$2:$R$17,COLUMN(R126)-9,FALSE) -> 0 | S126: =原始值!L126+VLOOKUP($H126,怪物强度修正!$A$2:$R$17,COLUMN(S126)-9,FALSE) -> 0 | T126: =原始值!M126+VLOOKUP($H126,怪物强度修正!$A$2:$R$17,COLUMN(T126)-9,FALSE) -> 0 | U126: =原始值!N126+VLOOKUP($H126,怪物强度修正!$A$2:$R$17,COLUMN(U126)-9,FALSE) -> 480 | V126: 1 | W126: =原始值!P126+VLOOKUP($H126,怪物强度修正!$A$2:$R$17,COLUMN(W126)-9,FALSE) -> 13 | X126: =原始值!Q126+VLOOKUP($H126,怪物强度修正!$A$2:$R$17,COLUMN(X126)-9,FALSE) -> 13 | Y126: =原始值!R126+VLOOKUP($H126,怪物强度修正!$A$2:$R$17,COLUMN(Y126)-9,FALSE) -> 75 | Z126: =原始值!S126+VLOOKUP($H126,怪物强度修正!$A$2:$R$17,COLUMN(Z126)-9,FALSE) -> 300 | AA126: =原始值!T126+VLOOKUP($H126,怪物强度修正!$A$2:$R$17,COLUMN(AA126)-9,FALSE) -> 50
...

Sheet 怪物强度修正
B1: catPhyAtk | C1: catMaxPhyAtk | D1: catMagAtk | E1: catMaxMagAtk | F1: catTaoAtk | G1: catMaxTaoAtk | H1: catPhyDef | I1: catMaxPhyDef | J1: catMagDef | K1: catMaxMagDef | L1: catMaxHp | M1: catMaxMp | N1: catAccurate | O1: catAgility | P1: catHpRecovery | Q1: catHpRecoveryTap | R1: catTapIncrease
A2: 边界村 | B2: 0 | C2: 0 | D2: 0 | E2: 0 | F2: 0 | G2: 0 | H2: 0 | I2: 0 | J2: 0 | K2: 0 | L2: 0 | M2: 0 | N2: 0 | O2: -3 | P2: 0 | Q2: 0 | R2: 0
A3: 比奇省 | B3: 0 | C3: 0 | D3: 0 | E3: 0 | F3: 0 | G3: 0 | H3: 0 | I3: 0 | J3: 0 | K3: 0 | L3: 0 | M3: 0 | N3: 0 | O3: -2 | P3: 0 | Q3: 0 | R3: 0
A4: 沃玛森林 | B4: 0 | C4: 0 | D4: 0 | E4: 0 | F4: 0 | G4: 0 | H4: 0 | I4: 0 | J4: 0 | K4: 0 | L4: 0 | M4: 0 | N4: 0 | O4: -1 | P4: 0 | Q4: 0 | R4: 0
A5: 盟重 | B5: 0 | C5: 0 | D5: 0 | E5: 0 | F5: 0 | G5: 0 | H5: 0 | I5: 0 | J5: 0 | K5: 0 | L5: 0 | M5: 0 | N5: 0 | O5: 0 | P5: 0 | Q5: 0 | R5: 0
A6: 比奇矿区 | B6: 0 | C6: 0 | D6: 0 | E6: 0 | F6: 0 | G6: 0 | H6: 0 | I6: 0 | J6: 0 | K6: 0 | L6: 0 | M6: 0 | N6: 0 | O6: 0 | P6: 0 | Q6: 0 | R6: 0
A7: 沃玛寺庙 | B7: -2 | C7: -2 | D7: 0 | E7: 0 | F7: 0 | G7: 0 | H7: 0 | I7: 0 | J7: 0 | K7: 0 | L7: 0 | M7: 0 | N7: 0 | O7: 0 | P7: 0 | Q7: 0 | R7: 0
A8: 死亡峡谷 | B8: 3 | C8: 3 | D8: 0 | E8: 0 | F8: 0 | G8: 0 | H8: 1 | I8: 1 | J8: 2 | K8: 2 | L8: 0 | M8: 0 | N8: 0 | O8: 0 | P8: 0 | Q8: 0 | R8: 0
A9: 石墓 | B9: 3 | C9: 3 | D9: 0 | E9: 0 | F9: 0 | G9: 0 | H9: 1 | I9: 1 | J9: 2 | K9: 2 | L9: 0 | M9: 0 | N9: 0 | O9: 0 | P9: 0 | Q9: 0 | R9: 0
A10: 祖玛寺庙 | B10: 4 | C10: 4 | D10: 0 | E10: 0 | F10: 0 | G10: 0 | H10: 1 | I10: 1 | J10: 2 | K10: 2 | L10: 0 | M10: 0 | N10: 0 | O10: 0 | P10: 0 | Q10: 0 | R10: 0
A11: 虹魔教坛 | B11: 0 | C11: 0 | D11: 0 | E11: 0 | F11: 0 | G11: 0 | H11: 0 | I11: 0 | J11: 0 | K11: 0 | L11: 0 | M11: 0 | N11: 0 | O11: 0 | P11: 0 | Q11: 0 | R11: 0
A12: 赤月峡谷 | B12: 5 | C12: 5 | D12: 0 | E12: 0 | F12: 0 | G12: 0 | H12: 1 | I12: 1 | J12: 2 | K12: 2 | L12: 0 | M12: 0 | N12: 0 | O12: 0 | P12: 0 | Q12: 0 | R12: 0

Sheet 原始值
A1: TemplateID | B1: Description | C1: Map | D1: catPhyAtk | E1: catMaxPhyAtk | F1: catMagAtk | G1: catMaxMagAtk | H1: catTaoAtk | I1: catMaxTaoAtk | J1: catPhyDef | K1: catMaxPhyDef | L1: catMagDef | M1: catMaxMagDef | N1: catMaxHp | O1: catMaxMp | P1: catAccurate | Q1: catAgility | R1: catHpRecovery | S1: catHpRecoveryTap | T1: catTapIncrease
A2: Both | B2: Both | C2: Both | D2: Both | E2: Both | F2: Both | G2: Both | H2: Both | I2: Both | J2: Both | K2: Both | L2: Both | M2: Both | N2: Both | O2: Both | P2: Both | Q2: Both | R2: Both | S2: Both | T2: Both
B3: 默认数据行 | C3: 所在地图 | D3: 0 | E3: 0 | F3: 0 | G3: 0 | H3: 0 | I3: 0 | J3: 0 | K3: 0 | L3: 0 | M3: 0 | N3: 0 | O3: 0 | P3: 0 | Q3: 0 | R3: 0 | S3: 0 | T3: 0
A4: 11 | B4: 标准物理型
A5: 1 | B5: 战士模板
A6: 100 | B6: 标准NPC | D6: 0 | E6: 0 | F6: 0 | G6: 0 | H6: 0 | I6: 0 | J6: 0 | K6: 0 | L6: 0 | M6: 0 | N6: 9999 | O6: 0 | P6: 5 | Q6: 5 | R6: 75 | S6: 300 | T6: 50
A7: 6 | B7: 物件模板 | D7: 2 | E7: 4 | F7: 1 | G7: 1 | H7: 1 | I7: 1 | J7: 1 | K7: 1 | L7: 1 | M7: 1 | N7: 50 | O7: 0 | P7: 5 | Q7: 10 | R7: 75 | S7: 300 | T7: 50
A8: 101 | B8: 稻草人 | C8: 边界村 | D8: =1 -> 1 | E8: 2 | F8: 0 | G8: 0 | H8: 0 | I8: 0 | J8: 0 | K8: 0 | L8: 0 | M8: 0 | N8: 15 | O8: 0 | P8: 5 | Q8: 10 | R8: 75 | S8: 300 | T8: 50
A9: 102 | B9: 钉耙猫 | C9: 边界村 | D9: 2 | E9: 4 | F9: 0 | G9: 0 | H9: 0 | I9: 0 | J9: 0 | K9: 0 | L9: 0 | M9: 0 | N9: 23 | O9: 0 | P9: 5 | Q9: 10 | R9: 75 | S9: 300 | T9: 50
A10: 103 | B10: 半兽人_BJC | C10: 边界村 | D10: 3 | E10: 7 | F10: 0 | G10: 0 | H10: 0 | I10: 0 | J10: 1 | K10: 1 | L10: 0 | M10: 0 | N10: 30 | O10: 0 | P10: 6 | Q10: 11 | R10: 75 | S10: 300 | T10: 50
A11: 104 | B11: 半兽人战士 | C11: 比奇省 | D11: 5 | E11: 12 | F11: 0 | G11: 0 | H11: 0 | I11: 0 | J11: 3 | K11: 3 | L11: 1 | M11: 1 | N11: 100 | O11: 0 | P11: 10 | Q11: 15 | R11: 75 | S11: 300 | T11: 50
A12: 1041 | B12: 半兽人战士_BJC | C12: 边界村 | D12: 4 | E12: 9 | F12: 0 | G12: 0 | H12: 0 | I12: 0 | J12: 1 | K12: 1 | L12: 0 | M12: 0 | N12: 35 | O12: 0 | P12: 10 | Q12: 12 | R12: 75 | S12: 300 | T12: 50
A13: 1042 | B13: 半兽人战士_BQS | C13: 比奇省 | D13: 5 | E13: 11 | F13: 0 | G13: 0 | H13: 0 | I13: 0 | J13: 1 | K13: 1 | L13: 0 | M13: 0 | N13: 45 | O13: 0 | P13: 10 | Q13: 12 | R13: 75 | S13: 300 | T13: 50
A14: 105 | B14: 半兽人勇士 | C14: 比奇省 | D14: 15 | E14: 32 | F14: 0 | G14: 0 | H14: 0 | I14: 0 | J14: 0 | K14: 0 | L14: 0 | M14: 0 | N14: 300 | O14: 0 | P14: 13 | Q14: 15 | R14: 75 | S14: 300 | T14: 50
A15: 1051 | B15: 半兽人勇士_BJC | C15: 边界村 | D15: 6 | E15: 13 | F15: 0 | G15: 0 | H15: 0 | I15: 0 | J15: 2 | K15: 2 | L15: 1 | M15: 1 | N15: 65 | O15: 0 | P15: 13 | Q15: 13 | R15: 75 | S15: 300 | T15: 50
A16: 1052 | B16: 半兽人勇士_BQS | C16: 比奇省 | D16: 6 | E16: 13 | F16: 0 | G16: 0 | H16: 0 | I16: 0 | J16: 2 | K16: 2 | L16: 1 | M16: 1 | N16: 65 | O16: 0 | P16: 13 | Q16: 13 | R16: 75 | S16: 300 | T16: 50
A17: 106 | B17: 鹿 | C17: 边界村 | D17: 2 | E17: 4 | F17: 0 | G17: 0 | H17: 0 | I17: 0 | J17: 0 | K17: 0 | L17: 0 | M17: 0 | N17: 15 | O17: 0 | P17: 12 | Q17: 4 | R17: 75 | S17: 300 | T17: 50
A18: 107 | B18: 残肢僵尸 | C18: 比奇矿区 | D18: 5 | E18: 12 | F18: 0 | G18: 0 | H18: 0 | I18: 0 | J18: 2 | K18: 2 | L18: 1 | M18: 1 | N18: 155 | O18: 0 | P18: 12 | Q18: 15 | R18: 75 | S18: 300 | T18: 50
A19: 108 | B19: 直立僵尸 | C19: 比奇矿区 | D19: 5 | E19: 15 | F19: 0 | G19: 0 | H19: 0 | I19: 0 | J19: 2 | K19: 2 | L19: 1 | M19: 1 | N19: 155 | O19: 0 | P19: 12 | Q19: 15 | R19: 75 | S19: 300 | T19: 50
A20: 109 | B20: 和尚僵尸 | C20: 比奇矿区 | D20: 8 | E20: 15 | F20: 0 | G20: 0 | H20: 0 | I20: 0 | J20: 2 | K20: 2 | L20: 1 | M20: 1 | N20: 155 | O20: 0 | P20: 12 | Q20: 15 | R20: 75 | S20: 300 | T20: 50
... A63: 152 | B63: 暴牙蜘蛛 | C63: 赤月峡谷 | D63: 22 | E63: 34 | F63: 0 | G63: 0 | H63: 0 | I63: 0 | J63: 12 | K63: 12 | L63: 30 | M63: 30 | N63: 500 | O63: 0 | P63: 17 | Q63: 17 | R63: 75 | S63: 300 | T63: 50
A64: 201 | B64: =B8&"微型" -> 稻草人微型 | C64: =C8 -> 边界村 | D64: =ROUND(D8*0.8,0) -> 1 | E64: =ROUND(E8*0.8,0) -> 2 | F64: =ROUND(F8*0.8,0) -> 0 | G64: =ROUND(G8*0.8,0) -> 0 | H64: =ROUND(H8*0.8,0) -> 0 | I64: =ROUND(I8*0.8,0) -> 0 | J64: =J8 -> 0 | K64: =K8 -> 0 | L64: =L8 -> 0 | M64: =M8 -> 0 | N64: =ROUND(N8*0.7,0) -> 11 | O64: =ROUND(O8*0.8,0) -> 0 | P64: =P8 -> 5 | Q64: =Q8 -> 10 | R64: =R8 -> 75 | S64: =S8 -> 300 | T64: =T8 -> 50
A65: 202 | B65: =B9&"微型" -> 钉耙猫微型 | C65: =C9 -> 边界村 | D65: =ROUND(D9*0.8,0) -> 2 | E65: =ROUND(E9*0.8,0) -> 3 | F65: =ROUND(F9*0.8,0) -> 0 | G65: =ROUND(G9*0.8,0) -> 0 | H65: =ROUND(H9*0.8,0) -> 0 | I65: =ROUND(I9*0.8,0) -> 0 | J65: =J9 -> 0 | K65: =K9 -> 0 | L65: =L9 -> 0 | M65: =M9 -> 0 | N65: =ROUND(N9*0.7,0) -> 16 | O65: =ROUND(O9*0.8,0) -> 0 | P65: =P9 -> 5 | Q65: =Q9 -> 10 | R65: =R9 -> 75 | S65: =S9 -> 300 | T65: =T9 -> 50
A66: 203 | B66: =B10&"微型" -> 半兽人_BJC微型 | C66: =C10 -> 边界村 | D66: =ROUND(D10*0.8,0) -> 2 | E66: =ROUND(E10*0.8,0) -> 6 | F66: =ROUND(F10*0.8,0) -> 0 | G66: =ROUND(G10*0.8,0) -> 0 | H66: =ROUND(H10*0.8,0) -> 0 | I66: =ROUND(I10*0.8,0) -> 0 | J66: =J10 -> 1 | K66: =K10 -> 1 | L66: =L10 -> 0 | M66: =M10 -> 0 | N66: =ROUND(N10*0.7,0) -> 21 | O66: =ROUND(O10*0.8,0) -> 0 | P66: =P10 -> 6 | Q66: =Q10 -> 11 | R66: =R10 -> 75 | S66: =S10 -> 300 | T66: =T10 -> 50
A67: 204 | B67: =B11&"微型" -> 半兽人战士微型 | C67: =C11 -> 比奇省 | D67: =ROUND(D11*0.8,0) -> 4 | E67: =ROUND(E11*0.8,0) -> 10 | F67: =ROUND(F11*0.8,0) -> 0 | G67: =ROUND(G11*0.8,0) -> 0 | H67: =ROUND(H11*0.8,0) -> 0 | I67: =ROUND(I11*0.8,0) -> 0 | J67: =J11 -> 3 | K67: =K11 -> 3 | L67: =L11 -> 1 | M67: =M11 -> 1 | N67: =ROUND(N11*0.7,0) -> 70 | O67: =ROUND(O11*0.8,0) -> 0 | P67: =P11 -> 10 | Q67: =Q11 -> 15 | R67: =R11 -> 75 | S67: =S11 -> 300 | T67: =T11 -> 50
A68: 2041 | B68: =B12&"微型" -> 半兽人战士_BJC微型 | C68: =C12 -> 边界村 | D68: =ROUND(D12*0.8,0) -> 3 | E68: =ROUND(E12*0.8,0) -> 7 | F68: =ROUND(F12*0.8,0) -> 0 | G68: =ROUND(G12*0.8,0) -> 0 | H68: =ROUND(H12*0.8,0) -> 0 | I68: =ROUND(I12*0.8,0) -> 0 | J68: =J12 -> 1 | K68: =K12 -> 1 | L68: =L12 -> 0 | M68: =M12 -> 0 | N68: =ROUND(N12*0.7,0) -> 25 | O68: =ROUND(O12*0.8,0) -> 0 | P68: =P12 -> 10 | Q68: =Q12 -> 12 | R68: =R12 -> 75 | S68: =S12 -> 300 | T68: =T12 -> 50
A69: 2042 | B69: =B13&"微型" -> 半兽人战士_BQS微型 | C69: =C13 -> 比奇省 | D69: =ROUND(D13*0.8,0) -> 4 | E69: =ROUND(E13*0.8,0) -> 9 | F69: =ROUND(F13*0.8,0) -> 0 | G69: =ROUND(G13*0.8,0) -> 0 | H69: =ROUND(H13*0.8,0) -> 0 | I69: =ROUND(I13*0.8,0) -> 0 | J69: =J13 -> 1 | K69: =K13 -> 1 | L69: =L13 -> 0 | M69: =M13 -> 0 | N69: =ROUND(N13*0.7,0) -> 32 | O69: =ROUND(O13*0.8,0) -> 0 | P69: =P13 -> 10 | Q69: =Q13 -> 12 | R69: =R13 -> 75 | S69: =S13 -> 300 | T69: =T13 -> 50
A70: 205 | B70: =B14&"微型" -> 半兽人勇士微型 | C70: =C14 -> 比奇省 | D70: =ROUND(D14*0.8,0) -> 12 | E70: =ROUND(E14*0.8,0) -> 26 | F70: =ROUND(F14*0.8,0) -> 0 | G70: =ROUND(G14*0.8,0) -> 0 | H70: =ROUND(H14*0.8,0) -> 0 | I70: =ROUND(I14*0.8,0) -> 0 | J70: =J14 -> 0 | K70: =K14 -> 0 | L70: =L14 -> 0 | M70: =M14 -> 0 | N70: =ROUND(N14*0.7,0) -> 210 | O70: =ROUND(O14*0.8,0) -> 0 | P70: =P14 -> 13 | Q70: =Q14 -> 15 | R70: =R14 -> 75 | S70: =S14 -> 300 | T70: =T14 -> 50
A71: 2051 | B71: =B15&"微型" -> 半兽人勇士_BJC微型 | C71: =C15 -> 边界村 | D71: =ROUND(D15*0.8,0) -> 5 | E71: =ROUND(E15*0.8,0) -> 10 | F71: =ROUND(F15*0.8,0) -> 0 | G71: =ROUND(G15*0.8,0) -> 0 | H71: =ROUND(H15*0.8,0) -> 0 | I71: =ROUND(I15*0.8,0) -> 0 | J71: =J15 -> 2 | K71: =K15 -> 2 | L71: =L15 -> 1 | M71: =M15 -> 1 | N71: =ROUND(N15*0.7,0) -> 46 | O71: =ROUND(O15*0.8,0) -> 0 | P71: =P15 -> 13 | Q71: =Q15 -> 13 | R71: =R15 -> 75 | S71: =S15 -> 300 | T71: =T15 -> 50
A72: 2052 | B72: =B16&"微型" -> 半兽人勇士_BQS微型 | C72: =C16 -> 比奇省 | D72: =ROUND(D16*0.8,0) -> 5 | E72: =ROUND(E16*0.8,0) -> 10 | F72: =ROUND(F16*0.8,0) -> 0 | G72: =ROUND(G16*0.8,0) -> 0 | H72: =ROUND(H16*0.8,0) -> 0 | I72: =ROUND(I16*0.8,0) -> 0 | J72: =J16 -> 2 | K72: =K16 -> 2 | L72: =L16 -> 1 | M72: =M16 -> 1 | N72: =ROUND(N16*0.7,0) -> 46 | O72: =ROUND(O16*0.8,0) -> 0 | P72: =P16 -> 13 | Q72: =Q16 -> 13 | R72: =R16 -> 75 | S72: =S16 -> 300 | T72: =T16 -> 50
A73: 206 | B73: =B17&"微型" -> 鹿微型 | C73: =C17 -> 边界村 | D73: =ROUND(D17*0.8,0) -> 2 | E73: =ROUND(E17*0.8,0) -> 3 | F73: =ROUND(F17*0.8,0) -> 0 | G73: =ROUND(G17*0.8,0) -> 0 | H73: =ROUND(H17*0.8,0) -> 0 | I73: =ROUND(I17*0.8,0) -> 0 | J73: =J17 -> 0 | K73: =K17 -> 0 | L73: =L17 -> 0 | M73: =M17 -> 0 | N73: =ROUND(N17*0.7,0) -> 11 | O73: =ROUND(O17*0.8,0) -> 0 | P73: =P17 -> 12 | Q73: =Q17 -> 4 | R73: =R17 -> 75 | S73: =S17 -> 300 | T73: =T17 -> 50
A74: 207 | B74: =B18&"微型" -> 残肢僵尸微型 | C74: =C18 -> 比奇矿区 | D74: =ROUND(D18*0.8,0) -> 4 | E74: =ROUND(E18*0.8,0) -> 10 | F74: =ROUND(F18*0.8,0) -> 0 | G74: =ROUND(G18*0.8,0) -> 0 | H74: =ROUND(H18*0.8,0) -> 0 | I74: =ROUND(I18*0.8,0) -> 0 | J74: =J18 -> 2 | K74: =K18 -> 2 | L74: =L18 -> 1 | M74: =M18 -> 1 | N74: =ROUND(N18*0.7,0) -> 109 | O74: =ROUND(O18*0.8,0) -> 0 | P74: =P18 -> 12 | Q74: =Q18 -> 15 | R74: =R18 -> 75 | S74: =S18 -> 300 | T74: =T18 -> 50
A75: 208 | B75: =B19&"微型" -> 直立僵尸微型 | C75: =C19 -> 比奇矿区 | D75: =ROUND(D19*0.8,0) -> 4 | E75: =ROUND(E19*0.8,0) -> 12 | F75: =ROUND(F19*0.8,0) -> 0 | G75: =ROUND(G19*0.8,0) -> 0 | H75: =ROUND(H19*0.8,0) -> 0 | I75: =ROUND(I19*0.8,0) -> 0 | J75: =J19 -> 2 | K75: =K19 -> 2 | L75: =L19 -> 1 | M75: =M19 -> 1 | N75: =ROUND(N19*0.7,0) -> 109 | O75: =ROUND(O19*0.8,0) -> 0 | P75: =P19 -> 12 | Q75: =Q19 -> 15 | R75: =R19 -> 75 | S75: =S19 -> 300 | T75: =T19 -> 50
... A87: 219 | B87: =B31&"微型" -> 多角虫微型 | C87: =C31 -> 盟重 | D87: =ROUND(D31*0.8,0) -> 6 | E87: =ROUND(E31*0.8,0) -> 6 | F87: =ROUND(F31*0.8,0) -> 0 | G87: =ROUND(G31*0.8,0) -> 0 | H87: =ROUND(H31*0.8,0) -> 0 | I87: =ROUND(I31*0.8,0) -> 0 | J87: =J31 -> 0 | K87: =K31 -> 0 | L87: =L31 -> 0 | M87: =M31 -> 0 | N87: =ROUND(N31*0.7,0) -> 36 | O87: =ROUND(O31*0.8,0) -> 0 | P87: =P31 -> 10 | Q87: =Q31 -> 13 | R87: =R31 -> 75 | S87: =S31 -> 300 | T87: =T31 -> 50
A88: 220 | B88: =B32&"微型" -> 蜈蚣微型 | C88: =C32 -> 死亡峡谷 | D88: =ROUND(D32*0.8,0) -> 10 | E88: =ROUND(E32*0.8,0) -> 14 | F88: =ROUND(F32*0.8,0) -> 0 | G88: =ROUND(G32*0.8,0) -> 0 | H88: =ROUND(H32*0.8,0) -> 0 | I88: =ROUND(I32*0.8,0) -> 0 | J88: =J32 -> 0 | K88: =K32 -> 0 | L88: =L32 -> 5 | M88: =M32 -> 5 | N88: =ROUND(N32*0.7,-1) -> 160 | O88: =ROUND(O32*0.8,0) -> 0 | P88: =P32 -> 13 | Q88: =Q32 -> 15 | R88: =R32 -> 75 | S88: =S32 -> 300 | T88: =T32 -> 50
A89: 221 | B89: =B33&"微型" -> 巨型蠕虫微型 | C89: =C33 -> 死亡峡谷 | D89: =ROUND(D33*0.8,0) -> 12 | E89: =ROUND(E33*0.8,0) -> 14 | F89: =ROUND(F33*0.8,0) -> 0 | G89: =ROUND(G33*0.8,0) -> 0 | H89: =ROUND(H33*0.8,0) -> 0 | I89: =ROUND(I33*0.8,0) -> 0 | J89: =J33 -> 3 | K89: =K33 -> 3 | L89: =L33 -> 3 | M89: =M33 -> 3 | N89: =ROUND(N33*0.7,-1) -> 140 | O89: =ROUND(O33*0.8,0) -> 0 | P89: =P33 -> 13 | Q89: =Q33 -> 15 | R89: =R33 -> 75 | S89: =S33 -> 300 | T89: =T33 -> 50
A90: 222 | B90: =B34&"微型" -> 钳虫微型 | C90: =C34 -> 死亡峡谷 | D90: =ROUND(D34*0.8,0) -> 12 | E90: =ROUND(E34*0.8,0) -> 20 | F90: =ROUND(F34*0.8,0) -> 0 | G90: =ROUND(G34*0.8,0) -> 0 | H90: =ROUND(H34*0.8,0) -> 0 | I90: =ROUND(I34*0.8,0) -> 0 | J90: =J34 -> 5 | K90: =K34 -> 5 | L90: =L34 -> 7 | M90: =M34 -> 7 | N90: =ROUND(N34*0.7,-1) -> 190 | O90: =ROUND(O34*0.8,0) -> 0 | P90: =P34 -> 13 | Q90: =Q34 -> 15 | R90: =R34 -> 75 | S90: =S34 -> 300 | T90: =T34 -> 50
A91: 223 | B91: =B35&"微型" -> 跳跳蜂微型 | C91: =C35 -> 死亡峡谷 | D91: =ROUND(D35*0.8,0) -> 10 | E91: =ROUND(E35*0.8,0) -> 14 | F91: =ROUND(F35*0.8,0) -> 0 | G91: =ROUND(G35*0.8,0) -> 0 | H91: =ROUND(H35*0.8,0) -> 0 | I91: =ROUND(I35*0.8,0) -> 0 | J91: =J35 -> 3 | K91: =K35 -> 3 | L91: =L35 -> 3 | M91: =M35 -> 3 | N91: =ROUND(N35*0.7,-1) -> 140 | O91: =ROUND(O35*0.8,0) -> 0 | P91: =P35 -> 13 | Q91: =Q35 -> 15 | R91: =R35 -> 75 | S91: =S35 -> 300 | T91: =T35 -> 50
A92: 224 | B92: =B36&"微型" -> 恶蛆微型 | C92: =C36 -> 石墓 | D92: =ROUND(D36*0.8,0) -> 8 | E92: =ROUND(E36*0.8,0) -> 12 | F92: =ROUND(F36*0.8,0) -> 0 | G92: =ROUND(G36*0.8,0) -> 0 | H92: =ROUND(H36*0.8,0) -> 0 | I92: =ROUND(I36*0.8,0) -> 0 | J92: =J36 -> 5 | K92: =K36 -> 5 | L92: =L36 -> 0 | M92: =M36 -> 0 | N92: =ROUND(N36*0.7,-1) -> 160 | O92: =ROUND(O36*0.8,0) -> 0 | P92: =P36 -> 13 | Q92: =Q36 -> 15 | R92: =R36 -> 75 | S92: =S36 -> 300 | T92: =T36 -> 50
A93: 225 | B93: =B37&"微型" -> 红野猪微型 | C93: =C37 -> 石墓 | D93: =ROUND(D37*0.8,0) -> 14 | E93: =ROUND(E37*0.8,0) -> 20 | F93: =ROUND(F37*0.8,0) -> 0 | G93: =ROUND(G37*0.8,0) -> 0 | H93: =ROUND(H37*0.8,0) -> 0 | I93: =ROUND(I37*0.8,0) -> 0 | J93: =J37 -> 0 | K93: =K37 -> 0 | L93: =L37 -> 8 | M93: =M37 -> 8 | N93: =ROUND(N37*0.7,-1) -> 230 | O93: =ROUND(O37*0.8,0) -> 0 | P93: =P37 -> 13 | Q93: =Q37 -> 15 | R93: =R37 -> 75 | S93: =S37 -> 300 | T93: =T37 -> 50
...

Sheet Sheet1
B1: 10 | C1: =B1-1 -> 9
B2: 18 | C2: =B2-1 -> 17
B3: 25 | C3: =B3-1 -> 24
B4: 90 | C4: =B4-1 -> 89
B5: 33 | C5: =B5-1 -> 32
B6: 40 | C6: =B6-1 -> 39
B7: 300 | C7: =B7-1 -> 299
B8: 60 | C8: =B8-1 -> 59
B9: 60 | C9: =B9-1 -> 59
B10: 15 | C10: =B10-1 -> 14
B11: 140 | C11: =B11-1 -> 139
B12: 150 | C12: =B12-1 -> 149 | J12: 30 | K12: 55 | M12: 45 | N12: 75
B13: 160 | C13: =B13-1 -> 159 | J13: 25 | K13: 35 | M13: =CEILING((J13*1.2),5) -> 30 | N13: =CEILING((K13*1.2),5) -> 45
B14: 170 | C14: =B14-1 -> 169 | J14: 35 | K14: 55 | M14: =CEILING((J14*1.2),5) -> 45 | N14: =CEILING((K14*1.2),5) -> 70
B15: 25 | C15: =B15-1 -> 24 | J15: 30 | K15: 45 | M15: =CEILING((J15*1.2),5) -> 40 | N15: =CEILING((K15*1.2),5) -> 55
B16: 200 | C16: =B16-1 -> 199 | J16: 25 | K16: 35 | M16: =CEILING((J16*1.2),5) -> 30 | N16: =CEILING((K16*1.2),5) -> 45
B17: 260 | C17: =B17-1 -> 259 | J17: 35 | K17: 50 | M17: =CEILING((J17*1.2),5) -> 45 | N17: =CEILING((K17*1.2),5) -> 60
B18: 280 | C18: =B18-1 -> 279 | J18: 25 | K18: 35 | M18: =CEILING((J18*1.2),5) -> 30 | N18: =CEILING((K18*1.2),5) -> 45
B19: 280 | C19: =B19-1 -> 279 | J19: 10 | K19: 65 | M19: =CEILING((J19*1.2),5) -> 15 | N19: =CEILING((K19*1.2),5) -> 80
B20: 290 | C20: =B20-1 -> 289 | J20: 20 | K20: 30 | M20: =CEILING((J20*1.2),5) -> 25 | N20: =CEILING((K20*1.2),5) -> 40
B21: 37 | C21: =B21-1 -> 36 | J21: 40 | K21: 55 | M21: =CEILING((J21*1.2),5) -> 50 | N21: =CEILING((K21*1.2),5) -> 70
B22: 35 | C22: =B22-1 -> 34 | J22: 30 | K22: 35 | M22: =CEILING((J22*1.2),5) -> 40 | N22: =CEILING((K22*1.2),5) -> 45
B23: 32 | C23: =B23-1 -> 31 | J23: 40 | K23: 60 | M23: =CEILING((J23*1.2),5) -> 50 | N23: =CEILING((K23*1.2),5) -> 75
B24: 230 | C24: =B24-1 -> 229 | J24: 10 | K24: 20 | M24: =CEILING((J24*1.2),5) -> 15 | N24: =CEILING((K24*1.2),5) -> 25
... B29: 320 | C29: =B29-1 -> 319 | J29: 50 | K29: 100 | M29: =CEILING((J29*1.2),5) -> 60 | N29: =CEILING((K29*1.2),5) -> 120
B30: 380 | C30: =B30-1 -> 379
B31: 1600 | C31: =B31-1 -> 1599
B32: 2000 | C32: =B32-1 -> 1999
B33: 2500 | C33: =B33-1 -> 2499
B34: 75 | C34: =B34-1 -> 74
B35: 75 | C35: =B35-1 -> 74
B36: 37 | C36: =B36-1 -> 36
B37: 37 | C37: =B37-1 -> 36
B38: 350 | C38: =B38-1 -> 349
B39: 370 | C39: =B39-1 -> 369
B40: 450 | C40: =B40-1 -> 449
B41: 480 | C41: =B41-1 -> 479
... B172: 130 | C172: =B172-1 -> 129
B184: 800
B186: 2500
...
