Workbook

Sheet Sheet2
A1: ShopID | B1: Index | C1: ShopName | D1: ItemID | E1: ItemName | F1: ItemCount | G1: CostItemID1 | H1: CostValue1 | I1: CostItemID2 | J1: CostValue2 | K1: RequireForceID | L1: Reputation | M1: RequireGuildBuildingID | N1: BuildingLevel | O1: MoneyType | P1: ShopTypeSell
A2: Server | B2: Server | C2: Server | D2: Server | E2: Server | F2: Server | G2: Server | H2: Server | I2: Server | J2: Server | K2: Server | L2: Server | M2: Server | N2: Server | O2: Server | P2: Server
A3: 0 | B3: 0 | D3: 0 | E3: 0 | F3: 0 | G3: -1 | H3: 0 | I3: -1 | J3: 0 | K3: -1 | L3: 0 | M3: 0 | N3: 0 | O3: -1 | P3: 0
A4: 1 | B4: 1 | C4: 随身商店 | D4: 301 | E4: =VLOOKUP(D4,装备道具ID!$A$1:$B$1221,2,FALSE) -> 金创药(小量) | F4: 1 | G4: MONEYTYPE_02 | H4: 80 | O4: -1 | P4: 1
A5: 1 | B5: 2 | C5: 随身商店 | D5: 302 | E5: =VLOOKUP(D5,装备道具ID!$A$1:$B$1221,2,FALSE) -> 金创药(中量) | F5: 1 | G5: MONEYTYPE_02 | H5: 260 | O5: -1 | P5: 1
A6: 4 | B6: 1 | C6: 药剂商店 | D6: 301 | E6: =VLOOKUP(D6,装备道具ID!$A$1:$B$1221,2,FALSE) -> 金创药(小量) | F6: 1 | G6: MONEYTYPE_02 | H6: 80 | O6: -1 | P6: 1
A7: 4 | B7: 2 | C7: 药剂商店 | D7: 302 | E7: =VLOOKUP(D7,装备道具ID!$A$1:$B$1221,2,FALSE) -> 金创药(中量) | F7: 1 | G7: MONEYTYPE_02 | H7: 260 | O7: -1 | P7: 1
A8: 4 | B8: 3 | C8: 药剂商店 | D8: 303 | E8: =VLOOKUP(D8,装备道具ID!$A$1:$B$1221,2,FALSE) -> 强效金创药 | F8: 1 | G8: MONEYTYPE_02 | H8: 700 | O8: -1 | P8: 1
A9: 4 | B9: 4 | C9: 药剂商店 | D9: 321 | E9: =VLOOKUP(D9,装备道具ID!$A$1:$B$1221,2,FALSE) -> 魔法药(小量) | F9: 1 | G9: MONEYTYPE_02 | H9: 80 | O9: -1 | P9: 1
A10: 4 | B10: 5 | C10: 药剂商店 | D10: 322 | E10: =VLOOKUP(D10,装备道具ID!$A$1:$B$1221,2,FALSE) -> 魔法药(中量) | F10: 1 | G10: MONEYTYPE_02 | H10: 260 | O10: -1 | P10: 1
A11: 4 | B11: 6 | C11: 药剂商店 | D11: 323 | E11: =VLOOKUP(D11,装备道具ID!$A$1:$B$1221,2,FALSE) -> 强效魔法药 | F11: 1 | G11: MONEYTYPE_02 | H11: 700 | O11: -1 | P11: 1
A12: 4 | B12: 7 | C12: 药剂商店 | D12: 351 | E12: =VLOOKUP(D12,装备道具ID!$A$1:$B$1221,2,FALSE) -> 太阳水 | F12: 1 | G12: MONEYTYPE_02 | H12: 1000 | O12: -1 | P12: 1
A13: 4 | B13: 8 | C13: 药剂商店 | D13: 352 | E13: =VLOOKUP(D13,装备道具ID!$A$1:$B$1221,2,FALSE) -> 强效太阳水 | F13: 1 | G13: MONEYTYPE_02 | H13: 2500 | O13: -1 | P13: 1
A14: 4 | B14: 9 | C14: 药剂商店 | D14: 361 | E14: =VLOOKUP(D14,装备道具ID!$A$1:$B$1221,2,FALSE) -> 金创药(小)包 | F14: 1 | G14: MONEYTYPE_02 | H14: =H6*8 -> 640 | O14: -1 | P14: 1
A15: 4 | B15: 10 | C15: 药剂商店 | D15: 362 | E15: =VLOOKUP(D15,装备道具ID!$A$1:$B$1221,2,FALSE) -> 金创药(中)包 | F15: 1 | G15: MONEYTYPE_02 | H15: =H7*8 -> 2080 | O15: -1 | P15: 1
A16: 4 | B16: 11 | C16: 药剂商店 | D16: 363 | E16: =VLOOKUP(D16,装备道具ID!$A$1:$B$1221,2,FALSE) -> 超级金创药 | F16: 1 | G16: MONEYTYPE_02 | H16: =H8*8+400 -> 6000 | O16: -1 | P16: 1
A17: 4 | B17: 12 | C17: 药剂商店 | D17: 371 | E17: =VLOOKUP(D17,装备道具ID!$A$1:$B$1221,2,FALSE) -> 魔法药(小)包 | F17: 1 | G17: MONEYTYPE_02 | H17: =H9*8 -> 640 | O17: -1 | P17: 1
A18: 4 | B18: 13 | C18: 药剂商店 | D18: 372 | E18: =VLOOKUP(D18,装备道具ID!$A$1:$B$1221,2,FALSE) -> 魔法药(中)包 | F18: 1 | G18: MONEYTYPE_02 | H18: =H10*8 -> 2080 | O18: -1 | P18: 1
A19: 4 | B19: 14 | C19: 药剂商店 | D19: 373 | E19: =VLOOKUP(D19,装备道具ID!$A$1:$B$1221,2,FALSE) -> 超级魔法药 | F19: 1 | G19: MONEYTYPE_02 | H19: =H11*8+400 -> 6000 | O19: -1 | P19: 1
A20: 4 | B20: 15 | C20: 药剂商店 | D20: 381 | E20: =VLOOKUP(D20,装备道具ID!$A$1:$B$1221,2,FALSE) -> 太阳水包 | F20: 1 | G20: MONEYTYPE_02 | H20: 7000 | O20: -1 | P20: 1
A21: 4 | B21: 16 | C21: 药剂商店 | D21: 382 | E21: =VLOOKUP(D21,装备道具ID!$A$1:$B$1221,2,FALSE) -> 强效太阳水包 | F21: 1 | G21: MONEYTYPE_02 | H21: 17000 | O21: -1 | P21: 1
A22: 4 | B22: 17 | C22: 药剂商店 | D22: 40001 | E22: =VLOOKUP(D22,装备道具ID!$A$1:$B$1221,2,FALSE) -> 灰色药粉(少量) | F22: 1 | G22: MONEYTYPE_02 | H22: 5000 | O22: -1 | P22: 1
A23: 4 | B23: 18 | C23: 药剂商店 | D23: 40002 | E23: =VLOOKUP(D23,装备道具ID!$A$1:$B$1221,2,FALSE) -> 灰色药粉(中量) | F23: 1 | G23: MONEYTYPE_02 | H23: 11000 | O23: -1 | P23: 1
A24: 4 | B24: 19 | C24: 药剂商店 | D24: 40003 | E24: =VLOOKUP(D24,装备道具ID!$A$1:$B$1221,2,FALSE) -> 灰色药粉(大量) | F24: 1 | G24: MONEYTYPE_02 | H24: 18000 | O24: -1 | P24: 1
A25: 4 | B25: 20 | C25: 药剂商店 | D25: 40011 | E25: =VLOOKUP(D25,装备道具ID!$A$1:$B$1221,2,FALSE) -> 黄色药粉(少量) | F25: 1 | G25: MONEYTYPE_02 | H25: 5000 | O25: -1 | P25: 1
A26: 4 | B26: 21 | C26: 药剂商店 | D26: 40012 | E26: =VLOOKUP(D26,装备道具ID!$A$1:$B$1221,2,FALSE) -> 黄色药粉(中量) | F26: 1 | G26: MONEYTYPE_02 | H26: 11000 | O26: -1 | P26: 1
A27: 4 | B27: 22 | C27: 药剂商店 | D27: 40013 | E27: =VLOOKUP(D27,装备道具ID!$A$1:$B$1221,2,FALSE) -> 黄色药粉(大量) | F27: 1 | G27: MONEYTYPE_02 | H27: 18000 | O27: -1 | P27: 1
A28: 34 | B28: 1 | C28: 野外药剂商店 | D28: 301 | E28: =VLOOKUP(D28,装备道具ID!$A$1:$B$1221,2,FALSE) -> 金创药(小量) | F28: 1 | G28: MONEYTYPE_02 | H28: =H6*1.5 -> 120 | O28: -1 | P28: 1
A29: 34 | B29: 2 | C29: 野外药剂商店 | D29: 302 | E29: =VLOOKUP(D29,装备道具ID!$A$1:$B$1221,2,FALSE) -> 金创药(中量) | F29: 1 | G29: MONEYTYPE_02 | H29: =H7*1.5 -> 390 | O29: -1 | P29: 1
A30: 34 | B30: 3 | C30: 野外药剂商店 | D30: 303 | E30: =VLOOKUP(D30,装备道具ID!$A$1:$B$1221,2,FALSE) -> 强效金创药 | F30: 1 | G30: MONEYTYPE_02 | H30: =H8*1.5 -> 1050 | O30: -1 | P30: 1
A31: 34 | B31: 4 | C31: 野外药剂商店 | D31: 321 | E31: =VLOOKUP(D31,装备道具ID!$A$1:$B$1221,2,FALSE) -> 魔法药(小量) | F31: 1 | G31: MONEYTYPE_02 | H31: =H9*1.5 -> 120 | O31: -1 | P31: 1
A32: 34 | B32: 5 | C32: 野外药剂商店 | D32: 322 | E32: =VLOOKUP(D32,装备道具ID!$A$1:$B$1221,2,FALSE) -> 魔法药(中量) | F32: 1 | G32: MONEYTYPE_02 | H32: =H10*1.5 -> 390 | O32: -1 | P32: 1
A33: 34 | B33: 6 | C33: 野外药剂商店 | D33: 323 | E33: =VLOOKUP(D33,装备道具ID!$A$1:$B$1221,2,FALSE) -> 强效魔法药 | F33: 1 | G33: MONEYTYPE_02 | H33: =H11*1.5 -> 1050 | O33: -1 | P33: 1
A34: 34 | B34: 7 | C34: 野外药剂商店 | D34: 351 | E34: =VLOOKUP(D34,装备道具ID!$A$1:$B$1221,2,FALSE) -> 太阳水 | F34: 1 | G34: MONEYTYPE_02 | H34: =H12*1.5 -> 1500 | O34: -1 | P34: 1
A35: 34 | B35: 8 | C35: 野外药剂商店 | D35: 352 | E35: =VLOOKUP(D35,装备道具ID!$A$1:$B$1221,2,FALSE) -> 强效太阳水 | F35: 1 | G35: MONEYTYPE_02 | H35: =H13*1.5 -> 3750 | O35: -1 | P35: 1
A36: 34 | B36: 9 | C36: 野外药剂商店 | D36: 361 | E36: =VLOOKUP(D36,装备道具ID!$A$1:$B$1221,2,FALSE) -> 金创药(小)包 | F36: 1 | G36: MONEYTYPE_02 | H36: =H14*1.5 -> 960 | O36: -1 | P36: 1
A37: 34 | B37: 10 | C37: 野外药剂商店 | D37: 362 | E37: =VLOOKUP(D37,装备道具ID!$A$1:$B$1221,2,FALSE) -> 金创药(中)包 | F37: 1 | G37: MONEYTYPE_02 | H37: =H15*1.5 -> 3120 | O37: -1 | P37: 1
A38: 34 | B38: 11 | C38: 野外药剂商店 | D38: 363 | E38: =VLOOKUP(D38,装备道具ID!$A$1:$B$1221,2,FALSE) -> 超级金创药 | F38: 1 | G38: MONEYTYPE_02 | H38: =H16*1.5 -> 9000 | O38: -1 | P38: 1
A39: 34 | B39: 12 | C39: 野外药剂商店 | D39: 371 | E39: =VLOOKUP(D39,装备道具ID!$A$1:$B$1221,2,FALSE) -> 魔法药(小)包 | F39: 1 | G39: MONEYTYPE_02 | H39: =H17*1.5 -> 960 | O39: -1 | P39: 1
... A49: 34 | B49: 22 | C49: 野外药剂商店 | D49: 40013 | E49: =VLOOKUP(D49,装备道具ID!$A$1:$B$1221,2,FALSE) -> 黄色药粉(大量) | F49: 1 | G49: MONEYTYPE_02 | H49: =H27*1.5 -> 27000 | O49: -1 | P49: 1
...

Sheet define
A1: 字段 | B1: 描述 | C1: 说明
A2: ShopID | B2: 商店id
A3: ShopName | B3: 商店名
A4: ItemID | B4: 道具id
A5: ItemCount | B5: 道具数量
A6: CostItemID1 | B6: 货币1 | C6: MONEYTYPE_01 | D6: 绑金
C7: MONEYTYPE_02 | D7: 金币
C8: MONEYTYPE_MORAL | D8: 道义值
C9: MONEYTYPE_ARENA | D9: 竞技场点数
C10: MONEYTYPE_BF | D10: 战场点数
A11: CostValue1 | B11: 货币数量
A12: CostItemID2 | B12: 货币2
A13: CostValue2 | B13: 货币数量
A14: RequireForceID | B14: 需求声望类型
A15: Reputation | B15: 消耗声望数量
A16: RequireGuildBuildingID | B16: 需求建筑编号 | C16: 公会
A17: BuildingLevel | B17: 需求建筑等级 | C17: 公会

Sheet Sheet3
A1: 1101 | B1: 防具商店（1级） | C1: 99980113 | D1: 1 | E1: MONEYTYPE_02 | F1: 3000
A2: 1101 | B2: 防具商店（1级） | C2: 99980114 | D2: 1 | E2: MONEYTYPE_02 | F2: 3000
A3: 1101 | B3: 防具商店（1级） | C3: 99990123 | D3: 1 | E3: MONEYTYPE_02 | F3: 3000
A4: 1101 | B4: 防具商店（1级） | C4: 99990124 | D4: 1 | E4: MONEYTYPE_02 | F4: 3000
A5: 1101 | B5: 防具商店（1级） | C5: 99990133 | D5: 1 | E5: MONEYTYPE_02 | F5: 3000
A6: 1101 | B6: 防具商店（1级） | C6: 99990134 | D6: 1 | E6: MONEYTYPE_02 | F6: 3000
A7: 1101 | B7: 防具商店（1级） | C7: 99980111 | D7: 1 | E7: MONEYTYPE_02 | F7: 1000 | H7: 第一套头
A8: 1101 | B8: 防具商店（1级） | C8: 99990121 | D8: 1 | E8: MONEYTYPE_02 | F8: 1000 | H8: 第一套头
A9: 1101 | B9: 防具商店（1级） | C9: 99990131 | D9: 1 | E9: MONEYTYPE_02 | F9: 1000 | H9: 道士第一套（女） | I9: 99990131 | J9: 3182 | K9: 纶巾6
A10: 1101 | B10: 防具商店（1级） | C10: 99980213 | D10: 1 | E10: MONEYTYPE_02 | F10: 6000 | H10: 战士第二套（男） | I10: 99980213 | J10: 3194 | K10: 轻型盔甲
A11: 1101 | B11: 防具商店（1级） | C11: 99980214 | D11: 1 | E11: MONEYTYPE_02 | F11: 6000 | H11: 战士第二套（男） | I11: 99980214 | J11: 4068 | K11: 熟铜护腿
A12: 1101 | B12: 防具商店（1级） | C12: 99980211 | D12: 1 | E12: MONEYTYPE_02 | F12: 4000 | H12: 战士第二套（男） | I12: 99980211 | J12: 3182 | K12: 皮质头盔
A13: 1101 | B13: 防具商店（1级） | C13: 99990223 | D13: 1 | E13: MONEYTYPE_02 | F13: 6000 | H13: 法师第二套（女） | I13: 99990223 | J13: 3158 | K13: 虹霞衣6
A14: 1101 | B14: 防具商店（1级） | C14: 99990224 | D14: 1 | E14: MONEYTYPE_02 | F14: 6000 | H14: 法师第二套（女） | I14: 99990224 | J14: 4068 | K14: 赤纹护腿6
A15: 1101 | B15: 防具商店（1级） | C15: 99990221 | D15: 1 | E15: MONEYTYPE_02 | F15: 4000 | H15: 法师第二套（女） | I15: 99990221 | J15: 3182 | K15: 魔法头盔6
A16: 1101 | B16: 防具商店（1级） | C16: 99990233 | D16: 1 | E16: MONEYTYPE_02 | F16: 6000 | H16: 道士第二套（女） | I16: 99990233 | J16: 4046 | K16: 雪灵道袍6
A17: 1101 | B17: 防具商店（1级） | C17: 99990234 | D17: 1 | E17: MONEYTYPE_02 | F17: 6000 | H17: 道士第二套（女） | I17: 99990234 | J17: 4068 | K17: 秘色裹腿6
A18: 1101 | B18: 防具商店（1级） | C18: 99990231 | D18: 1 | E18: MONEYTYPE_02 | F18: 4000 | H18: 道士第二套（女） | I18: 99990231 | J18: 3182 | K18: 尖角冠6
A19: 1101 | B19: 防具商店（1级） | C19: 99980313 | D19: 1 | E19: MONEYTYPE_02 | F19: 12000 | H19: 战士第三套（男） | I19: 99980313 | J19: 3195 | K19: 中型盔甲 | L19: 12000
A20: 1101 | B20: 防具商店（1级） | C20: 99980314 | D20: 1 | E20: MONEYTYPE_02 | F20: 12000 | H20: 战士第三套（男） | I20: 99980314 | J20: 4069 | K20: 铜甲护腿 | L20: 12000
A21: 1101 | B21: 防具商店（1级） | C21: 99980311 | D21: 1 | E21: MONEYTYPE_02 | F21: 10000 | H21: 战士第三套（男） | I21: 99980311 | J21: 3182 | K21: 骷髅头盔 | L21: 10000
A22: 1101 | B22: 防具商店（1级） | C22: 99990323 | D22: 1 | E22: MONEYTYPE_02 | F22: 12000 | H22: 法师第三套（女） | I22: 99990323 | J22: 3159 | K22: 绢丝法衣6
A23: 1101 | B23: 防具商店（1级） | C23: 99990324 | D23: 1 | E23: MONEYTYPE_02 | F23: 12000 | H23: 法师第三套（女） | I23: 99990324 | J23: 4075 | K23: 匠制护腿6
A24: 1101 | B24: 防具商店（1级） | C24: 99990321 | D24: 1 | E24: MONEYTYPE_02 | F24: 10000 | H24: 法师第三套（女） | I24: 99990321 | J24: 3182 | K24: 轻巧法冠6
A25: 1101 | B25: 防具商店（1级） | C25: 99990333 | D25: 1 | E25: MONEYTYPE_02 | F25: 12000 | H25: 道士第三套（女） | I25: 99990333 | J25: 4047 | K25: 青灵道袍6
A26: 1101 | B26: 防具商店（1级） | C26: 99990334 | D26: 1 | E26: MONEYTYPE_02 | F26: 12000 | H26: 道士第三套（女） | I26: 99990334 | J26: 4069 | K26: 暗纹护腿6
A27: 1101 | B27: 防具商店（1级） | C27: 99990331 | D27: 1 | E27: MONEYTYPE_02 | F27: 10000 | H27: 道士第三套（女） | I27: 99990331 | J27: 3182 | K27: 浩然头冠6

Sheet 装备道具ID
A1: 0 | B1: 绑金
A2: 1 | B2: 金币
A3: 10 | B3: 经验
A4: 301 | B4: 金创药(小量)
A5: 302 | B5: 金创药(中量)
A6: 303 | B6: 强效金创药
A7: 304 | B7: 超强金创药（占位）
A8: 305 | B8: 金创药（占位）
A9: 311 | B9: 小金创药(绑定)
A10: 312 | B10: 中金创药(绑定)
A11: 321 | B11: 魔法药(小量)
A12: 322 | B12: 魔法药(中量)
... A1178: 99990737 | B1178: 光芒道靴
